#VRML_SIM R2019a utf8
WorldInfo {
  info [
    "Example use of a Radar device."
  ]
}
Viewpoint {
  orientation -0.5272366550257311 0.6901337990525248 0.49571851791375254 1.8752113125043701
  position 40.08247715560596 96.76959453745982 0.19538810525006056
}
TexturedBackground {
}
TexturedBackgroundLight {
}
Floor {
  size 60 60
  tileSize 1 1
  appearance ThreadMetalPlate {
  }
}
DEF TREE Solid {
  translation 28.89193898219605 1.1839395514004166e-12 -15.224773678242421
  rotation 0 1 0 0.785398
  scale 1.7 1.7 1.7
  name "solid(13)"
}
DEF TREE Solid {
  translation 29.38328245186393 1.1057798504668056e-12 -27.371647210801477
  rotation 0 1 0 0.785398
  scale 1.7 1.7 1.7
  children [
    PottedTree {
    }
  ]
  name "solid(12)"
}
DEF TREE Solid {
  translation 29.2498480865009 1.1839395514004166e-12 -25.240366381720218
  rotation 0 1 0 0.785398
  scale 1.7 1.7 1.7
  children [
    PottedTree {
    }
  ]
  name "solid(9)"
}
DEF TREE Solid {
  translation 24.489622479827506 1.1555178419700126e-12 -29.27081452695333
  rotation 0 1 0 0.785398
  scale 1.7 1.7 1.7
  children [
    PottedTree {
    }
  ]
  name "solid(10)"
}
DEF TREE Solid {
  translation 29.315237398904305 1.1839395514004166e-12 -29.164363932616208
  rotation 0 1 0 0.785398
  scale 1.7 1.7 1.7
  children [
    PottedTree {
    }
  ]
  name "solid(11)"
}
DEF TREE Solid {
  translation 22.726601057852463 8.926170297387755e-13 -29.30529719051825
  rotation 0 1 0 0.785398
  scale 1.7 1.7 1.7
  children [
    PottedTree {
    }
  ]
  name "solid(3)"
}
DEF TREE Solid {
  translation 17.22571045899442 1.1981504061156186e-12 -29.46482327637598
  rotation 0 1 0 0.785398
  scale 1.7 1.7 1.7
  children [
    PottedTree {
    }
  ]
  name "solid(4)"
}
DEF TREE Solid {
  translation 15.348261977327612 1.1768341240428156e-12 -29.552400328544955
  rotation 0 1 0 0.785398
  scale 1.7 1.7 1.7
  children [
    PottedTree {
    }
  ]
  name "solid(6)"
}
DEF TREE Solid {
  translation 25.969017688696457 1.1839395514004166e-12 -29.349104315484997
  rotation 0 -0.9999999999999999 0 5.497787326359172
  scale 1.7 1.7 1.7
  children [
    PottedTree {
    }
  ]
  name "solid(7)"
}
DEF TREE Solid {
  translation 13.799800932581542 1.1839395514004166e-12 -29.451850495661464
  rotation 0 1 0 0.785398
  scale 1.7 1.7 1.7
  children [
    PottedTree {
    }
  ]
  name "solid(8)"
}
DEF TREE Solid {
  translation 27.62553588846127 1.1697286966852146e-12 -29.39846814582073
  rotation 0 1 0 0.785398
  scale 1.7 1.7 1.7
  children [
    PottedTree {
    }
  ]
  name "solid(2)"
}
DEF TREE Solid {
  translation 19.113304939263735 1.0667e-12 -29.4519526116953
  rotation 0 1 0 0.785398
  scale 1.7 1.7 1.7
  children [
    PottedTree {
    }
    PottedTree {
      name "potted tree(1)"
    }
    PottedTree {
      name "potted tree(2)"
    }
    PottedTree {
      name "potted tree(3)"
    }
    PottedTree {
      name "potted tree(4)"
    }
  ]
  name "solid(1)"
}
DEF TREE Solid {
  translation 20.970201339910542 1.102227136788005e-12 -29.434055941198316
  rotation 0 1 0 0.785398
  scale 1.7 1.7 1.7
  children [
    PottedTree {
    }
  ]
  name "solid(5)"
}
DEF OFFICES Transform {
  rotation 0 1 0 3.14159
  children [
    Panel {
      translation 28.4604 0 -24.5373
      name "panel(35)"
    }
    Panel {
      translation 28.4604 0 -17.2973
      name "panel(36)"
    }
    Panel {
      translation 28.4604 0 -10.2573
      name "panel(37)"
    }
    Panel {
      translation 27.0304 0 -24.5573
      name "panel(38)"
    }
    Panel {
      translation 27.0304 0 -17.2873
      name "panel(39)"
    }
    Panel {
      translation 27.0304 0 -10.2573
      name "panel(40)"
    }
    Panel {
      translation 27.0774 0 -10.6551
      rotation 0 1 0 1.5708
      name "panel(41)"
    }
    Panel {
      translation 27.0774 0 -15.6551
      rotation 0 1 0 1.5708
      name "panel(42)"
    }
    Panel {
      translation 27.0774 0 -17.7651
      rotation 0 1 0 1.5708
      name "panel(43)"
    }
    Panel {
      translation 27.0774 0 -22.8751
      rotation 0 1 0 1.5708
      name "panel(44)"
    }
    Panel {
      translation 27.0774 0 -24.9451
      rotation 0 1 0 1.5708
      name "panel(45)"
    }
    Panel {
      translation 24.2974 0 -10.6551
      rotation 0 1 0 1.5708
      name "panel(46)"
    }
    Panel {
      translation 24.2974 0 -15.6951
      rotation 0 1 0 1.5708
      name "panel(47)"
    }
    Panel {
      translation 24.2974 0 -17.8051
      rotation 0 1 0 1.5708
      name "panel(48)"
    }
    Panel {
      translation 24.2974 0 -22.8551
      rotation 0 1 0 1.5708
      name "panel(49)"
    }
    Panel {
      translation 24.2974 0 -25.0151
      rotation 0 1 0 1.5708
      name "panel(50)"
    }
    Panel {
      translation 21.2474 0 -10.6551
      rotation 0 1 0 1.5708
      name "panel(51)"
    }
    Panel {
      translation 21.2474 0 -15.6951
      rotation 0 1 0 1.5708
      name "panel(52)"
    }
    Panel {
      translation 21.2474 0 -17.7551
      rotation 0 1 0 1.5708
      name "panel(53)"
    }
    Panel {
      translation 21.2474 0 -22.8651
      rotation 0 1 0 1.5708
      name "panel(54)"
    }
    Panel {
      translation 21.27941328705038 -3.552713678800501e-15 -19.54699077672662
      rotation 0 1 0 1.5708
      name "panel(72)"
    }
    Panel {
      translation 21.331013210072776 0 -21.225957180431337
      rotation 0 1 0 1.5708
      name "panel(73)"
    }
    Panel {
      translation 21.242538389055508 -1.4566126083082054e-13 -12.525967859818088
      rotation 0 1 0 1.5708
      name "panel(23)"
    }
    Panel {
      translation 21.243462812112455 -8.881784197001252e-14 -14.137965874591316
      rotation 0 1 0 1.5708
      name "panel(71)"
    }
    Panel {
      translation 21.2474 0 -24.8851
      rotation 0 1 0 1.5708
      name "panel(55)"
    }
    Panel {
      translation 21.2474 0 -26.6151
      rotation 0 1 0 1.5708
      name "panel(56)"
    }
    Panel {
      translation 21.2474 0 -28.2551
      rotation 0 1 0 1.5708
      name "panel(57)"
    }
    Panel {
      translation 25.5604 0 -24.5873
      name "panel(58)"
    }
    Panel {
      translation 25.5604 0 -17.3073
      name "panel(59)"
    }
    Panel {
      translation 25.5604 0 -10.2573
      name "panel(60)"
    }
    Panel {
      translation 24.1004 0 -24.5973
      name "panel(61)"
    }
    Panel {
      translation 24.1004 0 -17.3373
      name "panel(62)"
    }
    Panel {
      translation 24.1004 0 -10.2573
      name "panel(63)"
    }
    Panel {
      translation 22.5504 0 -24.5873
      name "panel(64)"
    }
    Panel {
      translation 22.5504 0 -17.3273
      name "panel(65)"
    }
    Panel {
      translation 22.5504 0 -10.2573
      name "panel(66)"
    }
    Panel {
      translation 20.9704 0 -10.2573
      name "panel(67)"
    }
    Panel {
      translation 20.9704 0 -24.5773
      name "panel(68)"
    }
    Panel {
      translation 20.9704 0 -17.3573
      name "panel(69)"
    }
    WoodenChair {
      translation 28.2877 7.10543e-15 -16.5637
      name "wooden chair(15)"
    }
    WoodenChair {
      translation 28.2877 7.10543e-15 -23.9137
      name "wooden chair(16)"
    }
    WoodenChair {
      translation 28.2877 7.10543e-15 -18.1537
      rotation 0 1 0 3.14159
      name "wooden chair(17)"
    }
    WoodenChair {
      translation 28.2877 7.10543e-15 -25.1237
      rotation 0 1 0 3.14159
      name "wooden chair(18)"
    }
    WoodenChair {
      translation 25.7177 7.10543e-15 -23.8937
      name "wooden chair(19)"
    }
    WoodenChair {
      translation 25.7177 7.10543e-15 -18.0837
      rotation 0 1 0 3.14159
      name "wooden chair(20)"
    }
    WoodenChair {
      translation 28.2877 7.10543e-15 -11.1637
      rotation 0 1 0 3.14159
      name "wooden chair(21)"
    }
    WoodenChair {
      translation 25.7177 7.10543e-15 -25.2037
      rotation 0 1 0 3.14159
      name "wooden chair(22)"
    }
    WoodenChair {
      translation 22.9577 7.10543e-15 -23.8537
      name "wooden chair(23)"
    }
    WoodenChair {
      translation 25.7177 7.10543e-15 -16.5637
      name "wooden chair(24)"
    }
    WoodenChair {
      translation 22.9577 7.10543e-15 -18.0537
      rotation 0 1 0 3.14159
      name "wooden chair(25)"
    }
    WoodenChair {
      translation 25.7177 7.10543e-15 -11.1037
      rotation 0 1 0 3.14159
      name "wooden chair(26)"
    }
    WoodenChair {
      translation 22.9577 7.10543e-15 -25.0837
      rotation 0 1 0 3.14159
      name "wooden chair(27)"
    }
    WoodenChair {
      translation 22.9577 7.10543e-15 -16.5637
      name "wooden chair(28)"
    }
    WoodenChair {
      translation 22.9577 7.10543e-15 -11.1937
      rotation 0 1 0 3.14159
      name "wooden chair(29)"
    }
    Desk {
      translation 28.2877 7.10543e-15 -16.1837
      rotation 0 1 0 6.28319
      name "desk(15)"
    }
    Desk {
      translation 28.2877 7.10543e-15 -25.5337
      rotation 0 1 0 6.28319
      name "desk(16)"
    }
    Desk {
      translation 28.2877 7.10543e-15 -11.5037
      rotation 0 1 0 6.28319
      name "desk(17)"
    }
    Desk {
      translation 28.2877 7.10543e-15 -23.5237
      rotation 0 1 0 6.28319
      name "desk(18)"
    }
    Desk {
      translation 25.6977 7.10543e-15 -16.1837
      rotation 0 1 0 6.28319
      name "desk(19)"
    }
    Desk {
      translation 25.6977 7.10543e-15 -18.4537
      rotation 0 1 0 6.28319
      name "desk(20)"
    }
    Desk {
      translation 25.6977 7.10543e-15 -11.5337
      rotation 0 1 0 6.28319
      name "desk(21)"
    }
    Desk {
      translation 22.9277 7.10543e-15 -16.1837
      rotation 0 1 0 6.28319
      name "desk(22)"
    }
    Desk {
      translation 22.9277 7.10543e-15 -11.5737
      rotation 0 1 0 6.28319
      name "desk(23)"
    }
    Desk {
      translation 25.6977 7.10543e-15 -25.5537
      rotation 0 1 0 6.28319
      name "desk(24)"
    }
    Desk {
      translation 28.2877 7.10543e-15 -18.5337
      rotation 0 1 0 6.28319
      name "desk(25)"
    }
    Desk {
      translation 22.9277 7.10543e-15 -18.4537
      rotation 0 1 0 6.28319
      name "desk(26)"
    }
    Desk {
      translation 25.6977 7.10543e-15 -23.4937
      rotation 0 1 0 6.28319
      name "desk(27)"
    }
    Desk {
      translation 22.9277 7.10543e-15 -23.5337
      rotation 0 1 0 6.28319
      name "desk(28)"
    }
    Desk {
      translation 22.9277 7.10543e-15 -25.4837
      rotation 0 1 0 6.28319
      name "desk(29)"
    }
  ]
}
DEF OFFICES Transform {
  translation 0 0 -40
  rotation 0 1 0 3.14159
  children [
    Panel {
      translation 28.4604 0 -24.5373
      name "panel(1)"
    }
    Panel {
      translation 28.4604 0 -17.2973
      name "panel(2)"
    }
    Panel {
      translation 28.4604 0 -10.2573
      name "panel(3)"
    }
    Panel {
      translation 27.0304 0 -24.5573
      name "panel(4)"
    }
    Panel {
      translation 27.0304 0 -17.2873
      name "panel(5)"
    }
    Panel {
      translation 27.0304 0 -10.2573
      name "panel(6)"
    }
    Panel {
      translation 27.0774 0 -10.6551
      rotation 0 1 0 1.5708
      name "panel(7)"
    }
    Panel {
      translation 27.0774 0 -15.6551
      rotation 0 1 0 1.5708
      name "panel(8)"
    }
    Panel {
      translation 27.0774 0 -17.7651
      rotation 0 1 0 1.5708
      name "panel(9)"
    }
    Panel {
      translation 27.0774 0 -22.8751
      rotation 0 1 0 1.5708
      name "panel(10)"
    }
    Panel {
      translation 24.2974 0 -10.6551
      rotation 0 1 0 1.5708
      name "panel(12)"
    }
    Panel {
      translation 24.2974 0 -15.6951
      rotation 0 1 0 1.5708
      name "panel(13)"
    }
    Panel {
      translation 24.2974 0 -17.8051
      rotation 0 1 0 1.5708
      name "panel(14)"
    }
    Panel {
      translation 24.2974 0 -22.8551
      rotation 0 1 0 1.5708
      name "panel(15)"
    }
    Panel {
      translation 21.2474 0 -10.6551
      rotation 0 1 0 1.5708
      name "panel(17)"
    }
    Panel {
      translation 21.3952621435841 -9.947598300641403e-14 -15.729109202722
      rotation 0 1 0 1.5708
      name "panel(18)"
    }
    Panel {
      translation 21.31044627075896 -9.947598300641403e-14 -14.04973964987817
      rotation 0 1 0 1.5708
      name "panel(21)"
    }
    Panel {
      translation 21.296215948418833 -9.237055564881302e-14 -12.31909108621101
      rotation 0 1 0 1.5708
      name "panel(22)"
    }
    Panel {
      translation 21.2474 0 -17.7551
      rotation 0 1 0 1.5708
      name "panel(19)"
    }
    Panel {
      translation 21.181637678529647 1.0658141036401503e-14 -22.679400631189946
      rotation 0 1 0 1.5708
      name "panel(20)"
    }
    Panel {
      translation 21.187549941856076 7.105427357601002e-15 -21.115898284791456
      rotation 0 1 0 1.5708
      name "panel(11)2"
    }
    Panel {
      translation 21.20323799951621 2.2382096176443156e-13 -19.58767785752691
      rotation 0 1 0 1.5708
      name "panel(16)1"
    }
    Panel {
      translation 25.5604 0 -24.5873
      name "panel(24)"
    }
    Panel {
      translation 25.5604 0 -17.3073
      name "panel(25)"
    }
    Panel {
      translation 25.5604 0 -10.2573
      name "panel(26)"
    }
    Panel {
      translation 24.1004 0 -24.5973
      name "panel(27)"
    }
    Panel {
      translation 24.1004 0 -17.3373
      name "panel(28)"
    }
    Panel {
      translation 24.1004 0 -10.2573
      name "panel(29)"
    }
    Panel {
      translation 22.5504 0 -24.5873
      name "panel(30)"
    }
    Panel {
      translation 22.5504 0 -17.3273
      name "panel(31)"
    }
    Panel {
      translation 22.5504 0 -10.2573
      name "panel(32)"
    }
    Panel {
      translation 20.9704 0 -10.2573
      name "panel(33)"
    }
    Panel {
      translation 20.9704 0 -24.5773
      name "panel(34)"
    }
    Panel {
      translation 20.9704 0 -17.3573
      name "panel(70)"
    }
    WoodenChair {
      translation 28.2877 7.10543e-15 -16.5637
      name "wooden chair(1)"
    }
    WoodenChair {
      translation 28.2877 7.10543e-15 -23.9137
      name "wooden chair(2)"
    }
    WoodenChair {
      translation 28.2877 7.10543e-15 -18.1537
      rotation 0 1 0 3.14159
      name "wooden chair(3)"
    }
    WoodenChair {
      translation 25.7177 7.10543e-15 -23.8937
      name "wooden chair(5)"
    }
    WoodenChair {
      translation 25.7177 7.10543e-15 -18.0837
      rotation 0 1 0 3.14159
      name "wooden chair(6)"
    }
    WoodenChair {
      translation 28.2877 7.10543e-15 -11.1637
      rotation 0 1 0 3.14159
      name "wooden chair(7)"
    }
    WoodenChair {
      translation 22.9577 7.10543e-15 -23.8537
      name "wooden chair(9)"
    }
    WoodenChair {
      translation 25.7177 7.10543e-15 -16.5637
      name "wooden chair(10)"
    }
    WoodenChair {
      translation 22.9577 7.10543e-15 -18.0537
      rotation 0 1 0 3.14159
      name "wooden chair(11)"
    }
    WoodenChair {
      translation 25.7177 7.10543e-15 -11.1037
      rotation 0 1 0 3.14159
      name "wooden chair(12)"
    }
    WoodenChair {
      translation 22.9577 7.10543e-15 -16.5637
      name "wooden chair(14)"
    }
    WoodenChair {
      translation 22.9577 7.10543e-15 -11.1937
      rotation 0 1 0 3.14159
      name "wooden chair(30)"
    }
    Desk {
      translation 28.2877 7.10543e-15 -16.1837
      rotation 0 1 0 6.28319
      name "desk(1)"
    }
    Desk {
      translation 28.2877 7.10543e-15 -11.5037
      rotation 0 1 0 6.28319
      name "desk(3)"
    }
    Desk {
      translation 28.2877 7.10543e-15 -23.5237
      rotation 0 1 0 6.28319
      name "desk(4)"
    }
    Desk {
      translation 25.6977 7.10543e-15 -16.1837
      rotation 0 1 0 6.28319
      name "desk(5)"
    }
    Desk {
      translation 25.6977 7.10543e-15 -18.4537
      rotation 0 1 0 6.28319
      name "desk(6)"
    }
    Desk {
      translation 25.6977 7.10543e-15 -11.5337
      rotation 0 1 0 6.28319
      name "desk(7)"
    }
    Desk {
      translation 22.9277 7.10543e-15 -16.1837
      rotation 0 1 0 6.28319
      name "desk(8)"
    }
    Desk {
      translation 22.9277 7.10543e-15 -11.5737
      rotation 0 1 0 6.28319
      name "desk(9)"
    }
    Desk {
      translation 28.2877 7.10543e-15 -18.5337
      rotation 0 1 0 6.28319
      name "desk(11)"
    }
    Desk {
      translation 22.9277 7.10543e-15 -18.4537
      rotation 0 1 0 6.28319
      name "desk(12)"
    }
    Desk {
      translation 25.6977 7.10543e-15 -23.4937
      rotation 0 1 0 6.28319
      name "desk(13)"
    }
    Desk {
      translation 22.9277 7.10543e-15 -23.5337
      rotation 0 1 0 6.28319
      name "desk(14)"
    }
  ]
}
DEF BOXES Transform {
  translation -2 0 0
  children [
    WoodenBox {
      translation 26.7873 0.89 9.13591
      name "wooden box(1)"
    }
    WoodenBox {
      translation 25.3406 0.3 9.13625
      name "wooden box(2)"
    }
    WoodenBox {
      translation 25.8306 0.91 9.13625
      name "wooden box(3)"
    }
    WoodenBox {
      translation 24.8506 0.9 9.13625
      name "wooden box(4)"
    }
    WoodenBox {
      translation 24.3706 0.3 9.13625
      name "wooden box(5)"
    }
    WoodenBox {
      translation 26.3006 0.3 9.13625
      name "wooden box(6)"
    }
    WoodenBox {
      translation 27.317 0.3 9.14677
      name "wooden box(14)"
    }
  ]
}
DEF BOXES Transform {
  translation -7 0 0
  children [
    WoodenBox {
      translation 26.7873 0.89 9.13591
      name "wooden box(7)"
    }
    WoodenBox {
      translation 25.3406 0.3 9.13625
      name "wooden box(8)"
    }
    WoodenBox {
      translation 25.8306 0.91 9.13625
      name "wooden box(9)"
    }
    WoodenBox {
      translation 24.8506 0.9 9.13625
      name "wooden box(10)"
    }
    WoodenBox {
      translation 24.3706 0.3 9.13625
      name "wooden box(11)"
    }
    WoodenBox {
      translation 26.3006 0.3 9.13625
      name "wooden box(12)"
    }
    WoodenBox {
      translation 27.317 0.3 9.14677
      name "wooden box(13)"
    }
  ]
}
DEF BOXES Transform {
  translation -12 0 0
  children [
    WoodenBox {
      translation 26.7873 0.89 9.13591
      name "wooden box9"
    }
    WoodenBox {
      translation 25.3406 0.3 9.13625
      name "wooden box10"
    }
    WoodenBox {
      translation 25.8306 0.91 9.13625
      name "wooden box11"
    }
    WoodenBox {
      translation 24.8506 0.9 9.13625
      name "wooden box12"
    }
    WoodenBox {
      translation 24.3706 0.3 9.13625
      name "wooden box13"
    }
    WoodenBox {
      translation 26.3006 0.3 9.13625
      name "wooden box14"
    }
    WoodenBox {
      translation 27.317 0.3 9.14677
      name "wooden box15"
    }
  ]
}
DEF BOXES Transform {
  translation -12 0 3
  children [
    WoodenBox {
      translation 26.7873 0.89 9.13591
      name "wooden box(16"
    }
    WoodenBox {
      translation 25.3406 0.3 9.13625
      name "wooden box(17"
    }
    WoodenBox {
      translation 25.8306 0.91 9.13625
      name "wooden box(18"
    }
    WoodenBox {
      translation 24.8506 0.9 9.13625
      name "wooden box(19"
    }
    WoodenBox {
      translation 24.3706 0.3 9.13625
      name "wooden box20"
    }
    WoodenBox {
      translation 26.3006 0.3 9.13625
      name "wooden box21"
    }
    WoodenBox {
      translation 27.317 0.3 9.14677
      name "wooden box22"
    }
  ]
}
DEF BOXES Transform {
  translation -7 0 3
  children [
    WoodenBox {
      translation 26.7873 0.89 9.13591
      name "wooden box(10)23"
    }
    WoodenBox {
      translation 25.3406 0.3 9.13625
      name "wooden box(10)24"
    }
    WoodenBox {
      translation 25.8306 0.91 9.13625
      name "wooden box25"
    }
    WoodenBox {
      translation 24.8506 0.9 9.13625
      name "wooden box(10)26"
    }
    WoodenBox {
      translation 24.3706 0.3 9.13625
      name "wooden box(10)27"
    }
    WoodenBox {
      translation 26.3006 0.3 9.13625
      name "wooden box(10)28"
    }
    WoodenBox {
      translation 27.317 0.3 9.14677
      name "wooden box(10)29"
    }
  ]
}
DEF BOXES Transform {
  translation -2 0 3
  children [
    WoodenBox {
      translation 26.7873 0.89 9.13591
      name "wooden box(10)30"
    }
    WoodenBox {
      translation 25.3406 0.3 9.13625
      name "wooden box(10)31"
    }
    WoodenBox {
      translation 25.8306 0.91 9.13625
      name "wooden box(10)32"
    }
    WoodenBox {
      translation 24.8506 0.9 9.13625
      name "wooden box(10)33"
    }
    WoodenBox {
      translation 24.3706 0.3 9.13625
      name "wooden box(10)34"
    }
    WoodenBox {
      translation 26.3006 0.3 9.13625
      name "wooden box(10)35"
    }
    WoodenBox {
      translation 27.317 0.3 9.14677
      name "wooden box(10)36"
    }
  ]
}
DEF KITCHEN Transform {
  translation 27.9 0 21.8
  rotation 0 1 0 4.71239
  children [
    Cabinet {
      hidden translation_6 1.2164136364845035e-10 0.6897927756036063 0.6999999969259818
      hidden rotation_6 -0.9992244179339315 6.755054741792268e-10 -0.0393771838073219 -9.532555680748614e-05
      hidden position_6_0 0.003135823567824303
      hidden translation_7 9.954193388450605e-07 0 0.0006294250598424035
      hidden rotation_7 0 1 0 0.0031629452532116386
      translation 1 0.83 -2.15
      depth 0.7
      outerThickness 0.02
      rowsHeights [
        0.2, 0.2, 0.2, 0.2, 0.2, 0.34
      ]
      columnsWidths [
        0.4
      ]
      layout [
        "LeftSidedDoor (1, 1, 1, 6, 1.5)"
        "Shelf (1,2, 1, 0)"
        "Shelf (1,3, 1, 0)"
        "Shelf (1,4, 1, 0)"
        "Shelf (1,5, 1, 0)"
        "Shelf (1,6, 1, 0)"
      ]
      handle CabinetHandle {
        translation -0.3 0 0
        handleLength 0.1
        handleRadius 0.008
        handleColor 0.427451 0.513725 0.533333
      }
    }
    Cabinet {
      hidden translation_6 -1.2156320394751674e-10 1.0747983548799014 0.6699999973167152
      hidden rotation_6 0.9989771605585497 2.4553570290684696e-09 -0.0452176147356055 9.11144152905939e-05
      hidden position_6_0 -0.0032783818727812365
      hidden translation_7 -1.1967705460802502e-06 0 0.0007238402537346866
      hidden rotation_7 0 -1 0 0.00330672258088197
      hidden translation_10 -1.2156320394751674e-10 1.7447983548771793 0.6699999973167152
      hidden rotation_10 0.9989771659283051 2.459359134739265e-09 -0.04521749610329366 9.111441902214395e-05
      hidden position_10_0 -0.0032783813703426614
      hidden translation_11 -1.1967701836479439e-06 0 0.0007238401440400405
      hidden rotation_11 0 -1 0 0.0033067220627565315
      translation -1.65 0.15 0.11
      rotation 0 1 0 1.5708
      name "cabinet(1)"
      depth 0.67
      outerThickness 0.02
      rowsHeights [
        0.68, 0.25, 0.25, 0.25, 0.25, 0.34
      ]
      columnsWidths [
        0.44
      ]
      layout [
        "RightSidedDoor (1, 2, 1, 3, 1.5)"
        "RightSidedDoor (1, 5, 1, 2, 1.5)"
        "Shelf (1,2, 1, 0)"
        "Shelf (1,3, 1, 0)"
        "Shelf (1,4, 1, 0)"
        "Shelf (1,5, 1, 0)"
        "Shelf (1,6, 1, 0)"
      ]
      handle CabinetHandle {
        translation -0.15 0 0
        handleLength 0.1
        handleRadius 0.008
        handleColor 0.427451 0.513725 0.533333
      }
    }
    Cabinet {
      hidden translation_6 -0.44000000006634465 0.33982522977671903 0.49999999892513003
      hidden rotation_6 0.9981151783753445 2.3225558776438684e-09 -0.06136848292693981 6.711369753771215e-05
      hidden position_6_0 -0.0024136165230558178
      hidden translation_7 -6.486772320124512e-07 0 0.0005329075635484584
      hidden rotation_7 0 -1 0 0.0024344818738269124
      hidden translation_10 6.645706207564217e-11 0.3398252297720077 0.4999999989251265
      hidden rotation_10 -0.998108336808285 2.3423903817361254e-09 -0.061479655121017295 -6.711416745141697e-05
      hidden position_10_0 0.0024140979344216746
      hidden translation_11 6.489360116213039e-07 0 0.0005330138504707402
      hidden rotation_11 0 1 0 0.002434967456237292
      hidden translation_14 0.4400000000664406 0.3398252297757862 0.4999999989251265
      hidden rotation_14 -0.9981083305651094 2.3324652593797278e-09 -0.06147975647748082 -6.711415995244264e-05
      hidden position_14_0 0.002414097426591279
      hidden translation_15 6.48935740782397e-07 0 0.0005330137393089681
      hidden rotation_15 0 1 0 0.002434966927152908
      translation 0.1 1.4 -2.15
      name "cabinet(2)"
      outerThickness 0.02
      rowsHeights [
        0.21, 0.21, 0.22
      ]
      columnsWidths [
        0.44, 0.44, 0.44
      ]
      layout [
        "RightSidedDoor (1, 1, 1, 3, 1.5)"
        "LeftSidedDoor (2, 1, 1, 3, 1.5)"
        "LeftSidedDoor (3, 1, 1, 3, 1.5)"
        "Shelf (1, 2, 3, 0)"
        "Shelf (1, 3, 2, 0)"
        "Shelf (1, 1, 0, 1)"
        "Shelf (2, 1, 0, 3)"
      ]
      handle CabinetHandle {
        translation -0.2 0 0
        handleLength 0.1
        handleRadius 0.008
        handleColor 0.427451 0.513725 0.533333
      }
    }
    Cabinet {
      hidden translation_6 -6.633982252424175e-11 0.3398252297924218 0.49999999892513003
      hidden rotation_6 0.9981151853869252 2.3146823799231454e-09 -0.0613683688884068 6.711366412250827e-05
      hidden position_6_0 -0.002413615817833587
      hidden translation_7 -6.486768532043552e-07 0 0.000532907408005363
      hidden rotation_7 0 -1 0 0.00243448118976547
      translation -1.647 1.4 -0.37
      rotation 0 1 0 1.5708
      name "cabinet(3)"
      outerThickness 0.02
      rowsHeights [
        0.21, 0.21, 0.22
      ]
      columnsWidths [
        0.44
      ]
      layout [
        "RightSidedDoor (1, 1, 1, 3, 1.5)"
        "Shelf (1, 2 ,1 , 0)"
        "Shelf (1, 3 ,1 , 0)"
      ]
      handle CabinetHandle {
        translation -0.2 0 0
        handleLength 0.1
        handleRadius 0.008
        handleColor 0.427451 0.513725 0.533333
      }
    }
    Cabinet {
      hidden translation_6 -0.06500000007011408 0.3398252267479095 0.4999999989260324
      hidden rotation_6 0.997844878623633 4.985661140851771e-09 -0.06561705726857124 6.713823200740346e-05
      hidden position_6_0 -0.002567814345359597
      hidden translation_7 -7.842621784215353e-07 0 0.0006056067971027078
      hidden rotation_7 0 -0.9999999999999999 0 0.00259000308983241
      hidden translation_10 0.4049998800128485 0.3398253218441457 0.4999999688445165
      hidden rotation_10 -0.9978399554746016 0.0006305443853776326 -0.06568885500770469 -6.69043401312128e-05
      hidden position_10_0 -6.960192022432192e-07
      hidden translation_11 5.751903012496395e-07 0 -0.0005186399651356948
      hidden rotation_11 0 -1 0 0.0022180707376868248
      hidden translation_14 -0.4700000000507565 0.3398252380493004 0.4999999989282031
      hidden rotation_14 0.9988692620858078 1.759732780054864e-09 -0.04754153195000712 6.704569286856746e-05
      hidden position_14_0 -0.0018875933332575309
      hidden translation_15 -3.065795446399733e-07 0 0.00032204932215805954
      hidden rotation_15 0 -0.9999999999999999 0 0.0019039285673621358
      translation -1.48 0.15 -0.79
      rotation 0 1 0 1.5708
      name "cabinet(4)"
      outerThickness 0.02
      rowsHeights [
        0.21, 0.21, 0.22
      ]
      columnsWidths [
        0.34, 0.47, 0.47
      ]
      layout [
        "RightSidedDoor (2, 1, 1, 3, 1.5)"
        "LeftSidedDoor (3, 1, 1, 3, 1.5)"
        "RightSidedDoor (1, 1, 1, 3, 1.5)"
        "Shelf (1, 2, 1, 0)"
        "Shelf (1, 3, 1, 0)"
        "Shelf (1, 1, 0, 3)"
        "Shelf (2, 1, 0, 3)"
      ]
      handle CabinetHandle {
        translation 0.1 0 0
        handleLength 0.1
        handleRadius 0.008
        handleColor 0.427451 0.513725 0.533333
      }
    }
    Cabinet {
      hidden translation_6 -0.049999999837286424 0.26979274743924486 0.6999999969222905
      hidden rotation_6 -0.9985933186297331 7.372596530733002e-09 -0.0530224856834928 -9.542748311794067e-05
      hidden position_6_0 0.00414803850433144
      hidden translation_7 2.3512973392203484e-06 0 0.0011239868912563487
      hidden rotation_7 0 1 0 0.004183845768352454
      hidden translation_10 0.8650000001297151 0.3397927699762804 0.6999999969269979
      hidden rotation_10 -0.9991066945169079 2.971614462297556e-09 -0.04225888038623393 -9.534511276156536e-05
      hidden position_10_0 0.0033577093585097904
      hidden translation_11 1.2268586087604838e-06 0 0.0007245066946139735
      hidden rotation_11 0 1 0 0.003386738717502961
      hidden translation_14 0.4349999998702607 0.339792769971875 0.6999999969269943
      hidden rotation_14 0.9991066895262286 2.963463264646015e-09 -0.04225899837833692 9.534511976070595e-05
      hidden position_14_0 -0.003357709959911283
      hidden translation_15 -1.2268590426356418e-06 0 0.0007245068228146598
      hidden rotation_15 0 -1 0 0.0033867393035048998
      hidden translation_18 -0.7000000000000242 0.14444505826051582 0.6999999296505557
      hidden rotation_18 -1 5.958699942483004e-13 -2.4170849498133576e-13 -0.0003726393481011877
      hidden position_18_0 0.05183113753606969
      hidden translation_19 0 0 0.5949082704948935
      hidden translation_26 -0.6999995666049905 0.39447214582637236 0.6999999023134791
      hidden rotation_26 0.9999996762007174 0.0007885837298224821 -0.00016041870707941917 0.000332718068205212
      hidden position_26_0 0.001007632916059459
      hidden translation_27 0 0 0.4377439285074085
      hidden translation_34 -0.7000000000001059 0.5894889177579528 0.6999999113323092
      hidden rotation_34 -1 1.5719717297322313e-10 7.129336297981412e-10 -0.000348893155374972
      hidden position_34_0 0.0021138173870484805
      hidden translation_35 0 0 0.5452227145240434
      hidden translation_42 -0.05000000000007532 0.5894889181948293 0.699999911332668
      hidden rotation_42 -1 1.0691992990216655e-10 3.888090932023128e-09 -0.00034889186563008453
      hidden position_42_0 0.00211380683928992
      hidden translation_43 0 0 0.5452165217085932
      translation 0.12 0.15 -2.15
      name "cabinet(5)"
      depth 0.7
      outerThickness 0.02
      rowsHeights [
        0.25, 0.25, 0.14
      ]
      columnsWidths [
        0.76, 0.54, 0.43, 0.43
      ]
      layout [
        "LeftSidedDoor (2, 1, 1, 2, 1.5)"
        "LeftSidedDoor (4, 1, 1, 3, 1.5)"
        "RightSidedDoor (3, 1, 1, 3, 1.5)"
        "Drawer (1, 1, 1, 1, 3.5)"
        "Drawer (1, 2, 1, 1, 3.5)"
        "Drawer (1, 3, 1, 1, 3.5)"
        "Drawer (2, 3, 1, 1, 3.5)"
        "Shelf (1, 2, 1, 0)"
        "Shelf (1, 3, 2, 0)"
        "Shelf (3, 2, 2, 0)"
        "Shelf (1, 1, 0, 3)"
        "Shelf (2, 1, 0, 3)"
        "Shelf (3, 1, 0, 1)"
      ]
      handle CabinetHandle {
        handleLength 0.1
        handleRadius 0.008
        handleColor 0.427451 0.513725 0.533333
      }
    }
    SolidBox {
      translation 0.12 0.07 -1.55
      size 2.2 0.16 0.2
      appearance PBRAppearance {
        baseColor 0.8 0.8 0.8
        roughness 0.5
        metalness 0
        textureTransform TextureTransform {
          scale 4 4
        }
      }
    }
    SolidBox {
      translation -1.08 0.07 -0.65
      rotation 0 1 0 1.5708
      name "box(1)"
      size 2 0.16 0.2
      appearance PBRAppearance {
        baseColor 0.8 0.8 0.8
        roughness 0.5
        metalness 0
        textureTransform TextureTransform {
          scale 4 4
        }
      }
    }
    SolidBox {
      translation 1.12 0.07 -1.9
      rotation 0 -1 0 4.71239
      name "box(2)"
      size 0.5 0.16 0.2
      appearance PBRAppearance {
        roughness 0.5
        metalness 0
        textureTransform TextureTransform {
          scale 4 4
        }
      }
    }
    SolidBox {
      translation -1.415 0.07 0.25
      rotation 0 -1 0 6.28318
      name "box(3)"
      size 0.47 0.16 0.2
      appearance PBRAppearance {
        baseColor 0.8 0.8 0.8
        roughness 0.5
        metalness 0
        textureTransform TextureTransform {
          scale 4 4
        }
      }
    }
    Fridge {
      hidden position_0_0 -3.38384007087553e-07
      hidden position_0_1 1.1228729742421234e-06
      hidden rotation_1 0 -1 0 3.897159347123516e-07
      hidden rotation_2 0 1 0 1.3460623968406233e-06
      translation 1.57 0 -1.8
      rotation 0 1 0 4.71239
    }
    Worktop {
      translation -1.31 0.86 -0.345
      rotation 0 1 0 4.71239
      size 0.43 0.06 0.7
    }
    Worktop {
      translation -1.531 0.86 -0.78
      rotation 0 1 0 4.71239
      name "worktop(1)"
      size 0.44 0.06 0.237
    }
    Worktop {
      translation -1.003 0.86 -0.780001
      rotation 0 1 0 4.71239
      name "worktop(2)"
      size 0.442 0.06 0.085
    }
    Worktop {
      translation -1.306 0.86 -1.22
      rotation 0 -1 0 1.5708
      name "worktop(3)"
      size 0.44 0.06 0.69
    }
    Worktop {
      translation -0.435 0.86 -1.79
      name "worktop(4)"
      size 2.43 0.06 0.7
    }
    Sink {
      translation -1.33 0.87 -0.78
      rotation 0 1 0 4.71239
    }
    HotPlate {
      translation -1.14971 0.86 -1.62912
      rotation 0 -1 0 5.49779
    }
    Oven {
      hidden position_0_0 -6.665471380558688e-37
      translation -1.24 0.51 0.11
    }
  ]
}
DEF INTERNAL_WINDOW Window {
  translation -11.283624405978252 -1.5987211554602254e-14 -0.9089969314674011
  rotation 0 -1 0 3.141591686718346
  name "window(4)"
  size 0.9 2.7 0.2
}
DEF INTERNAL_WINDOW Window {
  translation -7.764715143088619 -1.4210854715202004e-14 -0.9394903033116844
  rotation 0 -1 0 3.141591686718346
  name "window(3)"
  size 0.9 2.7 0.2
}
DEF INTERNAL_WINDOW Window {
  translation -9.547060928142615 -1.2434497875801753e-14 -0.9229028115136266
  rotation 0 -1 0 3.141591686718346
  name "window(2)"
  size 0.9 2.7 0.2
}
DEF INTERNAL_WINDOW Window {
  translation -10.424088153855532 -1.4210854715202004e-14 -0.9263832371812324
  rotation 0 -1 0 3.141591686718346
  name "window(1)"
  size 0.9 2.7 0.2
}
DEF INTERNAL_WALL Wall {
  translation -20.841722096896945 1.7763568394002505e-15 -0.895663661597073
  name "wall(7)"
  size 18.2 2.7 0.2
}
DEF INTERNAL_WINDOW Window {
  translation -8.661028945763917 3.197442310920451e-14 -0.9265567823689587
  rotation 0 -1 0 3.141591686718346
  size 0.9 2.7 0.2
}
DEF INTERNAL_WALL Wall {
  translation 18.841850244600412 -1.0004599999999999e-09 20.10700920905251
  name "wall(13)"
  size 22.5 2.4 0.2
}
DEF INTERNAL_WALL Wall {
  translation 18.485403866389234 -1.0004599999999999e-09 -20.560992229375792
  rotation 0 1 0 6.283185307179586
  name "WALL1"
  size 22.5 2.4 0.2
}
DEF EXTERNAL_WALL Wall {
  translation -30 0 0
  rotation 0 1 0 1.5708
  name "wall(12)"
  size 60 2.4 0.2
}
DEF EXTERNAL_WALL Wall {
  translation 30 0 0
  rotation 0 1 0 1.5708
  name "wall(11)"
  size 60 2.4 0.2
}
DEF EXTERNAL_WALL Wall {
  translation -27.45 0 30
  name "wall(10)"
  size 5.3 2.4 0.2
}
DEF DOUBLE_WINDOW Transform {
  translation -24 0 30
  children [
    Window {
      translation -0.4 0 0
      name "window(21)"
    }
    Window {
      translation 0.4 0 0
      name "window(22)"
    }
  ]
}
DEF DOUBLE_WINDOW Transform {
  translation -12 0 30
  children [
    Window {
      translation -0.4 0 0
      name "window(19)"
    }
    Window {
      translation 0.4 0 0
      name "window(20)"
    }
  ]
}
DEF DOUBLE_WINDOW Transform {
  translation 12 0 30
  children [
    Window {
      translation -0.4 0 0
      name "window(17)"
    }
    Window {
      translation 0.4 0 0
      name "window(18)"
    }
  ]
}
DEF DOUBLE_WINDOW Transform {
  translation 24 0 30
  children [
    Window {
      translation -0.4 0 0
      name "window(15)"
    }
    Window {
      translation 0.4 0 0
      name "window(16)"
    }
  ]
}
DEF EXTERNAL_WALL Wall {
  translation -18 0 30
  name "wall(8)"
  size 10.4 2.4 0.2
}
DEF EXTERNAL_WALL Wall {
  translation 27.45 0 30
  name "wall(9)"
  size 5.3 2.4 0.2
}
DEF EXTERNAL_WALL Wall {
  translation 18 0 30
  name "wall(6)"
  size 10.4 2.4 0.2
}
DEF EXTERNAL_WALL Wall {
  translation 0 0 30
  name "wall(5)"
  size 22.4 2.4 0.2
}
DEF DOUBLE_WINDOW Transform {
  translation -12 0 -30
  children [
    Window {
      translation -0.4 0 0
      name "window(11)"
    }
    Window {
      translation 0.4 0 0
      name "window(12)"
    }
  ]
}
DEF DOUBLE_WINDOW Transform {
  translation -24 0 -30
  children [
    Window {
      translation -0.4 0 0
      name "window(13)"
    }
    Window {
      translation 0.4 0 0
      name "window(14)"
    }
  ]
}
DEF DOUBLE_WINDOW Transform {
  translation 24 0 -30
  children [
    Window {
      translation -0.4 0 0
      name "window(7)"
    }
    Window {
      translation 0.4 0 0
      name "window(8)"
    }
  ]
}
DEF EXTERNAL_WALL Wall {
  translation -27.45 0 -30
  name "wall(4)"
  size 5.3 2.4 0.2
}
DEF EXTERNAL_WALL Wall {
  translation 27.45 0 -30
  name "wall(3)"
  size 5.3 2.4 0.2
}
DEF EXTERNAL_WALL Wall {
  translation -18 0 -30
  name "wall(2)"
  size 10.4 2.4 0.2
}
DEF EXTERNAL_WALL Wall {
  translation 18 0 -30
  name "wall(1)"
  size 10.4 2.4 0.2
}
DEF EXTERNAL_WALL Wall {
  translation 0 0 -30
  size 22.4 2.4 0.2
}
Shape {
  appearance PBRAppearance {
    baseColor 0 0 1
    roughness 1
    metalness 0
  }
  geometry IndexedFaceSet {
    coord Coordinate {
      point [
        0.21 0 0.07
        0.09 0 0.22
        0.25 0 0.26
        0.21 0.0001 0.07
        0.09 0.0001 0.22
        0.25 0.0001 0.26
      ]
    }
    coordIndex [
      2, 1, 0, -1, 3, 4, 5, -1, 0, 1
      4, 3, -1, 1, 2, 5, 4, -1, 2, 0
      3, 5, -1
    ]
  }
}
DEF YELLOW_BOX Solid {
  translation 7.575177875154338 1.2299999999997016 14.566063051090254
  rotation 0 0.9999999999999999 0 3.142388812563314
  children [
    DEF Shape Shape {
      appearance DEF PBR PBRAppearance {
        roughness 0.03934117200000009
        metalness 0
      }
      geometry DEF geometryBox Box {
        size 0.30000000000000004 2.6999999999999997 11
      }
    }
  ]
  name "YELLOW_BOX"
  boundingObject Shape {
    appearance PBRAppearance {
      roughness 1.1102230246251565e-16
      metalness 0
    }
    geometry USE geometryBox
  }
}
DEF MyBot1 Robot {
  translation 27.99999992349172 -0.0004426658513224241 27.999999941797597
  rotation 0.024669399365892783 -0.999625877972576 -0.011812062583773255 -0.8937219706987969
  children [
    Emitter {
      channel 1
      baudRate 115200
    }
    Transform {
      translation 0 0.0415 0
      children [
        Shape {
          appearance PBRAppearance {
            baseColor 0.0820075 0.364731 0.8
            roughness 1
            metalness 0
          }
          geometry DEF BODY Cylinder {
            height 0.08
            radius 0.045
          }
        }
      ]
    }
    HingeJoint {
      jointParameters HingeJointParameters {
        position 76.03200974254013
        axis -1 0 0
        anchor 0 0.025 0
      }
      device [
        RotationalMotor {
          name "left wheel motor1"
          consumptionFactor 70
        }
        PositionSensor {
          name "left wheel sensor"
        }
      ]
      endPoint Solid {
        translation -0.044999975873086066 0.025212115180554003 -1.542929400714314e-06
        rotation -0.9999998918029794 0.0003806369970275567 -0.00026741261396755786 1.9316464747819821
        children [
          DEF WHEEL Transform {
            rotation 0 0 1 1.57
            children [
              Shape {
                appearance PBRAppearance {
                  baseColor 1 0 0
                  roughness 1
                  metalness 0
                }
                geometry Cylinder {
                  height 0.01
                  radius 0.025
                }
              }
            ]
          }
        ]
        name "left wheel"
        boundingObject USE WHEEL
        physics DEF PHYSICS_WHEEL Physics {
          density -1
          mass 0.05
        }
        linearVelocity -2.19405379246057e-08 -3.6386327195714398e-09 -1.7647141503998607e-08
        angularVelocity -8.576000400498974e-07 -5.634587902559527e-10 1.066241222951259e-06
      }
    }
    HingeJoint {
      jointParameters HingeJointParameters {
        position 76.03204409394739
        axis -1 0 0
        anchor 0 0.025 0
      }
      device [
        RotationalMotor {
          name "right wheel motor1"
          consumptionFactor 70
        }
        PositionSensor {
          name "right wheel sensor"
        }
      ]
      endPoint Solid {
        translation 0.044999989753531276 0.025212064463461387 -1.5432396487395145e-06
        rotation -0.999999913208402 -0.0003814768348264451 0.0001675070543137093 2.3290006272274155
        children [
          USE WHEEL
        ]
        name "right wheel"
        boundingObject USE WHEEL
        physics USE PHYSICS_WHEEL
        linearVelocity -2.1942256463736167e-08 -3.6388451718494347e-09 -1.764851437116576e-08
        angularVelocity -8.575951556920352e-07 6.51534769397266e-10 1.0662454650622266e-06
      }
    }
    DistanceSensor {
      translation -0.02 0.063 -0.042
      rotation 0 1 0 2.07
      children [
        DEF SENSOR Transform {
          rotation 0 0 1 1.57
          children [
            Shape {
              appearance PBRAppearance {
                baseColor 0.975691 0.981481 0.0252992
                roughness 1
                metalness 0
              }
              geometry Cylinder {
                height 0.004
                radius 0.008
              }
            }
          ]
        }
      ]
      name "ds0"
      lookupTable [
        0 1024 0
        0.05 1024 0
        0.15 0 0
      ]
      numberOfRays 2
      aperture 1
    }
    DistanceSensor {
      translation 0.02 0.063 -0.042
      rotation 0 1 0 1.07
      children [
        USE SENSOR
      ]
      name "ds1"
      lookupTable [
        0 1024 0
        0.05 1024 0
        0.15 0 0
      ]
      numberOfRays 2
      aperture 1
    }
    DEF SMILE Transform {
      translation 0 0.025 -0.036
      rotation 0.7745972408364944 0.44721228048294853 0.4472139204829502 1.8234794
      children [
        Shape {
          appearance PBRAppearance {
            baseColor 0.721569 0.290196 0.290196
            roughness 1
            metalness 0
          }
          geometry Cylinder {
            height 0.018
            radius 0.009
            subdivision 3
          }
        }
      ]
    }
    Radar {
      translation 0 0.1 0
      children [
        Shape {
          appearance PBRAppearance {
            baseColor 0.403922 0.403922 0.403922
            roughness 1
            metalness 0
          }
          geometry DEF BOX Box {
            size 0.04 0.04 0.04
          }
        }
      ]
      minRange 0.01
      maxRange 80
      horizontalFieldOfView 2
      verticalFieldOfView 0.5
      frequency 28
      transmittedPower 28
    }
  ]
  name "MyBot1"
  boundingObject Transform {
    translation 0 0.0415 0
    children [
      USE BODY
    ]
  }
  physics Physics {
    density -1
    mass 0.5
  }
  controller "unmovingrobot1"
  battery [
    0, 100, 30
  ]
  cpuConsumption 5
  linearVelocity -6.020476864848631e-09 -3.543478499068436e-09 -4.844685080759857e-09
  angularVelocity 2.514415275612854e-07 3.728248875779219e-11 -3.126197112808466e-07
}
DEF MyBot2 Robot {
  translation 27.999999982322276 -0.0004426671208237823 -24.9999999019526
  rotation 0.0018735856482171753 -0.9999283947773994 -0.011819263712770645 -2.8275102182080993
  children [
    Emitter {
      name "emitter2"
      channel 2
      baudRate 115200
    }
    Transform {
      translation 0 0.0415 0
      children [
        Shape {
          appearance PBRAppearance {
            baseColor 0.0820075 0.364731 0.8
            roughness 1
            metalness 0
          }
          geometry DEF BODY Cylinder {
            height 0.08
            radius 0.045
          }
        }
      ]
    }
    HingeJoint {
      jointParameters HingeJointParameters {
        position 76.03199390094494
        axis -1 0 0
        anchor 0 0.025 0
      }
      device [
        RotationalMotor {
          name "left wheel motor1"
          consumptionFactor 70
        }
        PositionSensor {
          name "left wheel sensor"
        }
      ]
      endPoint Solid {
        translation -0.04499995669495855 0.025212115599072736 -1.4987286425178277e-06
        rotation -0.9999998918133123 0.00038067409051280223 -0.0002673211559476756 1.9316352860129298
        children [
          DEF WHEEL Transform {
            rotation 0 0 1 1.57
            children [
              Shape {
                appearance PBRAppearance {
                  baseColor 1 0 0
                  roughness 1
                  metalness 0
                }
                geometry Cylinder {
                  height 0.01
                  radius 0.025
                }
              }
            ]
          }
        ]
        name "left wheel"
        boundingObject USE WHEEL
        physics DEF PHYSICS_WHEEL Physics {
          density -1
          mass 0.05
        }
        linearVelocity -8.698420193610497e-09 -3.6377398515696627e-09 2.6778246785819063e-08
        angularVelocity 1.3013793573742402e-06 -6.231316358444379e-10 4.227933919598114e-07
      }
    }
    HingeJoint {
      jointParameters HingeJointParameters {
        position 76.03196425503327
        axis -1 0 0
        anchor 0 0.025 0
      }
      device [
        RotationalMotor {
          name "right wheel motor1"
          consumptionFactor 70
        }
        PositionSensor {
          name "right wheel sensor"
        }
      ]
      endPoint Solid {
        translation 0.04499997063249231 0.02521206487363057 -1.4988578248054704e-06
        rotation -0.9999999132145931 -0.00038149259397133044 0.00016743418651342468 2.328925448800918
        children [
          USE WHEEL
        ]
        name "right wheel"
        boundingObject USE WHEEL
        physics USE PHYSICS_WHEEL
        linearVelocity -8.699750263397446e-09 -3.6398396474624026e-09 2.6782361918567527e-08
        angularVelocity 1.3013635338301377e-06 5.919362039379686e-10 4.227816775891952e-07
      }
    }
    DistanceSensor {
      translation -0.02 0.063 -0.042
      rotation 0 1 0 2.07
      children [
        DEF SENSOR Transform {
          rotation 0 0 1 1.57
          children [
            Shape {
              appearance PBRAppearance {
                baseColor 0.975691 0.981481 0.0252992
                roughness 1
                metalness 0
              }
              geometry Cylinder {
                height 0.004
                radius 0.008
              }
            }
          ]
        }
      ]
      name "ds0"
      lookupTable [
        0 1024 0
        0.05 1024 0
        0.15 0 0
      ]
      numberOfRays 2
      aperture 1
    }
    DistanceSensor {
      translation 0.02 0.063 -0.042
      rotation 0 1 0 1.07
      children [
        USE SENSOR
      ]
      name "ds1"
      lookupTable [
        0 1024 0
        0.05 1024 0
        0.15 0 0
      ]
      numberOfRays 2
      aperture 1
    }
    DEF SMILE Transform {
      translation 0 0.025 -0.036
      rotation 0.7745972408364944 0.44721228048294853 0.4472139204829502 1.8234794
      children [
        Shape {
          appearance PBRAppearance {
            baseColor 0.721569 0.290196 0.290196
            roughness 1
            metalness 0
          }
          geometry Cylinder {
            height 0.018
            radius 0.009
            subdivision 3
          }
        }
      ]
    }
    Radar {
      translation 0 0.1 0
      rotation 0 1 0 6.021385901
      children [
        Shape {
          appearance PBRAppearance {
            baseColor 0.403922 0.403922 0.403922
            roughness 1
            metalness 0
          }
          geometry DEF BOX Box {
            size 0.04 0.04 0.04
          }
        }
      ]
      minRange 0.01
      maxRange 78
      horizontalFieldOfView 2
      verticalFieldOfView 0.4
    }
  ]
  name "MyBot2"
  boundingObject Transform {
    translation 0 0.0415 0
    children [
      USE BODY
    ]
  }
  physics Physics {
    density -1
    mass 0.5
  }
  controller "unmovingrobot2"
  cpuConsumption 0.5
  linearVelocity -2.3923280101714813e-09 -3.543583545706488e-09 7.347429457321703e-09
  angularVelocity -3.8157576101384e-07 -2.2521071393394092e-11 -1.2393364566483988e-07
}
DEF DOUBLE_WINDOW Transform {
  translation 12 0 -30
  children [
    Window {
      translation -0.4 0 0
      name "window(9)"
    }
    Window {
      translation 0.4 0 0
      name "window(10)"
    }
  ]
}
DEF MyBot3 Robot {
  translation -25.99999992722388 -0.0004427248348622681 -26.99999993797476
  rotation -0.005357217406880562 -0.9999157878577333 -0.011820212117563827 2.2902711769056108
  children [
    Emitter {
      name "emitter3"
      channel 3
      baudRate 115200
    }
    Transform {
      translation 0 0.0415 0
      children [
        Shape {
          appearance PBRAppearance {
            baseColor 0.0820075 0.364731 0.8
            roughness 1
            metalness 0
          }
          geometry DEF BODY Cylinder {
            height 0.08
            radius 0.045
          }
        }
      ]
    }
    HingeJoint {
      jointParameters HingeJointParameters {
        position 76.03199119409925
        axis -1 0 0
        anchor 0 0.025 0
      }
      device [
        RotationalMotor {
          name "left wheel motor1"
          consumptionFactor 70
        }
        PositionSensor {
          name "left wheel sensor"
        }
      ]
      endPoint Solid {
        translation -0.04499995633981145 0.02521211546492243 1.5101613266430209e-06
        rotation -0.999999891910708 0.00038451689638473646 -0.0002613911409847565 1.9329360467894574
        children [
          DEF WHEEL Transform {
            rotation 0 0 1 1.57
            children [
              Shape {
                appearance PBRAppearance {
                  baseColor 1 0 0
                  roughness 1
                  metalness 0
                }
                geometry Cylinder {
                  height 0.01
                  radius 0.025
                }
              }
            ]
          }
        ]
        name "left wheel"
        boundingObject USE WHEEL
        physics DEF PHYSICS_WHEEL Physics {
          density -1
          mass 0.05
        }
        linearVelocity 2.117887169243716e-08 -3.6372195921785584e-09 1.855344823595283e-08
        angularVelocity 9.01626514163553e-07 -5.558182474580826e-10 -1.0292178102629002e-06
      }
    }
    HingeJoint {
      jointParameters HingeJointParameters {
        position 76.03193867616973
        axis -1 0 0
        anchor 0 0.025 0
      }
      device [
        RotationalMotor {
          name "right wheel motor1"
          consumptionFactor 70
        }
        PositionSensor {
          name "right wheel sensor"
        }
      ]
      endPoint Solid {
        translation 0.04499997016563732 0.025212064861078666 1.5106805840535008e-06
        rotation -0.9999999132624315 -0.00038388457571327916 0.00016157896447780736 2.330203655241697
        children [
          USE WHEEL
        ]
        name "right wheel"
        boundingObject USE WHEEL
        physics USE PHYSICS_WHEEL
        linearVelocity 2.1180365909548315e-08 -3.637201828610157e-09 1.855472017690819e-08
        angularVelocity 9.016236393078944e-07 6.590728308961547e-10 -1.0292240632785518e-06
      }
    }
    DistanceSensor {
      translation -0.02 0.063 -0.042
      rotation 0 1 0 2.8553981609999997
      children [
        DEF SENSOR Transform {
          rotation 0 0 1 1.57
          children [
            Shape {
              appearance PBRAppearance {
                baseColor 0.975691 0.981481 0.0252992
                roughness 1
                metalness 0
              }
              geometry Cylinder {
                height 0.004
                radius 0.008
              }
            }
          ]
        }
      ]
      name "ds0"
      lookupTable [
        0 1024 0
        0.05 1024 0
        0.15 0 0
      ]
      numberOfRays 2
      aperture 1
    }
    DistanceSensor {
      translation 0.02 0.063 -0.042
      rotation 0 1 0 1.07
      children [
        USE SENSOR
      ]
      name "ds1"
      lookupTable [
        0 1024 0
        0.05 1024 0
        0.15 0 0
      ]
      numberOfRays 2
      aperture 1
    }
    DEF SMILE Transform {
      translation 0 0.025 -0.036
      rotation 0.7745972408364944 0.44721228048294853 0.4472139204829502 1.8234794
      children [
        Shape {
          appearance PBRAppearance {
            baseColor 0.721569 0.290196 0.290196
            roughness 1
            metalness 0
          }
          geometry Cylinder {
            height 0.018
            radius 0.009
            subdivision 3
          }
        }
      ]
    }
    DEF Radar Radar {
      translation 0 0.1 0
      rotation 0 1 0 6.283185307179586
      children [
        Shape {
          appearance PBRAppearance {
            baseColor 0.403922 0.403922 0.403922
            roughness 1
            metalness 0
          }
          geometry DEF BOX Box {
            size 0.04 0.04 0.04
          }
        }
      ]
      minRange 0.01
      maxRange 79.23140049567527
      horizontalFieldOfView 2
      transmittedPower 77
    }
  ]
  name "MyBot3"
  boundingObject Transform {
    translation 0 0.0415 0
    children [
      USE BODY
    ]
  }
  physics Physics {
    density -1
    mass 0.5
  }
  controller "unmovingrobot3"
  linearVelocity 5.812867369101025e-09 -3.5461241054690723e-09 5.094149006401599e-09
  angularVelocity -2.643109689399584e-07 4.4891165852193423e-11 3.0171492811422234e-07
}
DEF TRAIL Shape {
  appearance Appearance {
    material Material {
      diffuseColor 0 1 0
      emissiveColor 0 1 0
    }
  }
  geometry DEF TRAIL_LINE_SET IndexedLineSet {
    coord Coordinate {
      point [
        0 0 0, 0 0 0, 0 0 0, 0 0 0, 0 0 0, 0 0 0, 0 0 0, 0 0 0, 0 0 0, 0 0 0, 0 0 0, 0 0 0, 0 0 0, 0 0 0, 0 0 0, 0 0 0, 0 0 0, 0 0 0, 0 0 0, 0 0 0, 0 0 0, 0 0 0, 0 0 0, 0 0 0, 0 0 0, 0 0 0, 0 0 0, 0 0 0, 0 0 0, 0 0 0, 0 0 0, 0 0 0, 0 0 0, 0 0 0, 0 0 0, 0 0 0, 0 0 0, 0 0 0, 0 0 0, 0 0 0, 0 0 0, 0 0 0, 0 0 0, 0 0 0, 0 0 0, 0 0 0, 0 0 0, 0 0 0, 0 0 0, 0 0 0, 0 0 0, 0 0 0, 0 0 0, 0 0 0, 0 0 0, 0 0 0, 0 0 0, 0 0 0, 0 0 0, 0 0 0, 0 0 0, 0 0 0, 0 0 0, 0 0 0, 0 0 0, 0 0 0, 0 0 0, 0 0 0, 0 0 0, 0 0 0, 0 0 0, 0 0 0, 0 0 0, 0 0 0, 0 0 0, 0 0 0, 0 0 0, 0 0 0, 0 0 0, 0 0 0, 0 0 0, 0 0 0, 0 0 0, 0 0 0, 0 0 0, 0 0 0, 0 0 0, 0 0 0, 0 0 0, 0 0 0, 0 0 0, 0 0 0, 0 0 0, 0 0 0, 0 0 0, 0 0 0, 0 0 0, 0 0 0, 0 0 0, 0 0 0, 0 0 0, 0 0 0, 0 0 0, 0 0 0, 0 0 0, 0 0 0, 0 0 0, 0 0 0, 0 0 0, 0 0 0, 0 0 0, 0 0 0, 0 0 0, 0 0 0, 0 0 0, 0 0 0, 0 0 0, 0 0 0, 0 0 0, 0 0 0, 0 0 0, 0 0 0, 0 0 0, 0 0 0, 0 0 0, 0 0 0, 0 0 0, 0 0 0, 0 0 0, 0 0 0, 0 0 0, 0 0 0, 0 0 0, 0 0 0, 0 0 0, 0 0 0, 0 0 0, 0 0 0, 0 0 0, 0 0 0, 0 0 0, 0 0 0, 0 0 0, 0 0 0, 0 0 0, 0 0 0, 0 0 0, 0 0 0, 0 0 0, 0 0 0, 0 0 0, 0 0 0, 0 0 0, 0 0 0, 0 0 0, 0 0 0, 0 0 0, 0 0 0, 0 0 0, 0 0 0, 0 0 0, 0 0 0, 0 0 0, 0 0 0, 0 0 0, 0 0 0, 0 0 0, 0 0 0, 0 0 0, 0 0 0, 0 0 0, 0 0 0, 0 0 0, 0 0 0, 0 0 0, 0 0 0, 0 0 0, 0 0 0, 0 0 0, 0 0 0, 0 0 0, 0 0 0, 0 0 0, 0 0 0, 0 0 0, 0 0 0, 0 0 0, 0 0 0, 0 0 0, 0 0 0, 0 0 0, 0 0 0, 0 0 0, 0 0 0, 0 0 0, 0 0 0, 0 0 0, 0 0 0, 0 0 0, 0 0 0
      ]
    }
    coordIndex [
      0, 1, -1, 1, 2, -1, 2, 2, -1, 0, 0, -1, 0, 0, -1, 0, 0, -1, 0, 0, -1, 0, 0, -1, 0, 0, -1, 0, 0, -1, 0, 0, -1, 0, 0, -1, 0, 0, -1, 0, 0, -1, 0, 0, -1, 0, 0, -1, 0, 0, -1, 0, 0, -1, 0, 0, -1, 0, 0, -1, 0, 0, -1, 0, 0, -1, 0, 0, -1, 0, 0, -1, 0, 0, -1, 0, 0, -1, 0, 0, -1, 0, 0, -1, 0, 0, -1, 0, 0, -1, 0, 0, -1, 0, 0, -1, 0, 0, -1, 0, 0, -1, 0, 0, -1, 0, 0, -1, 0, 0, -1, 0, 0, -1, 0, 0, -1, 0, 0, -1, 0, 0, -1, 0, 0, -1, 0, 0, -1, 0, 0, -1, 0, 0, -1, 0, 0, -1, 0, 0, -1, 0, 0, -1, 0, 0, -1, 0, 0, -1, 0, 0, -1, 0, 0, -1, 0, 0, -1, 0, 0, -1, 0, 0, -1, 0, 0, -1, 0, 0, -1, 0, 0, -1, 0, 0, -1, 0, 0, -1, 0, 0, -1, 0, 0, -1, 0, 0, -1, 0, 0, -1, 0, 0, -1, 0, 0, -1, 0, 0, -1, 0, 0, -1, 0, 0, -1, 0, 0, -1, 0, 0, -1, 0, 0, -1, 0, 0, -1, 0, 0, -1, 0, 0, -1, 0, 0, -1, 0, 0, -1, 0, 0, -1, 0, 0, -1, 0, 0, -1, 0, 0, -1, 0, 0, -1, 0, 0, -1, 0, 0, -1, 0, 0, -1, 0, 0, -1, 0, 0, -1, 0, 0, -1, 0, 0, -1, 0, 0, -1, 0, 0, -1, 0, 0, -1, 0, 0, -1, 0, 0, -1, 0, 0, -1, 0, 0, -1, 0, 0, -1, 0, 0, -1, 0, 0, -1, 0, 0, -1, 0, 0, -1, 0, 0, -1, 0, 0, -1, 0, 0, -1, 0, 0, -1, 0, 0, -1, 0, 0, -1, 0, 0, -1, 0, 0, -1, 0, 0, -1, 0, 0, -1, 0, 0, -1, 0, 0, -1, 0, 0, -1, 0, 0, -1, 0, 0, -1, 0, 0, -1, 0, 0, -1, 0, 0, -1, 0, 0, -1, 0, 0, -1, 0, 0, -1, 0, 0, -1, 0, 0, -1, 0, 0, -1, 0, 0, -1, 0, 0, -1, 0, 0, -1, 0, 0, -1, 0, 0, -1, 0, 0, -1, 0, 0, -1, 0, 0, -1, 0, 0, -1, 0, 0, -1, 0, 0, -1, 0, 0, -1, 0, 0, -1, 0, 0, -1, 0, 0, -1, 0, 0, -1, 0, 0, -1, 0, 0, -1, 0, 0, -1, 0, 0, -1, 0, 0, -1, 0, 0, -1, 0, 0, -1, 0, 0, -1, 0, 0, -1, 0, 0, -1, 0, 0, -1, 0, 0, -1, 0, 0, -1, 0, 0, -1, 0, 0, -1, 0, 0, -1, 0, 0, -1, 0, 0, -1, 0, 0, -1, 0, 0, -1, 0, 0, -1, 0, 0, -1, 0, 0, -1, 0, 0, -1, 0, 0, -1, 0, 0, -1, 0, 0, -1, 0, 0, -1, 0, 0, -1, 0, 0, -1, 0, 0, -1, 0, 0, -1, 0, 0, -1, 0, 0, -1, 0, 0, -1, 0, 0, -1, 0, 0, -1, 0, 0, -1, 0, 0, -1, 0, 0, -1, 0, 0, -1, 0, 0, -1, 0, 0, -1, 0, 0, -1, 0, 0, -1, 0, 0, -1, 0, 0, -1, 0, 0, -1, 0, 0, -1, 0, 0, -1, 0, 0, -1, 0, 0, -1, 0, 0, -1, 0, 0, -1, 0, 0, -1, 0, 0, -1, 0, 0, -1, 0, 0, -1, 0, 0, -1
    ]
  }
}
DEF Supervisior1 Robot {
  translation 0 -1 0
  children [
    DEF emittertoyellowbox Emitter {
      name "emittertoyellowbox"
      channel 7
    }
    Receiver {
      channel 8
    }
    DEF emitter Emitter {
      channel 8
    }
    Receiver {
      name "receiver2"
      channel 3
    }
    Receiver {
      name "receiver1"
      channel 2
    }
    Receiver {
      name "receiver0"
      channel 1
    }
  ]
  controller "matlab_supervisor"
  supervisor TRUE
  cpuConsumption 0.5
}
DEF PIONEER_3AT Pioneer3at {
  hidden position_0_0 5492.979070551543
  hidden position_0_1 5669.172950710371
  hidden position_0_2 5559.284863522814
  hidden position_0_3 5755.055620173752
  hidden rotation_8 1 0 0 1.2911394363580704
  hidden rotation_9 1 0 0 4.277710605783096
  hidden rotation_10 1 0 0 4.324921246221243
  hidden rotation_11 -1 0 0 3.526697920326017
  translation 26.31012765821493 0.10757688844159898 -23.03936582031246
  rotation 0.0003954872396072095 0.9999998437751991 0.000395018253552633 -1.570693851841771
  controller "ros"
  controllerArgs "--name=pioneer3at"
  extensionSlot [
    DEF RADAR_TARGET Solid {
      translation 0 0.19999999999999998 0
      children [
        Shape {
          appearance PBRAppearance {
            baseColor 1 0 0
            roughness 1
            metalness 0
          }
          geometry DEF BOX Box {
            size 0.04 0.04 0.04
          }
        }
      ]
      name ""
      radarCrossSection 1
    }
    Camera {
      translation 0 0.17 -0.22
      width 256
      height 128
      motionBlur 500
      noise 0.02
    }
    Accelerometer {
      lookupTable [
        -39.24 -39.24 0.005
        39.24 39.24 0.005
      ]
    }
    Gyro {
      lookupTable [
        -50 -50 0.005
        50 50 0.005
      ]
    }
    SickLms291 {
      translation 0 0.23 -0.136
      noise 0.1
    }
    GPS {
    }
    InertialUnit {
    }
  ]
}
