#VRML_SIM R2019a utf8
WorldInfo {
  info [
    "Example use of a Radar device."
  ]
}
Viewpoint {
  orientation -0.9999407696243731 0.009549360390956508 0.00522177739280499 1.0008461951798295
  position -1.134222616253913 77.89748827028185 48.832321948047316
}
TexturedBackground {
}
TexturedBackgroundLight {
}
Floor {
  size 60 60
  tileSize 1 1
  appearance ThreadMetalPlate {
  }
}
DEF KITCHEN Transform {
  translation 27.9 0 21.8
  rotation 0 1 0 4.71239
  children [
    Cabinet {
      translation 1 0.83 -2.15
      depth 0.7
      outerThickness 0.02
      rowsHeights [
        0.2, 0.2, 0.2, 0.2, 0.2, 0.34
      ]
      columnsWidths [
        0.4
      ]
      layout [
        "LeftSidedDoor (1, 1, 1, 6, 1.5)"
        "Shelf (1,2, 1, 0)"
        "Shelf (1,3, 1, 0)"
        "Shelf (1,4, 1, 0)"
        "Shelf (1,5, 1, 0)"
        "Shelf (1,6, 1, 0)"
      ]
      handle CabinetHandle {
        translation -0.3 0 0
        handleLength 0.1
        handleRadius 0.008
        handleColor 0.427451 0.513725 0.533333
      }
    }
    Cabinet {
      translation -1.65 0.15 0.11
      rotation 0 1 0 1.5708
      name "cabinet(1)"
      depth 0.67
      outerThickness 0.02
      rowsHeights [
        0.68, 0.25, 0.25, 0.25, 0.25, 0.34
      ]
      columnsWidths [
        0.44
      ]
      layout [
        "RightSidedDoor (1, 2, 1, 3, 1.5)"
        "RightSidedDoor (1, 5, 1, 2, 1.5)"
        "Shelf (1,2, 1, 0)"
        "Shelf (1,3, 1, 0)"
        "Shelf (1,4, 1, 0)"
        "Shelf (1,5, 1, 0)"
        "Shelf (1,6, 1, 0)"
      ]
      handle CabinetHandle {
        translation -0.15 0 0
        handleLength 0.1
        handleRadius 0.008
        handleColor 0.427451 0.513725 0.533333
      }
    }
    Cabinet {
      translation 0.1 1.4 -2.15
      name "cabinet(2)"
      outerThickness 0.02
      rowsHeights [
        0.21, 0.21, 0.22
      ]
      columnsWidths [
        0.44, 0.44, 0.44
      ]
      layout [
        "RightSidedDoor (1, 1, 1, 3, 1.5)"
        "LeftSidedDoor (2, 1, 1, 3, 1.5)"
        "LeftSidedDoor (3, 1, 1, 3, 1.5)"
        "Shelf (1, 2, 3, 0)"
        "Shelf (1, 3, 2, 0)"
        "Shelf (1, 1, 0, 1)"
        "Shelf (2, 1, 0, 3)"
      ]
      handle CabinetHandle {
        translation -0.2 0 0
        handleLength 0.1
        handleRadius 0.008
        handleColor 0.427451 0.513725 0.533333
      }
    }
    Cabinet {
      translation -1.647 1.4 -0.37
      rotation 0 1 0 1.5708
      name "cabinet(3)"
      outerThickness 0.02
      rowsHeights [
        0.21, 0.21, 0.22
      ]
      columnsWidths [
        0.44
      ]
      layout [
        "RightSidedDoor (1, 1, 1, 3, 1.5)"
        "Shelf (1, 2 ,1 , 0)"
        "Shelf (1, 3 ,1 , 0)"
      ]
      handle CabinetHandle {
        translation -0.2 0 0
        handleLength 0.1
        handleRadius 0.008
        handleColor 0.427451 0.513725 0.533333
      }
    }
    Cabinet {
      translation -1.48 0.15 -0.79
      rotation 0 1 0 1.5708
      name "cabinet(4)"
      outerThickness 0.02
      rowsHeights [
        0.21, 0.21, 0.22
      ]
      columnsWidths [
        0.34, 0.47, 0.47
      ]
      layout [
        "RightSidedDoor (2, 1, 1, 3, 1.5)"
        "LeftSidedDoor (3, 1, 1, 3, 1.5)"
        "RightSidedDoor (1, 1, 1, 3, 1.5)"
        "Shelf (1, 2, 1, 0)"
        "Shelf (1, 3, 1, 0)"
        "Shelf (1, 1, 0, 3)"
        "Shelf (2, 1, 0, 3)"
      ]
      handle CabinetHandle {
        translation 0.1 0 0
        handleLength 0.1
        handleRadius 0.008
        handleColor 0.427451 0.513725 0.533333
      }
    }
    Cabinet {
      translation 0.12 0.15 -2.15
      name "cabinet(5)"
      depth 0.7
      outerThickness 0.02
      rowsHeights [
        0.25, 0.25, 0.14
      ]
      columnsWidths [
        0.76, 0.54, 0.43, 0.43
      ]
      layout [
        "LeftSidedDoor (2, 1, 1, 2, 1.5)"
        "LeftSidedDoor (4, 1, 1, 3, 1.5)"
        "RightSidedDoor (3, 1, 1, 3, 1.5)"
        "Drawer (1, 1, 1, 1, 3.5)"
        "Drawer (1, 2, 1, 1, 3.5)"
        "Drawer (1, 3, 1, 1, 3.5)"
        "Drawer (2, 3, 1, 1, 3.5)"
        "Shelf (1, 2, 1, 0)"
        "Shelf (1, 3, 2, 0)"
        "Shelf (3, 2, 2, 0)"
        "Shelf (1, 1, 0, 3)"
        "Shelf (2, 1, 0, 3)"
        "Shelf (3, 1, 0, 1)"
      ]
      handle CabinetHandle {
        handleLength 0.1
        handleRadius 0.008
        handleColor 0.427451 0.513725 0.533333
      }
    }
    SolidBox {
      translation 0.12 0.07 -1.55
      size 2.2 0.16 0.2
      appearance PBRAppearance {
        baseColor 0.8 0.8 0.8
        roughness 0.5
        metalness 0
        textureTransform TextureTransform {
          scale 4 4
        }
      }
    }
    SolidBox {
      translation -1.08 0.07 -0.65
      rotation 0 1 0 1.5708
      name "box(1)"
      size 2 0.16 0.2
      appearance PBRAppearance {
        baseColor 0.8 0.8 0.8
        roughness 0.5
        metalness 0
        textureTransform TextureTransform {
          scale 4 4
        }
      }
    }
    SolidBox {
      translation 1.12 0.07 -1.9
      rotation 0 -1 0 4.71239
      name "box(2)"
      size 0.5 0.16 0.2
      appearance PBRAppearance {
        roughness 0.5
        metalness 0
        textureTransform TextureTransform {
          scale 4 4
        }
      }
    }
    SolidBox {
      translation -1.415 0.07 0.25
      rotation 0 -1 0 6.28318
      name "box(3)"
      size 0.47 0.16 0.2
      appearance PBRAppearance {
        baseColor 0.8 0.8 0.8
        roughness 0.5
        metalness 0
        textureTransform TextureTransform {
          scale 4 4
        }
      }
    }
    Fridge {
      translation 1.57 0 -1.8
      rotation 0 1 0 4.71239
    }
    Worktop {
      translation -1.31 0.86 -0.345
      rotation 0 1 0 4.71239
      size 0.43 0.06 0.7
    }
    Worktop {
      translation -1.531 0.86 -0.78
      rotation 0 1 0 4.71239
      name "worktop(1)"
      size 0.44 0.06 0.237
    }
    Worktop {
      translation -1.003 0.86 -0.780001
      rotation 0 1 0 4.71239
      name "worktop(2)"
      size 0.442 0.06 0.085
    }
    Worktop {
      translation -1.306 0.86 -1.22
      rotation 0 -1 0 1.5708
      name "worktop(3)"
      size 0.44 0.06 0.69
    }
    Worktop {
      translation -0.435 0.86 -1.79
      name "worktop(4)"
      size 2.43 0.06 0.7
    }
    Sink {
      translation -1.33 0.87 -0.78
      rotation 0 1 0 4.71239
    }
    HotPlate {
      translation -1.14971 0.86 -1.62912
      rotation 0 -1 0 5.49779
    }
    Oven {
      translation -1.24 0.51 0.11
    }
  ]
}
DEF INTERNAL_WINDOW Window {
  translation -11.283624405978252 -1.5987211554602254e-14 -0.9089969314674011
  rotation 0 -1 0 3.141591686718346
  name "window(4)"
  size 0.9 2.7 0.2
}
DEF INTERNAL_WINDOW Window {
  translation -7.764715143088619 -1.4210854715202004e-14 -0.9394903033116844
  rotation 0 -1 0 3.141591686718346
  name "window(3)"
  size 0.9 2.7 0.2
}
DEF INTERNAL_WINDOW Window {
  translation -9.547060928142615 -1.2434497875801753e-14 -0.9229028115136266
  rotation 0 -1 0 3.141591686718346
  name "window(2)"
  size 0.9 2.7 0.2
}
DEF INTERNAL_WINDOW Window {
  translation -10.424088153855532 -1.4210854715202004e-14 -0.9263832371812324
  rotation 0 -1 0 3.141591686718346
  name "window(1)"
  size 0.9 2.7 0.2
}
DEF INTERNAL_WALL Wall {
  translation -20.841722096896945 1.7763568394002505e-15 -0.895663661597073
  name "wall(7)"
  size 18.2 2.7 0.2
}
DEF INTERNAL_WINDOW Window {
  translation -8.661028945763917 3.197442310920451e-14 -0.9265567823689587
  rotation 0 -1 0 3.141591686718346
  size 0.9 2.7 0.2
}
DEF INTERNAL_WALL Wall {
  translation 18.841850244600412 -1.0004599999999999e-09 20.10700920905251
  name "wall(13)"
  size 22.5 2.4 0.2
}
DEF EXTERNAL_WALL Wall {
  translation -30 0 0
  rotation 0 1 0 1.5708
  name "wall(12)"
  size 60 2.4 0.2
}
DEF EXTERNAL_WALL Wall {
  translation 30 0 0
  rotation 0 1 0 1.5708
  name "wall(11)"
  size 60 2.4 0.2
}
DEF EXTERNAL_WALL Wall {
  translation -27.45 0 30
  name "wall(10)"
  size 5.3 2.4 0.2
}
DEF DOUBLE_WINDOW Transform {
  translation -24 0 30
  children [
    Window {
      translation -0.4 0 0
      name "window(21)"
    }
    Window {
      translation 0.4 0 0
      name "window(22)"
    }
  ]
}
DEF DOUBLE_WINDOW Transform {
  translation -12 0 30
  children [
    Window {
      translation -0.4 0 0
      name "window(19)"
    }
    Window {
      translation 0.4 0 0
      name "window(20)"
    }
  ]
}
DEF DOUBLE_WINDOW Transform {
  translation 12 0 30
  children [
    Window {
      translation -0.4 0 0
      name "window(17)"
    }
    Window {
      translation 0.4 0 0
      name "window(18)"
    }
  ]
}
DEF DOUBLE_WINDOW Transform {
  translation 24 0 30
  children [
    Window {
      translation -0.4 0 0
      name "window(15)"
    }
    Window {
      translation 0.4 0 0
      name "window(16)"
    }
  ]
}
DEF EXTERNAL_WALL Wall {
  translation -18 0 30
  name "wall(8)"
  size 10.4 2.4 0.2
}
DEF EXTERNAL_WALL Wall {
  translation 27.45 0 30
  name "wall(9)"
  size 5.3 2.4 0.2
}
DEF EXTERNAL_WALL Wall {
  translation 18 0 30
  name "wall(6)"
  size 10.4 2.4 0.2
}
DEF EXTERNAL_WALL Wall {
  translation 0 0 30
  name "wall(5)"
  size 22.4 2.4 0.2
}
DEF DOUBLE_WINDOW Transform {
  translation -12 0 -30
  children [
    Window {
      translation -0.4 0 0
      name "window(11)"
    }
    Window {
      translation 0.4 0 0
      name "window(12)"
    }
  ]
}
DEF DOUBLE_WINDOW Transform {
  translation -24 0 -30
  children [
    Window {
      translation -0.4 0 0
      name "window(13)"
    }
    Window {
      translation 0.4 0 0
      name "window(14)"
    }
  ]
}
DEF DOUBLE_WINDOW Transform {
  translation 24 0 -30
  children [
    Window {
      translation -0.4 0 0
      name "window(7)"
    }
    Window {
      translation 0.4 0 0
      name "window(8)"
    }
  ]
}
DEF EXTERNAL_WALL Wall {
  translation -27.45 0 -30
  name "wall(4)"
  size 5.3 2.4 0.2
}
DEF EXTERNAL_WALL Wall {
  translation 27.45 0 -30
  name "wall(3)"
  size 5.3 2.4 0.2
}
DEF EXTERNAL_WALL Wall {
  translation -18 0 -30
  name "wall(2)"
  size 10.4 2.4 0.2
}
DEF EXTERNAL_WALL Wall {
  translation 18 0 -30
  name "wall(1)"
  size 10.4 2.4 0.2
}
DEF EXTERNAL_WALL Wall {
  translation 0 0 -30
  size 22.4 2.4 0.2
}
Shape {
  appearance PBRAppearance {
    baseColor 0 0 1
    roughness 1
    metalness 0
  }
  geometry IndexedFaceSet {
    coord Coordinate {
      point [
        0.21 0 0.07
        0.09 0 0.22
        0.25 0 0.26
        0.21 0.0001 0.07
        0.09 0.0001 0.22
        0.25 0.0001 0.26
      ]
    }
    coordIndex [
      2, 1, 0, -1, 3, 4, 5, -1, 0, 1
      4, 3, -1, 1, 2, 5, 4, -1, 2, 0
      3, 5, -1
    ]
  }
}
DEF E_PUCK2 E-puck {
  translation -4.784167051842149 -6.396824233341133e-05 4.781665900866141
  rotation 2.9767367957027358e-06 0.9999999999955341 -2.6564178734434993e-07 -2.963585693346755
  name "E_PUCK2"
  controller "matlab"
  emitter_channel 8
  receiver_channel 8
  turretSlot [
    DEF receiverepuck Receiver {
      name "receiverepuck"
      channel 8
    }
    Display {
      width 42
      height 30
    }
  ]
}
DEF YELLOW_BOX Solid {
  translation 7.737125407908302 1.22 14.127257821329414
  rotation 0 1 0 3.142388850922486
  children [
    DEF Shape Shape {
      appearance DEF PBR PBRAppearance {
        baseColor 1 1 0
        roughness 0.03934117200000009
        metalness 0
      }
      geometry DEF geometryBox Box {
        size 0.30000000000000004 2.5 11.9
      }
    }
  ]
  name "YELLOW_BOX"
  boundingObject Shape {
    appearance PBRAppearance {
      roughness 1.1102230246251565e-16
      metalness 0
    }
    geometry USE geometryBox
  }
}
DEF MyBot1 Robot {
  translation 28.708867697241438 -0.00044266573700219025 25.90395365604251
  rotation 0.024669433256044763 -0.9996258770637358 -0.011812068717304069 -0.8937213064915877
  children [
    Emitter {
      channel 1
      baudRate 115200
    }
    Transform {
      translation 0 0.0415 0
      children [
        Shape {
          appearance PBRAppearance {
            baseColor 0.0820075 0.364731 0.8
            roughness 1
            metalness 0
          }
          geometry DEF BODY Cylinder {
            height 0.08
            radius 0.045
          }
        }
      ]
    }
    HingeJoint {
      jointParameters HingeJointParameters {
        position 76.03201080341961
        axis -1 0 0
        anchor 0 0.025 0
      }
      device [
        RotationalMotor {
          name "left wheel motor1"
          consumptionFactor 70
        }
        PositionSensor {
          name "left wheel sensor"
        }
      ]
      endPoint Solid {
        translation -0.044999975873086094 0.025212115178917017 -1.5431544293604893e-06
        rotation -0.9999998918030587 0.00038063671557166757 -0.0002674127177911387 1.9316475356613518
        children [
          DEF WHEEL Transform {
            rotation 0 0 1 1.57
            children [
              Shape {
                appearance PBRAppearance {
                  baseColor 1 0 0
                  roughness 1
                  metalness 0
                }
                geometry Cylinder {
                  height 0.01
                  radius 0.025
                }
              }
            ]
          }
        ]
        name "left wheel"
        boundingObject USE WHEEL
        physics DEF PHYSICS_WHEEL Physics {
          density -1
          mass 0.05
        }
      }
    }
    HingeJoint {
      jointParameters HingeJointParameters {
        position 76.03204515482092
        axis -1 0 0
        anchor 0 0.025 0
      }
      device [
        RotationalMotor {
          name "right wheel motor1"
          consumptionFactor 70
        }
        PositionSensor {
          name "right wheel sensor"
        }
      ]
      endPoint Solid {
        translation 0.044999989753531325 0.025212064461824085 -1.5434646223142233e-06
        rotation -0.9999999132084414 -0.0003814766589169113 0.00016750721843585397 2.3290016881008557
        children [
          USE WHEEL
        ]
        name "right wheel"
        boundingObject USE WHEEL
        physics USE PHYSICS_WHEEL
      }
    }
    DistanceSensor {
      translation -0.02 0.063 -0.042
      rotation 0 1 0 2.07
      children [
        DEF SENSOR Transform {
          rotation 0 0 1 1.57
          children [
            Shape {
              appearance PBRAppearance {
                baseColor 0.975691 0.981481 0.0252992
                roughness 1
                metalness 0
              }
              geometry Cylinder {
                height 0.004
                radius 0.008
              }
            }
          ]
        }
      ]
      name "ds0"
      lookupTable [
        0 1024 0
        0.05 1024 0
        0.15 0 0
      ]
      numberOfRays 2
      aperture 1
    }
    DistanceSensor {
      translation 0.02 0.063 -0.042
      rotation 0 1 0 1.07
      children [
        USE SENSOR
      ]
      name "ds1"
      lookupTable [
        0 1024 0
        0.05 1024 0
        0.15 0 0
      ]
      numberOfRays 2
      aperture 1
    }
    DEF SMILE Transform {
      translation 0 0.025 -0.036
      rotation 0.7745972408364944 0.44721228048294853 0.4472139204829502 1.8234794
      children [
        Shape {
          appearance PBRAppearance {
            baseColor 0.721569 0.290196 0.290196
            roughness 1
            metalness 0
          }
          geometry Cylinder {
            height 0.018
            radius 0.009
            subdivision 3
          }
        }
      ]
    }
    Radar {
      translation 0 0.1 0
      children [
        Shape {
          appearance PBRAppearance {
            baseColor 0.403922 0.403922 0.403922
            roughness 1
            metalness 0
          }
          geometry DEF BOX Box {
            size 0.04 0.04 0.04
          }
        }
      ]
      minRange 0.01
      maxRange 65
      horizontalFieldOfView 2
      verticalFieldOfView 0.4
      occlusion TRUE
    }
  ]
  name "MyBot1"
  boundingObject Transform {
    translation 0 0.0415 0
    children [
      USE BODY
    ]
  }
  physics Physics {
    density -1
    mass 0.5
  }
  controller "unmovingrobot1"
  battery [
    0, 100, 30
  ]
  cpuConsumption 5
}
DEF MyBot2 Robot {
  translation 27.95568573943095 -0.00044266701054538476 -25.683825676870082
  rotation 0.0018736327474873431 -0.9999283946166173 -0.011819269848936562 -2.827502605762398
  children [
    Emitter {
      name "emitter2"
      channel 2
      baudRate 115200
    }
    Transform {
      translation 0 0.0415 0
      children [
        Shape {
          appearance PBRAppearance {
            baseColor 0.0820075 0.364731 0.8
            roughness 1
            metalness 0
          }
          geometry DEF BODY Cylinder {
            height 0.08
            radius 0.045
          }
        }
      ]
    }
    HingeJoint {
      jointParameters HingeJointParameters {
        position 76.03199425296188
        axis -1 0 0
        anchor 0 0.025 0
      }
      device [
        RotationalMotor {
          name "left wheel motor1"
          consumptionFactor 70
        }
        PositionSensor {
          name "left wheel sensor"
        }
      ]
      endPoint Solid {
        translation -0.044999956694958605 0.025212115598545144 -1.4988033108039896e-06
        rotation -0.9999998918133387 0.000380673997132201 -0.0002673211904152949 1.9316356380298365
        children [
          DEF WHEEL Transform {
            rotation 0 0 1 1.57
            children [
              Shape {
                appearance PBRAppearance {
                  baseColor 1 0 0
                  roughness 1
                  metalness 0
                }
                geometry Cylinder {
                  height 0.01
                  radius 0.025
                }
              }
            ]
          }
        ]
        name "left wheel"
        boundingObject USE WHEEL
        physics DEF PHYSICS_WHEEL Physics {
          density -1
          mass 0.05
        }
      }
    }
    HingeJoint {
      jointParameters HingeJointParameters {
        position 76.03196460680314
        axis -1 0 0
        anchor 0 0.025 0
      }
      device [
        RotationalMotor {
          name "right wheel motor1"
          consumptionFactor 70
        }
        PositionSensor {
          name "right wheel sensor"
        }
      ]
      endPoint Solid {
        translation 0.04499997063249233 0.025212064873103304 -1.4989324228394379e-06
        rotation -0.9999999132146064 -0.0003814925356509734 0.00016743424094086676 2.328925800570759
        children [
          USE WHEEL
        ]
        name "right wheel"
        boundingObject USE WHEEL
        physics USE PHYSICS_WHEEL
      }
    }
    DistanceSensor {
      translation -0.02 0.063 -0.042
      rotation 0 1 0 2.07
      children [
        DEF SENSOR Transform {
          rotation 0 0 1 1.57
          children [
            Shape {
              appearance PBRAppearance {
                baseColor 0.975691 0.981481 0.0252992
                roughness 1
                metalness 0
              }
              geometry Cylinder {
                height 0.004
                radius 0.008
              }
            }
          ]
        }
      ]
      name "ds0"
      lookupTable [
        0 1024 0
        0.05 1024 0
        0.15 0 0
      ]
      numberOfRays 2
      aperture 1
    }
    DistanceSensor {
      translation 0.02 0.063 -0.042
      rotation 0 1 0 1.07
      children [
        USE SENSOR
      ]
      name "ds1"
      lookupTable [
        0 1024 0
        0.05 1024 0
        0.15 0 0
      ]
      numberOfRays 2
      aperture 1
    }
    DEF SMILE Transform {
      translation 0 0.025 -0.036
      rotation 0.7745972408364944 0.44721228048294853 0.4472139204829502 1.8234794
      children [
        Shape {
          appearance PBRAppearance {
            baseColor 0.721569 0.290196 0.290196
            roughness 1
            metalness 0
          }
          geometry Cylinder {
            height 0.018
            radius 0.009
            subdivision 3
          }
        }
      ]
    }
    Radar {
      translation 0 0.1 0
      rotation 0 1 0 6.021385901
      children [
        Shape {
          appearance PBRAppearance {
            baseColor 0.403922 0.403922 0.403922
            roughness 1
            metalness 0
          }
          geometry DEF BOX Box {
            size 0.04 0.04 0.04
          }
        }
      ]
      minRange 0.01
      maxRange 78
      horizontalFieldOfView 2
      verticalFieldOfView 0.4
      occlusion TRUE
    }
  ]
  name "MyBot2"
  boundingObject Transform {
    translation 0 0.0415 0
    children [
      USE BODY
    ]
  }
  physics Physics {
    density -1
    mass 0.5
  }
  controller "unmovingrobot2"
  cpuConsumption 0.5
}
DEF DOUBLE_WINDOW Transform {
  translation 12 0 -30
  children [
    Window {
      translation -0.4 0 0
      name "window(9)"
    }
    Window {
      translation 0.4 0 0
      name "window(10)"
    }
  ]
}
DEF MyBot3 Robot {
  translation -26.901268340356037 -0.00044266629499561255 -27.395249240690294
  rotation 0.005433216999680235 -0.9999153964622854 0.011818632353396044 2.280140678309225
  children [
    Emitter {
      name "emitter3"
      channel 3
      baudRate 115200
    }
    Transform {
      translation 0 0.0415 0
      children [
        Shape {
          appearance PBRAppearance {
            baseColor 0.0820075 0.364731 0.8
            roughness 1
            metalness 0
          }
          geometry DEF BODY Cylinder {
            height 0.08
            radius 0.045
          }
        }
      ]
    }
    HingeJoint {
      jointParameters HingeJointParameters {
        position 76.03198979206194
        axis -1 0 0
        anchor 0 0.025 0
      }
      device [
        RotationalMotor {
          name "left wheel motor1"
          consumptionFactor 70
        }
        PositionSensor {
          name "left wheel sensor"
        }
      ]
      endPoint Solid {
        translation -0.044999956339811444 0.02521211546280492 1.5104587204385102e-06
        rotation -0.9999998919106033 0.00038451726575432265 -0.0002613909979602274 1.9329346447522984
        children [
          DEF WHEEL Transform {
            rotation 0 0 1 1.57
            children [
              Shape {
                appearance PBRAppearance {
                  baseColor 1 0 0
                  roughness 1
                  metalness 0
                }
                geometry Cylinder {
                  height 0.01
                  radius 0.025
                }
              }
            ]
          }
        ]
        name "left wheel"
        boundingObject USE WHEEL
        physics DEF PHYSICS_WHEEL Physics {
          density -1
          mass 0.05
        }
      }
    }
    HingeJoint {
      jointParameters HingeJointParameters {
        position 76.03193761087333
        axis -1 0 0
        anchor 0 0.025 0
      }
      device [
        RotationalMotor {
          name "right wheel motor1"
          consumptionFactor 70
        }
        PositionSensor {
          name "right wheel sensor"
        }
      ]
      endPoint Solid {
        translation 0.04499997016563733 0.025212064859469224 1.5109064959870295e-06
        rotation -0.999999913262392 -0.00038388474960473253 0.00016157879696903065 2.330202589945387
        children [
          USE WHEEL
        ]
        name "right wheel"
        boundingObject USE WHEEL
        physics USE PHYSICS_WHEEL
      }
    }
    DistanceSensor {
      translation -0.02 0.063 -0.042
      rotation 0 1 0 2.8553981609999997
      children [
        DEF SENSOR Transform {
          rotation 0 0 1 1.57
          children [
            Shape {
              appearance PBRAppearance {
                baseColor 0.975691 0.981481 0.0252992
                roughness 1
                metalness 0
              }
              geometry Cylinder {
                height 0.004
                radius 0.008
              }
            }
          ]
        }
      ]
      name "ds0"
      lookupTable [
        0 1024 0
        0.05 1024 0
        0.15 0 0
      ]
      numberOfRays 2
      aperture 1
    }
    DistanceSensor {
      translation 0.02 0.063 -0.042
      rotation 0 1 0 1.07
      children [
        USE SENSOR
      ]
      name "ds1"
      lookupTable [
        0 1024 0
        0.05 1024 0
        0.15 0 0
      ]
      numberOfRays 2
      aperture 1
    }
    DEF SMILE Transform {
      translation 0 0.025 -0.036
      rotation 0.7745972408364944 0.44721228048294853 0.4472139204829502 1.8234794
      children [
        Shape {
          appearance PBRAppearance {
            baseColor 0.721569 0.290196 0.290196
            roughness 1
            metalness 0
          }
          geometry Cylinder {
            height 0.018
            radius 0.009
            subdivision 3
          }
        }
      ]
    }
    DEF Radar Radar {
      translation 0 0.1 0
      rotation 0 1 0 6.283185307179586
      children [
        Shape {
          appearance PBRAppearance {
            baseColor 0.403922 0.403922 0.403922
            roughness 1
            metalness 0
          }
          geometry DEF BOX Box {
            size 0.04 0.04 0.04
          }
        }
      ]
      minRange 0.01
      maxRange 74.79926538130816
      horizontalFieldOfView 2
      transmittedPower 76
      occlusion TRUE
    }
  ]
  name "MyBot3"
  boundingObject Transform {
    translation 0 0.0415 0
    children [
      USE BODY
    ]
  }
  physics Physics {
    density -1
    mass 0.5
  }
  controller "unmovingrobot3"
}
DEF TRAIL Shape {
  appearance Appearance {
    material Material {
      diffuseColor 0 1 0
      emissiveColor 0 1 0
    }
  }
  geometry DEF TRAIL_LINE_SET IndexedLineSet {
    coord Coordinate {
      point [
        0 0 0, 0 0 0, 0 0 0, 0 0 0, 0 0 0, 0 0 0, 0 0 0, 0 0 0, 0 0 0, 0 0 0, 0 0 0, 0 0 0, 0 0 0, 0 0 0, 0 0 0, 0 0 0, 0 0 0, 0 0 0, 0 0 0, 0 0 0, 0 0 0, 0 0 0, 0 0 0, 0 0 0, 0 0 0, 0 0 0, 0 0 0, 0 0 0, 0 0 0, 0 0 0, 0 0 0, 0 0 0, 0 0 0, 0 0 0, 0 0 0, 0 0 0, 0 0 0, 0 0 0, 0 0 0, 0 0 0, 0 0 0, 0 0 0, 0 0 0, 0 0 0, 0 0 0, 0 0 0, 0 0 0, 0 0 0, 0 0 0, 0 0 0, 0 0 0, 0 0 0, 0 0 0, 0 0 0, 0 0 0, 0 0 0, 0 0 0, 0 0 0, 0 0 0, 0 0 0, 0 0 0, 0 0 0, 0 0 0, 0 0 0, 0 0 0, 0 0 0, 0 0 0, 0 0 0, 0 0 0, 0 0 0, 0 0 0, 0 0 0, 0 0 0, 0 0 0, 0 0 0, 0 0 0, 0 0 0, 0 0 0, 0 0 0, 0 0 0, 0 0 0, 0 0 0, 0 0 0, 0 0 0, 0 0 0, 0 0 0, 0 0 0, 0 0 0, 0 0 0, 0 0 0, 0 0 0, 0 0 0, 0 0 0, 0 0 0, 0 0 0, 0 0 0, 0 0 0, 0 0 0, 0 0 0, 0 0 0, 0 0 0, 0 0 0, 0 0 0, 0 0 0, 0 0 0, 0 0 0, 0 0 0, 0 0 0, 0 0 0, 0 0 0, 0 0 0, 0 0 0, 0 0 0, 0 0 0, 0 0 0, 0 0 0, 0 0 0, 0 0 0, 0 0 0, 0 0 0, 0 0 0, 0 0 0, 0 0 0, 0 0 0, 0 0 0, 0 0 0, 0 0 0, 0 0 0, 0 0 0, 0 0 0, 0 0 0, 0 0 0, 0 0 0, 0 0 0, 0 0 0, 0 0 0, 0 0 0, 0 0 0, 0 0 0, 0 0 0, 0 0 0, 0 0 0, 0 0 0, 0 0 0, 0 0 0, 0 0 0, 0 0 0, 0 0 0, 0 0 0, 0 0 0, 0 0 0, 0 0 0, 0 0 0, 0 0 0, 0 0 0, 0 0 0, 0 0 0, 0 0 0, 0 0 0, 0 0 0, 0 0 0, 0 0 0, 0 0 0, 0 0 0, 0 0 0, 0 0 0, 0 0 0, 0 0 0, 0 0 0, 0 0 0, 0 0 0, 0 0 0, 0 0 0, 0 0 0, 0 0 0, 0 0 0, 0 0 0, 0 0 0, 0 0 0, 0 0 0, 0 0 0, 0 0 0, 0 0 0, 0 0 0, 0 0 0, 0 0 0, 0 0 0, 0 0 0, 0 0 0, 0 0 0, 0 0 0, 0 0 0, 0 0 0, 0 0 0, 0 0 0, 0 0 0, 0 0 0, 0 0 0, 0 0 0, 0 0 0
      ]
    }
    coordIndex [
      0, 1, -1, 1, 2, -1, 2, 2, -1, 0, 0, -1, 0, 0, -1, 0, 0, -1, 0, 0, -1, 0, 0, -1, 0, 0, -1, 0, 0, -1, 0, 0, -1, 0, 0, -1, 0, 0, -1, 0, 0, -1, 0, 0, -1, 0, 0, -1, 0, 0, -1, 0, 0, -1, 0, 0, -1, 0, 0, -1, 0, 0, -1, 0, 0, -1, 0, 0, -1, 0, 0, -1, 0, 0, -1, 0, 0, -1, 0, 0, -1, 0, 0, -1, 0, 0, -1, 0, 0, -1, 0, 0, -1, 0, 0, -1, 0, 0, -1, 0, 0, -1, 0, 0, -1, 0, 0, -1, 0, 0, -1, 0, 0, -1, 0, 0, -1, 0, 0, -1, 0, 0, -1, 0, 0, -1, 0, 0, -1, 0, 0, -1, 0, 0, -1, 0, 0, -1, 0, 0, -1, 0, 0, -1, 0, 0, -1, 0, 0, -1, 0, 0, -1, 0, 0, -1, 0, 0, -1, 0, 0, -1, 0, 0, -1, 0, 0, -1, 0, 0, -1, 0, 0, -1, 0, 0, -1, 0, 0, -1, 0, 0, -1, 0, 0, -1, 0, 0, -1, 0, 0, -1, 0, 0, -1, 0, 0, -1, 0, 0, -1, 0, 0, -1, 0, 0, -1, 0, 0, -1, 0, 0, -1, 0, 0, -1, 0, 0, -1, 0, 0, -1, 0, 0, -1, 0, 0, -1, 0, 0, -1, 0, 0, -1, 0, 0, -1, 0, 0, -1, 0, 0, -1, 0, 0, -1, 0, 0, -1, 0, 0, -1, 0, 0, -1, 0, 0, -1, 0, 0, -1, 0, 0, -1, 0, 0, -1, 0, 0, -1, 0, 0, -1, 0, 0, -1, 0, 0, -1, 0, 0, -1, 0, 0, -1, 0, 0, -1, 0, 0, -1, 0, 0, -1, 0, 0, -1, 0, 0, -1, 0, 0, -1, 0, 0, -1, 0, 0, -1, 0, 0, -1, 0, 0, -1, 0, 0, -1, 0, 0, -1, 0, 0, -1, 0, 0, -1, 0, 0, -1, 0, 0, -1, 0, 0, -1, 0, 0, -1, 0, 0, -1, 0, 0, -1, 0, 0, -1, 0, 0, -1, 0, 0, -1, 0, 0, -1, 0, 0, -1, 0, 0, -1, 0, 0, -1, 0, 0, -1, 0, 0, -1, 0, 0, -1, 0, 0, -1, 0, 0, -1, 0, 0, -1, 0, 0, -1, 0, 0, -1, 0, 0, -1, 0, 0, -1, 0, 0, -1, 0, 0, -1, 0, 0, -1, 0, 0, -1, 0, 0, -1, 0, 0, -1, 0, 0, -1, 0, 0, -1, 0, 0, -1, 0, 0, -1, 0, 0, -1, 0, 0, -1, 0, 0, -1, 0, 0, -1, 0, 0, -1, 0, 0, -1, 0, 0, -1, 0, 0, -1, 0, 0, -1, 0, 0, -1, 0, 0, -1, 0, 0, -1, 0, 0, -1, 0, 0, -1, 0, 0, -1, 0, 0, -1, 0, 0, -1, 0, 0, -1, 0, 0, -1, 0, 0, -1, 0, 0, -1, 0, 0, -1, 0, 0, -1, 0, 0, -1, 0, 0, -1, 0, 0, -1, 0, 0, -1, 0, 0, -1, 0, 0, -1, 0, 0, -1, 0, 0, -1, 0, 0, -1, 0, 0, -1, 0, 0, -1, 0, 0, -1, 0, 0, -1, 0, 0, -1, 0, 0, -1, 0, 0, -1, 0, 0, -1, 0, 0, -1, 0, 0, -1, 0, 0, -1, 0, 0, -1, 0, 0, -1, 0, 0, -1, 0, 0, -1, 0, 0, -1, 0, 0, -1, 0, 0, -1, 0, 0, -1, 0, 0, -1, 0, 0, -1, 0, 0, -1, 0, 0, -1, 0, 0, -1, 0, 0, -1, 0, 0, -1
    ]
  }
}
DEF Supervisior1 Robot {
  translation 0 -1 0
  children [
    DEF emitter9 Emitter {
      name "emitter9"
      channel 9
    }
    DEF emittertoyellowbox Emitter {
      name "emittertoyellowbox"
      channel 7
    }
    Receiver {
      channel 8
    }
    DEF emitter Emitter {
      channel 8
    }
    Receiver {
      name "receiver2"
      channel 3
    }
    Receiver {
      name "receiver1"
      channel 2
    }
    Receiver {
      name "receiver0"
      channel 1
    }
  ]
  controller "supervisor12_3"
  supervisor TRUE
  cpuConsumption 0.5
}
DEF PIONEER_3AT Pioneer3at {
  translation 7.79679816601549 0.1076110687995452 -0.15875774163875567
  rotation -6.558898012352265e-05 0.9999999227025435 0.0003876764021381445 2.8049753199616103
  controller "ros"
  controllerArgs "--name=pioneer3at"
  extensionSlot [
    DEF RADAR_TARGET Solid {
      translation 0 0.19999999999999998 0
      children [
        Shape {
          appearance PBRAppearance {
            baseColor 1 0 0
            roughness 1
            metalness 0
          }
          geometry DEF BOX Box {
            size 0.04 0.04 0.04
          }
        }
      ]
      name ""
      radarCrossSection 1
    }
    Camera {
      translation 0 0.17 -0.22
      width 256
      height 128
      motionBlur 500
      noise 0.02
    }
    Accelerometer {
      lookupTable [
        -39.24 -39.24 0.005
        39.24 39.24 0.005
      ]
    }
    Gyro {
      lookupTable [
        -50 -50 0.005
        50 50 0.005
      ]
    }
    SickLms291 {
      translation 0 0.23 -0.136
      noise 0.1
    }
    GPS {
    }
    InertialUnit {
    }
  ]
}
