#VRML_SIM R2019a utf8
WorldInfo {
  info [
    "Example use of a Radar device."
  ]
}
Viewpoint {
  orientation -0.9939621243051002 0.08656989364719375 0.06741623662594812 1.329172283815585
  position -1.584634366308005 137.6209015760155 44.02862863352629
}
TexturedBackground {
}
TexturedBackgroundLight {
}
Floor {
  size 60 60
  tileSize 1 1
  appearance ThreadMetalPlate {
  }
}
DEF KITCHEN Transform {
  translation 27.9 0 21.8
  rotation 0 1 0 4.71239
  children [
    Cabinet {
      hidden translation_6 4.858122792938957e-10 0.6895858148244683 0.6999999877129319
      hidden rotation_6 -0.9992241779573237 5.75188429457274e-09 -0.03938327291516976 -0.0001904711614922333
      hidden position_6_0 0.0008252642702646062
      hidden translation_7 6.776557723298104e-08 0 0.00016422757114115303
      hidden rotation_7 0 1 0 0.0008252642703046527
      translation 1 0.83 -2.15
      depth 0.7
      outerThickness 0.02
      rowsHeights [
        0.2, 0.2, 0.2, 0.2, 0.2, 0.34
      ]
      columnsWidths [
        0.4
      ]
      layout [
        "LeftSidedDoor (1, 1, 1, 6, 1.5)"
        "Shelf (1,2, 1, 0)"
        "Shelf (1,3, 1, 0)"
        "Shelf (1,4, 1, 0)"
        "Shelf (1,5, 1, 0)"
        "Shelf (1,6, 1, 0)"
      ]
      handle CabinetHandle {
        translation -0.3 0 0
        handleLength 0.1
        handleRadius 0.008
        handleColor 0.427451 0.513725 0.533333
      }
    }
    Cabinet {
      hidden translation_6 -4.851052892718144e-10 1.074596973256894 0.6699999892725899
      hidden rotation_6 0.9989766262025682 1.1664332754325265e-08 -0.0452294185341141 0.00018204076748668842
      hidden position_6_0 -0.000862444320735784
      hidden translation_7 -8.141002216799365e-08 0 0.00018878903840519203
      hidden rotation_7 0 -1 0 0.0008624443206932233
      hidden translation_10 -4.851017365581356e-10 1.7445969732813658 0.6699999892725934
      hidden rotation_10 0.9989766326148846 1.1667216641841514e-08 -0.04522927690584593 0.00018204072842781585
      hidden position_10_0 -0.0008624441027402389
      hidden translation_11 -8.140998147831979e-08 0 0.0001887889906859846
      hidden rotation_11 0 -1 0 0.000862444102882333
      translation -1.65 0.15 0.11
      rotation 0 1 0 1.5708
      name "cabinet(1)"
      depth 0.67
      outerThickness 0.02
      rowsHeights [
        0.68, 0.25, 0.25, 0.25, 0.25, 0.34
      ]
      columnsWidths [
        0.44
      ]
      layout [
        "RightSidedDoor (1, 2, 1, 3, 1.5)"
        "RightSidedDoor (1, 5, 1, 2, 1.5)"
        "Shelf (1,2, 1, 0)"
        "Shelf (1,3, 1, 0)"
        "Shelf (1,4, 1, 0)"
        "Shelf (1,5, 1, 0)"
        "Shelf (1,6, 1, 0)"
      ]
      handle CabinetHandle {
        translation -0.15 0 0
        handleLength 0.1
        handleRadius 0.008
        handleColor 0.427451 0.513725 0.533333
      }
    }
    Cabinet {
      hidden translation_6 -0.4400000002650053 0.33965066761544693 0.49999999569715214
      hidden rotation_6 0.9981139467773881 1.153535417434659e-08 -0.061388510720372526 0.00013408887977678024
      hidden position_6_0 -0.0006349560267409172
      hidden translation_7 -4.412686285815148e-08 0 0.00013899186491404735
      hidden rotation_7 0 -1 0 0.0006349560265654661
      hidden translation_10 2.6545876607997343e-10 0.3396506676263642 0.4999999956971344
      hidden rotation_10 -0.9981070899550744 1.1562599907829943e-08 -0.061499894157736865 -0.00013408977802653607
      hidden position_10_0 0.0006350821064219772
      hidden translation_11 4.414438825595113e-08 0 0.00013901946375066704
      hidden rotation_11 0 0.9999999999999999 0 0.0006350821063524538
      hidden translation_14 0.44000000026543873 0.3396506676364406 0.4999999956971344
      hidden rotation_14 -0.9981070837453372 1.1566741509132333e-08 -0.061499994938036165 -0.00013408975771947004
      hidden position_14_0 0.0006350819707935686
      hidden translation_15 4.414436974298219e-08 0 0.0001390194340616142
      hidden rotation_15 0 1 0 0.0006350819706954789
      translation 0.1 1.4 -2.15
      name "cabinet(2)"
      outerThickness 0.02
      rowsHeights [
        0.21, 0.21, 0.22
      ]
      columnsWidths [
        0.44, 0.44, 0.44
      ]
      layout [
        "RightSidedDoor (1, 1, 1, 3, 1.5)"
        "LeftSidedDoor (2, 1, 1, 3, 1.5)"
        "LeftSidedDoor (3, 1, 1, 3, 1.5)"
        "Shelf (1, 2, 3, 0)"
        "Shelf (1, 3, 2, 0)"
        "Shelf (1, 1, 0, 1)"
        "Shelf (2, 1, 0, 3)"
      ]
      handle CabinetHandle {
        translation -0.2 0 0
        handleLength 0.1
        handleRadius 0.008
        handleColor 0.427451 0.513725 0.533333
      }
    }
    Cabinet {
      hidden translation_6 -2.6497559701965656e-10 0.33965066765201146 0.4999999956971628
      hidden rotation_6 0.998113936642243 1.1532540343794578e-08 -0.061388675507169435 0.00013408880443583027
      hidden position_6_0 -0.000634955717786383
      hidden translation_7 -4.412682028109849e-08 0 0.00013899179728391333
      hidden rotation_7 0 -1 0 0.0006349557181293159
      translation -1.647 1.4 -0.37
      rotation 0 1 0 1.5708
      name "cabinet(3)"
      outerThickness 0.02
      rowsHeights [
        0.21, 0.21, 0.22
      ]
      columnsWidths [
        0.44
      ]
      layout [
        "RightSidedDoor (1, 1, 1, 3, 1.5)"
        "Shelf (1, 2 ,1 , 0)"
        "Shelf (1, 3 ,1 , 0)"
      ]
      handle CabinetHandle {
        translation -0.2 0 0
        handleLength 0.1
        handleRadius 0.008
        handleColor 0.427451 0.513725 0.533333
      }
    }
    Cabinet {
      hidden translation_6 -0.06500000027951813 0.339650666023115 0.4999999956999517
      hidden rotation_6 0.997843126617826 1.939111675571177e-08 -0.06564369475860322 0.0001341286091469709
      hidden position_6_0 -0.0006752983726266469
      hidden translation_7 -5.3315359266337126e-08 0 0.00015790162997816691
      hidden rotation_7 0 -1 0 0.0006752983724137555
      hidden translation_10 0.4049977179302502 0.33965068141193133 0.499999907241925
      hidden rotation_10 -0.9977486868062696 0.006550988400244706 -0.06674310846330492 -0.00013356493605764353
      hidden position_10_0 -0.002209533369804852
      hidden translation_11 5.707710017677226e-07 0 -0.0005166437198153599
      hidden rotation_11 0 -1 0 0.0022095333697251572
      hidden translation_14 -0.4700000002026492 0.3396506704334735 0.49999999571378595
      hidden rotation_14 0.9988690144548423 6.45076164776714e-09 -0.04754673450419176 0.00013398162416183404
      hidden position_14_0 -0.0004970144730895774
      hidden translation_15 -2.0892002267069998e-08 0 8.406999466189287e-05
      hidden rotation_15 0 -1 0 0.0004970144727567214
      translation -1.48 0.15 -0.79
      rotation 0 1 0 1.5708
      name "cabinet(4)"
      outerThickness 0.02
      rowsHeights [
        0.21, 0.21, 0.22
      ]
      columnsWidths [
        0.34, 0.47, 0.47
      ]
      layout [
        "RightSidedDoor (2, 1, 1, 3, 1.5)"
        "LeftSidedDoor (3, 1, 1, 3, 1.5)"
        "RightSidedDoor (1, 1, 1, 3, 1.5)"
        "Shelf (1, 2, 1, 0)"
        "Shelf (1, 3, 1, 0)"
        "Shelf (1, 1, 0, 3)"
        "Shelf (2, 1, 0, 3)"
      ]
      handle CabinetHandle {
        translation 0.1 0 0
        handleLength 0.1
        handleRadius 0.008
        handleColor 0.427451 0.513725 0.533333
      }
    }
    Cabinet {
      hidden translation_6 -0.049999999351932445 0.26958580301998114 0.6999999876917471
      hidden rotation_6 -0.9985918436547857 3.043646122923516e-08 -0.053050257173128966 -0.00019060922951150095
      hidden position_6_0 0.0010899603433578164
      hidden translation_7 1.5957990412429623e-07 0 0.00029281778826448614
      hidden rotation_7 0 1 0 0.0010899603432471797
      hidden translation_10 0.8650000005174903 0.3395858117560687 0.6999999877170815
      hidden rotation_10 -0.9991062925505475 1.2258611686339002e-08 -0.042268382816231166 -0.00019049817167550779
      hidden position_10_0 0.0008833962820396673
      hidden translation_11 8.347235169736678e-08 0 0.0001889805250556136
      hidden rotation_11 0 1 0 0.0008833962819794954
      hidden translation_14 0.4349999994824678 0.33958581176973 0.6999999877170922
      hidden rotation_14 0.9991062903991694 1.2259195760375013e-08 -0.04226843366876034 0.00019049815187540355
      hidden position_14_0 -0.0008833961977176673
      hidden translation_15 -8.347233582117752e-08 0 0.00018898050701703672
      hidden rotation_15 0 -1 0 0.0008833961975247668
      hidden translation_18 -0.7000000000000348 0.14389958028058095 0.699999755372243
      hidden rotation_18 -1 1.3656899533483916e-12 8.298463258193353e-15 -0.0007316453796847169
      hidden position_18_0 0.5558116595877706
      hidden translation_19 0 0 0.5558116595877706
      hidden translation_26 -0.6999991329881041 0.3940316741609654 0.6999996933623258
      hidden rotation_26 0.9999994470243038 0.0006747677835679844 -0.0008066222938846435 0.0006306534844559814
      hidden position_26_0 0.4377800279406668
      hidden translation_27 0 0 0.4377800279406668
      hidden translation_34 -0.6999999999999673 0.5891508586950758 0.6999997719081748
      hidden rotation_34 -1 3.1997629618600855e-12 -9.775168651562587e-09 -0.0006245467244368863
      hidden position_34_0 0.5433668834044814
      hidden translation_35 0 0 0.5433668834044814
      hidden translation_42 -0.04999999999996163 0.5891508588402443 0.6999997719088356
      hidden rotation_42 1 1.3154633250501162e-11 4.655955937467567e-09 0.0006245442468292673
      hidden position_42_0 0.5433606998736414
      hidden translation_43 0 0 0.5433606998736414
      translation 0.12 0.15 -2.15
      name "cabinet(5)"
      depth 0.7
      outerThickness 0.02
      rowsHeights [
        0.25, 0.25, 0.14
      ]
      columnsWidths [
        0.76, 0.54, 0.43, 0.43
      ]
      layout [
        "LeftSidedDoor (2, 1, 1, 2, 1.5)"
        "LeftSidedDoor (4, 1, 1, 3, 1.5)"
        "RightSidedDoor (3, 1, 1, 3, 1.5)"
        "Drawer (1, 1, 1, 1, 3.5)"
        "Drawer (1, 2, 1, 1, 3.5)"
        "Drawer (1, 3, 1, 1, 3.5)"
        "Drawer (2, 3, 1, 1, 3.5)"
        "Shelf (1, 2, 1, 0)"
        "Shelf (1, 3, 2, 0)"
        "Shelf (3, 2, 2, 0)"
        "Shelf (1, 1, 0, 3)"
        "Shelf (2, 1, 0, 3)"
        "Shelf (3, 1, 0, 1)"
      ]
      handle CabinetHandle {
        handleLength 0.1
        handleRadius 0.008
        handleColor 0.427451 0.513725 0.533333
      }
    }
    SolidBox {
      translation 0.12 0.07 -1.55
      size 2.2 0.16 0.2
      appearance PBRAppearance {
        baseColor 0.8 0.8 0.8
        roughness 0.5
        metalness 0
        textureTransform TextureTransform {
          scale 4 4
        }
      }
    }
    SolidBox {
      translation -1.08 0.07 -0.65
      rotation 0 1 0 1.5708
      name "box(1)"
      size 2 0.16 0.2
      appearance PBRAppearance {
        baseColor 0.8 0.8 0.8
        roughness 0.5
        metalness 0
        textureTransform TextureTransform {
          scale 4 4
        }
      }
    }
    SolidBox {
      translation 1.12 0.07 -1.9
      rotation 0 -1 0 4.71239
      name "box(2)"
      size 0.5 0.16 0.2
      appearance PBRAppearance {
        roughness 0.5
        metalness 0
        textureTransform TextureTransform {
          scale 4 4
        }
      }
    }
    SolidBox {
      translation -1.415 0.07 0.25
      rotation 0 -1 0 6.28318
      name "box(3)"
      size 0.47 0.16 0.2
      appearance PBRAppearance {
        baseColor 0.8 0.8 0.8
        roughness 0.5
        metalness 0
        textureTransform TextureTransform {
          scale 4 4
        }
      }
    }
    Fridge {
      hidden position_0_0 -6.764432420937373e-07
      hidden position_0_1 2.2450056491224756e-06
      hidden rotation_1 0 -1 0 6.763223241514129e-07
      hidden rotation_2 0 1 0 2.2450863083183995e-06
      translation 1.57 0 -1.8
      rotation 0 1 0 4.71239
    }
    Worktop {
      translation -1.31 0.86 -0.345
      rotation 0 1 0 4.71239
      size 0.43 0.06 0.7
    }
    Worktop {
      translation -1.531 0.86 -0.78
      rotation 0 1 0 4.71239
      name "worktop(1)"
      size 0.44 0.06 0.237
    }
    Worktop {
      translation -1.003 0.86 -0.780001
      rotation 0 1 0 4.71239
      name "worktop(2)"
      size 0.442 0.06 0.085
    }
    Worktop {
      translation -1.306 0.86 -1.22
      rotation 0 -1 0 1.5708
      name "worktop(3)"
      size 0.44 0.06 0.69
    }
    Worktop {
      translation -0.435 0.86 -1.79
      name "worktop(4)"
      size 2.43 0.06 0.7
    }
    Sink {
      translation -1.33 0.87 -0.78
      rotation 0 1 0 4.71239
    }
    HotPlate {
      translation -1.14971 0.86 -1.62912
      rotation 0 -1 0 5.49779
    }
    Oven {
      hidden position_0_0 -9.77616449219552e-38
      translation -1.24 0.51 0.11
    }
  ]
}
DEF INTERNAL_WINDOW Window {
  translation -11.283624405978252 -1.5987211554602254e-14 -0.9089969314674011
  rotation 0 -1 0 3.141591686718346
  name "window(4)"
  size 0.9 2.7 0.2
}
DEF INTERNAL_WINDOW Window {
  translation -7.764715143088619 -1.4210854715202004e-14 -0.9394903033116844
  rotation 0 -1 0 3.141591686718346
  name "window(3)"
  size 0.9 2.7 0.2
}
DEF INTERNAL_WINDOW Window {
  translation -9.547060928142615 -1.2434497875801753e-14 -0.9229028115136266
  rotation 0 -1 0 3.141591686718346
  name "window(2)"
  size 0.9 2.7 0.2
}
DEF INTERNAL_WINDOW Window {
  translation -10.424088153855532 -1.4210854715202004e-14 -0.9263832371812324
  rotation 0 -1 0 3.141591686718346
  name "window(1)"
  size 0.9 2.7 0.2
}
DEF INTERNAL_WALL Wall {
  translation -20.841722096896945 1.7763568394002505e-15 -0.895663661597073
  name "wall(7)"
  size 18.2 2.7 0.2
}
DEF INTERNAL_WINDOW Window {
  translation -8.661028945763917 3.197442310920451e-14 -0.9265567823689587
  rotation 0 -1 0 3.141591686718346
  size 0.9 2.7 0.2
}
DEF INTERNAL_WALL Wall {
  translation 18.841850244600412 -1.0004599999999999e-09 20.10700920905251
  name "wall(13)"
  size 22.5 2.4 0.2
}
DEF EXTERNAL_WALL Wall {
  translation -30 0 0
  rotation 0 1 0 1.5708
  name "wall(12)"
  size 60 2.4 0.2
}
DEF EXTERNAL_WALL Wall {
  translation 30 0 0
  rotation 0 1 0 1.5708
  name "wall(11)"
  size 60 2.4 0.2
}
DEF EXTERNAL_WALL Wall {
  translation -27.45 0 30
  name "wall(10)"
  size 5.3 2.4 0.2
}
DEF DOUBLE_WINDOW Transform {
  translation -24 0 30
  children [
    Window {
      translation -0.4 0 0
      name "window(21)"
    }
    Window {
      translation 0.4 0 0
      name "window(22)"
    }
  ]
}
DEF DOUBLE_WINDOW Transform {
  translation -12 0 30
  children [
    Window {
      translation -0.4 0 0
      name "window(19)"
    }
    Window {
      translation 0.4 0 0
      name "window(20)"
    }
  ]
}
DEF DOUBLE_WINDOW Transform {
  translation 12 0 30
  children [
    Window {
      translation -0.4 0 0
      name "window(17)"
    }
    Window {
      translation 0.4 0 0
      name "window(18)"
    }
  ]
}
DEF DOUBLE_WINDOW Transform {
  translation 24 0 30
  children [
    Window {
      translation -0.4 0 0
      name "window(15)"
    }
    Window {
      translation 0.4 0 0
      name "window(16)"
    }
  ]
}
DEF EXTERNAL_WALL Wall {
  translation -18 0 30
  name "wall(8)"
  size 10.4 2.4 0.2
}
DEF EXTERNAL_WALL Wall {
  translation 27.45 0 30
  name "wall(9)"
  size 5.3 2.4 0.2
}
DEF EXTERNAL_WALL Wall {
  translation 18 0 30
  name "wall(6)"
  size 10.4 2.4 0.2
}
DEF EXTERNAL_WALL Wall {
  translation 0 0 30
  name "wall(5)"
  size 22.4 2.4 0.2
}
DEF DOUBLE_WINDOW Transform {
  translation -12 0 -30
  children [
    Window {
      translation -0.4 0 0
      name "window(11)"
    }
    Window {
      translation 0.4 0 0
      name "window(12)"
    }
  ]
}
DEF DOUBLE_WINDOW Transform {
  translation -24 0 -30
  children [
    Window {
      translation -0.4 0 0
      name "window(13)"
    }
    Window {
      translation 0.4 0 0
      name "window(14)"
    }
  ]
}
DEF DOUBLE_WINDOW Transform {
  translation 24 0 -30
  children [
    Window {
      translation -0.4 0 0
      name "window(7)"
    }
    Window {
      translation 0.4 0 0
      name "window(8)"
    }
  ]
}
DEF EXTERNAL_WALL Wall {
  translation -27.45 0 -30
  name "wall(4)"
  size 5.3 2.4 0.2
}
DEF EXTERNAL_WALL Wall {
  translation 27.45 0 -30
  name "wall(3)"
  size 5.3 2.4 0.2
}
DEF EXTERNAL_WALL Wall {
  translation -18 0 -30
  name "wall(2)"
  size 10.4 2.4 0.2
}
DEF EXTERNAL_WALL Wall {
  translation 18 0 -30
  name "wall(1)"
  size 10.4 2.4 0.2
}
DEF EXTERNAL_WALL Wall {
  translation 0 0 -30
  size 22.4 2.4 0.2
}
Shape {
  appearance PBRAppearance {
    baseColor 0 0 1
    roughness 1
    metalness 0
  }
  geometry IndexedFaceSet {
    coord Coordinate {
      point [
        0.21 0 0.07
        0.09 0 0.22
        0.25 0 0.26
        0.21 0.0001 0.07
        0.09 0.0001 0.22
        0.25 0.0001 0.26
      ]
    }
    coordIndex [
      2, 1, 0, -1, 3, 4, 5, -1, 0, 1
      4, 3, -1, 1, 2, 5, 4, -1, 2, 0
      3, 5, -1
    ]
  }
}
DEF YELLOW_BOX Solid {
  translation 7.348756188127709 1.22 23.541290456945653
  rotation 0 1 0 3.142388850922486
  children [
    DEF Shape Shape {
      appearance DEF PBR PBRAppearance {
        baseColor 1 1 0
        roughness 0.03934117200000009
        metalness 0
      }
      geometry DEF geometryBox Box {
        size 0.30000000000000004 2.5 11.9
      }
    }
  ]
  name "YELLOW_BOX"
  boundingObject Shape {
    appearance PBRAppearance {
      roughness 1.1102230246251565e-16
      metalness 0
    }
    geometry USE geometryBox
  }
}
DEF MyBot1 Robot {
  translation 28.000000007377153 -0.00044385087554563163 28.00000000634367
  rotation 0.02466988170616117 -0.9996258634069904 -0.01181228785768245 -0.8937216031968319
  children [
    Emitter {
      channel 1
      baudRate 115200
    }
    Transform {
      translation 0 0.0415 0
      children [
        Shape {
          appearance PBRAppearance {
            baseColor 0.0820075 0.364731 0.8
            roughness 1
            metalness 0
          }
          geometry DEF BODY Cylinder {
            height 0.08
            radius 0.045
          }
        }
      ]
    }
    HingeJoint {
      jointParameters HingeJointParameters {
        position 76.03200974304195
        axis -1 0 0
        anchor 0 0.025 0
      }
      device [
        RotationalMotor {
          name "left wheel motor1"
          consumptionFactor 70
        }
        PositionSensor {
          name "left wheel sensor"
        }
      ]
      endPoint Solid {
        translation -0.04499997587308603 0.025212115180553225 -1.5429295071599957e-06
        rotation -0.9999998918029794 0.0003806369968944196 -0.00026741261401666956 1.9316464752838096
        children [
          DEF WHEEL Transform {
            rotation 0 0 1 1.57
            children [
              Shape {
                appearance PBRAppearance {
                  baseColor 1 0 0
                  roughness 1
                  metalness 0
                }
                geometry Cylinder {
                  height 0.01
                  radius 0.025
                }
              }
            ]
          }
        ]
        name "left wheel"
        boundingObject USE WHEEL
        physics DEF PHYSICS_WHEEL Physics {
          density -1
          mass 0.05
        }
        linearVelocity 3.91875431876881e-08 9.27915475153899e-06 3.246158694152154e-08
        angularVelocity 1.1355208327787042e-06 -1.047874350890524e-09 -1.4121308937806096e-06
      }
    }
    HingeJoint {
      jointParameters HingeJointParameters {
        position 76.03204409444184
        axis -1 0 0
        anchor 0 0.025 0
      }
      device [
        RotationalMotor {
          name "right wheel motor1"
          consumptionFactor 70
        }
        PositionSensor {
          name "right wheel sensor"
        }
      ]
      endPoint Solid {
        translation 0.04499998975353129 0.025212064463460623 -1.5432397535942245e-06
        rotation -0.9999999132084019 -0.00038147683474445705 0.00016750705439020356 2.329000627721869
        children [
          USE WHEEL
        ]
        name "right wheel"
        boundingObject USE WHEEL
        physics USE PHYSICS_WHEEL
        linearVelocity 4.007807987426075e-08 9.279186117025875e-06 3.132443312766577e-08
        angularVelocity 1.1361537225439792e-06 3.173621945049791e-10 -1.411627465652246e-06
      }
    }
    DistanceSensor {
      translation -0.02 0.063 -0.042
      rotation 0 1 0 2.07
      children [
        DEF SENSOR Transform {
          rotation 0 0 1 1.57
          children [
            Shape {
              appearance PBRAppearance {
                baseColor 0.975691 0.981481 0.0252992
                roughness 1
                metalness 0
              }
              geometry Cylinder {
                height 0.004
                radius 0.008
              }
            }
          ]
        }
      ]
      name "ds0"
      lookupTable [
        0 1024 0
        0.05 1024 0
        0.15 0 0
      ]
      numberOfRays 2
      aperture 1
    }
    DistanceSensor {
      translation 0.02 0.063 -0.042
      rotation 0 1 0 1.07
      children [
        USE SENSOR
      ]
      name "ds1"
      lookupTable [
        0 1024 0
        0.05 1024 0
        0.15 0 0
      ]
      numberOfRays 2
      aperture 1
    }
    DEF SMILE Transform {
      translation 0 0.025 -0.036
      rotation 0.7745972408364944 0.44721228048294853 0.4472139204829502 1.8234794
      children [
        Shape {
          appearance PBRAppearance {
            baseColor 0.721569 0.290196 0.290196
            roughness 1
            metalness 0
          }
          geometry Cylinder {
            height 0.018
            radius 0.009
            subdivision 3
          }
        }
      ]
    }
    Radar {
      translation 0 0.1 0
      children [
        Shape {
          appearance PBRAppearance {
            baseColor 0.403922 0.403922 0.403922
            roughness 1
            metalness 0
          }
          geometry DEF BOX Box {
            size 0.04 0.04 0.04
          }
        }
      ]
      minRange 0.01
      maxRange 80
      horizontalFieldOfView 2
      verticalFieldOfView 0.5
      frequency 28
      transmittedPower 28
    }
  ]
  name "MyBot1"
  boundingObject Transform {
    translation 0 0.0415 0
    children [
      USE BODY
    ]
  }
  physics Physics {
    density -1
    mass 0.5
  }
  controller "unmovingrobot1"
  battery [
    0, 100, 30
  ]
  cpuConsumption 5
  linearVelocity 9.715588946415737e-08 9.271927350034372e-06 7.813613423056596e-08
  angularVelocity 2.2436073279038744e-06 -3.728657302254681e-10 -2.7891626710862327e-06
}
DEF MyBot2 Robot {
  translation 28.000003639963104 -0.0004427202892341997 -25.000578087257786
  rotation 0.001873529655630249 -0.9999284012160969 -0.011818727852418961 -2.8275026859791716
  children [
    Emitter {
      name "emitter2"
      channel 2
      baudRate 115200
    }
    Transform {
      translation 0 0.0415 0
      children [
        Shape {
          appearance PBRAppearance {
            baseColor 0.0820075 0.364731 0.8
            roughness 1
            metalness 0
          }
          geometry DEF BODY Cylinder {
            height 0.08
            radius 0.045
          }
        }
      ]
    }
    HingeJoint {
      jointParameters HingeJointParameters {
        position 76.03199319269041
        axis -1 0 0
        anchor 0 0.025 0
      }
      device [
        RotationalMotor {
          name "left wheel motor1"
          consumptionFactor 70
        }
        PositionSensor {
          name "left wheel sensor"
        }
      ]
      endPoint Solid {
        translation -0.04499995669495857 0.025212115600134165 -1.4985784106837476e-06
        rotation -0.9999998918132594 0.0003806742783937006 -0.00026732108659914837 1.9316345777584765
        children [
          DEF WHEEL Transform {
            rotation 0 0 1 1.57
            children [
              Shape {
                appearance PBRAppearance {
                  baseColor 1 0 0
                  roughness 1
                  metalness 0
                }
                geometry Cylinder {
                  height 0.01
                  radius 0.025
                }
              }
            ]
          }
        ]
        name "left wheel"
        boundingObject USE WHEEL
        physics DEF PHYSICS_WHEEL Physics {
          density -1
          mass 0.05
        }
        linearVelocity -8.689906201077435e-08 4.1725039462267415e-07 2.150731684464278e-07
        angularVelocity 9.079469064390733e-06 -4.3544650748912874e-08 3.2024638872887724e-06
      }
    }
    HingeJoint {
      jointParameters HingeJointParameters {
        position 76.03196354674051
        axis -1 0 0
        anchor 0 0.025 0
      }
      device [
        RotationalMotor {
          name "right wheel motor1"
          consumptionFactor 70
        }
        PositionSensor {
          name "right wheel sensor"
        }
      ]
      endPoint Solid {
        translation 0.04499997063249234 0.025212064874692148 -1.4987076207900664e-06
        rotation -0.9999999132145668 -0.0003814927114000801 0.00016743407692310642 2.32892474050822
        children [
          USE WHEEL
        ]
        name "right wheel"
        boundingObject USE WHEEL
        physics USE PHYSICS_WHEEL
        linearVelocity -6.630459217471737e-08 3.956316623526111e-07 2.237612938523148e-07
        angularVelocity 9.077768360288051e-06 -4.316334309802752e-08 3.2024530241158306e-06
      }
    }
    DistanceSensor {
      translation -0.02 0.063 -0.042
      rotation 0 1 0 2.07
      children [
        DEF SENSOR Transform {
          rotation 0 0 1 1.57
          children [
            Shape {
              appearance PBRAppearance {
                baseColor 0.975691 0.981481 0.0252992
                roughness 1
                metalness 0
              }
              geometry Cylinder {
                height 0.004
                radius 0.008
              }
            }
          ]
        }
      ]
      name "ds0"
      lookupTable [
        0 1024 0
        0.05 1024 0
        0.15 0 0
      ]
      numberOfRays 2
      aperture 1
    }
    DistanceSensor {
      translation 0.02 0.063 -0.042
      rotation 0 1 0 1.07
      children [
        USE SENSOR
      ]
      name "ds1"
      lookupTable [
        0 1024 0
        0.05 1024 0
        0.15 0 0
      ]
      numberOfRays 2
      aperture 1
    }
    DEF SMILE Transform {
      translation 0 0.025 -0.036
      rotation 0.7745972408364944 0.44721228048294853 0.4472139204829502 1.8234794
      children [
        Shape {
          appearance PBRAppearance {
            baseColor 0.721569 0.290196 0.290196
            roughness 1
            metalness 0
          }
          geometry Cylinder {
            height 0.018
            radius 0.009
            subdivision 3
          }
        }
      ]
    }
    Radar {
      translation 0 0.1 0
      rotation 0 1 0 6.021385901
      children [
        Shape {
          appearance PBRAppearance {
            baseColor 0.403922 0.403922 0.403922
            roughness 1
            metalness 0
          }
          geometry DEF BOX Box {
            size 0.04 0.04 0.04
          }
        }
      ]
      minRange 0.01
      maxRange 78
      horizontalFieldOfView 2
      verticalFieldOfView 0.4
    }
  ]
  name "MyBot2"
  boundingObject Transform {
    translation 0 0.0415 0
    children [
      USE BODY
    ]
  }
  physics Physics {
    density -1
    mass 0.5
  }
  controller "unmovingrobot2"
  cpuConsumption 0.5
  linearVelocity -1.210069779875857e-07 4.026182110262651e-07 3.342975168935385e-07
  angularVelocity 7.393020507204194e-06 -4.348221790793851e-08 2.654790257394368e-06
}
DEF DOUBLE_WINDOW Transform {
  translation 12 0 -30
  children [
    Window {
      translation -0.4 0 0
      name "window(9)"
    }
    Window {
      translation 0.4 0 0
      name "window(10)"
    }
  ]
}
DEF MyBot3 Robot {
  translation -26.000336438285505 -0.00044385201026723997 -27.000193706594455
  rotation 0.005434395562790925 -0.9999153955179682 0.01181817037500109 2.279924555334966
  children [
    Emitter {
      name "emitter3"
      channel 3
      baudRate 115200
    }
    Transform {
      translation 0 0.0415 0
      children [
        Shape {
          appearance PBRAppearance {
            baseColor 0.0820075 0.364731 0.8
            roughness 1
            metalness 0
          }
          geometry DEF BODY Cylinder {
            height 0.08
            radius 0.045
          }
        }
      ]
    }
    HingeJoint {
      jointParameters HingeJointParameters {
        position 76.0319912066948
        axis -1 0 0
        anchor 0 0.025 0
      }
      device [
        RotationalMotor {
          name "left wheel motor1"
          consumptionFactor 70
        }
        PositionSensor {
          name "left wheel sensor"
        }
      ]
      endPoint Solid {
        translation -0.04499995633981145 0.025212115464941454 1.5101586549333656e-06
        rotation -0.999999891910709 0.0003845168930664148 -0.0002613911422696521 1.9329360593850067
        children [
          DEF WHEEL Transform {
            rotation 0 0 1 1.57
            children [
              Shape {
                appearance PBRAppearance {
                  baseColor 1 0 0
                  roughness 1
                  metalness 0
                }
                geometry Cylinder {
                  height 0.01
                  radius 0.025
                }
              }
            ]
          }
        ]
        name "left wheel"
        boundingObject USE WHEEL
        physics DEF PHYSICS_WHEEL Physics {
          density -1
          mass 0.05
        }
        linearVelocity -1.8285038580478423e-07 9.373640584576313e-06 -4.787661666556741e-08
        angularVelocity -2.8410058963833656e-06 -4.498214719173745e-08 6.4095414418549934e-06
      }
    }
    HingeJoint {
      jointParameters HingeJointParameters {
        position 76.03193902549697
        axis -1 0 0
        anchor 0 0.025 0
      }
      device [
        RotationalMotor {
          name "right wheel motor1"
          consumptionFactor 70
        }
        PositionSensor {
          name "right wheel sensor"
        }
      ]
      endPoint Solid {
        translation 0.04499997016563732 0.025212064861606376 1.5106065040228981e-06
        rotation -0.9999999132624446 -0.00038388451869158835 0.00016157901940652068 2.330204004568904
        children [
          USE WHEEL
        ]
        name "right wheel"
        boundingObject USE WHEEL
        physics USE PHYSICS_WHEEL
        linearVelocity -1.4065111670841754e-07 9.191974010620999e-06 -9.505108023698645e-08
        angularVelocity -2.8405718162225403e-06 -4.1834131343293376e-08 6.410268955428624e-06
      }
    }
    DistanceSensor {
      translation -0.02 0.063 -0.042
      rotation 0 1 0 2.8553981609999997
      children [
        DEF SENSOR Transform {
          rotation 0 0 1 1.57
          children [
            Shape {
              appearance PBRAppearance {
                baseColor 0.975691 0.981481 0.0252992
                roughness 1
                metalness 0
              }
              geometry Cylinder {
                height 0.004
                radius 0.008
              }
            }
          ]
        }
      ]
      name "ds0"
      lookupTable [
        0 1024 0
        0.05 1024 0
        0.15 0 0
      ]
      numberOfRays 2
      aperture 1
    }
    DistanceSensor {
      translation 0.02 0.063 -0.042
      rotation 0 1 0 1.07
      children [
        USE SENSOR
      ]
      name "ds1"
      lookupTable [
        0 1024 0
        0.05 1024 0
        0.15 0 0
      ]
      numberOfRays 2
      aperture 1
    }
    DEF SMILE Transform {
      translation 0 0.025 -0.036
      rotation 0.7745972408364944 0.44721228048294853 0.4472139204829502 1.8234794
      children [
        Shape {
          appearance PBRAppearance {
            baseColor 0.721569 0.290196 0.290196
            roughness 1
            metalness 0
          }
          geometry Cylinder {
            height 0.018
            radius 0.009
            subdivision 3
          }
        }
      ]
    }
    DEF Radar Radar {
      translation 0 0.1 0
      rotation 0 1 0 6.283185307179586
      children [
        Shape {
          appearance PBRAppearance {
            baseColor 0.403922 0.403922 0.403922
            roughness 1
            metalness 0
          }
          geometry DEF BOX Box {
            size 0.04 0.04 0.04
          }
        }
      ]
      minRange 0.01
      maxRange 83.92615612605775
      horizontalFieldOfView 2
      transmittedPower 78
    }
  ]
  name "MyBot3"
  boundingObject Transform {
    translation 0 0.0415 0
    children [
      USE BODY
    ]
  }
  physics Physics {
    density -1
    mass 0.5
  }
  controller "unmovingrobot3"
  linearVelocity -3.135753009185656e-07 9.269208342290842e-06 -1.60739741104627e-07
  angularVelocity -3.993934578322775e-06 -4.3476559938099313e-08 7.754114657200938e-06
}
DEF TRAIL Shape {
  appearance Appearance {
    material Material {
      diffuseColor 0 1 0
      emissiveColor 0 1 0
    }
  }
  geometry DEF TRAIL_LINE_SET IndexedLineSet {
    coord Coordinate {
      point [
        0 0 0, 0 0 0, 0 0 0, 0 0 0, 0 0 0, 0 0 0, 0 0 0, 0 0 0, 0 0 0, 0 0 0, 0 0 0, 0 0 0, 0 0 0, 0 0 0, 0 0 0, 0 0 0, 0 0 0, 0 0 0, 0 0 0, 0 0 0, 0 0 0, 0 0 0, 0 0 0, 0 0 0, 0 0 0, 0 0 0, 0 0 0, 0 0 0, 0 0 0, 0 0 0, 0 0 0, 0 0 0, 0 0 0, 0 0 0, 0 0 0, 0 0 0, 0 0 0, 0 0 0, 0 0 0, 0 0 0, 0 0 0, 0 0 0, 0 0 0, 0 0 0, 0 0 0, 0 0 0, 0 0 0, 0 0 0, 0 0 0, 0 0 0, 0 0 0, 0 0 0, 0 0 0, 0 0 0, 0 0 0, 0 0 0, 0 0 0, 0 0 0, 0 0 0, 0 0 0, 0 0 0, 0 0 0, 0 0 0, 0 0 0, 0 0 0, 0 0 0, 0 0 0, 0 0 0, 0 0 0, 0 0 0, 0 0 0, 0 0 0, 0 0 0, 0 0 0, 0 0 0, 0 0 0, 0 0 0, 0 0 0, 0 0 0, 0 0 0, 0 0 0, 0 0 0, 0 0 0, 0 0 0, 0 0 0, 0 0 0, 0 0 0, 0 0 0, 0 0 0, 0 0 0, 0 0 0, 0 0 0, 0 0 0, 0 0 0, 0 0 0, 0 0 0, 0 0 0, 0 0 0, 0 0 0, 0 0 0, 0 0 0, 0 0 0, 0 0 0, 0 0 0, 0 0 0, 0 0 0, 0 0 0, 0 0 0, 0 0 0, 0 0 0, 0 0 0, 0 0 0, 0 0 0, 0 0 0, 0 0 0, 0 0 0, 0 0 0, 0 0 0, 0 0 0, 0 0 0, 0 0 0, 0 0 0, 0 0 0, 0 0 0, 0 0 0, 0 0 0, 0 0 0, 0 0 0, 0 0 0, 0 0 0, 0 0 0, 0 0 0, 0 0 0, 0 0 0, 0 0 0, 0 0 0, 0 0 0, 0 0 0, 0 0 0, 0 0 0, 0 0 0, 0 0 0, 0 0 0, 0 0 0, 0 0 0, 0 0 0, 0 0 0, 0 0 0, 0 0 0, 0 0 0, 0 0 0, 0 0 0, 0 0 0, 0 0 0, 0 0 0, 0 0 0, 0 0 0, 0 0 0, 0 0 0, 0 0 0, 0 0 0, 0 0 0, 0 0 0, 0 0 0, 0 0 0, 0 0 0, 0 0 0, 0 0 0, 0 0 0, 0 0 0, 0 0 0, 0 0 0, 0 0 0, 0 0 0, 0 0 0, 0 0 0, 0 0 0, 0 0 0, 0 0 0, 0 0 0, 0 0 0, 0 0 0, 0 0 0, 0 0 0, 0 0 0, 0 0 0, 0 0 0, 0 0 0, 0 0 0, 0 0 0, 0 0 0, 0 0 0, 0 0 0, 0 0 0, 0 0 0, 0 0 0, 0 0 0, 0 0 0, 0 0 0, 0 0 0
      ]
    }
    coordIndex [
      0, 1, -1, 1, 2, -1, 2, 2, -1, 0, 0, -1, 0, 0, -1, 0, 0, -1, 0, 0, -1, 0, 0, -1, 0, 0, -1, 0, 0, -1, 0, 0, -1, 0, 0, -1, 0, 0, -1, 0, 0, -1, 0, 0, -1, 0, 0, -1, 0, 0, -1, 0, 0, -1, 0, 0, -1, 0, 0, -1, 0, 0, -1, 0, 0, -1, 0, 0, -1, 0, 0, -1, 0, 0, -1, 0, 0, -1, 0, 0, -1, 0, 0, -1, 0, 0, -1, 0, 0, -1, 0, 0, -1, 0, 0, -1, 0, 0, -1, 0, 0, -1, 0, 0, -1, 0, 0, -1, 0, 0, -1, 0, 0, -1, 0, 0, -1, 0, 0, -1, 0, 0, -1, 0, 0, -1, 0, 0, -1, 0, 0, -1, 0, 0, -1, 0, 0, -1, 0, 0, -1, 0, 0, -1, 0, 0, -1, 0, 0, -1, 0, 0, -1, 0, 0, -1, 0, 0, -1, 0, 0, -1, 0, 0, -1, 0, 0, -1, 0, 0, -1, 0, 0, -1, 0, 0, -1, 0, 0, -1, 0, 0, -1, 0, 0, -1, 0, 0, -1, 0, 0, -1, 0, 0, -1, 0, 0, -1, 0, 0, -1, 0, 0, -1, 0, 0, -1, 0, 0, -1, 0, 0, -1, 0, 0, -1, 0, 0, -1, 0, 0, -1, 0, 0, -1, 0, 0, -1, 0, 0, -1, 0, 0, -1, 0, 0, -1, 0, 0, -1, 0, 0, -1, 0, 0, -1, 0, 0, -1, 0, 0, -1, 0, 0, -1, 0, 0, -1, 0, 0, -1, 0, 0, -1, 0, 0, -1, 0, 0, -1, 0, 0, -1, 0, 0, -1, 0, 0, -1, 0, 0, -1, 0, 0, -1, 0, 0, -1, 0, 0, -1, 0, 0, -1, 0, 0, -1, 0, 0, -1, 0, 0, -1, 0, 0, -1, 0, 0, -1, 0, 0, -1, 0, 0, -1, 0, 0, -1, 0, 0, -1, 0, 0, -1, 0, 0, -1, 0, 0, -1, 0, 0, -1, 0, 0, -1, 0, 0, -1, 0, 0, -1, 0, 0, -1, 0, 0, -1, 0, 0, -1, 0, 0, -1, 0, 0, -1, 0, 0, -1, 0, 0, -1, 0, 0, -1, 0, 0, -1, 0, 0, -1, 0, 0, -1, 0, 0, -1, 0, 0, -1, 0, 0, -1, 0, 0, -1, 0, 0, -1, 0, 0, -1, 0, 0, -1, 0, 0, -1, 0, 0, -1, 0, 0, -1, 0, 0, -1, 0, 0, -1, 0, 0, -1, 0, 0, -1, 0, 0, -1, 0, 0, -1, 0, 0, -1, 0, 0, -1, 0, 0, -1, 0, 0, -1, 0, 0, -1, 0, 0, -1, 0, 0, -1, 0, 0, -1, 0, 0, -1, 0, 0, -1, 0, 0, -1, 0, 0, -1, 0, 0, -1, 0, 0, -1, 0, 0, -1, 0, 0, -1, 0, 0, -1, 0, 0, -1, 0, 0, -1, 0, 0, -1, 0, 0, -1, 0, 0, -1, 0, 0, -1, 0, 0, -1, 0, 0, -1, 0, 0, -1, 0, 0, -1, 0, 0, -1, 0, 0, -1, 0, 0, -1, 0, 0, -1, 0, 0, -1, 0, 0, -1, 0, 0, -1, 0, 0, -1, 0, 0, -1, 0, 0, -1, 0, 0, -1, 0, 0, -1, 0, 0, -1, 0, 0, -1, 0, 0, -1, 0, 0, -1, 0, 0, -1, 0, 0, -1, 0, 0, -1, 0, 0, -1, 0, 0, -1, 0, 0, -1, 0, 0, -1, 0, 0, -1, 0, 0, -1, 0, 0, -1, 0, 0, -1, 0, 0, -1, 0, 0, -1, 0, 0, -1, 0, 0, -1, 0, 0, -1
    ]
  }
}
DEF Supervisior1 Robot {
  translation 0 -1 0
  children [
    DEF emittertoyellowbox Emitter {
      name "emittertoyellowbox"
      channel 7
    }
    Receiver {
      channel 8
    }
    DEF emitter Emitter {
      channel 8
    }
    Receiver {
      name "receiver2"
      channel 3
    }
    Receiver {
      name "receiver1"
      channel 2
    }
    Receiver {
      name "receiver0"
      channel 1
    }
  ]
  controller "matlab_supervisor"
  supervisor TRUE
  cpuConsumption 0.5
}
DEF PIONEER_3AT Pioneer3at {
  hidden position_0_0 556.8159338213042
  hidden position_0_1 556.8156987333601
  hidden position_0_2 556.8458737648992
  hidden position_0_3 556.8468186485063
  hidden linearVelocity_0 -0.4119409736301871 -3.747449963113195e-11 0.5708945925209647
  hidden angularVelocity_0 -4.079642055616763e-07 1.2151721089314953e-06 5.75627209267277e-07
  hidden rotation_8 -1 0 0 3.8956267895005467
  hidden rotation_9 -1 0 0 3.8953917015565263
  hidden rotation_10 -1 0 0 3.9255667330956285
  hidden rotation_11 -0.9999999999999999 0 0 3.926511616702704
  translation -1.8714506009582548 0.10761106879959186 2.590875618809089
  rotation -0.00012498939051139616 0.9999999170284289 0.0003877122482461331 2.5165359685465916
  controller "ros"
  controllerArgs "--name=pioneer3at"
  extensionSlot [
    DEF RADAR_TARGET Solid {
      translation 0 0.19999999999999998 0
      children [
        Shape {
          appearance PBRAppearance {
            baseColor 1 0 0
            roughness 1
            metalness 0
          }
          geometry DEF BOX Box {
            size 0.04 0.04 0.04
          }
        }
      ]
      name ""
      radarCrossSection 1
    }
    Camera {
      translation 0 0.17 -0.22
      width 256
      height 128
      motionBlur 500
      noise 0.02
    }
    Accelerometer {
      lookupTable [
        -39.24 -39.24 0.005
        39.24 39.24 0.005
      ]
    }
    Gyro {
      lookupTable [
        -50 -50 0.005
        50 50 0.005
      ]
    }
    SickLms291 {
      translation 0 0.23 -0.136
      noise 0.1
    }
    GPS {
    }
    InertialUnit {
    }
  ]
}
