#VRML_SIM R2019a utf8
WorldInfo {
  info [
    "Example use of a Radar device."
  ]
}
Viewpoint {
  orientation -0.9999407696243731 0.009549360390956508 0.00522177739280499 1.0008461951798295
  position -1.134222616253913 77.89748827028185 48.832321948047316
}
TexturedBackground {
}
TexturedBackgroundLight {
}
Floor {
  size 60 60
  tileSize 1 1
  appearance ThreadMetalPlate {
  }
}
DEF BOXES Transform {
  translation -2 0 3
  children [
    WoodenBox {
      translation 26.7873 0.89 9.13591
      name "wooden box(10)"
    }
    WoodenBox {
      translation 25.3406 0.3 9.13625
      name "wooden box(10)"
    }
    WoodenBox {
      translation 25.8306 0.91 9.13625
      name "wooden box(10)"
    }
    WoodenBox {
      translation 24.8506 0.9 9.13625
      name "wooden box(10)"
    }
    WoodenBox {
      translation 24.3706 0.3 9.13625
      name "wooden box(10)"
    }
    WoodenBox {
      translation 26.3006 0.3 9.13625
      name "wooden box(10)"
    }
    WoodenBox {
      translation 27.317 0.3 9.14677
      name "wooden box(10)"
    }
  ]
}
DEF KITCHEN Transform {
  translation 27.9 0 21.8
  rotation 0 1 0 4.71239
  children [
    Cabinet {
      hidden translation_6 5.194067398406332e-12 0.6899585867248957 0.6999999998757893
      hidden rotation_6 0.9992241284228792 1.265100449237495e-09 0.03938452967266981 1.904342034598963e-05
      hidden position_6_0 1.2343125230752668e-05
      hidden translation_7 1.515909620053435e-11 0 2.456281920857411e-06
      hidden rotation_7 0 0.9999999999999999 0 1.23431275228495e-05
      translation 1 0.83 -2.15
      depth 0.7
      outerThickness 0.02
      rowsHeights [
        0.2, 0.2, 0.2, 0.2, 0.2, 0.34
      ]
      columnsWidths [
        0.4
      ]
      layout [
        "LeftSidedDoor (1, 1, 1, 6, 1.5)"
        "Shelf (1,2, 1, 0)"
        "Shelf (1,3, 1, 0)"
        "Shelf (1,4, 1, 0)"
        "Shelf (1,5, 1, 0)"
        "Shelf (1,6, 1, 0)"
      ]
      handle CabinetHandle {
        translation -0.3 0 0
        handleLength 0.1
        handleRadius 0.008
        handleColor 0.427451 0.513725 0.533333
      }
    }
    Cabinet {
      hidden translation_6 -5.019984428145108e-12 1.0749597026453568 0.6699999998917683
      hidden rotation_6 0.9989765043038655 1.7583586533778575e-09 -0.04523211081553392 1.8200091256146583e-05
      hidden position_6_0 -1.2890524724134005e-05
      hidden translation_7 -1.8186840922140846e-11 0 2.821735862034788e-06
      hidden rotation_7 0 -0.9999999999999999 0 1.2890529385118086e-05
      hidden translation_10 -5.023537141823908e-12 1.7449597026397117 0.6699999998917683
      hidden rotation_10 0.9989765205642323 1.7556012262970237e-09 -0.04523175169479901 1.8200099695422885e-05
      hidden position_10_0 -1.289052932562421e-05
      hidden translation_11 -1.8186840922140846e-11 0 2.821736869300994e-06
      hidden rotation_11 0 -1 0 1.2890529385118086e-05
      translation -1.65 0.15 0.11
      rotation 0 1 0 1.5708
      name "cabinet(1)"
      depth 0.67
      outerThickness 0.02
      rowsHeights [
        0.68, 0.25, 0.25, 0.25, 0.25, 0.34
      ]
      columnsWidths [
        0.44
      ]
      layout [
        "RightSidedDoor (1, 2, 1, 3, 1.5)"
        "RightSidedDoor (1, 5, 1, 2, 1.5)"
        "Shelf (1,2, 1, 0)"
        "Shelf (1,3, 1, 0)"
        "Shelf (1,4, 1, 0)"
        "Shelf (1,5, 1, 0)"
        "Shelf (1,6, 1, 0)"
      ]
      handle CabinetHandle {
        translation -0.15 0 0
        handleLength 0.1
        handleRadius 0.008
        handleColor 0.427451 0.513725 0.533333
      }
    }
    Cabinet {
      hidden translation_6 -0.440000000002879 0.33996507089594896 0.4999999999561382
      hidden rotation_6 0.9981136736477043 1.1842622373055399e-09 -0.06139295136645428 1.3405974413555978e-05
      hidden position_6_0 -9.490514100505245e-06
      hidden translation_7 -9.858169836007846e-12 0 2.0774735365694117e-06
      hidden rotation_7 0 -1 0 9.49053073025733e-06
      hidden translation_10 2.8812507935072063e-12 0.3399650708962625 0.4999999999561382
      hidden rotation_10 -0.9981068020199733 1.1759726444651795e-09 -0.06150456699678286 -1.3406066054338464e-05
      hidden position_10_0 9.49238027716674e-06
      hidden translation_11 9.862055616594034e-12 0 2.077882042640595e-06
      hidden rotation_11 0 1 0 9.492402260689697e-06
      hidden translation_14 0.440000000002879 0.33996507089766714 0.4999999999561382
      hidden rotation_14 -0.9981067952911904 1.1759728953030415e-09 -0.06150467619254439 -1.340606319479216e-05
      hidden position_14_0 9.492383184385624e-06
      hidden translation_15 9.862055616594034e-12 0 2.0778826790308087e-06
      hidden rotation_15 0 1 0 9.492402260689697e-06
      translation 0.1 1.4 -2.15
      name "cabinet(2)"
      outerThickness 0.02
      rowsHeights [
        0.21, 0.21, 0.22
      ]
      columnsWidths [
        0.44, 0.44, 0.44
      ]
      layout [
        "RightSidedDoor (1, 1, 1, 3, 1.5)"
        "LeftSidedDoor (2, 1, 1, 3, 1.5)"
        "LeftSidedDoor (3, 1, 1, 3, 1.5)"
        "Shelf (1, 2, 3, 0)"
        "Shelf (1, 3, 2, 0)"
        "Shelf (1, 1, 0, 1)"
        "Shelf (2, 1, 0, 3)"
      ]
      handle CabinetHandle {
        translation -0.2 0 0
        handleLength 0.1
        handleRadius 0.008
        handleColor 0.427451 0.513725 0.533333
      }
    }
    Cabinet {
      hidden translation_6 -2.8776980798284058e-12 0.3399650708960731 0.49999999995613464
      hidden rotation_6 0.9981136370116988 1.175004481429517e-09 -0.06139354698401628 1.340597464921668e-05
      hidden position_6_0 -9.490513995172876e-06
      hidden translation_7 -9.858169836007846e-12 0 2.0774735135121563e-06
      hidden rotation_7 0 -1 0 9.49053073025733e-06
      translation -1.647 1.4 -0.37
      rotation 0 1 0 1.5708
      name "cabinet(3)"
      outerThickness 0.02
      rowsHeights [
        0.21, 0.21, 0.22
      ]
      columnsWidths [
        0.44
      ]
      layout [
        "RightSidedDoor (1, 1, 1, 3, 1.5)"
        "Shelf (1, 2 ,1 , 0)"
        "Shelf (1, 3 ,1 , 0)"
      ]
      handle CabinetHandle {
        translation -0.2 0 0
        handleLength 0.1
        handleRadius 0.008
        handleColor 0.427451 0.513725 0.533333
      }
    }
    Cabinet {
      hidden translation_6 -0.06500000000265871 0.3399650708840344 0.49999999995679545
      hidden rotation_6 0.9978427240240172 6.496282405147538e-09 -0.0656498142596683 1.3409639133806484e-05
      hidden position_6_0 -1.0087353265162427e-05
      hidden translation_7 -1.1896428286917171e-11 0 2.3586753771866034e-06
      hidden rotation_7 0 -1 0 1.0087370759101712e-05
      hidden translation_10 0.40499999754408833 0.33996504439999153 0.49999999992748556
      hidden rotation_10 -0.997841165875639 7.383250247186951e-05 -0.06567345150597215 -1.3405959613864377e-05
      hidden position_10_0 -0.0022294628686485318
      hidden translation_11 5.811138880373878e-07 0 -0.0005213037234043928
      hidden rotation_11 0 -1 0 0.002229462868711275
      hidden translation_14 -0.47000000000193154 0.3399650708928751 0.49999999995714006
      hidden rotation_14 0.9988689556881849 2.752086561280809e-09 -0.047547969066984816 1.3395845461232092e-05
      hidden position_14_0 -7.439006930861267e-06
      hidden translation_15 -4.6802839381854255e-12 0 1.258308022343578e-06
      hidden rotation_15 0 -1 0 7.439008308766687e-06
      translation -1.48 0.15 -0.79
      rotation 0 1 0 1.5708
      name "cabinet(4)"
      outerThickness 0.02
      rowsHeights [
        0.21, 0.21, 0.22
      ]
      columnsWidths [
        0.34, 0.47, 0.47
      ]
      layout [
        "RightSidedDoor (2, 1, 1, 3, 1.5)"
        "LeftSidedDoor (3, 1, 1, 3, 1.5)"
        "RightSidedDoor (1, 1, 1, 3, 1.5)"
        "Shelf (1, 2, 1, 0)"
        "Shelf (1, 3, 1, 0)"
        "Shelf (1, 1, 0, 3)"
        "Shelf (2, 1, 0, 3)"
      ]
      handle CabinetHandle {
        translation 0.1 0 0
        handleLength 0.1
        handleRadius 0.008
        handleColor 0.427451 0.513725 0.533333
      }
    }
    Cabinet {
      hidden translation_6 -0.0499999999935703 0.26995858667284345 0.6999999998760522
      hidden rotation_6 -0.9985915085422603 8.331525939317993e-09 -0.053056564789786216 -1.9055560011470776e-05
      hidden position_6_0 1.6259643760586666e-05
      hidden translation_7 3.5512315310626263e-11 0 4.368153296089135e-06
      hidden rotation_7 0 1 0 1.625964564767065e-05
      hidden translation_10 0.865000000005157 0.33995858670346746 0.6999999998766882
      hidden rotation_10 -0.9991061995425874 3.4450916698840913e-09 -0.04227058120688107 -1.9045699517930683e-05
      hidden position_10_0 1.3205279990783395e-05
      hidden translation_11 1.8652079880610017e-11 0 2.8249395219462357e-06
      hidden rotation_11 0 1 0 1.3205287647531116e-05
      hidden translation_14 0.4349999999948402 0.33995858669960544 0.6999999998766917
      hidden rotation_14 0.9991062000152104 3.4392613828794822e-09 -0.04227057003597476 1.904570521448198e-05
      hidden position_14_0 -1.3205278018885033e-05
      hidden translation_15 -1.8652079880610017e-11 0 2.8249391001078788e-06
      hidden rotation_15 0 -1 0 1.3205287647531116e-05
      hidden translation_18 -0.7000000000000028 0.14489008843360382 0.7000000237711284
      hidden rotation_18 0.9999999999999999 0 2.843378353990958e-13 7.290127344714015e-05
      hidden position_18_0 0.5428347743482714
      hidden translation_19 0 0 0.5428347743482714
      hidden translation_26 -0.6999999996090089 0.3948944072079541 0.6999999896314577
      hidden rotation_26 -0.9999999999801382 6.233366100790502e-06 9.31942924636424e-07 -6.651822351933733e-05
      hidden position_26_0 0.43651526390389883
      hidden translation_27 0 0 0.43651526390389883
      hidden translation_34 -0.7000000000000028 0.5898900871250763 0.7000000237729687
      hidden rotation_34 1 1.522872674992446e-12 3.087758194778385e-13 7.290320741203961e-05
      hidden position_34_0 0.5428665313109562
      hidden translation_35 0 0 0.5428665313109562
      hidden translation_42 -0.05000000000000071 0.589890087379058 0.70000002377272
      hidden rotation_42 -1 1.5228805171496082e-12 3.848098963012316e-13 -7.290283199295457e-05
      hidden position_42_0 0.542860350567324
      hidden translation_43 0 0 0.542860350567324
      translation 0.12 0.15 -2.15
      name "cabinet(5)"
      depth 0.7
      outerThickness 0.02
      rowsHeights [
        0.25, 0.25, 0.14
      ]
      columnsWidths [
        0.76, 0.54, 0.43, 0.43
      ]
      layout [
        "LeftSidedDoor (2, 1, 1, 2, 1.5)"
        "LeftSidedDoor (4, 1, 1, 3, 1.5)"
        "RightSidedDoor (3, 1, 1, 3, 1.5)"
        "Drawer (1, 1, 1, 1, 3.5)"
        "Drawer (1, 2, 1, 1, 3.5)"
        "Drawer (1, 3, 1, 1, 3.5)"
        "Drawer (2, 3, 1, 1, 3.5)"
        "Shelf (1, 2, 1, 0)"
        "Shelf (1, 3, 2, 0)"
        "Shelf (3, 2, 2, 0)"
        "Shelf (1, 1, 0, 3)"
        "Shelf (2, 1, 0, 3)"
        "Shelf (3, 1, 0, 1)"
      ]
      handle CabinetHandle {
        handleLength 0.1
        handleRadius 0.008
        handleColor 0.427451 0.513725 0.533333
      }
    }
    SolidBox {
      translation 0.12 0.07 -1.55
      size 2.2 0.16 0.2
      appearance PBRAppearance {
        baseColor 0.8 0.8 0.8
        roughness 0.5
        metalness 0
        textureTransform TextureTransform {
          scale 4 4
        }
      }
    }
    SolidBox {
      translation -1.08 0.07 -0.65
      rotation 0 1 0 1.5708
      name "box(1)"
      size 2 0.16 0.2
      appearance PBRAppearance {
        baseColor 0.8 0.8 0.8
        roughness 0.5
        metalness 0
        textureTransform TextureTransform {
          scale 4 4
        }
      }
    }
    SolidBox {
      translation 1.12 0.07 -1.9
      rotation 0 -1 0 4.71239
      name "box(2)"
      size 0.5 0.16 0.2
      appearance PBRAppearance {
        roughness 0.5
        metalness 0
        textureTransform TextureTransform {
          scale 4 4
        }
      }
    }
    SolidBox {
      translation -1.415 0.07 0.25
      rotation 0 -1 0 6.28318
      name "box(3)"
      size 0.47 0.16 0.2
      appearance PBRAppearance {
        baseColor 0.8 0.8 0.8
        roughness 0.5
        metalness 0
        textureTransform TextureTransform {
          scale 4 4
        }
      }
    }
    Fridge {
      hidden position_0_0 -6.763729825902464e-08
      hidden position_0_1 2.2448619781774018e-07
      hidden rotation_1 0 -1 0 6.664001874625056e-08
      hidden rotation_2 0 1 0 2.2500259981366257e-07
      translation 1.57 0 -1.8
      rotation 0 1 0 4.71239
    }
    Worktop {
      translation -1.31 0.86 -0.345
      rotation 0 1 0 4.71239
      size 0.43 0.06 0.7
    }
    Worktop {
      translation -1.531 0.86 -0.78
      rotation 0 1 0 4.71239
      name "worktop(1)"
      size 0.44 0.06 0.237
    }
    Worktop {
      translation -1.003 0.86 -0.780001
      rotation 0 1 0 4.71239
      name "worktop(2)"
      size 0.442 0.06 0.085
    }
    Worktop {
      translation -1.306 0.86 -1.22
      rotation 0 -1 0 1.5708
      name "worktop(3)"
      size 0.44 0.06 0.69
    }
    Worktop {
      translation -0.435 0.86 -1.79
      name "worktop(4)"
      size 2.43 0.06 0.7
    }
    Sink {
      translation -1.33 0.87 -0.78
      rotation 0 1 0 4.71239
    }
    HotPlate {
      translation -1.14971 0.86 -1.62912
      rotation 0 -1 0 5.49779
    }
    Oven {
      hidden position_0_0 -9.292241313668246e-39
      translation -1.24 0.51 0.11
    }
  ]
}
DEF INTERNAL_WINDOW Window {
  translation -11.283624405978252 -1.5987211554602254e-14 -0.9089969314674011
  rotation 0 -1 0 3.141591686718346
  name "window(4)"
  size 0.9 2.7 0.2
}
DEF INTERNAL_WINDOW Window {
  translation -7.764715143088619 -1.4210854715202004e-14 -0.9394903033116844
  rotation 0 -1 0 3.141591686718346
  name "window(3)"
  size 0.9 2.7 0.2
}
DEF INTERNAL_WINDOW Window {
  translation -9.547060928142615 -1.2434497875801753e-14 -0.9229028115136266
  rotation 0 -1 0 3.141591686718346
  name "window(2)"
  size 0.9 2.7 0.2
}
DEF INTERNAL_WINDOW Window {
  translation -10.424088153855532 -1.4210854715202004e-14 -0.9263832371812324
  rotation 0 -1 0 3.141591686718346
  name "window(1)"
  size 0.9 2.7 0.2
}
DEF INTERNAL_WALL Wall {
  translation -20.841722096896945 1.7763568394002505e-15 -0.895663661597073
  name "wall(7)"
  size 18.2 2.7 0.2
}
DEF INTERNAL_WINDOW Window {
  translation -8.661028945763917 3.197442310920451e-14 -0.9265567823689587
  rotation 0 -1 0 3.141591686718346
  size 0.9 2.7 0.2
}
DEF INTERNAL_WALL Wall {
  translation 18.841850244600412 -1.0004599999999999e-09 20.10700920905251
  name "wall(13)"
  size 22.5 2.4 0.2
}
DEF EXTERNAL_WALL Wall {
  translation -30 0 0
  rotation 0 1 0 1.5708
  name "wall(12)"
  size 60 2.4 0.2
}
DEF EXTERNAL_WALL Wall {
  translation 30 0 0
  rotation 0 1 0 1.5708
  name "wall(11)"
  size 60 2.4 0.2
}
DEF EXTERNAL_WALL Wall {
  translation -27.45 0 30
  name "wall(10)"
  size 5.3 2.4 0.2
}
DEF DOUBLE_WINDOW Transform {
  translation -24 0 30
  children [
    Window {
      translation -0.4 0 0
      name "window(21)"
    }
    Window {
      translation 0.4 0 0
      name "window(22)"
    }
  ]
}
DEF DOUBLE_WINDOW Transform {
  translation -12 0 30
  children [
    Window {
      translation -0.4 0 0
      name "window(19)"
    }
    Window {
      translation 0.4 0 0
      name "window(20)"
    }
  ]
}
DEF DOUBLE_WINDOW Transform {
  translation 12 0 30
  children [
    Window {
      translation -0.4 0 0
      name "window(17)"
    }
    Window {
      translation 0.4 0 0
      name "window(18)"
    }
  ]
}
DEF DOUBLE_WINDOW Transform {
  translation 24 0 30
  children [
    Window {
      translation -0.4 0 0
      name "window(15)"
    }
    Window {
      translation 0.4 0 0
      name "window(16)"
    }
  ]
}
DEF EXTERNAL_WALL Wall {
  translation -18 0 30
  name "wall(8)"
  size 10.4 2.4 0.2
}
DEF EXTERNAL_WALL Wall {
  translation 27.45 0 30
  name "wall(9)"
  size 5.3 2.4 0.2
}
DEF EXTERNAL_WALL Wall {
  translation 18 0 30
  name "wall(6)"
  size 10.4 2.4 0.2
}
DEF EXTERNAL_WALL Wall {
  translation 0 0 30
  name "wall(5)"
  size 22.4 2.4 0.2
}
DEF DOUBLE_WINDOW Transform {
  translation -12 0 -30
  children [
    Window {
      translation -0.4 0 0
      name "window(11)"
    }
    Window {
      translation 0.4 0 0
      name "window(12)"
    }
  ]
}
DEF DOUBLE_WINDOW Transform {
  translation -24 0 -30
  children [
    Window {
      translation -0.4 0 0
      name "window(13)"
    }
    Window {
      translation 0.4 0 0
      name "window(14)"
    }
  ]
}
DEF DOUBLE_WINDOW Transform {
  translation 24 0 -30
  children [
    Window {
      translation -0.4 0 0
      name "window(7)"
    }
    Window {
      translation 0.4 0 0
      name "window(8)"
    }
  ]
}
DEF EXTERNAL_WALL Wall {
  translation -27.45 0 -30
  name "wall(4)"
  size 5.3 2.4 0.2
}
DEF EXTERNAL_WALL Wall {
  translation 27.45 0 -30
  name "wall(3)"
  size 5.3 2.4 0.2
}
DEF EXTERNAL_WALL Wall {
  translation -18 0 -30
  name "wall(2)"
  size 10.4 2.4 0.2
}
DEF EXTERNAL_WALL Wall {
  translation 18 0 -30
  name "wall(1)"
  size 10.4 2.4 0.2
}
DEF EXTERNAL_WALL Wall {
  translation 0 0 -30
  size 22.4 2.4 0.2
}
Shape {
  appearance PBRAppearance {
    baseColor 0 0 1
    roughness 1
    metalness 0
  }
  geometry IndexedFaceSet {
    coord Coordinate {
      point [
        0.21 0 0.07
        0.09 0 0.22
        0.25 0 0.26
        0.21 0.0001 0.07
        0.09 0.0001 0.22
        0.25 0.0001 0.26
      ]
    }
    coordIndex [
      2, 1, 0, -1, 3, 4, 5, -1, 0, 1
      4, 3, -1, 1, 2, 5, 4, -1, 2, 0
      3, 5, -1
    ]
  }
}
DEF E_PUCK2 E-puck {
  hidden position_0_0 -5.2875991141189725e-14
  hidden position_0_1 2.668102846449379e-13
  hidden linearVelocity_0 -1.1789891121036812e-17 8.052817671947803e-16 4.9516407006578934e-15
  hidden angularVelocity_0 1.2570530449961125e-13 -7.101265052291033e-14 8.757855667554241e-14
  hidden linearVelocity_1 -7.298446354149139e-15 -2.042810167660669e-15 3.2026470650845105e-15
  hidden angularVelocity_1 2.5935960857688243e-13 -7.097198041693693e-14 1.071496959264178e-12
  hidden linearVelocity_2 8.481779687389128e-16 1.1546306929760952e-15 2.404923182825717e-15
  hidden angularVelocity_2 1.1468659499229466e-13 -7.120601193580148e-14 -2.321539711127682e-13
  translation -4.784167051842149 -6.396824233341133e-05 4.781665900866141
  rotation 2.9767367957027358e-06 0.9999999999955341 -2.6564178734434993e-07 -2.963585693346755
  name "E_PUCK2"
  controller "matlab"
  emitter_channel 8
  receiver_channel 8
  turretSlot [
    DEF receiverepuck Receiver {
      name "receiverepuck"
      channel 8
    }
    Display {
      width 42
      height 30
    }
  ]
}
DEF YELLOW_BOX Solid {
  translation 7.737125407908302 1.22 14.127257821329414
  rotation 0 1 0 3.142388850922486
  children [
    DEF Shape Shape {
      appearance DEF PBR PBRAppearance {
        baseColor 1 1 0
        roughness 0.03934117200000009
        metalness 0
      }
      geometry DEF geometryBox Box {
        size 0.30000000000000004 2.5 11.9
      }
    }
  ]
  name "YELLOW_BOX"
  boundingObject Shape {
    appearance PBRAppearance {
      roughness 1.1102230246251565e-16
      metalness 0
    }
    geometry USE geometryBox
  }
}
DEF MyBot1 Robot {
  translation 28.708867697241438 -0.00044266573700219025 25.90395365604251
  rotation 0.024669433256044763 -0.9996258770637358 -0.011812068717304069 -0.8937213064915877
  children [
    Emitter {
      channel 1
      baudRate 115200
    }
    Transform {
      translation 0 0.0415 0
      children [
        Shape {
          appearance PBRAppearance {
            baseColor 0.0820075 0.364731 0.8
            roughness 1
            metalness 0
          }
          geometry DEF BODY Cylinder {
            height 0.08
            radius 0.045
          }
        }
      ]
    }
    HingeJoint {
      jointParameters HingeJointParameters {
        position 76.03201080341961
        axis -1 0 0
        anchor 0 0.025 0
      }
      device [
        RotationalMotor {
          name "left wheel motor1"
          consumptionFactor 70
        }
        PositionSensor {
          name "left wheel sensor"
        }
      ]
      endPoint Solid {
        translation -0.04499997587308612 0.025212115178917017 -1.5431544293610585e-06
        rotation -0.9999998918030587 0.0003806367155716677 -0.00026741271779113867 1.9316475356613518
        children [
          DEF WHEEL Transform {
            rotation 0 0 1 1.57
            children [
              Shape {
                appearance PBRAppearance {
                  baseColor 1 0 0
                  roughness 1
                  metalness 0
                }
                geometry Cylinder {
                  height 0.01
                  radius 0.025
                }
              }
            ]
          }
        ]
        name "left wheel"
        boundingObject USE WHEEL
        physics DEF PHYSICS_WHEEL Physics {
          density -1
          mass 0.05
        }
        linearVelocity 2.1331616132818676e-08 3.3583884757603944e-08 1.8575731756675923e-08
        angularVelocity 8.593621503093471e-07 5.43822210421052e-10 -1.0706317875354802e-06
      }
    }
    HingeJoint {
      jointParameters HingeJointParameters {
        position 76.03204515482092
        axis -1 0 0
        anchor 0 0.025 0
      }
      device [
        RotationalMotor {
          name "right wheel motor1"
          consumptionFactor 70
        }
        PositionSensor {
          name "right wheel sensor"
        }
      ]
      endPoint Solid {
        translation 0.044999989753531325 0.025212064461824085 -1.5434646223150093e-06
        rotation -0.9999999132084414 -0.00038147665891691116 0.00016750721843585394 2.3290016881008557
        children [
          USE WHEEL
        ]
        name "right wheel"
        boundingObject USE WHEEL
        physics USE PHYSICS_WHEEL
        linearVelocity 2.2717797438383775e-08 3.3640253960245684e-08 1.6854871311643664e-08
        angularVelocity 8.615102344183299e-07 -6.663750816127813e-10 -1.0689111010338377e-06
      }
    }
    DistanceSensor {
      translation -0.02 0.063 -0.042
      rotation 0 1 0 2.07
      children [
        DEF SENSOR Transform {
          rotation 0 0 1 1.57
          children [
            Shape {
              appearance PBRAppearance {
                baseColor 0.975691 0.981481 0.0252992
                roughness 1
                metalness 0
              }
              geometry Cylinder {
                height 0.004
                radius 0.008
              }
            }
          ]
        }
      ]
      name "ds0"
      lookupTable [
        0 1024 0
        0.05 1024 0
        0.15 0 0
      ]
      numberOfRays 2
      aperture 1
    }
    DistanceSensor {
      translation 0.02 0.063 -0.042
      rotation 0 1 0 1.07
      children [
        USE SENSOR
      ]
      name "ds1"
      lookupTable [
        0 1024 0
        0.05 1024 0
        0.15 0 0
      ]
      numberOfRays 2
      aperture 1
    }
    DEF SMILE Transform {
      translation 0 0.025 -0.036
      rotation 0.7745972408364944 0.44721228048294853 0.4472139204829502 1.8234794
      children [
        Shape {
          appearance PBRAppearance {
            baseColor 0.721569 0.290196 0.290196
            roughness 1
            metalness 0
          }
          geometry Cylinder {
            height 0.018
            radius 0.009
            subdivision 3
          }
        }
      ]
    }
    Radar {
      translation 0 0.1 0
      children [
        Shape {
          appearance PBRAppearance {
            baseColor 0.403922 0.403922 0.403922
            roughness 1
            metalness 0
          }
          geometry DEF BOX Box {
            size 0.04 0.04 0.04
          }
        }
      ]
      minRange 0.01
      maxRange 65
      horizontalFieldOfView 2
      verticalFieldOfView 0.4
      occlusion TRUE
    }
  ]
  name "MyBot1"
  boundingObject Transform {
    translation 0 0.0415 0
    children [
      USE BODY
    ]
  }
  physics Physics {
    density -1
    mass 0.5
  }
  controller "unmovingrobot1"
  battery [
    0, 100, 30
  ]
  cpuConsumption 5
}
DEF MyBot2 Robot {
  translation 27.95568573943095 -0.00044266701054538476 -25.683825676870082
  rotation 0.0018736327474873431 -0.9999283946166173 -0.011819269848936562 -2.827502605762398
  children [
    Emitter {
      name "emitter2"
      channel 2
      baudRate 115200
    }
    Transform {
      translation 0 0.0415 0
      children [
        Shape {
          appearance PBRAppearance {
            baseColor 0.0820075 0.364731 0.8
            roughness 1
            metalness 0
          }
          geometry DEF BODY Cylinder {
            height 0.08
            radius 0.045
          }
        }
      ]
    }
    HingeJoint {
      jointParameters HingeJointParameters {
        position 76.03199425296188
        axis -1 0 0
        anchor 0 0.025 0
      }
      device [
        RotationalMotor {
          name "left wheel motor1"
          consumptionFactor 70
        }
        PositionSensor {
          name "left wheel sensor"
        }
      ]
      endPoint Solid {
        translation -0.044999956694958605 0.025212115598545144 -1.4988033108053448e-06
        rotation -0.9999998918133387 0.0003806739971322011 -0.00026732119041529486 1.9316356380298365
        children [
          DEF WHEEL Transform {
            rotation 0 0 1 1.57
            children [
              Shape {
                appearance PBRAppearance {
                  baseColor 1 0 0
                  roughness 1
                  metalness 0
                }
                geometry Cylinder {
                  height 0.01
                  radius 0.025
                }
              }
            ]
          }
        ]
        name "left wheel"
        boundingObject USE WHEEL
        physics DEF PHYSICS_WHEEL Physics {
          density -1
          mass 0.05
        }
        linearVelocity 9.784055406760224e-09 3.3583834735396624e-08 -2.6539892068054746e-08
        angularVelocity -1.3061135453537425e-06 5.440353991655213e-10 -4.2286937145262367e-07
      }
    }
    HingeJoint {
      jointParameters HingeJointParameters {
        position 76.03196460680314
        axis -1 0 0
        anchor 0 0.025 0
      }
      device [
        RotationalMotor {
          name "right wheel motor1"
          consumptionFactor 70
        }
        PositionSensor {
          name "right wheel sensor"
        }
      ]
      endPoint Solid {
        translation 0.04499997063249236 0.025212064873103304 -1.4989324228384214e-06
        rotation -0.9999999132146064 -0.0003814925356509733 0.00016743424094086673 2.3289258005707594
        children [
          USE WHEEL
        ]
        name "right wheel"
        boundingObject USE WHEEL
        physics USE PHYSICS_WHEEL
        linearVelocity 7.682950662832043e-09 3.36402015221874e-08 -2.7224175991021407e-08
        angularVelocity -1.3052685870556362e-06 -6.661366838343589e-10 -4.2548842266633416e-07
      }
    }
    DistanceSensor {
      translation -0.02 0.063 -0.042
      rotation 0 1 0 2.07
      children [
        DEF SENSOR Transform {
          rotation 0 0 1 1.57
          children [
            Shape {
              appearance PBRAppearance {
                baseColor 0.975691 0.981481 0.0252992
                roughness 1
                metalness 0
              }
              geometry Cylinder {
                height 0.004
                radius 0.008
              }
            }
          ]
        }
      ]
      name "ds0"
      lookupTable [
        0 1024 0
        0.05 1024 0
        0.15 0 0
      ]
      numberOfRays 2
      aperture 1
    }
    DistanceSensor {
      translation 0.02 0.063 -0.042
      rotation 0 1 0 1.07
      children [
        USE SENSOR
      ]
      name "ds1"
      lookupTable [
        0 1024 0
        0.05 1024 0
        0.15 0 0
      ]
      numberOfRays 2
      aperture 1
    }
    DEF SMILE Transform {
      translation 0 0.025 -0.036
      rotation 0.7745972408364944 0.44721228048294853 0.4472139204829502 1.8234794
      children [
        Shape {
          appearance PBRAppearance {
            baseColor 0.721569 0.290196 0.290196
            roughness 1
            metalness 0
          }
          geometry Cylinder {
            height 0.018
            radius 0.009
            subdivision 3
          }
        }
      ]
    }
    Radar {
      translation 0 0.1 0
      rotation 0 1 0 6.021385901
      children [
        Shape {
          appearance PBRAppearance {
            baseColor 0.403922 0.403922 0.403922
            roughness 1
            metalness 0
          }
          geometry DEF BOX Box {
            size 0.04 0.04 0.04
          }
        }
      ]
      minRange 0.01
      maxRange 78
      horizontalFieldOfView 2
      verticalFieldOfView 0.4
      occlusion TRUE
    }
  ]
  name "MyBot2"
  boundingObject Transform {
    translation 0 0.0415 0
    children [
      USE BODY
    ]
  }
  physics Physics {
    density -1
    mass 0.5
  }
  controller "unmovingrobot2"
  cpuConsumption 0.5
}
DEF DOUBLE_WINDOW Transform {
  translation 12 0 -30
  children [
    Window {
      translation -0.4 0 0
      name "window(9)"
    }
    Window {
      translation 0.4 0 0
      name "window(10)"
    }
  ]
}
DEF MyBot3 Robot {
  translation -26.901268340356037 -0.00044266629499561255 -27.395249240690294
  rotation 0.005433216999680235 -0.9999153964622854 0.011818632353396044 2.280140678309225
  children [
    Emitter {
      name "emitter3"
      channel 3
      baudRate 115200
    }
    Transform {
      translation 0 0.0415 0
      children [
        Shape {
          appearance PBRAppearance {
            baseColor 0.0820075 0.364731 0.8
            roughness 1
            metalness 0
          }
          geometry DEF BODY Cylinder {
            height 0.08
            radius 0.045
          }
        }
      ]
    }
    HingeJoint {
      jointParameters HingeJointParameters {
        position 76.03198979206194
        axis -1 0 0
        anchor 0 0.025 0
      }
      device [
        RotationalMotor {
          name "left wheel motor1"
          consumptionFactor 70
        }
        PositionSensor {
          name "left wheel sensor"
        }
      ]
      endPoint Solid {
        translation -0.0449999563398115 0.02521211546280492 1.510458720437941e-06
        rotation -0.9999998919106033 0.0003845172657543226 -0.0002613909979602274 1.9329346447522984
        children [
          DEF WHEEL Transform {
            rotation 0 0 1 1.57
            children [
              Shape {
                appearance PBRAppearance {
                  baseColor 1 0 0
                  roughness 1
                  metalness 0
                }
                geometry Cylinder {
                  height 0.01
                  radius 0.025
                }
              }
            ]
          }
        ]
        name "left wheel"
        boundingObject USE WHEEL
        physics DEF PHYSICS_WHEEL Physics {
          density -1
          mass 0.05
        }
        linearVelocity 2.216716216494295e-08 3.358675222386598e-08 1.7569872280806447e-08
        angularVelocity 8.951808770169064e-07 -5.483658241556639e-10 -1.0408523798845563e-06
      }
    }
    HingeJoint {
      jointParameters HingeJointParameters {
        position 76.03193761087333
        axis -1 0 0
        anchor 0 0.025 0
      }
      device [
        RotationalMotor {
          name "right wheel motor1"
          consumptionFactor 70
        }
        PositionSensor {
          name "right wheel sensor"
        }
      ]
      endPoint Solid {
        translation 0.0449999701656373 0.025212064859469224 1.510906495985986e-06
        rotation -0.999999913262392 -0.0003838847496047324 0.00016157879696903065 2.330202589945387
        children [
          USE WHEEL
        ]
        name "right wheel"
        boundingObject USE WHEEL
        physics USE PHYSICS_WHEEL
        linearVelocity 2.0729140041083386e-08 3.363714419890459e-08 1.9247613629866988e-08
        angularVelocity 8.930954191472582e-07 6.617394652911626e-10 -1.0426477996070664e-06
      }
    }
    DistanceSensor {
      translation -0.02 0.063 -0.042
      rotation 0 1 0 2.8553981609999997
      children [
        DEF SENSOR Transform {
          rotation 0 0 1 1.57
          children [
            Shape {
              appearance PBRAppearance {
                baseColor 0.975691 0.981481 0.0252992
                roughness 1
                metalness 0
              }
              geometry Cylinder {
                height 0.004
                radius 0.008
              }
            }
          ]
        }
      ]
      name "ds0"
      lookupTable [
        0 1024 0
        0.05 1024 0
        0.15 0 0
      ]
      numberOfRays 2
      aperture 1
    }
    DistanceSensor {
      translation 0.02 0.063 -0.042
      rotation 0 1 0 1.07
      children [
        USE SENSOR
      ]
      name "ds1"
      lookupTable [
        0 1024 0
        0.05 1024 0
        0.15 0 0
      ]
      numberOfRays 2
      aperture 1
    }
    DEF SMILE Transform {
      translation 0 0.025 -0.036
      rotation 0.7745972408364944 0.44721228048294853 0.4472139204829502 1.8234794
      children [
        Shape {
          appearance PBRAppearance {
            baseColor 0.721569 0.290196 0.290196
            roughness 1
            metalness 0
          }
          geometry Cylinder {
            height 0.018
            radius 0.009
            subdivision 3
          }
        }
      ]
    }
    DEF Radar Radar {
      translation 0 0.1 0
      rotation 0 1 0 6.283185307179586
      children [
        Shape {
          appearance PBRAppearance {
            baseColor 0.403922 0.403922 0.403922
            roughness 1
            metalness 0
          }
          geometry DEF BOX Box {
            size 0.04 0.04 0.04
          }
        }
      ]
      minRange 0.01
      maxRange 74.79926538130816
      horizontalFieldOfView 2
      transmittedPower 76
      occlusion TRUE
    }
  ]
  name "MyBot3"
  boundingObject Transform {
    translation 0 0.0415 0
    children [
      USE BODY
    ]
  }
  physics Physics {
    density -1
    mass 0.5
  }
  controller "unmovingrobot3"
}
DEF TRAIL Shape {
  appearance Appearance {
    material Material {
      diffuseColor 0 1 0
      emissiveColor 0 1 0
    }
  }
  geometry DEF TRAIL_LINE_SET IndexedLineSet {
    coord Coordinate {
      point [
        0 0 0, 0 0 0, 0 0 0, 0 0 0, 0 0 0, 0 0 0, 0 0 0, 0 0 0, 0 0 0, 0 0 0, 0 0 0, 0 0 0, 0 0 0, 0 0 0, 0 0 0, 0 0 0, 0 0 0, 0 0 0, 0 0 0, 0 0 0, 0 0 0, 0 0 0, 0 0 0, 0 0 0, 0 0 0, 0 0 0, 0 0 0, 0 0 0, 0 0 0, 0 0 0, 0 0 0, 0 0 0, 0 0 0, 0 0 0, 0 0 0, 0 0 0, 0 0 0, 0 0 0, 0 0 0, 0 0 0, 0 0 0, 0 0 0, 0 0 0, 0 0 0, 0 0 0, 0 0 0, 0 0 0, 0 0 0, 0 0 0, 0 0 0, 0 0 0, 0 0 0, 0 0 0, 0 0 0, 0 0 0, 0 0 0, 0 0 0, 0 0 0, 0 0 0, 0 0 0, 0 0 0, 0 0 0, 0 0 0, 0 0 0, 0 0 0, 0 0 0, 0 0 0, 0 0 0, 0 0 0, 0 0 0, 0 0 0, 0 0 0, 0 0 0, 0 0 0, 0 0 0, 0 0 0, 0 0 0, 0 0 0, 0 0 0, 0 0 0, 0 0 0, 0 0 0, 0 0 0, 0 0 0, 0 0 0, 0 0 0, 0 0 0, 0 0 0, 0 0 0, 0 0 0, 0 0 0, 0 0 0, 0 0 0, 0 0 0, 0 0 0, 0 0 0, 0 0 0, 0 0 0, 0 0 0, 0 0 0, 0 0 0, 0 0 0, 0 0 0, 0 0 0, 0 0 0, 0 0 0, 0 0 0, 0 0 0, 0 0 0, 0 0 0, 0 0 0, 0 0 0, 0 0 0, 0 0 0, 0 0 0, 0 0 0, 0 0 0, 0 0 0, 0 0 0, 0 0 0, 0 0 0, 0 0 0, 0 0 0, 0 0 0, 0 0 0, 0 0 0, 0 0 0, 0 0 0, 0 0 0, 0 0 0, 0 0 0, 0 0 0, 0 0 0, 0 0 0, 0 0 0, 0 0 0, 0 0 0, 0 0 0, 0 0 0, 0 0 0, 0 0 0, 0 0 0, 0 0 0, 0 0 0, 0 0 0, 0 0 0, 0 0 0, 0 0 0, 0 0 0, 0 0 0, 0 0 0, 0 0 0, 0 0 0, 0 0 0, 0 0 0, 0 0 0, 0 0 0, 0 0 0, 0 0 0, 0 0 0, 0 0 0, 0 0 0, 0 0 0, 0 0 0, 0 0 0, 0 0 0, 0 0 0, 0 0 0, 0 0 0, 0 0 0, 0 0 0, 0 0 0, 0 0 0, 0 0 0, 0 0 0, 0 0 0, 0 0 0, 0 0 0, 0 0 0, 0 0 0, 0 0 0, 0 0 0, 0 0 0, 0 0 0, 0 0 0, 0 0 0, 0 0 0, 0 0 0, 0 0 0, 0 0 0, 0 0 0, 0 0 0, 0 0 0, 0 0 0, 0 0 0, 0 0 0, 0 0 0, 0 0 0, 0 0 0, 0 0 0
      ]
    }
    coordIndex [
      0, 1, -1, 1, 2, -1, 2, 2, -1, 0, 0, -1, 0, 0, -1, 0, 0, -1, 0, 0, -1, 0, 0, -1, 0, 0, -1, 0, 0, -1, 0, 0, -1, 0, 0, -1, 0, 0, -1, 0, 0, -1, 0, 0, -1, 0, 0, -1, 0, 0, -1, 0, 0, -1, 0, 0, -1, 0, 0, -1, 0, 0, -1, 0, 0, -1, 0, 0, -1, 0, 0, -1, 0, 0, -1, 0, 0, -1, 0, 0, -1, 0, 0, -1, 0, 0, -1, 0, 0, -1, 0, 0, -1, 0, 0, -1, 0, 0, -1, 0, 0, -1, 0, 0, -1, 0, 0, -1, 0, 0, -1, 0, 0, -1, 0, 0, -1, 0, 0, -1, 0, 0, -1, 0, 0, -1, 0, 0, -1, 0, 0, -1, 0, 0, -1, 0, 0, -1, 0, 0, -1, 0, 0, -1, 0, 0, -1, 0, 0, -1, 0, 0, -1, 0, 0, -1, 0, 0, -1, 0, 0, -1, 0, 0, -1, 0, 0, -1, 0, 0, -1, 0, 0, -1, 0, 0, -1, 0, 0, -1, 0, 0, -1, 0, 0, -1, 0, 0, -1, 0, 0, -1, 0, 0, -1, 0, 0, -1, 0, 0, -1, 0, 0, -1, 0, 0, -1, 0, 0, -1, 0, 0, -1, 0, 0, -1, 0, 0, -1, 0, 0, -1, 0, 0, -1, 0, 0, -1, 0, 0, -1, 0, 0, -1, 0, 0, -1, 0, 0, -1, 0, 0, -1, 0, 0, -1, 0, 0, -1, 0, 0, -1, 0, 0, -1, 0, 0, -1, 0, 0, -1, 0, 0, -1, 0, 0, -1, 0, 0, -1, 0, 0, -1, 0, 0, -1, 0, 0, -1, 0, 0, -1, 0, 0, -1, 0, 0, -1, 0, 0, -1, 0, 0, -1, 0, 0, -1, 0, 0, -1, 0, 0, -1, 0, 0, -1, 0, 0, -1, 0, 0, -1, 0, 0, -1, 0, 0, -1, 0, 0, -1, 0, 0, -1, 0, 0, -1, 0, 0, -1, 0, 0, -1, 0, 0, -1, 0, 0, -1, 0, 0, -1, 0, 0, -1, 0, 0, -1, 0, 0, -1, 0, 0, -1, 0, 0, -1, 0, 0, -1, 0, 0, -1, 0, 0, -1, 0, 0, -1, 0, 0, -1, 0, 0, -1, 0, 0, -1, 0, 0, -1, 0, 0, -1, 0, 0, -1, 0, 0, -1, 0, 0, -1, 0, 0, -1, 0, 0, -1, 0, 0, -1, 0, 0, -1, 0, 0, -1, 0, 0, -1, 0, 0, -1, 0, 0, -1, 0, 0, -1, 0, 0, -1, 0, 0, -1, 0, 0, -1, 0, 0, -1, 0, 0, -1, 0, 0, -1, 0, 0, -1, 0, 0, -1, 0, 0, -1, 0, 0, -1, 0, 0, -1, 0, 0, -1, 0, 0, -1, 0, 0, -1, 0, 0, -1, 0, 0, -1, 0, 0, -1, 0, 0, -1, 0, 0, -1, 0, 0, -1, 0, 0, -1, 0, 0, -1, 0, 0, -1, 0, 0, -1, 0, 0, -1, 0, 0, -1, 0, 0, -1, 0, 0, -1, 0, 0, -1, 0, 0, -1, 0, 0, -1, 0, 0, -1, 0, 0, -1, 0, 0, -1, 0, 0, -1, 0, 0, -1, 0, 0, -1, 0, 0, -1, 0, 0, -1, 0, 0, -1, 0, 0, -1, 0, 0, -1, 0, 0, -1, 0, 0, -1, 0, 0, -1, 0, 0, -1, 0, 0, -1, 0, 0, -1, 0, 0, -1, 0, 0, -1, 0, 0, -1, 0, 0, -1, 0, 0, -1, 0, 0, -1, 0, 0, -1, 0, 0, -1, 0, 0, -1, 0, 0, -1, 0, 0, -1, 0, 0, -1
    ]
  }
}
DEF Supervisior1 Robot {
  translation 0 -1 0
  children [
    DEF emitter9 Emitter {
      name "emitter9"
      channel 9
    }
    DEF emittertoyellowbox Emitter {
      name "emittertoyellowbox"
      channel 7
    }
    Receiver {
      channel 8
    }
    DEF emitter Emitter {
      channel 8
    }
    Receiver {
      name "receiver2"
      channel 3
    }
    Receiver {
      name "receiver1"
      channel 2
    }
    Receiver {
      name "receiver0"
      channel 1
    }
  ]
  controller "supervisor12_3"
  supervisor TRUE
  cpuConsumption 0.5
}
DEF E_PUCK E-puck {
  hidden position_0_0 33.44293970192817
  hidden position_0_1 30.504515774100344
  hidden linearVelocity_0 0.01014315415623721 -2.467064826798092e-08 -0.026007689649900415
  hidden angularVelocity_0 0.001980519517704204 -0.055244796761375684 0.0007677135723001665
  hidden rotation_1 0.9999999999999999 0 0 4.256172141149351
  hidden linearVelocity_1 0.010661398526837883 1.44406414825914e-08 -0.027335771091900003
  hidden angularVelocity_1 -1.3729495707927426 -0.05554569644094748 -0.5354732110731875
  hidden rotation_2 -1 0 0 5.3717745453819985
  hidden linearVelocity_2 0.0096177269072825 -2.9549274582765097e-08 -0.024659569390665152
  hidden angularVelocity_2 -1.2266760299440922 -0.05548989040364257 -0.4784376598761571
  translation -1.2533961781157905 -6.39930201431875e-05 -15.742853385974964
  rotation 0.002370595230794705 0.9999971028379149 0.0004178445027225573 -0.37280566791738995
  name "e-puck camera"
  controller "advanced_path_planning_potential_field"
  emitter_channel 10
  receiver_channel 9
  turretSlot [
    DEF RADAR_TARGET Solid {
      scale 0.5 0.5 0.5
      children [
        Shape {
          appearance PBRAppearance {
            baseColor 1 0 0
            roughness 1
            metalness 0
          }
          geometry DEF BOX Box {
            size 0.04 0.04 0.04
          }
        }
      ]
      name ""
    }
    Display {
      width 100
      height 100
    }
  ]
}
DEF PIONEER_3AT Pioneer3at {
  hidden position_0_0 53.248005595435814
  hidden position_0_1 53.24800328535265
  hidden position_0_2 53.2479890469841
  hidden position_0_3 53.24798958745113
  hidden linearVelocity_0 -0.23252842593159986 -5.699085045603385e-12 0.6644896771288656
  hidden angularVelocity_0 1.9339942405208464e-07 2.015509495059907e-06 -5.5379356942551e-07
  hidden rotation_8 -1 0 0 2.982523137999122
  hidden linearVelocity_8 -0.2325285253487112 -1.1335428744752575e-07 0.664489486991059
  hidden angularVelocity_8 6.040815037655782 -1.3718340251646943e-06 2.1138952842563055
  hidden rotation_9 -1 0 0 2.9825208279159607
  hidden linearVelocity_9 -0.23252862224068055 1.1325005978092801e-07 0.6644897638782647
  hidden angularVelocity_9 6.04081509713159 -1.3718339851639916e-06 2.1138953050689997
  hidden rotation_10 -1 0 0 2.9825065895474108
  hidden linearVelocity_10 -0.23252834012256238 -1.1325757416103098e-07 0.6644895518039212
  hidden angularVelocity_10 6.040815045507008 -1.3692023633742627e-06 2.1138952618174245
  hidden rotation_11 -1 0 0 2.9825071300144383
  hidden linearVelocity_11 -0.23252843701517387 1.1334677199824158e-07 0.664489828691049
  hidden angularVelocity_11 6.040815104982857 -1.369202218559979e-06 2.1138952826300947
  translation 7.79679816601549 0.1076110687995452 -0.15875774163875567
  rotation -6.558898012352265e-05 0.9999999227025435 0.0003876764021381445 2.8049753199616103
  controller "ros"
  controllerArgs "--name=pioneer3at"
  extensionSlot [
    DEF RADAR_TARGET Solid {
      translation 0 0.19999999999999998 0
      children [
        Shape {
          appearance PBRAppearance {
            baseColor 1 0 0
            roughness 1
            metalness 0
          }
          geometry DEF BOX Box {
            size 0.04 0.04 0.04
          }
        }
      ]
      name ""
      radarCrossSection 1
    }
    Camera {
      translation 0 0.17 -0.22
      width 256
      height 128
      motionBlur 500
      noise 0.02
    }
    Accelerometer {
      lookupTable [
        -39.24 -39.24 0.005
        39.24 39.24 0.005
      ]
    }
    Gyro {
      lookupTable [
        -50 -50 0.005
        50 50 0.005
      ]
    }
    SickLms291 {
      translation 0 0.23 -0.136
      noise 0.1
    }
    GPS {
    }
    InertialUnit {
    }
  ]
}
