#VRML_SIM R2019a utf8
WorldInfo {
  info [
    "Example use of a Radar device."
  ]
}
Viewpoint {
  orientation 0.031233159428276164 -0.9066863025037584 -0.420647641862154 3.2777803103222523
  position 23.478177851487093 28.822882692027463 -42.827625284903185
  follow "Pioneer 3-AT"
}
TexturedBackground {
}
TexturedBackgroundLight {
}
Floor {
  size 60 60
  tileSize 1 1
  appearance ThreadMetalPlate {
  }
}
DEF EXTERNAL_WALL Wall {
  translation 89.7133638651399 0 60.17951284376509
  rotation 0 1 0 1.5708
  name "wall(19)"
  size 60 2.4 0.2
}
DEF EXTERNAL_WALL Wall {
  translation 59.85207236429487 -4.263256414560601e-14 29.966743621106065
  rotation 0 -1 0 6.283181648405866
  name "wall(20)"
  size 60 2.4 0.2
}
Floor {
  translation 0 0 60
  name "floor(1)"
  size 60 60
  tileSize 1 1
  appearance ThreadMetalPlate {
  }
}
Floor {
  translation 60 0 60
  name "floor(2)"
  size 60 60
  tileSize 1 1
  appearance ThreadMetalPlate {
  }
}
DEF INTERNAL_WALL Wall {
  translation 12.999726668015313 -9.988683842718972e-10 90.00895734773937
  rotation 0 1 0 3.1415926248204133
  name "wall(25)"
  size 23.700000000000003 2.4 0.2
}
DEF INTERNAL_WALL Wall {
  translation 1.4190668037250127 -1.0050785277824405e-09 79.04773453810829
  rotation 0 1 0 1.5707963220000003
  name "wall(24)"
  size 22.5 2.4 0.2
}
DEF INTERNAL_WALL Wall {
  translation -29.534678120224477 -1.001063961325396e-09 71.278441619034
  rotation 0 1 0 1.5707963220000003
  name "wall(17)"
  size 37.800000000000004 2.4 0.2
}
DEF INTERNAL_WALL Wall {
  translation -10.552219319607213 -1.001063961325396e-09 41.223352168123434
  rotation 0 1 0 1.5707963220000003
  name "wall(18)"
  size 22.5 2.4 0.2
}
DEF TREE Solid {
  translation 28.89193898219605 1.1839395514004166e-12 -15.224773678242421
  rotation 0 1 0 0.785398
  scale 1.7 1.7 1.7
  name "solid(13)"
}
DEF TREE Solid {
  translation 29.38328245186393 1.1057798504668056e-12 -27.371647210801477
  rotation 0 1 0 0.785398
  scale 1.7 1.7 1.7
  children [
    PottedTree {
    }
  ]
  name "solid(12)"
}
DEF TREE Solid {
  translation 29.2498480865009 1.1839395514004166e-12 -25.240366381720218
  rotation 0 1 0 0.785398
  scale 1.7 1.7 1.7
  children [
    PottedTree {
    }
  ]
  name "solid(9)"
}
DEF TREE Solid {
  translation 24.489622479827506 1.1555178419700126e-12 -29.27081452695333
  rotation 0 1 0 0.785398
  scale 1.7 1.7 1.7
  children [
    PottedTree {
    }
  ]
  name "solid(10)"
}
DEF TREE Solid {
  translation 29.315237398904305 1.1839395514004166e-12 -29.164363932616208
  rotation 0 1 0 0.785398
  scale 1.7 1.7 1.7
  children [
    PottedTree {
    }
  ]
  name "solid(11)"
}
DEF TREE Solid {
  translation 22.726601057852463 8.926170297387755e-13 -29.30529719051825
  rotation 0 1 0 0.785398
  scale 1.7 1.7 1.7
  children [
    PottedTree {
    }
  ]
  name "solid(3)"
}
DEF TREE Solid {
  translation 17.22571045899442 1.1981504061156186e-12 -29.46482327637598
  rotation 0 1 0 0.785398
  scale 1.7 1.7 1.7
  children [
    PottedTree {
    }
  ]
  name "solid(4)"
}
DEF TREE Solid {
  translation 15.348261977327612 1.1768341240428156e-12 -29.552400328544955
  rotation 0 1 0 0.785398
  scale 1.7 1.7 1.7
  children [
    PottedTree {
    }
  ]
  name "solid(6)"
}
DEF TREE Solid {
  translation 25.969017688696457 1.1839395514004166e-12 -29.349104315484997
  rotation 0 -0.9999999999999999 0 5.497787326359172
  scale 1.7 1.7 1.7
  children [
    PottedTree {
    }
  ]
  name "solid(7)"
}
DEF TREE Solid {
  translation 13.799800932581542 1.1839395514004166e-12 -29.451850495661464
  rotation 0 1 0 0.785398
  scale 1.7 1.7 1.7
  children [
    PottedTree {
    }
  ]
  name "solid(8)"
}
DEF TREE Solid {
  translation 27.62553588846127 1.1697286966852146e-12 -29.39846814582073
  rotation 0 1 0 0.785398
  scale 1.7 1.7 1.7
  children [
    PottedTree {
    }
  ]
  name "solid(2)"
}
DEF TREE Solid {
  translation 19.113304939263735 1.0667e-12 -29.4519526116953
  rotation 0 1 0 0.785398
  scale 1.7 1.7 1.7
  children [
    PottedTree {
    }
    PottedTree {
      name "potted tree(1)"
    }
    PottedTree {
      name "potted tree(2)"
    }
    PottedTree {
      name "potted tree(3)"
    }
    PottedTree {
      name "potted tree(4)"
    }
  ]
  name "solid(1)"
}
DEF TREE Solid {
  translation 20.970201339910542 1.102227136788005e-12 -29.434055941198316
  rotation 0 1 0 0.785398
  scale 1.7 1.7 1.7
  children [
    PottedTree {
    }
  ]
  name "solid(5)"
}
DEF OFFICES Transform {
  rotation 0 1 0 3.14159
  children [
    Panel {
      translation 28.4604 0 -24.5373
      name "panel(35)"
    }
    Panel {
      translation 28.4604 0 -17.2973
      name "panel(36)"
    }
    Panel {
      translation 28.4604 0 -10.2573
      name "panel(37)"
    }
    Panel {
      translation 27.0304 0 -24.5573
      name "panel(38)"
    }
    Panel {
      translation 27.0304 0 -17.2873
      name "panel(39)"
    }
    Panel {
      translation 27.0304 0 -10.2573
      name "panel(40)"
    }
    Panel {
      translation 27.0774 0 -10.6551
      rotation 0 1 0 1.5708
      name "panel(41)"
    }
    Panel {
      translation 27.0774 0 -15.6551
      rotation 0 1 0 1.5708
      name "panel(42)"
    }
    Panel {
      translation 27.0774 0 -17.7651
      rotation 0 1 0 1.5708
      name "panel(43)"
    }
    Panel {
      translation 27.0774 0 -22.8751
      rotation 0 1 0 1.5708
      name "panel(44)"
    }
    Panel {
      translation 27.0774 0 -24.9451
      rotation 0 1 0 1.5708
      name "panel(45)"
    }
    Panel {
      translation 24.2974 0 -10.6551
      rotation 0 1 0 1.5708
      name "panel(46)"
    }
    Panel {
      translation 24.2974 0 -15.6951
      rotation 0 1 0 1.5708
      name "panel(47)"
    }
    Panel {
      translation 24.2974 0 -17.8051
      rotation 0 1 0 1.5708
      name "panel(48)"
    }
    Panel {
      translation 24.2974 0 -22.8551
      rotation 0 1 0 1.5708
      name "panel(49)"
    }
    Panel {
      translation 24.2974 0 -25.0151
      rotation 0 1 0 1.5708
      name "panel(50)"
    }
    Panel {
      translation 21.2474 0 -10.6551
      rotation 0 1 0 1.5708
      name "panel(51)"
    }
    Panel {
      translation 21.2474 0 -15.6951
      rotation 0 1 0 1.5708
      name "panel(52)"
    }
    Panel {
      translation 21.2474 0 -17.7551
      rotation 0 1 0 1.5708
      name "panel(53)"
    }
    Panel {
      translation 21.2474 0 -22.8651
      rotation 0 1 0 1.5708
      name "panel(54)"
    }
    Panel {
      translation 21.27941328705038 -3.552713678800501e-15 -19.54699077672662
      rotation 0 1 0 1.5708
      name "panel(72)"
    }
    Panel {
      translation 21.331013210072776 0 -21.225957180431337
      rotation 0 1 0 1.5708
      name "panel(73)"
    }
    Panel {
      translation 21.242538389055508 -1.4566126083082054e-13 -12.525967859818088
      rotation 0 1 0 1.5708
      name "panel(23)"
    }
    Panel {
      translation 21.243462812112455 -8.881784197001252e-14 -14.137965874591316
      rotation 0 1 0 1.5708
      name "panel(71)"
    }
    Panel {
      translation 21.2474 0 -24.8851
      rotation 0 1 0 1.5708
      name "panel(55)"
    }
    Panel {
      translation 21.2474 0 -26.6151
      rotation 0 1 0 1.5708
      name "panel(56)"
    }
    Panel {
      translation 21.2474 0 -28.2551
      rotation 0 1 0 1.5708
      name "panel(57)"
    }
    Panel {
      translation 25.5604 0 -24.5873
      name "panel(58)"
    }
    Panel {
      translation 25.5604 0 -17.3073
      name "panel(59)"
    }
    Panel {
      translation 25.5604 0 -10.2573
      name "panel(60)"
    }
    Panel {
      translation 24.1004 0 -24.5973
      name "panel(61)"
    }
    Panel {
      translation 24.1004 0 -17.3373
      name "panel(62)"
    }
    Panel {
      translation 24.1004 0 -10.2573
      name "panel(63)"
    }
    Panel {
      translation 22.5504 0 -24.5873
      name "panel(64)"
    }
    Panel {
      translation 22.5504 0 -17.3273
      name "panel(65)"
    }
    Panel {
      translation 22.5504 0 -10.2573
      name "panel(66)"
    }
    Panel {
      translation 20.9704 0 -10.2573
      name "panel(67)"
    }
    Panel {
      translation 20.9704 0 -24.5773
      name "panel(68)"
    }
    Panel {
      translation 20.9704 0 -17.3573
      name "panel(69)"
    }
    WoodenChair {
      translation 28.2877 7.10543e-15 -16.5637
      name "wooden chair(15)"
    }
    WoodenChair {
      translation 28.2877 7.10543e-15 -23.9137
      name "wooden chair(16)"
    }
    WoodenChair {
      translation 28.2877 7.10543e-15 -18.1537
      rotation 0 1 0 3.14159
      name "wooden chair(17)"
    }
    WoodenChair {
      translation 28.2877 7.10543e-15 -25.1237
      rotation 0 1 0 3.14159
      name "wooden chair(18)"
    }
    WoodenChair {
      translation 25.7177 7.10543e-15 -23.8937
      name "wooden chair(19)"
    }
    WoodenChair {
      translation 25.7177 7.10543e-15 -18.0837
      rotation 0 1 0 3.14159
      name "wooden chair(20)"
    }
    WoodenChair {
      translation 28.2877 7.10543e-15 -11.1637
      rotation 0 1 0 3.14159
      name "wooden chair(21)"
    }
    WoodenChair {
      translation 25.7177 7.10543e-15 -25.2037
      rotation 0 1 0 3.14159
      name "wooden chair(22)"
    }
    WoodenChair {
      translation 22.9577 7.10543e-15 -23.8537
      name "wooden chair(23)"
    }
    WoodenChair {
      translation 25.7177 7.10543e-15 -16.5637
      name "wooden chair(24)"
    }
    WoodenChair {
      translation 22.9577 7.10543e-15 -18.0537
      rotation 0 1 0 3.14159
      name "wooden chair(25)"
    }
    WoodenChair {
      translation 25.7177 7.10543e-15 -11.1037
      rotation 0 1 0 3.14159
      name "wooden chair(26)"
    }
    WoodenChair {
      translation 22.9577 7.10543e-15 -25.0837
      rotation 0 1 0 3.14159
      name "wooden chair(27)"
    }
    WoodenChair {
      translation 22.9577 7.10543e-15 -16.5637
      name "wooden chair(28)"
    }
    WoodenChair {
      translation 22.9577 7.10543e-15 -11.1937
      rotation 0 1 0 3.14159
      name "wooden chair(29)"
    }
    Desk {
      translation 28.2877 7.10543e-15 -16.1837
      rotation 0 1 0 6.28319
      name "desk(15)"
    }
    Desk {
      translation 28.2877 7.10543e-15 -25.5337
      rotation 0 1 0 6.28319
      name "desk(16)"
    }
    Desk {
      translation 28.2877 7.10543e-15 -11.5037
      rotation 0 1 0 6.28319
      name "desk(17)"
    }
    Desk {
      translation 28.2877 7.10543e-15 -23.5237
      rotation 0 1 0 6.28319
      name "desk(18)"
    }
    Desk {
      translation 25.6977 7.10543e-15 -16.1837
      rotation 0 1 0 6.28319
      name "desk(19)"
    }
    Desk {
      translation 25.6977 7.10543e-15 -18.4537
      rotation 0 1 0 6.28319
      name "desk(20)"
    }
    Desk {
      translation 25.6977 7.10543e-15 -11.5337
      rotation 0 1 0 6.28319
      name "desk(21)"
    }
    Desk {
      translation 22.9277 7.10543e-15 -16.1837
      rotation 0 1 0 6.28319
      name "desk(22)"
    }
    Desk {
      translation 22.9277 7.10543e-15 -11.5737
      rotation 0 1 0 6.28319
      name "desk(23)"
    }
    Desk {
      translation 25.6977 7.10543e-15 -25.5537
      rotation 0 1 0 6.28319
      name "desk(24)"
    }
    Desk {
      translation 28.2877 7.10543e-15 -18.5337
      rotation 0 1 0 6.28319
      name "desk(25)"
    }
    Desk {
      translation 22.9277 7.10543e-15 -18.4537
      rotation 0 1 0 6.28319
      name "desk(26)"
    }
    Desk {
      translation 25.6977 7.10543e-15 -23.4937
      rotation 0 1 0 6.28319
      name "desk(27)"
    }
    Desk {
      translation 22.9277 7.10543e-15 -23.5337
      rotation 0 1 0 6.28319
      name "desk(28)"
    }
    Desk {
      translation 22.9277 7.10543e-15 -25.4837
      rotation 0 1 0 6.28319
      name "desk(29)"
    }
  ]
}
DEF OFFICES Transform {
  translation 0 0 -40
  rotation 0 1 0 3.14159
  children [
    Panel {
      translation 28.4604 0 -24.5373
      name "panel(1)"
    }
    Panel {
      translation 28.4604 0 -17.2973
      name "panel(2)"
    }
    Panel {
      translation 28.4604 0 -10.2573
      name "panel(3)"
    }
    Panel {
      translation 27.0304 0 -24.5573
      name "panel(4)"
    }
    Panel {
      translation 27.0304 0 -17.2873
      name "panel(5)"
    }
    Panel {
      translation 27.0304 0 -10.2573
      name "panel(6)"
    }
    Panel {
      translation 27.0774 0 -10.6551
      rotation 0 1 0 1.5708
      name "panel(7)"
    }
    Panel {
      translation 27.0774 0 -15.6551
      rotation 0 1 0 1.5708
      name "panel(8)"
    }
    Panel {
      translation 27.0774 0 -17.7651
      rotation 0 1 0 1.5708
      name "panel(9)"
    }
    Panel {
      translation 27.0774 0 -22.8751
      rotation 0 1 0 1.5708
      name "panel(10)"
    }
    Panel {
      translation 24.2974 0 -10.6551
      rotation 0 1 0 1.5708
      name "panel(12)"
    }
    Panel {
      translation 24.2974 0 -15.6951
      rotation 0 1 0 1.5708
      name "panel(13)"
    }
    Panel {
      translation 24.2974 0 -17.8051
      rotation 0 1 0 1.5708
      name "panel(14)"
    }
    Panel {
      translation 24.2974 0 -22.8551
      rotation 0 1 0 1.5708
      name "panel(15)"
    }
    Panel {
      translation 21.2474 0 -10.6551
      rotation 0 1 0 1.5708
      name "panel(17)"
    }
    Panel {
      translation 21.3952621435841 -9.947598300641403e-14 -15.729109202722
      rotation 0 1 0 1.5708
      name "panel(18)"
    }
    Panel {
      translation 21.31044627075896 -9.947598300641403e-14 -14.04973964987817
      rotation 0 1 0 1.5708
      name "panel(21)"
    }
    Panel {
      translation 21.296215948418833 -9.237055564881302e-14 -12.31909108621101
      rotation 0 1 0 1.5708
      name "panel(22)"
    }
    Panel {
      translation 21.2474 0 -17.7551
      rotation 0 1 0 1.5708
      name "panel(19)"
    }
    Panel {
      translation 21.181637678529647 1.0658141036401503e-14 -22.679400631189946
      rotation 0 1 0 1.5708
      name "panel(20)"
    }
    Panel {
      translation 21.187549941856076 7.105427357601002e-15 -21.115898284791456
      rotation 0 1 0 1.5708
      name "panel(11)2"
    }
    Panel {
      translation 21.20323799951621 2.2382096176443156e-13 -19.58767785752691
      rotation 0 1 0 1.5708
      name "panel(16)1"
    }
    Panel {
      translation 25.5604 0 -24.5873
      name "panel(24)"
    }
    Panel {
      translation 25.5604 0 -17.3073
      name "panel(25)"
    }
    Panel {
      translation 25.5604 0 -10.2573
      name "panel(26)"
    }
    Panel {
      translation 24.1004 0 -24.5973
      name "panel(27)"
    }
    Panel {
      translation 24.1004 0 -17.3373
      name "panel(28)"
    }
    Panel {
      translation 24.1004 0 -10.2573
      name "panel(29)"
    }
    Panel {
      translation 22.5504 0 -24.5873
      name "panel(30)"
    }
    Panel {
      translation 22.5504 0 -17.3273
      name "panel(31)"
    }
    Panel {
      translation 22.5504 0 -10.2573
      name "panel(32)"
    }
    Panel {
      translation 20.9704 0 -10.2573
      name "panel(33)"
    }
    Panel {
      translation 20.9704 0 -24.5773
      name "panel(34)"
    }
    Panel {
      translation 20.9704 0 -17.3573
      name "panel(70)"
    }
    WoodenChair {
      translation 28.2877 7.10543e-15 -16.5637
      name "wooden chair(1)"
    }
    WoodenChair {
      translation 28.2877 7.10543e-15 -23.9137
      name "wooden chair(2)"
    }
    WoodenChair {
      translation 28.2877 7.10543e-15 -18.1537
      rotation 0 1 0 3.14159
      name "wooden chair(3)"
    }
    WoodenChair {
      translation 25.7177 7.10543e-15 -23.8937
      name "wooden chair(5)"
    }
    WoodenChair {
      translation 25.7177 7.10543e-15 -18.0837
      rotation 0 1 0 3.14159
      name "wooden chair(6)"
    }
    WoodenChair {
      translation 28.2877 7.10543e-15 -11.1637
      rotation 0 1 0 3.14159
      name "wooden chair(7)"
    }
    WoodenChair {
      translation 22.9577 7.10543e-15 -23.8537
      name "wooden chair(9)"
    }
    WoodenChair {
      translation 25.7177 7.10543e-15 -16.5637
      name "wooden chair(10)"
    }
    WoodenChair {
      translation 22.9577 7.10543e-15 -18.0537
      rotation 0 1 0 3.14159
      name "wooden chair(11)"
    }
    WoodenChair {
      translation 25.7177 7.10543e-15 -11.1037
      rotation 0 1 0 3.14159
      name "wooden chair(12)"
    }
    WoodenChair {
      translation 22.9577 7.10543e-15 -16.5637
      name "wooden chair(14)"
    }
    WoodenChair {
      translation 22.9577 7.10543e-15 -11.1937
      rotation 0 1 0 3.14159
      name "wooden chair(30)"
    }
    Desk {
      translation 28.2877 7.10543e-15 -16.1837
      rotation 0 1 0 6.28319
      name "desk(1)"
    }
    Desk {
      translation 28.2877 7.10543e-15 -11.5037
      rotation 0 1 0 6.28319
      name "desk(3)"
    }
    Desk {
      translation 28.2877 7.10543e-15 -23.5237
      rotation 0 1 0 6.28319
      name "desk(4)"
    }
    Desk {
      translation 25.6977 7.10543e-15 -16.1837
      rotation 0 1 0 6.28319
      name "desk(5)"
    }
    Desk {
      translation 25.6977 7.10543e-15 -18.4537
      rotation 0 1 0 6.28319
      name "desk(6)"
    }
    Desk {
      translation 25.6977 7.10543e-15 -11.5337
      rotation 0 1 0 6.28319
      name "desk(7)"
    }
    Desk {
      translation 22.9277 7.10543e-15 -16.1837
      rotation 0 1 0 6.28319
      name "desk(8)"
    }
    Desk {
      translation 22.9277 7.10543e-15 -11.5737
      rotation 0 1 0 6.28319
      name "desk(9)"
    }
    Desk {
      translation 28.2877 7.10543e-15 -18.5337
      rotation 0 1 0 6.28319
      name "desk(11)"
    }
    Desk {
      translation 22.9277 7.10543e-15 -18.4537
      rotation 0 1 0 6.28319
      name "desk(12)"
    }
    Desk {
      translation 25.6977 7.10543e-15 -23.4937
      rotation 0 1 0 6.28319
      name "desk(13)"
    }
    Desk {
      translation 22.9277 7.10543e-15 -23.5337
      rotation 0 1 0 6.28319
      name "desk(14)"
    }
  ]
}
DEF BOXES Transform {
  translation -2 0 0
  children [
    WoodenBox {
      translation 26.7873 0.89 9.13591
      name "wooden box(1)"
    }
    WoodenBox {
      translation 25.3406 0.3 9.13625
      name "wooden box(2)"
    }
    WoodenBox {
      translation 25.8306 0.91 9.13625
      name "wooden box(3)"
    }
    WoodenBox {
      translation 24.8506 0.9 9.13625
      name "wooden box(4)"
    }
    WoodenBox {
      translation 24.3706 0.3 9.13625
      name "wooden box(5)"
    }
    WoodenBox {
      translation 26.3006 0.3 9.13625
      name "wooden box(6)"
    }
    WoodenBox {
      translation 27.317 0.3 9.14677
      name "wooden box(14)"
    }
  ]
}
DEF BOXES Transform {
  translation -7 0 0
  children [
    WoodenBox {
      translation 26.7873 0.89 9.13591
      name "wooden box(7)"
    }
    WoodenBox {
      translation 25.3406 0.3 9.13625
      name "wooden box(8)"
    }
    WoodenBox {
      translation 25.8306 0.91 9.13625
      name "wooden box(9)"
    }
    WoodenBox {
      translation 24.8506 0.9 9.13625
      name "wooden box(10)"
    }
    WoodenBox {
      translation 24.3706 0.3 9.13625
      name "wooden box(11)"
    }
    WoodenBox {
      translation 26.3006 0.3 9.13625
      name "wooden box(12)"
    }
    WoodenBox {
      translation 27.317 0.3 9.14677
      name "wooden box(13)"
    }
  ]
}
DEF BOXES Transform {
  translation -12 0 0
  children [
    WoodenBox {
      translation 26.7873 0.89 9.13591
      name "wooden box9"
    }
    WoodenBox {
      translation 25.3406 0.3 9.13625
      name "wooden box10"
    }
    WoodenBox {
      translation 25.8306 0.91 9.13625
      name "wooden box11"
    }
    WoodenBox {
      translation 24.8506 0.9 9.13625
      name "wooden box12"
    }
    WoodenBox {
      translation 24.3706 0.3 9.13625
      name "wooden box13"
    }
    WoodenBox {
      translation 26.3006 0.3 9.13625
      name "wooden box14"
    }
    WoodenBox {
      translation 27.317 0.3 9.14677
      name "wooden box15"
    }
  ]
}
DEF BOXES Transform {
  translation -12 0 3
  children [
    WoodenBox {
      translation 26.7873 0.89 9.13591
      name "wooden box(16"
    }
    WoodenBox {
      translation 25.3406 0.3 9.13625
      name "wooden box(17"
    }
    WoodenBox {
      translation 25.8306 0.91 9.13625
      name "wooden box(18"
    }
    WoodenBox {
      translation 24.8506 0.9 9.13625
      name "wooden box(19"
    }
    WoodenBox {
      translation 24.3706 0.3 9.13625
      name "wooden box20"
    }
    WoodenBox {
      translation 26.3006 0.3 9.13625
      name "wooden box21"
    }
    WoodenBox {
      translation 27.317 0.3 9.14677
      name "wooden box22"
    }
  ]
}
DEF BOXES Transform {
  translation -7 0 3
  children [
    WoodenBox {
      translation 26.7873 0.89 9.13591
      name "wooden box(10)23"
    }
    WoodenBox {
      translation 25.3406 0.3 9.13625
      name "wooden box(10)24"
    }
    WoodenBox {
      translation 25.8306 0.91 9.13625
      name "wooden box25"
    }
    WoodenBox {
      translation 24.8506 0.9 9.13625
      name "wooden box(10)26"
    }
    WoodenBox {
      translation 24.3706 0.3 9.13625
      name "wooden box(10)27"
    }
    WoodenBox {
      translation 26.3006 0.3 9.13625
      name "wooden box(10)28"
    }
    WoodenBox {
      translation 27.317 0.3 9.14677
      name "wooden box(10)29"
    }
  ]
}
DEF BOXES Transform {
  translation -2 0 3
  children [
    WoodenBox {
      translation 26.7873 0.89 9.13591
      name "wooden box(10)30"
    }
    WoodenBox {
      translation 25.3406 0.3 9.13625
      name "wooden box(10)31"
    }
    WoodenBox {
      translation 25.8306 0.91 9.13625
      name "wooden box(10)32"
    }
    WoodenBox {
      translation 24.8506 0.9 9.13625
      name "wooden box(10)33"
    }
    WoodenBox {
      translation 24.3706 0.3 9.13625
      name "wooden box(10)34"
    }
    WoodenBox {
      translation 26.3006 0.3 9.13625
      name "wooden box(10)35"
    }
    WoodenBox {
      translation 27.317 0.3 9.14677
      name "wooden box(10)36"
    }
  ]
}
DEF INTERNAL_WALL Wall {
  translation 18.645432227942702 -1.0004173674358543e-09 14.333931507389142
  name "wall(13)"
  size 22.5 2.4 0.2
}
DEF INTERNAL_WALL Wall {
  translation 18.62695316156418 -1.000403156581139e-09 -12.768280399262135
  name "wall(7)"
  size 22.5 2.4 0.2
}
DEF INTERNAL_WALL Wall {
  translation 57.255442426250944 -9.994155021784325e-10 90.0353293998107
  rotation 0 1 0 6.283185307179586
  name "wall(5)"
  size 65.3 2.4 0.2
}
DEF INTERNAL_WALL Wall {
  translation -20.05029254949526 -1.0010852776074688e-09 52.452036506141766
  rotation 0 1 0 6.283185307179586
  name "wall(15)"
  size 18.599999999999998 2.4 0.2
}
DEF INTERNAL_WALL Wall {
  translation 20.435882174246963 -1.0012842295734816e-09 52.449268165445154
  rotation 0 1 0 6.283185307179586
  name "wall(16)"
  size 18.6 2.4 0.2
}
DEF INTERNAL_WALL Wall {
  translation -14.202887309318264 -1.0012842295734816e-09 90.16310011912796
  rotation 0 1 0 6.283185307179586
  name "wall(27)"
  size 30.6 2.4 0.2
}
DEF INTERNAL_WALL Wall {
  translation 11.08185009334247 -1.0001473611962654e-09 41.3519278527999
  rotation 0 1 0 1.5707963220000003
  name "wall(14)"
  size 22.5 2.4 0.2
}
DEF INTERNAL_WALL Wall {
  translation 29.816064189253492 -1.0001331503415502e-09 41.12404828133934
  rotation 0 1 0 1.5707963220000003
  name "wall(21)"
  size 22.5 2.4 0.2
}
DEF INTERNAL_WALL Wall {
  translation 24.676445168223694 -9.990815470926253e-10 78.89312758702458
  rotation 0 1 0 1.5707963220000003
  name "wall(22)"
  size 22.5 2.4 0.2
}
DEF INTERNAL_WALL Wall {
  translation 69.49257585548415 -1.0001615720509806e-09 40.838695656485214
  rotation 0 1 0 1.5707963220000003
  name "wall(26)"
  size 22.5 2.4 0.2
}
DEF INTERNAL_WALL Wall {
  translation 78.1622686542617 -9.990104928190493e-10 70.29868712753192
  rotation 0 -1 0 3.1415926631795865
  name "wall(23)"
  size 22.5 2.4 0.2
}
DEF EXTERNAL_WALL Wall {
  translation -30 0 0
  rotation 0 1 0 1.5708
  name "wall(12)"
  size 60 2.4 0.2
}
DEF EXTERNAL_WALL Wall {
  translation 30 0 0
  rotation 0 1 0 1.5708
  name "wall(11)"
  size 60 2.4 0.2
}
DEF EXTERNAL_WALL Wall {
  translation -27.45 0 30
  name "wall(10)"
  size 5.3 2.4 0.2
}
DEF DOUBLE_WINDOW Transform {
  translation -24 0 30
  children [
    Window {
      translation -0.4 0 0
      name "window(21)"
    }
    Window {
      translation 0.4 0 0
      name "window(22)"
    }
  ]
}
DEF DOUBLE_WINDOW Transform {
  translation -12 0 30
  children [
    Window {
      translation -0.4 0 0
      name "window(19)"
    }
    Window {
      translation 1.110375430352951 1.7763568394002505e-15 0.00656788148859988
      name "window(20)"
    }
    Window {
      translation 0.4 0 0
      name "window(1)"
    }
  ]
}
DEF DOUBLE_WINDOW Transform {
  translation 12 0 30
  children [
    Window {
      translation -0.4 0 0
      name "window(17)"
    }
    Window {
      translation 0.4 0 0
      name "window(18)"
    }
  ]
}
DEF DOUBLE_WINDOW Transform {
  translation 24 0 30
  children [
    Window {
      translation -0.4 0 0
      name "window(15)"
    }
    Window {
      translation 0.4 0 0
      name "window(16)"
    }
  ]
}
DEF EXTERNAL_WALL Wall {
  translation -18 0 30
  name "wall(8)"
  size 10.4 2.4 0.2
}
DEF EXTERNAL_WALL Wall {
  translation 27.45 0 30
  name "wall(9)"
  size 5.3 2.4 0.2
}
DEF EXTERNAL_WALL Wall {
  translation 18 0 30
  name "wall(6)"
  size 10.4 2.4 0.2
}
DEF DOUBLE_WINDOW Transform {
  translation -12 0 -30
  children [
    Window {
      translation -0.4 0 0
      name "window(11)"
    }
    Window {
      translation 0.4 0 0
      name "window(12)"
    }
  ]
}
DEF DOUBLE_WINDOW Transform {
  translation -24 0 -30
  children [
    Window {
      translation -0.4 0 0
      name "window(13)"
    }
    Window {
      translation 0.4 0 0
      name "window(14)"
    }
  ]
}
DEF DOUBLE_WINDOW Transform {
  translation 24 0 -30
  children [
    Window {
      translation -0.4 0 0
      name "window(7)"
    }
    Window {
      translation 0.4 0 0
      name "window(8)"
    }
  ]
}
DEF EXTERNAL_WALL Wall {
  translation -27.45 0 -30
  name "wall(4)"
  size 5.3 2.4 0.2
}
DEF EXTERNAL_WALL Wall {
  translation 27.45 0 -30
  name "wall(3)"
  size 5.3 2.4 0.2
}
DEF EXTERNAL_WALL Wall {
  translation -18 0 -30
  name "wall(2)"
  size 10.4 2.4 0.2
}
DEF EXTERNAL_WALL Wall {
  translation 18 0 -30
  name "wall(1)"
  size 10.4 2.4 0.2
}
DEF EXTERNAL_WALL Wall {
  translation 0 0 -30
  size 22.4 2.4 0.2
}
Shape {
  appearance PBRAppearance {
    baseColor 0 0 1
    roughness 1
    metalness 0
  }
  geometry IndexedFaceSet {
    coord Coordinate {
      point [
        0.21 0 0.07
        0.09 0 0.22
        0.25 0 0.26
        0.21 0.0001 0.07
        0.09 0.0001 0.22
        0.25 0.0001 0.26
      ]
    }
    coordIndex [
      2, 1, 0, -1, 3, 4, 5, -1, 0, 1
      4, 3, -1, 1, 2, 5, 4, -1, 2, 0
      3, 5, -1
    ]
  }
}
DEF YELLOW_BOX Solid {
  translation 7.434533683526493 1.2300000000000568 8.57684380595601
  rotation 0 0.9999999999999999 0 3.142388812563314
  children [
    DEF Shape Shape {
      appearance DEF PBR PBRAppearance {
        roughness 0.03934117200000009
        metalness 0
      }
      geometry DEF geometryBox Box {
        size 0.30000000000000004 2.6999999999999997 11
      }
    }
  ]
  name "YELLOW_BOX"
  boundingObject Shape {
    appearance PBRAppearance {
      roughness 1.1102230246251565e-16
      metalness 0
    }
    geometry USE geometryBox
  }
}
DEF MyBot1 Robot {
  translation 28.000100893552553 -0.00028455660962644486 28.000148028949358
  rotation 0.04136536225142987 -0.9990527457974429 -0.01350991933351576 -0.6322715872945103
  children [
    Emitter {
      channel 1
      baudRate 115200
    }
    Transform {
      translation 0 0.0415 0
      children [
        Shape {
          appearance PBRAppearance {
            baseColor 0.0820075 0.364731 0.8
            roughness 1
            metalness 0
          }
          geometry DEF BODY Cylinder {
            height 0.08
            radius 0.045
          }
        }
      ]
    }
    HingeJoint {
      jointParameters HingeJointParameters {
        position 76.03200912342763
        axis -1 0 0
        anchor 0 0.025 0
      }
      device [
        RotationalMotor {
          name "left wheel motor1"
          consumptionFactor 70
        }
        PositionSensor {
          name "left wheel sensor"
        }
      ]
      endPoint Solid {
        translation -0.04499997587308605 0.025212115181509207 -1.5427980775556811e-06
        rotation -0.999999891802933 0.0003806371612808604 -0.00026741255337772203 1.9316458556695508
        children [
          DEF WHEEL Transform {
            rotation 0 0 1 1.57
            children [
              Shape {
                appearance PBRAppearance {
                  baseColor 1 0 0
                  roughness 1
                  metalness 0
                }
                geometry Cylinder {
                  height 0.01
                  radius 0.025
                }
              }
            ]
          }
        ]
        name "left wheel"
        boundingObject USE WHEEL
        physics DEF PHYSICS_WHEEL Physics {
          density -1
          mass 0.05
        }
        linearVelocity 2.2436053904589816e-08 7.796360179668223e-10 3.066182522548645e-08
        angularVelocity 1.3469339974253668e-06 1.076229733407669e-09 -9.855877594133283e-07
      }
    }
    HingeJoint {
      jointParameters HingeJointParameters {
        position 76.03204348436458
        axis -1 0 0
        anchor 0 0.025 0
      }
      device [
        RotationalMotor {
          name "right wheel motor1"
          consumptionFactor 70
        }
        PositionSensor {
          name "right wheel sensor"
        }
      ]
      endPoint Solid {
        translation 0.044999989753531255 0.02521206446440208 -1.5431103778872996e-06
        rotation -0.9999999132083792 -0.0003814769359049093 0.00016750696000833592 2.3290000176446557
        children [
          USE WHEEL
        ]
        name "right wheel"
        boundingObject USE WHEEL
        physics USE PHYSICS_WHEEL
        linearVelocity 2.2437124133842258e-08 7.806220381212366e-10 3.066264198867128e-08
        angularVelocity 1.346935116452052e-06 -1.1620583631443583e-09 -9.855939773079657e-07
      }
    }
    DistanceSensor {
      translation -0.02 0.063 -0.042
      rotation 0 1 0 2.07
      children [
        DEF SENSOR Transform {
          rotation 0 0 1 1.57
          children [
            Shape {
              appearance PBRAppearance {
                baseColor 0.975691 0.981481 0.0252992
                roughness 1
                metalness 0
              }
              geometry Cylinder {
                height 0.004
                radius 0.008
              }
            }
          ]
        }
      ]
      name "ds0"
      lookupTable [
        0 1024 0
        0.05 1024 0
        0.15 0 0
      ]
      numberOfRays 2
      aperture 1
    }
    DistanceSensor {
      translation 0.02 0.063 -0.042
      rotation 0 1 0 1.07
      children [
        USE SENSOR
      ]
      name "ds1"
      lookupTable [
        0 1024 0
        0.05 1024 0
        0.15 0 0
      ]
      numberOfRays 2
      aperture 1
    }
    DEF SMILE Transform {
      translation 0 0.025 -0.036
      rotation 0.7745972408364944 0.44721228048294853 0.4472139204829502 1.8234794
      children [
        Shape {
          appearance PBRAppearance {
            baseColor 0.721569 0.290196 0.290196
            roughness 1
            metalness 0
          }
          geometry Cylinder {
            height 0.018
            radius 0.009
            subdivision 3
          }
        }
      ]
    }
    Radar {
      translation 0 0.1 0
      children [
        Shape {
          appearance PBRAppearance {
            baseColor 0.403922 0.403922 0.403922
            roughness 1
            metalness 0
          }
          geometry DEF BOX Box {
            size 0.04 0.04 0.04
          }
        }
      ]
      minRange 0.01
      maxRange 80
      horizontalFieldOfView 2
      verticalFieldOfView 0.5
      frequency 28
      transmittedPower 28
    }
  ]
  name "MyBot1"
  boundingObject Transform {
    translation 0 0.0415 0
    children [
      USE BODY
    ]
  }
  physics Physics {
    density -1
    mass 0.5
  }
  controller "unmovingrobot1"
  battery [
    0, 100, 30
  ]
  cpuConsumption 5
  linearVelocity 6.644588525318855e-09 7.751901875963083e-10 9.084869918782327e-09
  angularVelocity -7.18106757639822e-08 -3.4365333163597113e-11 5.2560979980202746e-08
}
DEF MyBot2 Robot {
  translation 28.00000000263316 -0.00028455819904617957 -25.000000007957212
  rotation 0.0021447696997651906 -0.9999061865192963 -0.01352841910103949 -2.8275179301794306
  children [
    Emitter {
      name "emitter2"
      channel 2
      baudRate 115200
    }
    Transform {
      translation 0 0.0415 0
      children [
        Shape {
          appearance PBRAppearance {
            baseColor 0.0820075 0.364731 0.8
            roughness 1
            metalness 0
          }
          geometry DEF BODY Cylinder {
            height 0.08
            radius 0.045
          }
        }
      ]
    }
    HingeJoint {
      jointParameters HingeJointParameters {
        position 76.03199389976388
        axis -1 0 0
        anchor 0 0.025 0
      }
      device [
        RotationalMotor {
          name "left wheel motor1"
          consumptionFactor 70
        }
        PositionSensor {
          name "left wheel sensor"
        }
      ]
      endPoint Solid {
        translation -0.044999956694958536 0.025212115599074506 -1.498728391995189e-06
        rotation -0.9999998918133123 0.0003806740908261067 -0.00026732115583203206 1.9316352848318652
        children [
          DEF WHEEL Transform {
            rotation 0 0 1 1.57
            children [
              Shape {
                appearance PBRAppearance {
                  baseColor 1 0 0
                  roughness 1
                  metalness 0
                }
                geometry Cylinder {
                  height 0.01
                  radius 0.025
                }
              }
            ]
          }
        ]
        name "left wheel"
        boundingObject USE WHEEL
        physics DEF PHYSICS_WHEEL Physics {
          density -1
          mass 0.05
        }
        linearVelocity -1.1739127921727215e-08 -7.799691559284838e-10 3.613525767172389e-08
        angularVelocity 1.5873298116532755e-06 -1.066208363716533e-09 5.156716600665986e-07
      }
    }
    HingeJoint {
      jointParameters HingeJointParameters {
        position 76.03196425384856
        axis -1 0 0
        anchor 0 0.025 0
      }
      device [
        RotationalMotor {
          name "right wheel motor1"
          consumptionFactor 70
        }
        PositionSensor {
          name "right wheel sensor"
        }
      ]
      endPoint Solid {
        translation 0.044999970632492274 0.025212064873632346 -1.4988575735695216e-06
        rotation -0.999999913214593 -0.000381492594167746 0.00016743418633012 2.3289254476162013
        children [
          USE WHEEL
        ]
        name "right wheel"
        boundingObject USE WHEEL
        physics USE PHYSICS_WHEEL
        linearVelocity -1.173956510983411e-08 -7.809160251781574e-10 3.613604645263948e-08
        angularVelocity 1.5873369220942239e-06 1.1725452505986825e-09 5.156694047715761e-07
      }
    }
    DistanceSensor {
      translation -0.02 0.063 -0.042
      rotation 0 1 0 2.07
      children [
        DEF SENSOR Transform {
          rotation 0 0 1 1.57
          children [
            Shape {
              appearance PBRAppearance {
                baseColor 0.975691 0.981481 0.0252992
                roughness 1
                metalness 0
              }
              geometry Cylinder {
                height 0.004
                radius 0.008
              }
            }
          ]
        }
      ]
      name "ds0"
      lookupTable [
        0 1024 0
        0.05 1024 0
        0.15 0 0
      ]
      numberOfRays 2
      aperture 1
    }
    DistanceSensor {
      translation 0.02 0.063 -0.042
      rotation 0 1 0 1.07
      children [
        USE SENSOR
      ]
      name "ds1"
      lookupTable [
        0 1024 0
        0.05 1024 0
        0.15 0 0
      ]
      numberOfRays 2
      aperture 1
    }
    DEF SMILE Transform {
      translation 0 0.025 -0.036
      rotation 0.7745972408364944 0.44721228048294853 0.4472139204829502 1.8234794
      children [
        Shape {
          appearance PBRAppearance {
            baseColor 0.721569 0.290196 0.290196
            roughness 1
            metalness 0
          }
          geometry Cylinder {
            height 0.018
            radius 0.009
            subdivision 3
          }
        }
      ]
    }
    Radar {
      translation 0 0.1 0
      rotation 0 1 0 6.021385901
      children [
        Shape {
          appearance PBRAppearance {
            baseColor 0.403922 0.403922 0.403922
            roughness 1
            metalness 0
          }
          geometry DEF BOX Box {
            size 0.04 0.04 0.04
          }
        }
      ]
      minRange 0.01
      maxRange 78
      horizontalFieldOfView 2
      verticalFieldOfView 0.4
    }
  ]
  name "MyBot2"
  boundingObject Transform {
    translation 0 0.0415 0
    children [
      USE BODY
    ]
  }
  physics Physics {
    density -1
    mass 0.5
  }
  controller "unmovingrobot2"
  cpuConsumption 0.5
  linearVelocity -3.478164976419146e-09 -7.755774049655883e-10 1.0699844206332739e-08
  angularVelocity -8.466016186515582e-08 4.464394005998406e-11 -2.7490728034967615e-08
}
DEF DOUBLE_WINDOW Transform {
  translation 12 0 -30
  children [
    Window {
      translation -0.4 0 0
      name "window(9)"
    }
    Window {
      translation 0.4 0 0
      name "window(10)"
    }
  ]
}
DEF MyBot3 Robot {
  translation -26.000030668825165 -0.00028463584688438737 -27.00002129231395
  rotation -0.006131384410928373 -0.9998896800567834 -0.013529000005498299 2.29029058504834
  children [
    Emitter {
      name "emitter3"
      channel 3
      baudRate 115200
    }
    Transform {
      translation 0 0.0415 0
      children [
        Shape {
          appearance PBRAppearance {
            baseColor 0.0820075 0.364731 0.8
            roughness 1
            metalness 0
          }
          geometry DEF BODY Cylinder {
            height 0.08
            radius 0.045
          }
        }
      ]
    }
    HingeJoint {
      jointParameters HingeJointParameters {
        position 76.0319911929307
        axis -1 0 0
        anchor 0 0.025 0
      }
      device [
        RotationalMotor {
          name "left wheel motor1"
          consumptionFactor 70
        }
        PositionSensor {
          name "left wheel sensor"
        }
      ]
      endPoint Solid {
        translation -0.04499995633981143 0.025212115464920665 1.5101615745090932e-06
        rotation -0.9999998919107081 0.00038451689669259187 -0.00026139114086555124 1.9329360456209117
        children [
          DEF WHEEL Transform {
            rotation 0 0 1 1.57
            children [
              Shape {
                appearance PBRAppearance {
                  baseColor 1 0 0
                  roughness 1
                  metalness 0
                }
                geometry Cylinder {
                  height 0.01
                  radius 0.025
                }
              }
            ]
          }
        ]
        name "left wheel"
        boundingObject USE WHEEL
        physics DEF PHYSICS_WHEEL Physics {
          density -1
          mass 0.05
        }
        linearVelocity 2.8575356797906618e-08 -7.796287704309176e-10 2.5033305018455628e-08
        angularVelocity 1.099649598882238e-06 -1.0618767976004695e-09 -1.2552490609333146e-06
      }
    }
    HingeJoint {
      jointParameters HingeJointParameters {
        position 76.0319386749982
        axis -1 0 0
        anchor 0 0.025 0
      }
      device [
        RotationalMotor {
          name "right wheel motor1"
          consumptionFactor 70
        }
        PositionSensor {
          name "right wheel sensor"
        }
      ]
      endPoint Solid {
        translation 0.0449999701656373 0.025212064861076897 1.5106808324934548e-06
        rotation -0.9999999132624315 -0.0003838845759045113 0.00016157896429359452 2.330203654070168
        children [
          USE WHEEL
        ]
        name "right wheel"
        boundingObject USE WHEEL
        physics USE PHYSICS_WHEEL
        linearVelocity 2.8575807884158304e-08 -7.805595814147636e-10 2.5033842064869906e-08
        angularVelocity 1.0996504398483856e-06 1.1766683556744376e-09 -1.2552567470003053e-06
      }
    }
    DistanceSensor {
      translation -0.02 0.063 -0.042
      rotation 0 1 0 2.8553981609999997
      children [
        DEF SENSOR Transform {
          rotation 0 0 1 1.57
          children [
            Shape {
              appearance PBRAppearance {
                baseColor 0.975691 0.981481 0.0252992
                roughness 1
                metalness 0
              }
              geometry Cylinder {
                height 0.004
                radius 0.008
              }
            }
          ]
        }
      ]
      name "ds0"
      lookupTable [
        0 1024 0
        0.05 1024 0
        0.15 0 0
      ]
      numberOfRays 2
      aperture 1
    }
    DistanceSensor {
      translation 0.02 0.063 -0.042
      rotation 0 1 0 1.07
      children [
        USE SENSOR
      ]
      name "ds1"
      lookupTable [
        0 1024 0
        0.05 1024 0
        0.15 0 0
      ]
      numberOfRays 2
      aperture 1
    }
    DEF SMILE Transform {
      translation 0 0.025 -0.036
      rotation 0.7745972408364944 0.44721228048294853 0.4472139204829502 1.8234794
      children [
        Shape {
          appearance PBRAppearance {
            baseColor 0.721569 0.290196 0.290196
            roughness 1
            metalness 0
          }
          geometry Cylinder {
            height 0.018
            radius 0.009
            subdivision 3
          }
        }
      ]
    }
    DEF Radar Radar {
      translation 0 0.1 0
      rotation 0 1 0 6.283185307179586
      children [
        Shape {
          appearance PBRAppearance {
            baseColor 0.403922 0.403922 0.403922
            roughness 1
            metalness 0
          }
          geometry DEF BOX Box {
            size 0.04 0.04 0.04
          }
        }
      ]
      minRange 0.01
      maxRange 79.23140049567527
      horizontalFieldOfView 2
      transmittedPower 77
    }
  ]
  name "MyBot3"
  boundingObject Transform {
    translation 0 0.0415 0
    children [
      USE BODY
    ]
  }
  physics Physics {
    density -1
    mass 0.5
  }
  controller "unmovingrobot3"
  linearVelocity 8.45864153918574e-09 -7.801985475452961e-10 7.4125214781090005e-09
  angularVelocity -5.869447808837997e-08 4.885735005642248e-11 6.70172891285375e-08
}
DEF TRAIL Shape {
  appearance Appearance {
    material Material {
      diffuseColor 0 1 0
      emissiveColor 0 1 0
    }
  }
  geometry DEF TRAIL_LINE_SET IndexedLineSet {
    coord Coordinate {
      point [
        0 0 0, 0 0 0, 0 0 0, 0 0 0, 0 0 0, 0 0 0, 0 0 0, 0 0 0, 0 0 0, 0 0 0, 0 0 0, 0 0 0, 0 0 0, 0 0 0, 0 0 0, 0 0 0, 0 0 0, 0 0 0, 0 0 0, 0 0 0, 0 0 0, 0 0 0, 0 0 0, 0 0 0, 0 0 0, 0 0 0, 0 0 0, 0 0 0, 0 0 0, 0 0 0, 0 0 0, 0 0 0, 0 0 0, 0 0 0, 0 0 0, 0 0 0, 0 0 0, 0 0 0, 0 0 0, 0 0 0, 0 0 0, 0 0 0, 0 0 0, 0 0 0, 0 0 0, 0 0 0, 0 0 0, 0 0 0, 0 0 0, 0 0 0, 0 0 0, 0 0 0, 0 0 0, 0 0 0, 0 0 0, 0 0 0, 0 0 0, 0 0 0, 0 0 0, 0 0 0, 0 0 0, 0 0 0, 0 0 0, 0 0 0, 0 0 0, 0 0 0, 0 0 0, 0 0 0, 0 0 0, 0 0 0, 0 0 0, 0 0 0, 0 0 0, 0 0 0, 0 0 0, 0 0 0, 0 0 0, 0 0 0, 0 0 0, 0 0 0, 0 0 0, 0 0 0, 0 0 0, 0 0 0, 0 0 0, 0 0 0, 0 0 0, 0 0 0, 0 0 0, 0 0 0, 0 0 0, 0 0 0, 0 0 0, 0 0 0, 0 0 0, 0 0 0, 0 0 0, 0 0 0, 0 0 0, 0 0 0, 0 0 0, 0 0 0, 0 0 0, 0 0 0, 0 0 0, 0 0 0, 0 0 0, 0 0 0, 0 0 0, 0 0 0, 0 0 0, 0 0 0, 0 0 0, 0 0 0, 0 0 0, 0 0 0, 0 0 0, 0 0 0, 0 0 0, 0 0 0, 0 0 0, 0 0 0, 0 0 0, 0 0 0, 0 0 0, 0 0 0, 0 0 0, 0 0 0, 0 0 0, 0 0 0, 0 0 0, 0 0 0, 0 0 0, 0 0 0, 0 0 0, 0 0 0, 0 0 0, 0 0 0, 0 0 0, 0 0 0, 0 0 0, 0 0 0, 0 0 0, 0 0 0, 0 0 0, 0 0 0, 0 0 0, 0 0 0, 0 0 0, 0 0 0, 0 0 0, 0 0 0, 0 0 0, 0 0 0, 0 0 0, 0 0 0, 0 0 0, 0 0 0, 0 0 0, 0 0 0, 0 0 0, 0 0 0, 0 0 0, 0 0 0, 0 0 0, 0 0 0, 0 0 0, 0 0 0, 0 0 0, 0 0 0, 0 0 0, 0 0 0, 0 0 0, 0 0 0, 0 0 0, 0 0 0, 0 0 0, 0 0 0, 0 0 0, 0 0 0, 0 0 0, 0 0 0, 0 0 0, 0 0 0, 0 0 0, 0 0 0, 0 0 0, 0 0 0, 0 0 0, 0 0 0, 0 0 0, 0 0 0, 0 0 0, 0 0 0, 0 0 0, 0 0 0, 0 0 0, 0 0 0, 0 0 0, 0 0 0
      ]
    }
    coordIndex [
      0, 1, -1, 1, 2, -1, 2, 2, -1, 0, 0, -1, 0, 0, -1, 0, 0, -1, 0, 0, -1, 0, 0, -1, 0, 0, -1, 0, 0, -1, 0, 0, -1, 0, 0, -1, 0, 0, -1, 0, 0, -1, 0, 0, -1, 0, 0, -1, 0, 0, -1, 0, 0, -1, 0, 0, -1, 0, 0, -1, 0, 0, -1, 0, 0, -1, 0, 0, -1, 0, 0, -1, 0, 0, -1, 0, 0, -1, 0, 0, -1, 0, 0, -1, 0, 0, -1, 0, 0, -1, 0, 0, -1, 0, 0, -1, 0, 0, -1, 0, 0, -1, 0, 0, -1, 0, 0, -1, 0, 0, -1, 0, 0, -1, 0, 0, -1, 0, 0, -1, 0, 0, -1, 0, 0, -1, 0, 0, -1, 0, 0, -1, 0, 0, -1, 0, 0, -1, 0, 0, -1, 0, 0, -1, 0, 0, -1, 0, 0, -1, 0, 0, -1, 0, 0, -1, 0, 0, -1, 0, 0, -1, 0, 0, -1, 0, 0, -1, 0, 0, -1, 0, 0, -1, 0, 0, -1, 0, 0, -1, 0, 0, -1, 0, 0, -1, 0, 0, -1, 0, 0, -1, 0, 0, -1, 0, 0, -1, 0, 0, -1, 0, 0, -1, 0, 0, -1, 0, 0, -1, 0, 0, -1, 0, 0, -1, 0, 0, -1, 0, 0, -1, 0, 0, -1, 0, 0, -1, 0, 0, -1, 0, 0, -1, 0, 0, -1, 0, 0, -1, 0, 0, -1, 0, 0, -1, 0, 0, -1, 0, 0, -1, 0, 0, -1, 0, 0, -1, 0, 0, -1, 0, 0, -1, 0, 0, -1, 0, 0, -1, 0, 0, -1, 0, 0, -1, 0, 0, -1, 0, 0, -1, 0, 0, -1, 0, 0, -1, 0, 0, -1, 0, 0, -1, 0, 0, -1, 0, 0, -1, 0, 0, -1, 0, 0, -1, 0, 0, -1, 0, 0, -1, 0, 0, -1, 0, 0, -1, 0, 0, -1, 0, 0, -1, 0, 0, -1, 0, 0, -1, 0, 0, -1, 0, 0, -1, 0, 0, -1, 0, 0, -1, 0, 0, -1, 0, 0, -1, 0, 0, -1, 0, 0, -1, 0, 0, -1, 0, 0, -1, 0, 0, -1, 0, 0, -1, 0, 0, -1, 0, 0, -1, 0, 0, -1, 0, 0, -1, 0, 0, -1, 0, 0, -1, 0, 0, -1, 0, 0, -1, 0, 0, -1, 0, 0, -1, 0, 0, -1, 0, 0, -1, 0, 0, -1, 0, 0, -1, 0, 0, -1, 0, 0, -1, 0, 0, -1, 0, 0, -1, 0, 0, -1, 0, 0, -1, 0, 0, -1, 0, 0, -1, 0, 0, -1, 0, 0, -1, 0, 0, -1, 0, 0, -1, 0, 0, -1, 0, 0, -1, 0, 0, -1, 0, 0, -1, 0, 0, -1, 0, 0, -1, 0, 0, -1, 0, 0, -1, 0, 0, -1, 0, 0, -1, 0, 0, -1, 0, 0, -1, 0, 0, -1, 0, 0, -1, 0, 0, -1, 0, 0, -1, 0, 0, -1, 0, 0, -1, 0, 0, -1, 0, 0, -1, 0, 0, -1, 0, 0, -1, 0, 0, -1, 0, 0, -1, 0, 0, -1, 0, 0, -1, 0, 0, -1, 0, 0, -1, 0, 0, -1, 0, 0, -1, 0, 0, -1, 0, 0, -1, 0, 0, -1, 0, 0, -1, 0, 0, -1, 0, 0, -1, 0, 0, -1, 0, 0, -1, 0, 0, -1, 0, 0, -1, 0, 0, -1, 0, 0, -1, 0, 0, -1, 0, 0, -1, 0, 0, -1, 0, 0, -1, 0, 0, -1, 0, 0, -1, 0, 0, -1, 0, 0, -1, 0, 0, -1, 0, 0, -1
    ]
  }
}
DEF Supervisior1 Robot {
  translation 0 -1 0
  children [
    DEF emittertoyellowbox Emitter {
      name "emittertoyellowbox"
      channel 7
    }
    Receiver {
      channel 8
    }
    DEF emitter Emitter {
      channel 8
    }
    Receiver {
      name "receiver2"
      channel 3
    }
    Receiver {
      name "receiver1"
      channel 2
    }
    Receiver {
      name "receiver0"
      channel 1
    }
  ]
  controller "matlab_supervisor"
  supervisor TRUE
  cpuConsumption 0.5
}
DEF PIONEER_3AT Pioneer3at {
  hidden position_0_0 8809.584361168787
  hidden position_0_1 8981.357710481387
  hidden position_0_2 3333.3334179023996
  hidden position_0_3 9082.20651079001
  hidden translation_8 -0.197 0 0.1331
  hidden rotation_8 0.9999999999999999 0 0 2.2076910099361764
  hidden translation_9 0.197 0 0.1331
  hidden rotation_9 -1 0 0 2.95157758877012
  hidden translation_10 -0.197 0 -0.1331
  hidden rotation_10 1 0 0 1.0797161491453073
  hidden translation_11 0.197 0 -0.1331
  hidden rotation_11 -1 0 0 0.5893757314041328
  translation 24.703581770790116 0.10917422589808712 -23.389645683453203
  rotation 0.00014776349700780072 0.9999999890555495 -7.406071058004203e-06 1.8131974207485888
  controller "ros"
  controllerArgs "--name=pioneer3at"
  extensionSlot [
    DEF RADAR_TARGET Solid {
      translation 0 0.19999999999999998 0
      children [
        Shape {
          appearance PBRAppearance {
            baseColor 1 0 0
            roughness 1
            metalness 0
          }
          geometry DEF BOX Box {
            size 0.04 0.04 0.04
          }
        }
      ]
      name ""
      radarCrossSection 1
    }
    Camera {
      translation 0 0.17 -0.22
      width 256
      height 128
      motionBlur 500
      noise 0.02
    }
    Accelerometer {
      lookupTable [
        -39.24 -39.24 0.005
        39.24 39.24 0.005
      ]
    }
    Gyro {
      lookupTable [
        -50 -50 0.005
        50 50 0.005
      ]
    }
    SickLms291 {
      translation 0 0.23 -0.136
      noise 0.1
    }
    GPS {
    }
    InertialUnit {
    }
  ]
}
