#VRML_SIM R2019a utf8
WorldInfo {
  info [
    "Example use of a Radar device."
  ]
}
Viewpoint {
  orientation -0.4347312556680202 0.8062892122306275 0.4011314517534377 1.7052631850371025
  position 138.31076911164214 145.02884690337808 -11.677379980540874
}
TexturedBackground {
}
TexturedBackgroundLight {
}
Floor {
  translation 30 0 0
  rotation 0.7071067811865475 0.7071067811865475 0 0
  size 120 60
  tileSize 1 1
  appearance ThreadMetalPlate {
  }
}
Floor {
  translation 30 0 0
  rotation 0.7071067811865475 0.7071067811865475 0 0
  name "floor(1)"
  size 120 60
  tileSize 1 1
  appearance ThreadMetalPlate {
  }
}
DEF YELLOW_BOX Solid {
  translation -1.177245600960731 1.2299999999997016 -12.426632989252411
  rotation 0 0.9999999999999999 0 3.142388812563314
  children [
    DEF Shape Shape {
      appearance DEF PBR PBRAppearance {
        roughness 0.03934117200000009
        metalness 0
      }
      geometry DEF geometryBox Box {
        size 0.30000000000000004 2.6999999999999997 11
      }
    }
  ]
  name "YELLOW_BOX"
  boundingObject Shape {
    appearance PBRAppearance {
      roughness 1.1102230246251565e-16
      metalness 0
    }
    geometry USE geometryBox
  }
}
SolidRoundedBox {
  translation -17.7943406357252 -3.410605131648481e-13 -26.48373355845466
}
DEF TREE Solid {
  translation 28.89193898219605 1.1839395514004166e-12 -15.224773678242421
  rotation 0 1 0 0.785398
  scale 1.7 1.7 1.7
  name "solid(13)"
}
DEF TREE Solid {
  translation 29.38328245186393 1.1057798504668056e-12 -27.371647210801477
  rotation 0 1 0 0.785398
  scale 1.7 1.7 1.7
  children [
    PottedTree {
    }
  ]
  name "solid(12)"
}
DEF TREE Solid {
  translation 29.2498480865009 1.1839395514004166e-12 -25.240366381720218
  rotation 0 1 0 0.785398
  scale 1.7 1.7 1.7
  children [
    PottedTree {
    }
  ]
  name "solid(9)"
}
DEF TREE Solid {
  translation 24.489622479827506 1.1555178419700126e-12 -29.27081452695333
  rotation 0 1 0 0.785398
  scale 1.7 1.7 1.7
  children [
    PottedTree {
    }
  ]
  name "solid(10)"
}
DEF TREE Solid {
  translation 29.315237398904305 1.1839395514004166e-12 -29.164363932616208
  rotation 0 1 0 0.785398
  scale 1.7 1.7 1.7
  children [
    PottedTree {
    }
  ]
  name "solid(11)"
}
DEF TREE Solid {
  translation 22.726601057852463 8.926170297387755e-13 -29.30529719051825
  rotation 0 1 0 0.785398
  scale 1.7 1.7 1.7
  children [
    PottedTree {
    }
  ]
  name "solid(3)"
}
DEF TREE Solid {
  translation 17.22571045899442 1.1981504061156186e-12 -29.46482327637598
  rotation 0 1 0 0.785398
  scale 1.7 1.7 1.7
  children [
    PottedTree {
    }
  ]
  name "solid(4)"
}
DEF TREE Solid {
  translation 15.348261977327612 1.1768341240428156e-12 -29.552400328544955
  rotation 0 1 0 0.785398
  scale 1.7 1.7 1.7
  children [
    PottedTree {
    }
  ]
  name "solid(6)"
}
DEF TREE Solid {
  translation 25.969017688696457 1.1839395514004166e-12 -29.349104315484997
  rotation 0 -0.9999999999999999 0 5.497787326359172
  scale 1.7 1.7 1.7
  children [
    PottedTree {
    }
  ]
  name "solid(7)"
}
DEF TREE Solid {
  translation 13.799800932581542 1.1839395514004166e-12 -29.451850495661464
  rotation 0 1 0 0.785398
  scale 1.7 1.7 1.7
  children [
    PottedTree {
    }
  ]
  name "solid(8)"
}
DEF TREE Solid {
  translation 27.62553588846127 1.1697286966852146e-12 -29.39846814582073
  rotation 0 1 0 0.785398
  scale 1.7 1.7 1.7
  children [
    PottedTree {
    }
  ]
  name "solid(2)"
}
DEF TREE Solid {
  translation 19.113304939263735 1.0667e-12 -29.4519526116953
  rotation 0 1 0 0.785398
  scale 1.7 1.7 1.7
  children [
    PottedTree {
    }
    PottedTree {
      name "potted tree(1)"
    }
    PottedTree {
      name "potted tree(2)"
    }
    PottedTree {
      name "potted tree(3)"
    }
    PottedTree {
      name "potted tree(4)"
    }
  ]
  name "solid(1)"
}
DEF TREE Solid {
  translation 20.970201339910542 1.102227136788005e-12 -29.434055941198316
  rotation 0 1 0 0.785398
  scale 1.7 1.7 1.7
  children [
    PottedTree {
    }
  ]
  name "solid(5)"
}
DEF OFFICES Transform {
  rotation 0 1 0 3.14159
  children [
    Panel {
      translation 28.4604 0 -24.5373
      name "panel(35)"
    }
    Panel {
      translation 28.4604 0 -17.2973
      name "panel(36)"
    }
    Panel {
      translation 28.4604 0 -10.2573
      name "panel(37)"
    }
    Panel {
      translation 27.0304 0 -24.5573
      name "panel(38)"
    }
    Panel {
      translation 27.0304 0 -17.2873
      name "panel(39)"
    }
    Panel {
      translation 27.0304 0 -10.2573
      name "panel(40)"
    }
    Panel {
      translation 27.0774 0 -10.6551
      rotation 0 1 0 1.5708
      name "panel(41)"
    }
    Panel {
      translation 27.0774 0 -15.6551
      rotation 0 1 0 1.5708
      name "panel(42)"
    }
    Panel {
      translation 27.0774 0 -17.7651
      rotation 0 1 0 1.5708
      name "panel(43)"
    }
    Panel {
      translation 27.0774 0 -22.8751
      rotation 0 1 0 1.5708
      name "panel(44)"
    }
    Panel {
      translation 27.0774 0 -24.9451
      rotation 0 1 0 1.5708
      name "panel(45)"
    }
    Panel {
      translation 24.2974 0 -10.6551
      rotation 0 1 0 1.5708
      name "panel(46)"
    }
    Panel {
      translation 24.2974 0 -15.6951
      rotation 0 1 0 1.5708
      name "panel(47)"
    }
    Panel {
      translation 24.2974 0 -17.8051
      rotation 0 1 0 1.5708
      name "panel(48)"
    }
    Panel {
      translation 24.2974 0 -22.8551
      rotation 0 1 0 1.5708
      name "panel(49)"
    }
    Panel {
      translation 24.2974 0 -25.0151
      rotation 0 1 0 1.5708
      name "panel(50)"
    }
    Panel {
      translation 21.2474 0 -10.6551
      rotation 0 1 0 1.5708
      name "panel(51)"
    }
    Panel {
      translation 21.2474 0 -15.6951
      rotation 0 1 0 1.5708
      name "panel(52)"
    }
    Panel {
      translation 21.2474 0 -17.7551
      rotation 0 1 0 1.5708
      name "panel(53)"
    }
    Panel {
      translation 21.2474 0 -22.8651
      rotation 0 1 0 1.5708
      name "panel(54)"
    }
    Panel {
      translation 21.27941328705038 -3.552713678800501e-15 -19.54699077672662
      rotation 0 1 0 1.5708
      name "panel(72)"
    }
    Panel {
      translation 21.331013210072776 0 -21.225957180431337
      rotation 0 1 0 1.5708
      name "panel(73)"
    }
    Panel {
      translation 21.242538389055508 -1.4566126083082054e-13 -12.525967859818088
      rotation 0 1 0 1.5708
      name "panel(23)"
    }
    Panel {
      translation 21.243462812112455 -8.881784197001252e-14 -14.137965874591316
      rotation 0 1 0 1.5708
      name "panel(71)"
    }
    Panel {
      translation 21.2474 0 -24.8851
      rotation 0 1 0 1.5708
      name "panel(55)"
    }
    Panel {
      translation 21.2474 0 -26.6151
      rotation 0 1 0 1.5708
      name "panel(56)"
    }
    Panel {
      translation 21.2474 0 -28.2551
      rotation 0 1 0 1.5708
      name "panel(57)"
    }
    Panel {
      translation 25.5604 0 -24.5873
      name "panel(58)"
    }
    Panel {
      translation 25.5604 0 -17.3073
      name "panel(59)"
    }
    Panel {
      translation 25.5604 0 -10.2573
      name "panel(60)"
    }
    Panel {
      translation 24.1004 0 -24.5973
      name "panel(61)"
    }
    Panel {
      translation 24.1004 0 -17.3373
      name "panel(62)"
    }
    Panel {
      translation 24.1004 0 -10.2573
      name "panel(63)"
    }
    Panel {
      translation 22.5504 0 -24.5873
      name "panel(64)"
    }
    Panel {
      translation 22.5504 0 -17.3273
      name "panel(65)"
    }
    Panel {
      translation 22.5504 0 -10.2573
      name "panel(66)"
    }
    Panel {
      translation 20.9704 0 -10.2573
      name "panel(67)"
    }
    Panel {
      translation 20.9704 0 -24.5773
      name "panel(68)"
    }
    Panel {
      translation 20.9704 0 -17.3573
      name "panel(69)"
    }
    WoodenChair {
      translation 28.2877 7.10543e-15 -16.5637
      name "wooden chair(15)"
    }
    WoodenChair {
      translation 28.2877 7.10543e-15 -23.9137
      name "wooden chair(16)"
    }
    WoodenChair {
      translation 28.2877 7.10543e-15 -18.1537
      rotation 0 1 0 3.14159
      name "wooden chair(17)"
    }
    WoodenChair {
      translation 28.2877 7.10543e-15 -25.1237
      rotation 0 1 0 3.14159
      name "wooden chair(18)"
    }
    WoodenChair {
      translation 25.7177 7.10543e-15 -23.8937
      name "wooden chair(19)"
    }
    WoodenChair {
      translation 25.7177 7.10543e-15 -18.0837
      rotation 0 1 0 3.14159
      name "wooden chair(20)"
    }
    WoodenChair {
      translation 28.2877 7.10543e-15 -11.1637
      rotation 0 1 0 3.14159
      name "wooden chair(21)"
    }
    WoodenChair {
      translation 25.7177 7.10543e-15 -25.2037
      rotation 0 1 0 3.14159
      name "wooden chair(22)"
    }
    WoodenChair {
      translation 22.9577 7.10543e-15 -23.8537
      name "wooden chair(23)"
    }
    WoodenChair {
      translation 25.7177 7.10543e-15 -16.5637
      name "wooden chair(24)"
    }
    WoodenChair {
      translation 22.9577 7.10543e-15 -18.0537
      rotation 0 1 0 3.14159
      name "wooden chair(25)"
    }
    WoodenChair {
      translation 25.7177 7.10543e-15 -11.1037
      rotation 0 1 0 3.14159
      name "wooden chair(26)"
    }
    WoodenChair {
      translation 22.9577 7.10543e-15 -25.0837
      rotation 0 1 0 3.14159
      name "wooden chair(27)"
    }
    WoodenChair {
      translation 22.9577 7.10543e-15 -16.5637
      name "wooden chair(28)"
    }
    WoodenChair {
      translation 22.9577 7.10543e-15 -11.1937
      rotation 0 1 0 3.14159
      name "wooden chair(29)"
    }
    Desk {
      translation 28.2877 7.10543e-15 -16.1837
      rotation 0 1 0 6.28319
      name "desk(15)"
    }
    Desk {
      translation 28.2877 7.10543e-15 -25.5337
      rotation 0 1 0 6.28319
      name "desk(16)"
    }
    Desk {
      translation 28.2877 7.10543e-15 -11.5037
      rotation 0 1 0 6.28319
      name "desk(17)"
    }
    Desk {
      translation 28.2877 7.10543e-15 -23.5237
      rotation 0 1 0 6.28319
      name "desk(18)"
    }
    Desk {
      translation 25.6977 7.10543e-15 -16.1837
      rotation 0 1 0 6.28319
      name "desk(19)"
    }
    Desk {
      translation 25.6977 7.10543e-15 -18.4537
      rotation 0 1 0 6.28319
      name "desk(20)"
    }
    Desk {
      translation 25.6977 7.10543e-15 -11.5337
      rotation 0 1 0 6.28319
      name "desk(21)"
    }
    Desk {
      translation 22.9277 7.10543e-15 -16.1837
      rotation 0 1 0 6.28319
      name "desk(22)"
    }
    Desk {
      translation 22.9277 7.10543e-15 -11.5737
      rotation 0 1 0 6.28319
      name "desk(23)"
    }
    Desk {
      translation 25.6977 7.10543e-15 -25.5537
      rotation 0 1 0 6.28319
      name "desk(24)"
    }
    Desk {
      translation 28.2877 7.10543e-15 -18.5337
      rotation 0 1 0 6.28319
      name "desk(25)"
    }
    Desk {
      translation 22.9277 7.10543e-15 -18.4537
      rotation 0 1 0 6.28319
      name "desk(26)"
    }
    Desk {
      translation 25.6977 7.10543e-15 -23.4937
      rotation 0 1 0 6.28319
      name "desk(27)"
    }
    Desk {
      translation 22.9277 7.10543e-15 -23.5337
      rotation 0 1 0 6.28319
      name "desk(28)"
    }
    Desk {
      translation 22.9277 7.10543e-15 -25.4837
      rotation 0 1 0 6.28319
      name "desk(29)"
    }
  ]
}
DEF OFFICES Transform {
  translation 0 0 -40
  rotation 0 1 0 3.14159
  children [
    Panel {
      translation 28.4604 0 -24.5373
      name "panel(1)"
    }
    Panel {
      translation 28.4604 0 -17.2973
      name "panel(2)"
    }
    Panel {
      translation 28.4604 0 -10.2573
      name "panel(3)"
    }
    Panel {
      translation 27.0304 0 -24.5573
      name "panel(4)"
    }
    Panel {
      translation 27.0304 0 -17.2873
      name "panel(5)"
    }
    Panel {
      translation 27.0304 0 -10.2573
      name "panel(6)"
    }
    Panel {
      translation 27.0774 0 -10.6551
      rotation 0 1 0 1.5708
      name "panel(7)"
    }
    Panel {
      translation 27.0774 0 -15.6551
      rotation 0 1 0 1.5708
      name "panel(8)"
    }
    Panel {
      translation 27.0774 0 -17.7651
      rotation 0 1 0 1.5708
      name "panel(9)"
    }
    Panel {
      translation 27.0774 0 -22.8751
      rotation 0 1 0 1.5708
      name "panel(10)"
    }
    Panel {
      translation 24.2974 0 -10.6551
      rotation 0 1 0 1.5708
      name "panel(12)"
    }
    Panel {
      translation 24.2974 0 -15.6951
      rotation 0 1 0 1.5708
      name "panel(13)"
    }
    Panel {
      translation 24.2974 0 -17.8051
      rotation 0 1 0 1.5708
      name "panel(14)"
    }
    Panel {
      translation 24.2974 0 -22.8551
      rotation 0 1 0 1.5708
      name "panel(15)"
    }
    Panel {
      translation 21.2474 0 -10.6551
      rotation 0 1 0 1.5708
      name "panel(17)"
    }
    Panel {
      translation 21.3952621435841 -9.947598300641403e-14 -15.729109202722
      rotation 0 1 0 1.5708
      name "panel(18)"
    }
    Panel {
      translation 21.31044627075896 -9.947598300641403e-14 -14.04973964987817
      rotation 0 1 0 1.5708
      name "panel(21)"
    }
    Panel {
      translation 21.296215948418833 -9.237055564881302e-14 -12.31909108621101
      rotation 0 1 0 1.5708
      name "panel(22)"
    }
    Panel {
      translation 21.2474 0 -17.7551
      rotation 0 1 0 1.5708
      name "panel(19)"
    }
    Panel {
      translation 21.181637678529647 1.0658141036401503e-14 -22.679400631189946
      rotation 0 1 0 1.5708
      name "panel(20)"
    }
    Panel {
      translation 21.187549941856076 7.105427357601002e-15 -21.115898284791456
      rotation 0 1 0 1.5708
      name "panel(11)2"
    }
    Panel {
      translation 21.20323799951621 2.2382096176443156e-13 -19.58767785752691
      rotation 0 1 0 1.5708
      name "panel(16)1"
    }
    Panel {
      translation 25.5604 0 -24.5873
      name "panel(24)"
    }
    Panel {
      translation 25.5604 0 -17.3073
      name "panel(25)"
    }
    Panel {
      translation 25.5604 0 -10.2573
      name "panel(26)"
    }
    Panel {
      translation 24.1004 0 -24.5973
      name "panel(27)"
    }
    Panel {
      translation 24.1004 0 -17.3373
      name "panel(28)"
    }
    Panel {
      translation 24.1004 0 -10.2573
      name "panel(29)"
    }
    Panel {
      translation 22.5504 0 -24.5873
      name "panel(30)"
    }
    Panel {
      translation 22.5504 0 -17.3273
      name "panel(31)"
    }
    Panel {
      translation 22.5504 0 -10.2573
      name "panel(32)"
    }
    Panel {
      translation 20.9704 0 -10.2573
      name "panel(33)"
    }
    Panel {
      translation 20.9704 0 -24.5773
      name "panel(34)"
    }
    Panel {
      translation 20.9704 0 -17.3573
      name "panel(70)"
    }
    WoodenChair {
      translation 28.2877 7.10543e-15 -16.5637
      name "wooden chair(1)"
    }
    WoodenChair {
      translation 28.2877 7.10543e-15 -23.9137
      name "wooden chair(2)"
    }
    WoodenChair {
      translation 28.2877 7.10543e-15 -18.1537
      rotation 0 1 0 3.14159
      name "wooden chair(3)"
    }
    WoodenChair {
      translation 25.7177 7.10543e-15 -23.8937
      name "wooden chair(5)"
    }
    WoodenChair {
      translation 25.7177 7.10543e-15 -18.0837
      rotation 0 1 0 3.14159
      name "wooden chair(6)"
    }
    WoodenChair {
      translation 28.2877 7.10543e-15 -11.1637
      rotation 0 1 0 3.14159
      name "wooden chair(7)"
    }
    WoodenChair {
      translation 22.9577 7.10543e-15 -23.8537
      name "wooden chair(9)"
    }
    WoodenChair {
      translation 25.7177 7.10543e-15 -16.5637
      name "wooden chair(10)"
    }
    WoodenChair {
      translation 22.9577 7.10543e-15 -18.0537
      rotation 0 1 0 3.14159
      name "wooden chair(11)"
    }
    WoodenChair {
      translation 25.7177 7.10543e-15 -11.1037
      rotation 0 1 0 3.14159
      name "wooden chair(12)"
    }
    WoodenChair {
      translation 22.9577 7.10543e-15 -16.5637
      name "wooden chair(14)"
    }
    WoodenChair {
      translation 22.9577 7.10543e-15 -11.1937
      rotation 0 1 0 3.14159
      name "wooden chair(30)"
    }
    Desk {
      translation 28.2877 7.10543e-15 -16.1837
      rotation 0 1 0 6.28319
      name "desk(1)"
    }
    Desk {
      translation 28.2877 7.10543e-15 -11.5037
      rotation 0 1 0 6.28319
      name "desk(3)"
    }
    Desk {
      translation 28.2877 7.10543e-15 -23.5237
      rotation 0 1 0 6.28319
      name "desk(4)"
    }
    Desk {
      translation 25.6977 7.10543e-15 -16.1837
      rotation 0 1 0 6.28319
      name "desk(5)"
    }
    Desk {
      translation 25.6977 7.10543e-15 -18.4537
      rotation 0 1 0 6.28319
      name "desk(6)"
    }
    Desk {
      translation 25.6977 7.10543e-15 -11.5337
      rotation 0 1 0 6.28319
      name "desk(7)"
    }
    Desk {
      translation 22.9277 7.10543e-15 -16.1837
      rotation 0 1 0 6.28319
      name "desk(8)"
    }
    Desk {
      translation 22.9277 7.10543e-15 -11.5737
      rotation 0 1 0 6.28319
      name "desk(9)"
    }
    Desk {
      translation 28.2877 7.10543e-15 -18.5337
      rotation 0 1 0 6.28319
      name "desk(11)"
    }
    Desk {
      translation 22.9277 7.10543e-15 -18.4537
      rotation 0 1 0 6.28319
      name "desk(12)"
    }
    Desk {
      translation 25.6977 7.10543e-15 -23.4937
      rotation 0 1 0 6.28319
      name "desk(13)"
    }
    Desk {
      translation 22.9277 7.10543e-15 -23.5337
      rotation 0 1 0 6.28319
      name "desk(14)"
    }
  ]
}
DEF BOXES Transform {
  translation 2 0 10
  children [
    WoodenBox {
      translation 26.7873 0.89 9.13591
      name "wooden box(7)"
    }
    WoodenBox {
      translation 25.3406 0.3 9.13625
      name "wooden box(8)"
    }
    WoodenBox {
      translation 25.8306 0.91 9.13625
      name "wooden box(9)"
    }
    WoodenBox {
      translation 24.8506 0.9 9.13625
      name "wooden box(10)"
    }
    WoodenBox {
      translation 24.3706 0.3 9.13625
      name "wooden box(11)"
    }
    WoodenBox {
      translation 26.3006 0.3 9.13625
      name "wooden box(12)"
    }
    WoodenBox {
      translation 27.317 0.3 9.14677
      name "wooden box(13)"
    }
  ]
}
DEF BOXES Transform {
  translation -7 0 10
  children [
    WoodenBox {
      translation 26.7873 0.89 9.13591
      name "wooden box(10)23"
    }
    WoodenBox {
      translation 25.3406 0.3 9.13625
      name "wooden box(10)24"
    }
    WoodenBox {
      translation 25.8306 0.91 9.13625
      name "wooden box25"
    }
    WoodenBox {
      translation 24.8506 0.9 9.13625
      name "wooden box(10)26"
    }
    WoodenBox {
      translation 24.3706 0.3 9.13625
      name "wooden box(10)27"
    }
    WoodenBox {
      translation 26.3006 0.3 9.13625
      name "wooden box(10)28"
    }
    WoodenBox {
      translation 27.317 0.3 9.14677
      name "wooden box(10)29"
    }
  ]
}
DEF BOXES Transform {
  translation -2 0 10
  children [
    WoodenBox {
      translation 26.7873 0.89 9.13591
      name "wooden box(10)30"
    }
    WoodenBox {
      translation 25.3406 0.3 9.13625
      name "wooden box(10)31"
    }
    WoodenBox {
      translation 25.8306 0.91 9.13625
      name "wooden box(10)32"
    }
    WoodenBox {
      translation 24.8506 0.9 9.13625
      name "wooden box(10)33"
    }
    WoodenBox {
      translation 24.3706 0.3 9.13625
      name "wooden box(10)34"
    }
    WoodenBox {
      translation 26.3006 0.3 9.13625
      name "wooden box(10)35"
    }
    WoodenBox {
      translation 27.317 0.3 9.14677
      name "wooden box(10)36"
    }
  ]
}
DEF INTERNAL_WINDOW Window {
  translation -11.283624405978252 -1.5987211554602254e-14 -0.9089969314674011
  rotation 0 -1 0 3.141591686718346
  name "window(4)"
  size 0.9 2.7 0.2
}
DEF INTERNAL_WALL Wall {
  translation -20.841722096896945 1.7763568394002505e-15 -0.895663661597073
  name "wall(7)"
  size 18.2 2.7 0.2
}
DEF INTERNAL_WALL Wall {
  translation 22.33680788536912 -1.00072645352591e-09 -0.32206361776145265
  rotation 0 1 0 1.5707963220000003
  name "wall(13)17"
  size 27.4 2.4 0.2
}
DEF INTERNAL_WALL Wall {
  translation 14.75493091866229 -1.0006838209617643e-09 6.442068600406811
  rotation 0 -1 0 4.7123890043591725
  name "wall(1316"
  size 27.4 2.4 0.2
}
DEF INTERNAL_WALL Wall {
  translation 6.426275502676432 -1.0007122426711947e-09 -0.7324299451445846
  rotation 0 -1 0 4.7123890043591725
  name "wall(1315"
  size 27.4 2.4 0.2
}
DEF INTERNAL_WALL Wall {
  translation -1.264620374496264 -1.0007122426711947e-09 6.776545327163253
  rotation 0 -1 0 4.7123890043591725
  name "wall(1314"
  size 27.4 2.4 0.2
}
DEF INTERNAL_WALL Wall {
  translation 6.249121520955011 -1.0001153867731562e-09 -21.943904131171486
  rotation 0 1 0 1.5707963220000003
  name "wall(13123"
  size 15.9 2.4 0.2
}
DEF INTERNAL_WALL Wall {
  translation 14.432411492120242 -1.000101175918441e-09 -13.934505883459174
  name "wall(1312"
  size 15.9 2.4 0.2
}
DEF INTERNAL_WALL Wall {
  translation 22.254618151926593 -1.0001153867731562e-09 -22.204424402640733
  name "wall(1311"
  size 15.9 2.4 0.2
}
DEF INTERNAL_WALL Wall {
  translation 14.296785349750635 -1.0003249968802055e-09 20.5767634177167
  name "wall(14)"
  size 31.299999999999997 2.4 0.2
}
DEF EXTERNAL_WALL Wall {
  translation -30 0 0
  rotation 0 1 0 1.5708
  name "wall(12)"
  size 60 2.4 0.2
}
DEF EXTERNAL_WALL Wall {
  translation 29.840857291770405 -5.115907697472721e-13 -4.748827247581081
  rotation 0 1 0 1.5708
  name "wall(14)44"
  size 51 2.4 0.2
}
DEF EXTERNAL_WALL Wall {
  translation -27.45 0 30
  name "wall(10)"
  size 5.3 2.4 0.2
}
DEF DOUBLE_WINDOW Transform {
  translation -24 0 30
  children [
    Window {
      translation -0.4 0 0
      name "window(21)"
    }
    Window {
      translation 0.4 0 0
      name "window(22)"
    }
  ]
}
DEF DOUBLE_WINDOW Transform {
  translation -12 0 30
  children [
    Window {
      translation -0.4 0 0
      name "window(19)"
    }
    Window {
      translation 0.4 0 0
      name "window(20)"
    }
  ]
}
DEF DOUBLE_WINDOW Transform {
  translation 12 0 30
}
DEF DOUBLE_WINDOW Transform {
  translation 24 0 30
  children [
    Window {
      translation -0.4 0 0
      name "window(15)"
    }
    Window {
      translation 0.4 0 0
      name "window(16)"
    }
  ]
}
DEF EXTERNAL_WALL Wall {
  translation -18 0 30
  name "wall(8)"
  size 10.4 2.4 0.2
}
DEF EXTERNAL_WALL Wall {
  translation 27.45 0 30
  name "wall(9)"
  size 5.3 2.4 0.2
}
DEF EXTERNAL_WALL Wall {
  translation 18 0 30
  name "wall(6)"
  size 10.4 2.4 0.2
}
DEF EXTERNAL_WALL Wall {
  translation 0.7995902474737342 -2.5579538487363607e-13 29.963116458244034
  name "wall(5)"
  size 24 2.4 0.2
}
DEF DOUBLE_WINDOW Transform {
  translation -12 0 -30
  children [
    Window {
      translation -0.4 0 0
      name "window(11)"
    }
    Window {
      translation 0.4 0 0
      name "window(12)"
    }
  ]
}
DEF DOUBLE_WINDOW Transform {
  translation -24 0 -30
  children [
    Window {
      translation -0.4 0 0
      name "window(13)"
    }
    Window {
      translation 0.4 0 0
      name "window(14)"
    }
  ]
}
DEF DOUBLE_WINDOW Transform {
  translation 24 0 -30
  children [
    Window {
      translation -0.4 0 0
      name "window(7)"
    }
    Window {
      translation 0.4 0 0
      name "window(8)"
    }
  ]
}
DEF EXTERNAL_WALL Wall {
  translation -27.45 0 -30
  name "wall(4)"
  size 5.3 2.4 0.2
}
DEF EXTERNAL_WALL Wall {
  translation 27.45 0 -30
  name "wall(3)"
  size 5.3 2.4 0.2
}
DEF EXTERNAL_WALL Wall {
  translation -18 0 -30
  name "wall(2)"
  size 10.4 2.4 0.2
}
DEF EXTERNAL_WALL Wall {
  translation 18 0 -30
  name "wall(1)"
  size 10.4 2.4 0.2
}
DEF EXTERNAL_WALL Wall {
  translation 0 0 -30
  size 22.4 2.4 0.2
}
Shape {
  appearance PBRAppearance {
    baseColor 0 0 1
    roughness 1
    metalness 0
  }
  geometry IndexedFaceSet {
    coord Coordinate {
      point [
        0.21 0 0.07
        0.09 0 0.22
        0.25 0 0.26
        0.21 0.0001 0.07
        0.09 0.0001 0.22
        0.25 0.0001 0.26
      ]
    }
    coordIndex [
      2, 1, 0, -1, 3, 4, 5, -1, 0, 1
      4, 3, -1, 1, 2, 5, 4, -1, 2, 0
      3, 5, -1
    ]
  }
}
DEF MyBot1 Robot {
  translation 27.999999036701475 -0.000324059899197128 27.999999196884602
  rotation 0.027346702359564545 -0.9995402520085547 -0.01309360472644773 -0.893790073221419
  children [
    Emitter {
      channel 1
      baudRate 115200
    }
    Transform {
      translation 0 0.0415 0
      children [
        Shape {
          appearance PBRAppearance {
            baseColor 0.0820075 0.364731 0.8
            roughness 1
            metalness 0
          }
          geometry DEF BODY Cylinder {
            height 0.08
            radius 0.045
          }
        }
      ]
    }
    HingeJoint {
      jointParameters HingeJointParameters {
        position 76.03200966526748
        axis -1 0 0
        anchor 0 0.025 0
      }
      device [
        RotationalMotor {
          name "left wheel motor1"
          consumptionFactor 70
        }
        PositionSensor {
          name "left wheel sensor"
        }
      ]
      endPoint Solid {
        translation -0.04499997587308603 0.025212115180673227 -1.5429130100120012e-06
        rotation -0.9999998918029736 0.00038063701752832983 -0.000267412606405223 1.9316463975093445
        children [
          DEF WHEEL Transform {
            rotation 0 0 1 1.57
            children [
              Shape {
                appearance PBRAppearance {
                  baseColor 1 0 0
                  roughness 1
                  metalness 0
                }
                geometry Cylinder {
                  height 0.01
                  radius 0.025
                }
              }
            ]
          }
        ]
        name "left wheel"
        boundingObject USE WHEEL
        physics DEF PHYSICS_WHEEL Physics {
          density -1
          mass 0.05
        }
        linearVelocity 8.860463342467888e-08 -1.4043784318571667e-07 7.150091334605014e-08
        angularVelocity 2.9820223978399706e-06 -2.2742537096135316e-09 -3.7059512225832623e-06
      }
    }
    HingeJoint {
      jointParameters HingeJointParameters {
        position 76.03204401678502
        axis -1 0 0
        anchor 0 0.025 0
      }
      device [
        RotationalMotor {
          name "right wheel motor1"
          consumptionFactor 70
        }
        PositionSensor {
          name "right wheel sensor"
        }
      ]
      endPoint Solid {
        translation 0.04499998975353129 0.025212064463580465 -1.5432232853427658e-06
        rotation -0.999999913208399 -0.0003814768476211841 0.00016750704237632357 2.3290005500650532
        children [
          USE WHEEL
        ]
        name "right wheel"
        boundingObject USE WHEEL
        physics USE PHYSICS_WHEEL
        linearVelocity 8.862067677918855e-08 -1.403928361654004e-07 7.127477643783968e-08
        angularVelocity 2.9820886847582764e-06 -3.924801760971849e-09 -3.7060264613897825e-06
      }
    }
    DistanceSensor {
      translation -0.02 0.063 -0.042
      rotation 0 1 0 2.07
      children [
        DEF SENSOR Transform {
          rotation 0 0 1 1.57
          children [
            Shape {
              appearance PBRAppearance {
                baseColor 0.975691 0.981481 0.0252992
                roughness 1
                metalness 0
              }
              geometry Cylinder {
                height 0.004
                radius 0.008
              }
            }
          ]
        }
      ]
      name "ds0"
      lookupTable [
        0 1024 0
        0.05 1024 0
        0.15 0 0
      ]
      numberOfRays 2
      aperture 1
    }
    DistanceSensor {
      translation 0.02 0.063 -0.042
      rotation 0 1 0 1.07
      children [
        USE SENSOR
      ]
      name "ds1"
      lookupTable [
        0 1024 0
        0.05 1024 0
        0.15 0 0
      ]
      numberOfRays 2
      aperture 1
    }
    DEF SMILE Transform {
      translation 0 0.025 -0.036
      rotation 0.7745972408364944 0.44721228048294853 0.4472139204829502 1.8234794
      children [
        Shape {
          appearance PBRAppearance {
            baseColor 0.721569 0.290196 0.290196
            roughness 1
            metalness 0
          }
          geometry Cylinder {
            height 0.018
            radius 0.009
            subdivision 3
          }
        }
      ]
    }
    Radar {
      translation 0 0.1 0
      children [
        Shape {
          appearance PBRAppearance {
            baseColor 0.403922 0.403922 0.403922
            roughness 1
            metalness 0
          }
          geometry DEF BOX Box {
            size 0.04 0.04 0.04
          }
        }
      ]
      minRange 0.01
      maxRange 80
      horizontalFieldOfView 2
      verticalFieldOfView 0.5
      frequency 28
      transmittedPower 28
    }
  ]
  name "MyBot1"
  boundingObject Transform {
    translation 0 0.0415 0
    children [
      USE BODY
    ]
  }
  physics Physics {
    density -1
    mass 0.5
  }
  controller "unmovingrobot1"
  battery [
    0, 100, 30
  ]
  cpuConsumption 5
  linearVelocity 1.1205406127093899e-07 -1.3911448002087857e-07 9.002026486714822e-08
  angularVelocity 1.8768237708682418e-06 -3.099957678357783e-09 -2.3318483003030757e-06
}
DEF MyBot2 Robot {
  translation 27.999999585933928 -0.0003240613847974791 -24.999998856697598
  rotation 0.002077185699027803 -0.9999119971175877 -0.013102798170196616 -2.8275197095262534
  children [
    Emitter {
      name "emitter2"
      channel 2
      baudRate 115200
    }
    Transform {
      translation 0 0.0415 0
      children [
        Shape {
          appearance PBRAppearance {
            baseColor 0.0820075 0.364731 0.8
            roughness 1
            metalness 0
          }
          geometry DEF BODY Cylinder {
            height 0.08
            radius 0.045
          }
        }
      ]
    }
    HingeJoint {
      jointParameters HingeJointParameters {
        position 76.03199382354038
        axis -1 0 0
        anchor 0 0.025 0
      }
      device [
        RotationalMotor {
          name "left wheel motor1"
          consumptionFactor 70
        }
        PositionSensor {
          name "left wheel sensor"
        }
      ]
      endPoint Solid {
        translation -0.044999956694958564 0.025212115599188744 -1.498712223802604e-06
        rotation -0.9999998918133065 0.000380674111046149 -0.00026732114836863286 1.9316352086083723
        children [
          DEF WHEEL Transform {
            rotation 0 0 1 1.57
            children [
              Shape {
                appearance PBRAppearance {
                  baseColor 1 0 0
                  roughness 1
                  metalness 0
                }
                geometry Cylinder {
                  height 0.01
                  radius 0.025
                }
              }
            ]
          }
        ]
        name "left wheel"
        boundingObject USE WHEEL
        physics DEF PHYSICS_WHEEL Physics {
          density -1
          mass 0.05
        }
        linearVelocity 3.5443532196162335e-08 -1.404370786772572e-07 -1.082777519023746e-07
        angularVelocity -4.525292768749434e-06 -5.93299347725494e-09 -1.4707428766317064e-06
      }
    }
    HingeJoint {
      jointParameters HingeJointParameters {
        position 76.03196417806873
        axis -1 0 0
        anchor 0 0.025 0
      }
      device [
        RotationalMotor {
          name "right wheel motor1"
          consumptionFactor 70
        }
        PositionSensor {
          name "right wheel sensor"
        }
      ]
      endPoint Solid {
        translation 0.0449999706324923 0.02521206487374593 -1.4988415033300898e-06
        rotation -0.9999999132145904 -0.00038149260673137633 0.000167434174605118 2.328925371836385
        children [
          USE WHEEL
        ]
        name "right wheel"
        boundingObject USE WHEEL
        physics USE PHYSICS_WHEEL
        linearVelocity 3.5176595753245976e-08 -1.4042234031557338e-07 -1.0805885921787002e-07
        angularVelocity -4.525507431982042e-06 -7.562873868331239e-09 -1.4708175355030263e-06
      }
    }
    DistanceSensor {
      translation -0.02 0.063 -0.042
      rotation 0 1 0 2.07
      children [
        DEF SENSOR Transform {
          rotation 0 0 1 1.57
          children [
            Shape {
              appearance PBRAppearance {
                baseColor 0.975691 0.981481 0.0252992
                roughness 1
                metalness 0
              }
              geometry Cylinder {
                height 0.004
                radius 0.008
              }
            }
          ]
        }
      ]
      name "ds0"
      lookupTable [
        0 1024 0
        0.05 1024 0
        0.15 0 0
      ]
      numberOfRays 2
      aperture 1
    }
    DistanceSensor {
      translation 0.02 0.063 -0.042
      rotation 0 1 0 1.07
      children [
        USE SENSOR
      ]
      name "ds1"
      lookupTable [
        0 1024 0
        0.05 1024 0
        0.15 0 0
      ]
      numberOfRays 2
      aperture 1
    }
    DEF SMILE Transform {
      translation 0 0.025 -0.036
      rotation 0.7745972408364944 0.44721228048294853 0.4472139204829502 1.8234794
      children [
        Shape {
          appearance PBRAppearance {
            baseColor 0.721569 0.290196 0.290196
            roughness 1
            metalness 0
          }
          geometry Cylinder {
            height 0.018
            radius 0.009
            subdivision 3
          }
        }
      ]
    }
    Radar {
      translation 0 0.1 0
      rotation 0 1 0 6.021385901
      children [
        Shape {
          appearance PBRAppearance {
            baseColor 0.403922 0.403922 0.403922
            roughness 1
            metalness 0
          }
          geometry DEF BOX Box {
            size 0.04 0.04 0.04
          }
        }
      ]
      minRange 0.01
      maxRange 78
      horizontalFieldOfView 2
      verticalFieldOfView 0.4
    }
  ]
  name "MyBot2"
  boundingObject Transform {
    translation 0 0.0415 0
    children [
      USE BODY
    ]
  }
  physics Physics {
    density -1
    mass 0.5
  }
  controller "unmovingrobot2"
  cpuConsumption 0.5
  linearVelocity 4.423720746043706e-08 -1.3912855433769912e-07 -1.3702258969231167e-07
  angularVelocity -2.848218931011437e-06 -6.759184995483267e-09 -9.259516350865876e-07
}
DEF DOUBLE_WINDOW Transform {
  translation 12 0 -30
  children [
    Window {
      translation -0.4 0 0
      name "window(9)"
    }
    Window {
      translation 0.4 0 0
      name "window(10)"
    }
  ]
}
DEF MyBot3 Robot {
  translation -25.999999059045948 -0.0003241340568352069 -26.999999157797372
  rotation -0.005938629261665344 -0.9998965107066439 -0.013103456001026905 2.290284787422022
  children [
    Emitter {
      name "emitter3"
      channel 3
      baudRate 115200
    }
    Transform {
      translation 0 0.0415 0
      children [
        Shape {
          appearance PBRAppearance {
            baseColor 0.0820075 0.364731 0.8
            roughness 1
            metalness 0
          }
          geometry DEF BODY Cylinder {
            height 0.08
            radius 0.045
          }
        }
      ]
    }
    HingeJoint {
      jointParameters HingeJointParameters {
        position 76.0319911168616
        axis -1 0 0
        anchor 0 0.025 0
      }
      device [
        RotationalMotor {
          name "left wheel motor1"
          consumptionFactor 70
        }
        PositionSensor {
          name "left wheel sensor"
        }
      ]
      endPoint Solid {
        translation -0.04499995633981141 0.025212115464805788 1.5101777099394467e-06
        rotation -0.9999998919107022 0.0003845169167331419 -0.0002613911331055991 1.9329359695518211
        children [
          DEF WHEEL Transform {
            rotation 0 0 1 1.57
            children [
              Shape {
                appearance PBRAppearance {
                  baseColor 1 0 0
                  roughness 1
                  metalness 0
                }
                geometry Cylinder {
                  height 0.01
                  radius 0.025
                }
              }
            ]
          }
        ]
        name "left wheel"
        boundingObject USE WHEEL
        physics DEF PHYSICS_WHEEL Physics {
          density -1
          mass 0.05
        }
        linearVelocity -8.549207216023206e-08 -1.4043461046494267e-07 -7.510255425440881e-08
        angularVelocity -3.1343247427506948e-06 -9.754178099576474e-10 3.576182574836293e-06
      }
    }
    HingeJoint {
      jointParameters HingeJointParameters {
        position 76.0319385989964
        axis -1 0 0
        anchor 0 0.025 0
      }
      device [
        RotationalMotor {
          name "right wheel motor1"
          consumptionFactor 70
        }
        PositionSensor {
          name "right wheel sensor"
        }
      ]
      endPoint Solid {
        translation 0.044999970165637344 0.02521206486096208 1.510696949802548e-06
        rotation -0.9999999132624288 -0.0003838845883105044 0.0001615789523429624 2.330203578068379
        children [
          USE WHEEL
        ]
        name "right wheel"
        boundingObject USE WHEEL
        physics USE PHYSICS_WHEEL
        linearVelocity -8.556089688000533e-08 -1.4037869593867794e-07 -7.491522182312064e-08
        angularVelocity -3.1343667955203153e-06 -2.6273394883128263e-09 3.57622369311429e-06
      }
    }
    DistanceSensor {
      translation -0.02 0.063 -0.042
      rotation 0 1 0 2.8553981609999997
      children [
        DEF SENSOR Transform {
          rotation 0 0 1 1.57
          children [
            Shape {
              appearance PBRAppearance {
                baseColor 0.975691 0.981481 0.0252992
                roughness 1
                metalness 0
              }
              geometry Cylinder {
                height 0.004
                radius 0.008
              }
            }
          ]
        }
      ]
      name "ds0"
      lookupTable [
        0 1024 0
        0.05 1024 0
        0.15 0 0
      ]
      numberOfRays 2
      aperture 1
    }
    DistanceSensor {
      translation 0.02 0.063 -0.042
      rotation 0 1 0 1.07
      children [
        USE SENSOR
      ]
      name "ds1"
      lookupTable [
        0 1024 0
        0.05 1024 0
        0.15 0 0
      ]
      numberOfRays 2
      aperture 1
    }
    DEF SMILE Transform {
      translation 0 0.025 -0.036
      rotation 0.7745972408364944 0.44721228048294853 0.4472139204829502 1.8234794
      children [
        Shape {
          appearance PBRAppearance {
            baseColor 0.721569 0.290196 0.290196
            roughness 1
            metalness 0
          }
          geometry Cylinder {
            height 0.018
            radius 0.009
            subdivision 3
          }
        }
      ]
    }
    DEF Radar Radar {
      translation 0 0.1 0
      rotation 0 1 0 6.283185307179586
      children [
        Shape {
          appearance PBRAppearance {
            baseColor 0.403922 0.403922 0.403922
            roughness 1
            metalness 0
          }
          geometry DEF BOX Box {
            size 0.04 0.04 0.04
          }
        }
      ]
      minRange 0.01
      maxRange 79.23140049567527
      horizontalFieldOfView 2
      transmittedPower 77
    }
  ]
  name "MyBot3"
  boundingObject Transform {
    translation 0 0.0415 0
    children [
      USE BODY
    ]
  }
  physics Physics {
    density -1
    mass 0.5
  }
  controller "unmovingrobot3"
  linearVelocity -1.0807707232735079e-07 -1.3909185071272624e-07 -9.465320084482041e-08
  angularVelocity -1.9724108146035123e-06 -1.7979080116412542e-09 2.2498287439111294e-06
}
DEF TRAIL Shape {
  appearance Appearance {
    material Material {
      diffuseColor 0 1 0
      emissiveColor 0 1 0
    }
  }
  geometry DEF TRAIL_LINE_SET IndexedLineSet {
    coord Coordinate {
      point [
        0 0 0, 0 0 0, 0 0 0, 0 0 0, 0 0 0, 0 0 0, 0 0 0, 0 0 0, 0 0 0, 0 0 0, 0 0 0, 0 0 0, 0 0 0, 0 0 0, 0 0 0, 0 0 0, 0 0 0, 0 0 0, 0 0 0, 0 0 0, 0 0 0, 0 0 0, 0 0 0, 0 0 0, 0 0 0, 0 0 0, 0 0 0, 0 0 0, 0 0 0, 0 0 0, 0 0 0, 0 0 0, 0 0 0, 0 0 0, 0 0 0, 0 0 0, 0 0 0, 0 0 0, 0 0 0, 0 0 0, 0 0 0, 0 0 0, 0 0 0, 0 0 0, 0 0 0, 0 0 0, 0 0 0, 0 0 0, 0 0 0, 0 0 0, 0 0 0, 0 0 0, 0 0 0, 0 0 0, 0 0 0, 0 0 0, 0 0 0, 0 0 0, 0 0 0, 0 0 0, 0 0 0, 0 0 0, 0 0 0, 0 0 0, 0 0 0, 0 0 0, 0 0 0, 0 0 0, 0 0 0, 0 0 0, 0 0 0, 0 0 0, 0 0 0, 0 0 0, 0 0 0, 0 0 0, 0 0 0, 0 0 0, 0 0 0, 0 0 0, 0 0 0, 0 0 0, 0 0 0, 0 0 0, 0 0 0, 0 0 0, 0 0 0, 0 0 0, 0 0 0, 0 0 0, 0 0 0, 0 0 0, 0 0 0, 0 0 0, 0 0 0, 0 0 0, 0 0 0, 0 0 0, 0 0 0, 0 0 0, 0 0 0, 0 0 0, 0 0 0, 0 0 0, 0 0 0, 0 0 0, 0 0 0, 0 0 0, 0 0 0, 0 0 0, 0 0 0, 0 0 0, 0 0 0, 0 0 0, 0 0 0, 0 0 0, 0 0 0, 0 0 0, 0 0 0, 0 0 0, 0 0 0, 0 0 0, 0 0 0, 0 0 0, 0 0 0, 0 0 0, 0 0 0, 0 0 0, 0 0 0, 0 0 0, 0 0 0, 0 0 0, 0 0 0, 0 0 0, 0 0 0, 0 0 0, 0 0 0, 0 0 0, 0 0 0, 0 0 0, 0 0 0, 0 0 0, 0 0 0, 0 0 0, 0 0 0, 0 0 0, 0 0 0, 0 0 0, 0 0 0, 0 0 0, 0 0 0, 0 0 0, 0 0 0, 0 0 0, 0 0 0, 0 0 0, 0 0 0, 0 0 0, 0 0 0, 0 0 0, 0 0 0, 0 0 0, 0 0 0, 0 0 0, 0 0 0, 0 0 0, 0 0 0, 0 0 0, 0 0 0, 0 0 0, 0 0 0, 0 0 0, 0 0 0, 0 0 0, 0 0 0, 0 0 0, 0 0 0, 0 0 0, 0 0 0, 0 0 0, 0 0 0, 0 0 0, 0 0 0, 0 0 0, 0 0 0, 0 0 0, 0 0 0, 0 0 0, 0 0 0, 0 0 0, 0 0 0, 0 0 0, 0 0 0, 0 0 0, 0 0 0, 0 0 0, 0 0 0, 0 0 0, 0 0 0, 0 0 0
      ]
    }
    coordIndex [
      0, 1, -1, 1, 2, -1, 2, 2, -1, 0, 0, -1, 0, 0, -1, 0, 0, -1, 0, 0, -1, 0, 0, -1, 0, 0, -1, 0, 0, -1, 0, 0, -1, 0, 0, -1, 0, 0, -1, 0, 0, -1, 0, 0, -1, 0, 0, -1, 0, 0, -1, 0, 0, -1, 0, 0, -1, 0, 0, -1, 0, 0, -1, 0, 0, -1, 0, 0, -1, 0, 0, -1, 0, 0, -1, 0, 0, -1, 0, 0, -1, 0, 0, -1, 0, 0, -1, 0, 0, -1, 0, 0, -1, 0, 0, -1, 0, 0, -1, 0, 0, -1, 0, 0, -1, 0, 0, -1, 0, 0, -1, 0, 0, -1, 0, 0, -1, 0, 0, -1, 0, 0, -1, 0, 0, -1, 0, 0, -1, 0, 0, -1, 0, 0, -1, 0, 0, -1, 0, 0, -1, 0, 0, -1, 0, 0, -1, 0, 0, -1, 0, 0, -1, 0, 0, -1, 0, 0, -1, 0, 0, -1, 0, 0, -1, 0, 0, -1, 0, 0, -1, 0, 0, -1, 0, 0, -1, 0, 0, -1, 0, 0, -1, 0, 0, -1, 0, 0, -1, 0, 0, -1, 0, 0, -1, 0, 0, -1, 0, 0, -1, 0, 0, -1, 0, 0, -1, 0, 0, -1, 0, 0, -1, 0, 0, -1, 0, 0, -1, 0, 0, -1, 0, 0, -1, 0, 0, -1, 0, 0, -1, 0, 0, -1, 0, 0, -1, 0, 0, -1, 0, 0, -1, 0, 0, -1, 0, 0, -1, 0, 0, -1, 0, 0, -1, 0, 0, -1, 0, 0, -1, 0, 0, -1, 0, 0, -1, 0, 0, -1, 0, 0, -1, 0, 0, -1, 0, 0, -1, 0, 0, -1, 0, 0, -1, 0, 0, -1, 0, 0, -1, 0, 0, -1, 0, 0, -1, 0, 0, -1, 0, 0, -1, 0, 0, -1, 0, 0, -1, 0, 0, -1, 0, 0, -1, 0, 0, -1, 0, 0, -1, 0, 0, -1, 0, 0, -1, 0, 0, -1, 0, 0, -1, 0, 0, -1, 0, 0, -1, 0, 0, -1, 0, 0, -1, 0, 0, -1, 0, 0, -1, 0, 0, -1, 0, 0, -1, 0, 0, -1, 0, 0, -1, 0, 0, -1, 0, 0, -1, 0, 0, -1, 0, 0, -1, 0, 0, -1, 0, 0, -1, 0, 0, -1, 0, 0, -1, 0, 0, -1, 0, 0, -1, 0, 0, -1, 0, 0, -1, 0, 0, -1, 0, 0, -1, 0, 0, -1, 0, 0, -1, 0, 0, -1, 0, 0, -1, 0, 0, -1, 0, 0, -1, 0, 0, -1, 0, 0, -1, 0, 0, -1, 0, 0, -1, 0, 0, -1, 0, 0, -1, 0, 0, -1, 0, 0, -1, 0, 0, -1, 0, 0, -1, 0, 0, -1, 0, 0, -1, 0, 0, -1, 0, 0, -1, 0, 0, -1, 0, 0, -1, 0, 0, -1, 0, 0, -1, 0, 0, -1, 0, 0, -1, 0, 0, -1, 0, 0, -1, 0, 0, -1, 0, 0, -1, 0, 0, -1, 0, 0, -1, 0, 0, -1, 0, 0, -1, 0, 0, -1, 0, 0, -1, 0, 0, -1, 0, 0, -1, 0, 0, -1, 0, 0, -1, 0, 0, -1, 0, 0, -1, 0, 0, -1, 0, 0, -1, 0, 0, -1, 0, 0, -1, 0, 0, -1, 0, 0, -1, 0, 0, -1, 0, 0, -1, 0, 0, -1, 0, 0, -1, 0, 0, -1, 0, 0, -1, 0, 0, -1, 0, 0, -1, 0, 0, -1, 0, 0, -1, 0, 0, -1, 0, 0, -1, 0, 0, -1, 0, 0, -1, 0, 0, -1, 0, 0, -1, 0, 0, -1
    ]
  }
}
DEF Supervisior1 Robot {
  translation 0 -1 0
  children [
    DEF emittertoyellowbox Emitter {
      name "emittertoyellowbox"
      channel 7
    }
    Receiver {
      channel 8
    }
    DEF emitter Emitter {
      channel 8
    }
    Receiver {
      name "receiver2"
      channel 3
    }
    Receiver {
      name "receiver1"
      channel 2
    }
    Receiver {
      name "receiver0"
      channel 1
    }
  ]
  controller "matlab_supervisor"
  supervisor TRUE
  cpuConsumption 0.5
}
DEF PIONEER_3AT Pioneer3at {
  hidden position_0_0 -1.133568816762281e-06
  hidden position_0_1 5.292487203286156e-07
  hidden position_0_2 2.643185585863958e-06
  hidden position_0_3 5.585964926679679e-05
  hidden rotation_8 -1 0 0 4.605520314412674
  hidden rotation_9 -0.9999999999999999 0 0 3.857839810348658
  hidden rotation_10 1 0 0 2.021650003357375
  hidden rotation_11 -1 0 0 0.46822559607354475
  translation 23.99936568704156 0.108788447678076 -24.00002000045375
  rotation 0.00014316099093661272 0.9999999703853554 0.00019681010862525686 -1.8848407328604913
  controller "ros"
  controllerArgs "--name=pioneer3at"
  extensionSlot [
    DEF RADAR_TARGET Solid {
      translation 0 0.19999999999999998 0
      children [
        Shape {
          appearance PBRAppearance {
            baseColor 1 0 0
            roughness 1
            metalness 0
          }
          geometry DEF BOX Box {
            size 0.04 0.04 0.04
          }
        }
      ]
      name ""
      radarCrossSection 1
    }
    Camera {
      translation 0 0.17 -0.22
      width 256
      height 128
      motionBlur 500
      noise 0.02
    }
    Accelerometer {
      lookupTable [
        -39.24 -39.24 0.005
        39.24 39.24 0.005
      ]
    }
    Gyro {
      lookupTable [
        -50 -50 0.005
        50 50 0.005
      ]
    }
    SickLms291 {
      translation 0 0.23 -0.136
      noise 0.1
    }
    GPS {
    }
    InertialUnit {
    }
  ]
}
SolidTorus {
  translation -24.704992292002316 -1.0516032489249483e-12 -7.615645548699751
}
SolidTorus {
  translation -24.298614082938528 -7.247535904753022e-13 5.894821041662505
  name "torus(1)"
}
SolidTorus {
  translation -15.099835737317974 -6.963318810448982e-13 24.913351074303673
  name "torus(2)"
}
