#VRML_SIM R2019a utf8
WorldInfo {
  info [
    "Example use of a Radar device."
  ]
}
Viewpoint {
  orientation -0.5750967419280124 0.5857560489212038 0.571098580435992 2.074019026638704
  position 9.112089174587956 112.14500024571838 0.22141574660771468
  follow "wall(13)17"
  followOrientation TRUE
}
TexturedBackground {
}
TexturedBackgroundLight {
}
Floor {
  translation 30 0 0
  rotation 0.7071067811865475 0.7071067811865475 0 0
  size 120 60
  tileSize 1 1
  appearance ThreadMetalPlate {
  }
}
SolidTorus {
  translation 64.93577802139102 -1.0942358130705543e-12 4.581355359919176
  name "torus(3)"
}
DEF OUT_WALL Wall {
  translation 58.204489205248386 -2.9416469260468148e-12 5.555860459680742
  rotation 0 1 0 1.5707998847994753
  name "outwall6(7)"
  size 13 2.4 0.2
}
DEF OUT_WALL Wall {
  translation 90.01610721073573 -5.115907697472721e-13 0.02521955938559728
  rotation 0 -1 0 4.712385326405865
  name "outwall3"
  size 60 2.4 0.2
}
DEF OUT_WALL Wall {
  translation 38.11850114797957 -1.9895196601282805e-12 4.9489028097222025
  rotation 0 -1 0 4.712385326405865
  name "outwall4"
  size 50 2.4 0.2
}
DEF OUT_WALL Wall {
  translation 58.53885349408546 -2.0463630789890885e-12 -20.116021857576317
  rotation 0 1 0 3.639545706734746e-06
  name "outwall6"
  size 41 2.4 0.2
}
DEF OUT_WALL Wall {
  translation 79.11112601391267 -3.069544618483633e-12 0.5995430799751702
  rotation 0 1 0 1.5707999615457071
  name "outwall6(1)"
  size 41 2.4 0.2
}
DEF OUT_WALL Wall {
  translation 64.66909011208931 -3.367972567502875e-12 21.09675680699851
  rotation 0 -1 0 6.283181686841351
  name "outwall6(2)"
  size 29 2.4 0.2
}
DEF OUT_WALL Wall {
  translation 71.66121731166321 -2.9416469260468148e-12 2.171535761005348
  rotation 0 1 0 4.712392567158649
  name "outwall6(3)"
  size 20 2.4 0.2
}
DEF OUT_WALL Wall {
  translation 64.77492156143019 -2.9416469260468148e-12 12.071773095761873
  rotation 0 -1 0 3.1415890812005243
  name "outwall6(6)"
  size 13 2.4 0.2
}
DEF OUT_WALL Wall {
  translation 50.02370638457367 -2.9416469260468148e-12 6.580572468498337
  rotation 0 1 0 4.712392567158649
  name "outwall6(5)"
  size 29 2.4 0.2
}
DEF OUT_WALL Wall {
  translation 61.159057737052066 -2.8705926524708048e-12 -7.735770799816559
  rotation 0 1 0 3.141596206799475
  name "outwall6(4)"
  size 21 2.4 0.2
}
DEF OUT_WALL Wall {
  translation 59.87835135727737 -5.115907697472721e-13 -29.855079565529415
  rotation 0 -1 0 6.283181648405866
  name "outwall2"
  size 60 2.4 0.2
}
DEF YELLOW_BOX Solid {
  translation -1.456749798847497 1.2299999999997016 3.155366814255416
  rotation 0 0.9999999999999999 0 3.142388812563314
  children [
    DEF Shape Shape {
      appearance DEF PBR PBRAppearance {
        roughness 0.03934117200000009
        metalness 0
      }
      geometry DEF geometryBox Box {
        size 0.30000000000000004 2.6999999999999997 35
      }
    }
  ]
  name "YELLOW_BOX"
  boundingObject Shape {
    appearance PBRAppearance {
      roughness 1.1102230246251565e-16
      metalness 0
    }
    geometry USE geometryBox
  }
}
SolidRoundedBox {
  translation -17.7943406357252 -3.410605131648481e-13 -26.48373355845466
}
DEF OFFICES Transform {
  rotation 0 1 0 3.14159
  children [
    Panel {
      translation 28.4604 0 -24.5373
      name "panel(35)"
    }
    Panel {
      translation 28.4604 0 -17.2973
      name "panel(36)"
    }
    Panel {
      translation 28.4604 0 -10.2573
      name "panel(37)"
    }
    Panel {
      translation 27.0304 0 -24.5573
      name "panel(38)"
    }
    Panel {
      translation 27.0304 0 -17.2873
      name "panel(39)"
    }
    Panel {
      translation 27.0304 0 -10.2573
      name "panel(40)"
    }
    Panel {
      translation 27.0774 0 -10.6551
      rotation 0 1 0 1.5708
      name "panel(41)"
    }
    Panel {
      translation 27.0774 0 -15.6551
      rotation 0 1 0 1.5708
      name "panel(42)"
    }
    Panel {
      translation 27.0774 0 -17.7651
      rotation 0 1 0 1.5708
      name "panel(43)"
    }
    Panel {
      translation 27.0774 0 -22.8751
      rotation 0 1 0 1.5708
      name "panel(44)"
    }
    Panel {
      translation 27.0774 0 -24.9451
      rotation 0 1 0 1.5708
      name "panel(45)"
    }
    Panel {
      translation 24.2974 0 -10.6551
      rotation 0 1 0 1.5708
      name "panel(46)"
    }
    Panel {
      translation 24.2974 0 -15.6951
      rotation 0 1 0 1.5708
      name "panel(47)"
    }
    Panel {
      translation 24.2974 0 -17.8051
      rotation 0 1 0 1.5708
      name "panel(48)"
    }
    Panel {
      translation 24.2974 0 -22.8551
      rotation 0 1 0 1.5708
      name "panel(49)"
    }
    Panel {
      translation 24.2974 0 -25.0151
      rotation 0 1 0 1.5708
      name "panel(50)"
    }
    Panel {
      translation 21.2474 0 -10.6551
      rotation 0 1 0 1.5708
      name "panel(51)"
    }
    Panel {
      translation 21.2474 0 -15.6951
      rotation 0 1 0 1.5708
      name "panel(52)"
    }
    Panel {
      translation 21.2474 0 -17.7551
      rotation 0 1 0 1.5708
      name "panel(53)"
    }
    Panel {
      translation 21.2474 0 -22.8651
      rotation 0 1 0 1.5708
      name "panel(54)"
    }
    Panel {
      translation 21.27941328705038 -3.552713678800501e-15 -19.54699077672662
      rotation 0 1 0 1.5708
      name "panel(72)"
    }
    Panel {
      translation 21.331013210072776 0 -21.225957180431337
      rotation 0 1 0 1.5708
      name "panel(73)"
    }
    Panel {
      translation 21.242538389055508 -1.4566126083082054e-13 -12.525967859818088
      rotation 0 1 0 1.5708
      name "panel(23)"
    }
    Panel {
      translation 21.243462812112455 -8.881784197001252e-14 -14.137965874591316
      rotation 0 1 0 1.5708
      name "panel(71)"
    }
    Panel {
      translation 21.2474 0 -24.8851
      rotation 0 1 0 1.5708
      name "panel(55)"
    }
    Panel {
      translation 21.2474 0 -26.6151
      rotation 0 1 0 1.5708
      name "panel(56)"
    }
    Panel {
      translation 21.2474 0 -28.2551
      rotation 0 1 0 1.5708
      name "panel(57)"
    }
    Panel {
      translation 25.5604 0 -24.5873
      name "panel(58)"
    }
    Panel {
      translation 25.5604 0 -17.3073
      name "panel(59)"
    }
    Panel {
      translation 25.5604 0 -10.2573
      name "panel(60)"
    }
    Panel {
      translation 24.1004 0 -24.5973
      name "panel(61)"
    }
    Panel {
      translation 24.1004 0 -17.3373
      name "panel(62)"
    }
    Panel {
      translation 24.1004 0 -10.2573
      name "panel(63)"
    }
    Panel {
      translation 22.5504 0 -24.5873
      name "panel(64)"
    }
    Panel {
      translation 22.5504 0 -17.3273
      name "panel(65)"
    }
    Panel {
      translation 22.5504 0 -10.2573
      name "panel(66)"
    }
    Panel {
      translation 20.9704 0 -10.2573
      name "panel(67)"
    }
    Panel {
      translation 20.9704 0 -24.5773
      name "panel(68)"
    }
    Panel {
      translation 20.9704 0 -17.3573
      name "panel(69)"
    }
    WoodenChair {
      translation 28.2877 7.10543e-15 -16.5637
      name "wooden chair(15)"
    }
    WoodenChair {
      translation 28.2877 7.10543e-15 -23.9137
      name "wooden chair(16)"
    }
    WoodenChair {
      translation 28.2877 7.10543e-15 -18.1537
      rotation 0 1 0 3.14159
      name "wooden chair(17)"
    }
    WoodenChair {
      translation 28.2877 7.10543e-15 -25.1237
      rotation 0 1 0 3.14159
      name "wooden chair(18)"
    }
    WoodenChair {
      translation 25.7177 7.10543e-15 -23.8937
      name "wooden chair(19)"
    }
    WoodenChair {
      translation 25.7177 7.10543e-15 -18.0837
      rotation 0 1 0 3.14159
      name "wooden chair(20)"
    }
    WoodenChair {
      translation 28.2877 7.10543e-15 -11.1637
      rotation 0 1 0 3.14159
      name "wooden chair(21)"
    }
    WoodenChair {
      translation 25.7177 7.10543e-15 -25.2037
      rotation 0 1 0 3.14159
      name "wooden chair(22)"
    }
    WoodenChair {
      translation 22.9577 7.10543e-15 -23.8537
      name "wooden chair(23)"
    }
    WoodenChair {
      translation 25.7177 7.10543e-15 -16.5637
      name "wooden chair(24)"
    }
    WoodenChair {
      translation 22.9577 7.10543e-15 -18.0537
      rotation 0 1 0 3.14159
      name "wooden chair(25)"
    }
    WoodenChair {
      translation 25.7177 7.10543e-15 -11.1037
      rotation 0 1 0 3.14159
      name "wooden chair(26)"
    }
    WoodenChair {
      translation 22.9577 7.10543e-15 -25.0837
      rotation 0 1 0 3.14159
      name "wooden chair(27)"
    }
    WoodenChair {
      translation 22.9577 7.10543e-15 -16.5637
      name "wooden chair(28)"
    }
    WoodenChair {
      translation 22.9577 7.10543e-15 -11.1937
      rotation 0 1 0 3.14159
      name "wooden chair(29)"
    }
    Desk {
      translation 28.2877 7.10543e-15 -16.1837
      rotation 0 1 0 6.28319
      name "desk(15)"
    }
    Desk {
      translation 28.2877 7.10543e-15 -25.5337
      rotation 0 1 0 6.28319
      name "desk(16)"
    }
    Desk {
      translation 28.2877 7.10543e-15 -11.5037
      rotation 0 1 0 6.28319
      name "desk(17)"
    }
    Desk {
      translation 28.2877 7.10543e-15 -23.5237
      rotation 0 1 0 6.28319
      name "desk(18)"
    }
    Desk {
      translation 25.6977 7.10543e-15 -16.1837
      rotation 0 1 0 6.28319
      name "desk(19)"
    }
    Desk {
      translation 25.6977 7.10543e-15 -18.4537
      rotation 0 1 0 6.28319
      name "desk(20)"
    }
    Desk {
      translation 25.6977 7.10543e-15 -11.5337
      rotation 0 1 0 6.28319
      name "desk(21)"
    }
    Desk {
      translation 22.9277 7.10543e-15 -16.1837
      rotation 0 1 0 6.28319
      name "desk(22)"
    }
    Desk {
      translation 22.9277 7.10543e-15 -11.5737
      rotation 0 1 0 6.28319
      name "desk(23)"
    }
    Desk {
      translation 25.6977 7.10543e-15 -25.5537
      rotation 0 1 0 6.28319
      name "desk(24)"
    }
    Desk {
      translation 28.2877 7.10543e-15 -18.5337
      rotation 0 1 0 6.28319
      name "desk(25)"
    }
    Desk {
      translation 22.9277 7.10543e-15 -18.4537
      rotation 0 1 0 6.28319
      name "desk(26)"
    }
    Desk {
      translation 25.6977 7.10543e-15 -23.4937
      rotation 0 1 0 6.28319
      name "desk(27)"
    }
    Desk {
      translation 22.9277 7.10543e-15 -23.5337
      rotation 0 1 0 6.28319
      name "desk(28)"
    }
    Desk {
      translation 22.9277 7.10543e-15 -25.4837
      rotation 0 1 0 6.28319
      name "desk(29)"
    }
  ]
}
DEF OFFICES Transform {
  translation 0 0 -40
  rotation 0 1 0 3.14159
  children [
    Panel {
      translation 28.4604 0 -24.5373
      name "panel(1)"
    }
    Panel {
      translation 28.4604 0 -17.2973
      name "panel(2)"
    }
    Panel {
      translation 28.4604 0 -10.2573
      name "panel(3)"
    }
    Panel {
      translation 27.0304 0 -24.5573
      name "panel(4)"
    }
    Panel {
      translation 27.0304 0 -17.2873
      name "panel(5)"
    }
    Panel {
      translation 27.0304 0 -10.2573
      name "panel(6)"
    }
    Panel {
      translation 27.0774 0 -10.6551
      rotation 0 1 0 1.5708
      name "panel(7)"
    }
    Panel {
      translation 27.0774 0 -15.6551
      rotation 0 1 0 1.5708
      name "panel(8)"
    }
    Panel {
      translation 27.0774 0 -17.7651
      rotation 0 1 0 1.5708
      name "panel(9)"
    }
    Panel {
      translation 27.0774 0 -22.8751
      rotation 0 1 0 1.5708
      name "panel(10)"
    }
    Panel {
      translation 24.2974 0 -10.6551
      rotation 0 1 0 1.5708
      name "panel(12)"
    }
    Panel {
      translation 24.2974 0 -15.6951
      rotation 0 1 0 1.5708
      name "panel(13)"
    }
    Panel {
      translation 24.2974 0 -17.8051
      rotation 0 1 0 1.5708
      name "panel(14)"
    }
    Panel {
      translation 24.2974 0 -22.8551
      rotation 0 1 0 1.5708
      name "panel(15)"
    }
    Panel {
      translation 21.2474 0 -10.6551
      rotation 0 1 0 1.5708
      name "panel(17)"
    }
    Panel {
      translation 21.3952621435841 -9.947598300641403e-14 -15.729109202722
      rotation 0 1 0 1.5708
      name "panel(18)"
    }
    Panel {
      translation 21.31044627075896 -9.947598300641403e-14 -14.04973964987817
      rotation 0 1 0 1.5708
      name "panel(21)"
    }
    Panel {
      translation 21.296215948418833 -9.237055564881302e-14 -12.31909108621101
      rotation 0 1 0 1.5708
      name "panel(22)"
    }
    Panel {
      translation 21.2474 0 -17.7551
      rotation 0 1 0 1.5708
      name "panel(19)"
    }
    Panel {
      translation 21.181637678529647 1.0658141036401503e-14 -22.679400631189946
      rotation 0 1 0 1.5708
      name "panel(20)"
    }
    Panel {
      translation 21.187549941856076 7.105427357601002e-15 -21.115898284791456
      rotation 0 1 0 1.5708
      name "panel(11)2"
    }
    Panel {
      translation 21.20323799951621 2.2382096176443156e-13 -19.58767785752691
      rotation 0 1 0 1.5708
      name "panel(16)1"
    }
    Panel {
      translation 25.5604 0 -24.5873
      name "panel(24)"
    }
    Panel {
      translation 25.5604 0 -17.3073
      name "panel(25)"
    }
    Panel {
      translation 25.5604 0 -10.2573
      name "panel(26)"
    }
    Panel {
      translation 24.1004 0 -24.5973
      name "panel(27)"
    }
    Panel {
      translation 24.1004 0 -17.3373
      name "panel(28)"
    }
    Panel {
      translation 24.1004 0 -10.2573
      name "panel(29)"
    }
    Panel {
      translation 22.5504 0 -24.5873
      name "panel(30)"
    }
    Panel {
      translation 22.5504 0 -17.3273
      name "panel(31)"
    }
    Panel {
      translation 22.5504 0 -10.2573
      name "panel(32)"
    }
    Panel {
      translation 20.9704 0 -10.2573
      name "panel(33)"
    }
    Panel {
      translation 20.9704 0 -24.5773
      name "panel(34)"
    }
    Panel {
      translation 20.9704 0 -17.3573
      name "panel(70)"
    }
    WoodenChair {
      translation 28.2877 7.10543e-15 -16.5637
      name "wooden chair(1)"
    }
    WoodenChair {
      translation 28.2877 7.10543e-15 -23.9137
      name "wooden chair(2)"
    }
    WoodenChair {
      translation 28.2877 7.10543e-15 -18.1537
      rotation 0 1 0 3.14159
      name "wooden chair(3)"
    }
    WoodenChair {
      translation 25.7177 7.10543e-15 -23.8937
      name "wooden chair(5)"
    }
    WoodenChair {
      translation 25.7177 7.10543e-15 -18.0837
      rotation 0 1 0 3.14159
      name "wooden chair(6)"
    }
    WoodenChair {
      translation 28.2877 7.10543e-15 -11.1637
      rotation 0 1 0 3.14159
      name "wooden chair(7)"
    }
    WoodenChair {
      translation 22.9577 7.10543e-15 -23.8537
      name "wooden chair(9)"
    }
    WoodenChair {
      translation 25.7177 7.10543e-15 -16.5637
      name "wooden chair(10)"
    }
    WoodenChair {
      translation 22.9577 7.10543e-15 -18.0537
      rotation 0 1 0 3.14159
      name "wooden chair(11)"
    }
    WoodenChair {
      translation 25.7177 7.10543e-15 -11.1037
      rotation 0 1 0 3.14159
      name "wooden chair(12)"
    }
    WoodenChair {
      translation 22.9577 7.10543e-15 -16.5637
      name "wooden chair(14)"
    }
    WoodenChair {
      translation 22.9577 7.10543e-15 -11.1937
      rotation 0 1 0 3.14159
      name "wooden chair(30)"
    }
    Desk {
      translation 28.2877 7.10543e-15 -16.1837
      rotation 0 1 0 6.28319
      name "desk(1)"
    }
    Desk {
      translation 28.2877 7.10543e-15 -11.5037
      rotation 0 1 0 6.28319
      name "desk(3)"
    }
    Desk {
      translation 28.2877 7.10543e-15 -23.5237
      rotation 0 1 0 6.28319
      name "desk(4)"
    }
    Desk {
      translation 25.6977 7.10543e-15 -16.1837
      rotation 0 1 0 6.28319
      name "desk(5)"
    }
    Desk {
      translation 25.6977 7.10543e-15 -18.4537
      rotation 0 1 0 6.28319
      name "desk(6)"
    }
    Desk {
      translation 25.6977 7.10543e-15 -11.5337
      rotation 0 1 0 6.28319
      name "desk(7)"
    }
    Desk {
      translation 22.9277 7.10543e-15 -16.1837
      rotation 0 1 0 6.28319
      name "desk(8)"
    }
    Desk {
      translation 22.9277 7.10543e-15 -11.5737
      rotation 0 1 0 6.28319
      name "desk(9)"
    }
    Desk {
      translation 28.2877 7.10543e-15 -18.5337
      rotation 0 1 0 6.28319
      name "desk(11)"
    }
    Desk {
      translation 22.9277 7.10543e-15 -18.4537
      rotation 0 1 0 6.28319
      name "desk(12)"
    }
    Desk {
      translation 25.6977 7.10543e-15 -23.4937
      rotation 0 1 0 6.28319
      name "desk(13)"
    }
    Desk {
      translation 22.9277 7.10543e-15 -23.5337
      rotation 0 1 0 6.28319
      name "desk(14)"
    }
  ]
}
DEF INTERNAL_WALL Wall {
  translation -20.841722096896945 1.7763568394002505e-15 -0.895663661597073
  name "wall(7)"
  size 18.2 2.7 0.2
}
DEF INTERNAL_WALL Wall {
  translation 23.946530533498798 -1.0006980318164795e-09 -1.3465451669858979
  rotation 0 1 0 1.5707963220000003
  name "wall(13)17"
  size 31.5 2.4 0.2
}
DEF INTERNAL_WALL Wall {
  translation 15.468528286713703 -1.0017070025012588e-09 3.449740374749524
  rotation 0 -1 0 4.7123890043591725
  name "wall(1316"
  size 34.300000000000004 2.4 0.2
}
DEF INTERNAL_WALL Wall {
  translation 6.647038693892407 -1.0007193480985523e-09 0.6961701130002744
  rotation 0 -1 0 4.7123890043591725
  name "wall(1315"
  size 30.6 2.4 0.2
}
DEF INTERNAL_WALL Wall {
  translation 6.580376805989836 -1.0000727542090106e-09 -22.393753290059422
  rotation 0 1 0 1.5707963220000003
  name "wall(13123"
  size 15.9 2.4 0.2
}
DEF INTERNAL_WALL Wall {
  translation 15.504357040818558 -9.999093293797858e-10 -17.205538702438112
  name "wall(1312"
  size 17.099999999999998 2.4 0.2
}
DEF INTERNAL_WALL Wall {
  translation 20.527249419994213 -1.0000976232047622e-09 -24.03975349060693
  name "wall(1311"
  size 18.9 2.4 0.2
}
DEF INTERNAL_WALL Wall {
  translation 14.296785349750635 -1.0003249968802055e-09 20.5767634177167
  name "wall(14)"
  size 31.299999999999997 2.4 0.2
}
DEF EXTERNAL_WALL Wall {
  translation -30 0 0
  rotation 0 1 0 1.5708
  name "wall(12)"
  size 60 2.4 0.2
}
DEF EXTERNAL_WALL Wall {
  translation 29.840857291770405 -5.115907697472721e-13 -4.748827247581081
  rotation 0 1 0 1.5708
  name "wall(14)44"
  size 51 2.4 0.2
}
DEF OUT_WALL Wall {
  translation 60.23640877327777 -5.115907697472721e-13 29.96804236086333
  rotation 0 -1 0 6.283181648405866
  name "outwall1"
  size 60 2.4 0.2
}
DEF EXTERNAL_WALL Wall {
  translation -27.45 0 30
  name "wall(10)"
  size 5.3 2.4 0.2
}
DEF DOUBLE_WINDOW Transform {
  translation -24 0 30
  children [
    Window {
      translation -0.4 0 0
      name "window(21)"
    }
    Window {
      translation 0.4 0 0
      name "window(22)"
    }
  ]
}
DEF DOUBLE_WINDOW Transform {
  translation -12 0 30
  children [
    Window {
      translation -0.4 0 0
      name "window(19)"
    }
    Window {
      translation 0.4 0 0
      name "window(20)"
    }
  ]
}
DEF DOUBLE_WINDOW Transform {
  translation 12 0 30
}
DEF DOUBLE_WINDOW Transform {
  translation 24 0 30
  children [
    Window {
      translation -0.4 0 0
      name "window(15)"
    }
    Window {
      translation 0.4 0 0
      name "window(16)"
    }
  ]
}
DEF EXTERNAL_WALL Wall {
  translation -18 0 30
  name "wall(8)"
  size 10.4 2.4 0.2
}
DEF EXTERNAL_WALL Wall {
  translation 27.45 0 30
  name "wall(9)"
  size 5.3 2.4 0.2
}
DEF EXTERNAL_WALL Wall {
  translation 18 0 30
  name "wall(6)"
  size 10.4 2.4 0.2
}
DEF EXTERNAL_WALL Wall {
  translation 0.7995902474737342 -2.5579538487363607e-13 29.963116458244034
  name "wall(5)"
  size 24 2.4 0.2
}
DEF DOUBLE_WINDOW Transform {
  translation -12 0 -30
  children [
    Window {
      translation -0.4 0 0
      name "window(11)"
    }
    Window {
      translation 0.4 0 0
      name "window(12)"
    }
  ]
}
DEF DOUBLE_WINDOW Transform {
  translation -24 0 -30
  children [
    Window {
      translation -0.4 0 0
      name "window(13)"
    }
    Window {
      translation 0.4 0 0
      name "window(14)"
    }
  ]
}
DEF DOUBLE_WINDOW Transform {
  translation 24 0 -30
  children [
    Window {
      translation -0.4 0 0
      name "window(7)"
    }
    Window {
      translation 0.4 0 0
      name "window(8)"
    }
  ]
}
DEF EXTERNAL_WALL Wall {
  translation -27.45 0 -30
  name "wall(4)"
  size 5.3 2.4 0.2
}
DEF EXTERNAL_WALL Wall {
  translation 27.45 0 -30
  name "wall(3)"
  size 5.3 2.4 0.2
}
DEF EXTERNAL_WALL Wall {
  translation -18 0 -30
  name "wall(2)"
  size 10.4 2.4 0.2
}
DEF EXTERNAL_WALL Wall {
  translation 18 0 -30
  name "wall(1)"
  size 10.4 2.4 0.2
}
DEF EXTERNAL_WALL Wall {
  translation 0 0 -30
  size 22.4 2.4 0.2
}
Shape {
  appearance PBRAppearance {
    baseColor 0 0 1
    roughness 1
    metalness 0
  }
  geometry IndexedFaceSet {
    coord Coordinate {
      point [
        0.21 0 0.07
        0.09 0 0.22
        0.25 0 0.26
        0.21 0.0001 0.07
        0.09 0.0001 0.22
        0.25 0.0001 0.26
      ]
    }
    coordIndex [
      2, 1, 0, -1, 3, 4, 5, -1, 0, 1
      4, 3, -1, 1, 2, 5, 4, -1, 2, 0
      3, 5, -1
    ]
  }
}
DEF MyBot1 Robot {
  translation 28.000000010049853 -0.00044385070948577826 28.00000000823948
  rotation 0.024672367629649958 -0.9996258019932454 -0.011812292957271655 -0.8936434727464767
  children [
    Emitter {
      channel 1
      baudRate 115200
    }
    Transform {
      translation 0 0.0415 0
      children [
        Shape {
          appearance PBRAppearance {
            baseColor 0.0820075 0.364731 0.8
            roughness 1
            metalness 0
          }
          geometry DEF BODY Cylinder {
            height 0.08
            radius 0.045
          }
        }
      ]
    }
    HingeJoint {
      jointParameters HingeJointParameters {
        position 76.0320098423134
        axis -1 0 0
        anchor 0 0.025 0
      }
      device [
        RotationalMotor {
          name "left wheel motor1"
          consumptionFactor 70
        }
        PositionSensor {
          name "left wheel sensor"
        }
      ]
      endPoint Solid {
        translation -0.04499997587308602 0.02521211518040006 -1.5429505641382867e-06
        rotation -0.9999998918029869 0.0003806369705572689 -0.0002674126237319298 1.9316465745552422
        children [
          DEF WHEEL Transform {
            rotation 0 0 1 1.57
            children [
              Shape {
                appearance PBRAppearance {
                  baseColor 1 0 0
                  roughness 1
                  metalness 0
                }
                geometry Cylinder {
                  height 0.01
                  radius 0.025
                }
              }
            ]
          }
        ]
        name "left wheel"
        boundingObject USE WHEEL
        physics DEF PHYSICS_WHEEL Physics {
          density -1
          mass 0.05
        }
        linearVelocity 8.315668066323282e-08 9.284769695098816e-06 6.779268262116316e-08
        angularVelocity 2.853059178946552e-06 4.064984838207113e-11 -3.5469178011685794e-06
      }
    }
    HingeJoint {
      jointParameters HingeJointParameters {
        position 76.03204454779608
        axis -1 0 0
        anchor 0 0.025 0
      }
      device [
        RotationalMotor {
          name "right wheel motor1"
          consumptionFactor 70
        }
        PositionSensor {
          name "right wheel sensor"
        }
      ]
      endPoint Solid {
        translation 0.044999989753531276 0.025212064462760968 -1.5433358939176151e-06
        rotation -0.9999999132084187 -0.000381476759571178 0.0001675071245262531 2.329001081076061
        children [
          USE WHEEL
        ]
        name "right wheel"
        boundingObject USE WHEEL
        physics USE PHYSICS_WHEEL
        linearVelocity 8.400603473215192e-08 9.284797353380489e-06 6.671223328526089e-08
        angularVelocity 2.8536212072564723e-06 -1.018279703642418e-09 -3.546493702075214e-06
      }
    }
    DistanceSensor {
      translation -0.02 0.063 -0.042
      rotation 0 1 0 2.07
      children [
        DEF SENSOR Transform {
          rotation 0 0 1 1.57
          children [
            Shape {
              appearance PBRAppearance {
                baseColor 0.975691 0.981481 0.0252992
                roughness 1
                metalness 0
              }
              geometry Cylinder {
                height 0.004
                radius 0.008
              }
            }
          ]
        }
      ]
      name "ds0"
      lookupTable [
        0 1024 0
        0.05 1024 0
        0.15 0 0
      ]
      numberOfRays 2
      aperture 1
    }
    DistanceSensor {
      translation 0.02 0.063 -0.042
      rotation 0 1 0 1.07
      children [
        USE SENSOR
      ]
      name "ds1"
      lookupTable [
        0 1024 0
        0.05 1024 0
        0.15 0 0
      ]
      numberOfRays 2
      aperture 1
    }
    DEF SMILE Transform {
      translation 0 0.025 -0.036
      rotation 0.7745972408364944 0.44721228048294853 0.4472139204829502 1.8234794
      children [
        Shape {
          appearance PBRAppearance {
            baseColor 0.721569 0.290196 0.290196
            roughness 1
            metalness 0
          }
          geometry Cylinder {
            height 0.018
            radius 0.009
            subdivision 3
          }
        }
      ]
    }
    Radar {
      translation 0 0.1 0
      children [
        Shape {
          appearance PBRAppearance {
            baseColor 0.403922 0.403922 0.403922
            roughness 1
            metalness 0
          }
          geometry DEF BOX Box {
            size 0.04 0.04 0.04
          }
        }
      ]
      minRange 0.01
      maxRange 80
      horizontalFieldOfView 2
      verticalFieldOfView 0.5
      frequency 28
      transmittedPower 28
    }
  ]
  name "MyBot1"
  boundingObject Transform {
    translation 0 0.0415 0
    children [
      USE BODY
    ]
  }
  physics Physics {
    density -1
    mass 0.5
  }
  controller "unmovingrobot1"
  battery [
    0, 100, 30
  ]
  cpuConsumption 5
  linearVelocity 1.0941334269412759e-07 9.278368730403634e-06 8.801070400283648e-08
  angularVelocity 1.7458006973792304e-06 -4.830965522530191e-10 -2.1699277271709415e-06
}
DEF MyBot2 Robot {
  translation 29.000000005318828 -0.0004438519781709144 -29.000000011569508
  rotation 0.001873537653431732 -0.9999283921279979 -0.011819495462085 -2.8275241924627537
  children [
    Emitter {
      name "emitter2"
      channel 2
      baudRate 115200
    }
    Transform {
      translation 0 0.0415 0
      children [
        Shape {
          appearance PBRAppearance {
            baseColor 0.0820075 0.364731 0.8
            roughness 1
            metalness 0
          }
          geometry DEF BODY Cylinder {
            height 0.08
            radius 0.045
          }
        }
      ]
    }
    HingeJoint {
      jointParameters HingeJointParameters {
        position 76.03199417714993
        axis -1 0 0
        anchor 0 0.025 0
      }
      device [
        RotationalMotor {
          name "left wheel motor1"
          consumptionFactor 70
        }
        PositionSensor {
          name "left wheel sensor"
        }
      ]
      endPoint Solid {
        translation -0.04499995669495851 0.025212115598658772 -1.4987872299048312e-06
        rotation -0.9999998918133332 0.0003806740172430653 -0.00026732118299219355 1.9316355622178831
        children [
          DEF WHEEL Transform {
            rotation 0 0 1 1.57
            children [
              Shape {
                appearance PBRAppearance {
                  baseColor 1 0 0
                  roughness 1
                  metalness 0
                }
                geometry Cylinder {
                  height 0.01
                  radius 0.025
                }
              }
            ]
          }
        ]
        name "left wheel"
        boundingObject USE WHEEL
        physics DEF PHYSICS_WHEEL Physics {
          density -1
          mass 0.05
        }
        linearVelocity 3.3833015409736906e-08 9.284782020180884e-06 -1.0184438255817583e-07
        angularVelocity -4.329729227543712e-06 -1.003651894524102e-09 -1.4058757270995316e-06
      }
    }
    HingeJoint {
      jointParameters HingeJointParameters {
        position 76.03196453171361
        axis -1 0 0
        anchor 0 0.025 0
      }
      device [
        RotationalMotor {
          name "right wheel motor1"
          consumptionFactor 70
        }
        PositionSensor {
          name "right wheel sensor"
        }
      ]
      endPoint Solid {
        translation 0.04499997063249224 0.02521206487321586 -1.498916498983332e-06
        rotation -0.9999999132146035 -0.00038149254810015677 0.00016743422932267174 2.3289257254812314
        children [
          USE WHEEL
        ]
        name "right wheel"
        boundingObject USE WHEEL
        physics USE PHYSICS_WHEEL
        linearVelocity 3.250714021555204e-08 9.284774682260931e-06 -1.0221081097386198e-07
        angularVelocity -4.329580614386782e-06 -2.061777948442735e-09 -1.406567376177423e-06
      }
    }
    DistanceSensor {
      translation -0.02 0.063 -0.042
      rotation 0 1 0 2.07
      children [
        DEF SENSOR Transform {
          rotation 0 0 1 1.57
          children [
            Shape {
              appearance PBRAppearance {
                baseColor 0.975691 0.981481 0.0252992
                roughness 1
                metalness 0
              }
              geometry Cylinder {
                height 0.004
                radius 0.008
              }
            }
          ]
        }
      ]
      name "ds0"
      lookupTable [
        0 1024 0
        0.05 1024 0
        0.15 0 0
      ]
      numberOfRays 2
      aperture 1
    }
    DistanceSensor {
      translation 0.02 0.063 -0.042
      rotation 0 1 0 1.07
      children [
        USE SENSOR
      ]
      name "ds1"
      lookupTable [
        0 1024 0
        0.05 1024 0
        0.15 0 0
      ]
      numberOfRays 2
      aperture 1
    }
    DEF SMILE Transform {
      translation 0 0.025 -0.036
      rotation 0.7745972408364944 0.44721228048294853 0.4472139204829502 1.8234794
      children [
        Shape {
          appearance PBRAppearance {
            baseColor 0.721569 0.290196 0.290196
            roughness 1
            metalness 0
          }
          geometry Cylinder {
            height 0.018
            radius 0.009
            subdivision 3
          }
        }
      ]
    }
    Radar {
      translation 0 0.1 0
      rotation 0 1 0 6.021385901
      children [
        Shape {
          appearance PBRAppearance {
            baseColor 0.403922 0.403922 0.403922
            roughness 1
            metalness 0
          }
          geometry DEF BOX Box {
            size 0.04 0.04 0.04
          }
        }
      ]
      minRange 0.01
      maxRange 78
      horizontalFieldOfView 2
      verticalFieldOfView 0.4
    }
  ]
  name "MyBot2"
  boundingObject Transform {
    translation 0 0.0415 0
    children [
      USE BODY
    ]
  }
  physics Physics {
    density -1
    mass 0.5
  }
  controller "unmovingrobot2"
  cpuConsumption 0.5
  linearVelocity 4.332426966271625e-08 9.278363825586086e-06 -1.3358844460305941e-07
  angularVelocity -2.6491321318447845e-06 -1.5300467548430307e-09 -8.603163169526187e-07
}
DEF DOUBLE_WINDOW Transform {
  translation 12 0 -30
  children [
    Window {
      translation -0.4 0 0
      name "window(9)"
    }
    Window {
      translation 0.4 0 0
      name "window(10)"
    }
  ]
}
DEF MyBot3 Robot {
  translation -26.000000009886467 -0.00044390968247681045 -27.000000008605102
  rotation -0.005357331090161109 -0.9999157845107999 -0.011820443720187446 2.2902699596181693
  children [
    Emitter {
      name "emitter3"
      channel 3
      baudRate 115200
    }
    Transform {
      translation 0 0.0415 0
      children [
        Shape {
          appearance PBRAppearance {
            baseColor 0.0820075 0.364731 0.8
            roughness 1
            metalness 0
          }
          geometry DEF BODY Cylinder {
            height 0.08
            radius 0.045
          }
        }
      ]
    }
    HingeJoint {
      jointParameters HingeJointParameters {
        position 76.03199147051569
        axis -1 0 0
        anchor 0 0.025 0
      }
      device [
        RotationalMotor {
          name "left wheel motor1"
          consumptionFactor 70
        }
        PositionSensor {
          name "left wheel sensor"
        }
      ]
      endPoint Solid {
        translation -0.04499995633981136 0.025212115465339854 1.5101026944378643e-06
        rotation -0.9999998919107286 0.00038451682356230375 -0.00026139116918251433 1.932936323205869
        children [
          DEF WHEEL Transform {
            rotation 0 0 1 1.57
            children [
              Shape {
                appearance PBRAppearance {
                  baseColor 1 0 0
                  roughness 1
                  metalness 0
                }
                geometry Cylinder {
                  height 0.01
                  radius 0.025
                }
              }
            ]
          }
        ]
        name "left wheel"
        boundingObject USE WHEEL
        physics DEF PHYSICS_WHEEL Physics {
          density -1
          mass 0.05
        }
        linearVelocity -8.021954334838445e-08 9.284655360223044e-06 -7.1202221984006e-08
        angularVelocity -2.998697142097847e-06 1.6428471489956579e-10 3.4232781767931036e-06
      }
    }
    HingeJoint {
      jointParameters HingeJointParameters {
        position 76.03193895265363
        axis -1 0 0
        anchor 0 0.025 0
      }
      device [
        RotationalMotor {
          name "right wheel motor1"
          consumptionFactor 70
        }
        PositionSensor {
          name "right wheel sensor"
        }
      ]
      endPoint Solid {
        translation 0.04499997016563726 0.025212064861496335 1.5106219515304697e-06
        rotation -0.999999913262442 -0.00038388453058201477 0.0001615790079525313 2.330203931725576
        children [
          USE WHEEL
        ]
        name "right wheel"
        boundingObject USE WHEEL
        physics USE PHYSICS_WHEEL
        linearVelocity -8.111749272816651e-08 9.284687246009343e-06 -7.016202681458492e-08
        angularVelocity -2.9992368454722405e-06 -8.948732746366287e-10 3.4228268080754888e-06
      }
    }
    DistanceSensor {
      translation -0.02 0.063 -0.042
      rotation 0 1 0 2.8553981609999997
      children [
        DEF SENSOR Transform {
          rotation 0 0 1 1.57
          children [
            Shape {
              appearance PBRAppearance {
                baseColor 0.975691 0.981481 0.0252992
                roughness 1
                metalness 0
              }
              geometry Cylinder {
                height 0.004
                radius 0.008
              }
            }
          ]
        }
      ]
      name "ds0"
      lookupTable [
        0 1024 0
        0.05 1024 0
        0.15 0 0
      ]
      numberOfRays 2
      aperture 1
    }
    DistanceSensor {
      translation 0.02 0.063 -0.042
      rotation 0 1 0 1.07
      children [
        USE SENSOR
      ]
      name "ds1"
      lookupTable [
        0 1024 0
        0.05 1024 0
        0.15 0 0
      ]
      numberOfRays 2
      aperture 1
    }
    DEF SMILE Transform {
      translation 0 0.025 -0.036
      rotation 0.7745972408364944 0.44721228048294853 0.4472139204829502 1.8234794
      children [
        Shape {
          appearance PBRAppearance {
            baseColor 0.721569 0.290196 0.290196
            roughness 1
            metalness 0
          }
          geometry Cylinder {
            height 0.018
            radius 0.009
            subdivision 3
          }
        }
      ]
    }
    DEF Radar Radar {
      translation 0 0.1 0
      rotation 0 1 0 6.283185307179586
      children [
        Shape {
          appearance PBRAppearance {
            baseColor 0.403922 0.403922 0.403922
            roughness 1
            metalness 0
          }
          geometry DEF BOX Box {
            size 0.04 0.04 0.04
          }
        }
      ]
      minRange 0.01
      maxRange 79.23140049567527
      horizontalFieldOfView 2
      transmittedPower 77
    }
  ]
  name "MyBot3"
  boundingObject Transform {
    translation 0 0.0415 0
    children [
      USE BODY
    ]
  }
  physics Physics {
    density -1
    mass 0.5
  }
  controller "unmovingrobot3"
  linearVelocity -1.0558750375379357e-07 9.278270682694983e-06 -9.250093251241248e-08
  angularVelocity -1.834732428301064e-06 -3.591849271018767e-10 2.0940552911058424e-06
}
DEF TRAIL Shape {
  appearance Appearance {
    material Material {
      diffuseColor 0 1 0
      emissiveColor 0 1 0
    }
  }
  geometry DEF TRAIL_LINE_SET IndexedLineSet {
    coord Coordinate {
      point [
        0 0 0, 0 0 0, 0 0 0, 0 0 0, 0 0 0, 0 0 0, 0 0 0, 0 0 0, 0 0 0, 0 0 0, 0 0 0, 0 0 0, 0 0 0, 0 0 0, 0 0 0, 0 0 0, 0 0 0, 0 0 0, 0 0 0, 0 0 0, 0 0 0, 0 0 0, 0 0 0, 0 0 0, 0 0 0, 0 0 0, 0 0 0, 0 0 0, 0 0 0, 0 0 0, 0 0 0, 0 0 0, 0 0 0, 0 0 0, 0 0 0, 0 0 0, 0 0 0, 0 0 0, 0 0 0, 0 0 0, 0 0 0, 0 0 0, 0 0 0, 0 0 0, 0 0 0, 0 0 0, 0 0 0, 0 0 0, 0 0 0, 0 0 0, 0 0 0, 0 0 0, 0 0 0, 0 0 0, 0 0 0, 0 0 0, 0 0 0, 0 0 0, 0 0 0, 0 0 0, 0 0 0, 0 0 0, 0 0 0, 0 0 0, 0 0 0, 0 0 0, 0 0 0, 0 0 0, 0 0 0, 0 0 0, 0 0 0, 0 0 0, 0 0 0, 0 0 0, 0 0 0, 0 0 0, 0 0 0, 0 0 0, 0 0 0, 0 0 0, 0 0 0, 0 0 0, 0 0 0, 0 0 0, 0 0 0, 0 0 0, 0 0 0, 0 0 0, 0 0 0, 0 0 0, 0 0 0, 0 0 0, 0 0 0, 0 0 0, 0 0 0, 0 0 0, 0 0 0, 0 0 0, 0 0 0, 0 0 0, 0 0 0, 0 0 0, 0 0 0, 0 0 0, 0 0 0, 0 0 0, 0 0 0, 0 0 0, 0 0 0, 0 0 0, 0 0 0, 0 0 0, 0 0 0, 0 0 0, 0 0 0, 0 0 0, 0 0 0, 0 0 0, 0 0 0, 0 0 0, 0 0 0, 0 0 0, 0 0 0, 0 0 0, 0 0 0, 0 0 0, 0 0 0, 0 0 0, 0 0 0, 0 0 0, 0 0 0, 0 0 0, 0 0 0, 0 0 0, 0 0 0, 0 0 0, 0 0 0, 0 0 0, 0 0 0, 0 0 0, 0 0 0, 0 0 0, 0 0 0, 0 0 0, 0 0 0, 0 0 0, 0 0 0, 0 0 0, 0 0 0, 0 0 0, 0 0 0, 0 0 0, 0 0 0, 0 0 0, 0 0 0, 0 0 0, 0 0 0, 0 0 0, 0 0 0, 0 0 0, 0 0 0, 0 0 0, 0 0 0, 0 0 0, 0 0 0, 0 0 0, 0 0 0, 0 0 0, 0 0 0, 0 0 0, 0 0 0, 0 0 0, 0 0 0, 0 0 0, 0 0 0, 0 0 0, 0 0 0, 0 0 0, 0 0 0, 0 0 0, 0 0 0, 0 0 0, 0 0 0, 0 0 0, 0 0 0, 0 0 0, 0 0 0, 0 0 0, 0 0 0, 0 0 0, 0 0 0, 0 0 0, 0 0 0, 0 0 0, 0 0 0, 0 0 0, 0 0 0, 0 0 0, 0 0 0, 0 0 0
      ]
    }
    coordIndex [
      0, 1, -1, 1, 2, -1, 2, 2, -1, 0, 0, -1, 0, 0, -1, 0, 0, -1, 0, 0, -1, 0, 0, -1, 0, 0, -1, 0, 0, -1, 0, 0, -1, 0, 0, -1, 0, 0, -1, 0, 0, -1, 0, 0, -1, 0, 0, -1, 0, 0, -1, 0, 0, -1, 0, 0, -1, 0, 0, -1, 0, 0, -1, 0, 0, -1, 0, 0, -1, 0, 0, -1, 0, 0, -1, 0, 0, -1, 0, 0, -1, 0, 0, -1, 0, 0, -1, 0, 0, -1, 0, 0, -1, 0, 0, -1, 0, 0, -1, 0, 0, -1, 0, 0, -1, 0, 0, -1, 0, 0, -1, 0, 0, -1, 0, 0, -1, 0, 0, -1, 0, 0, -1, 0, 0, -1, 0, 0, -1, 0, 0, -1, 0, 0, -1, 0, 0, -1, 0, 0, -1, 0, 0, -1, 0, 0, -1, 0, 0, -1, 0, 0, -1, 0, 0, -1, 0, 0, -1, 0, 0, -1, 0, 0, -1, 0, 0, -1, 0, 0, -1, 0, 0, -1, 0, 0, -1, 0, 0, -1, 0, 0, -1, 0, 0, -1, 0, 0, -1, 0, 0, -1, 0, 0, -1, 0, 0, -1, 0, 0, -1, 0, 0, -1, 0, 0, -1, 0, 0, -1, 0, 0, -1, 0, 0, -1, 0, 0, -1, 0, 0, -1, 0, 0, -1, 0, 0, -1, 0, 0, -1, 0, 0, -1, 0, 0, -1, 0, 0, -1, 0, 0, -1, 0, 0, -1, 0, 0, -1, 0, 0, -1, 0, 0, -1, 0, 0, -1, 0, 0, -1, 0, 0, -1, 0, 0, -1, 0, 0, -1, 0, 0, -1, 0, 0, -1, 0, 0, -1, 0, 0, -1, 0, 0, -1, 0, 0, -1, 0, 0, -1, 0, 0, -1, 0, 0, -1, 0, 0, -1, 0, 0, -1, 0, 0, -1, 0, 0, -1, 0, 0, -1, 0, 0, -1, 0, 0, -1, 0, 0, -1, 0, 0, -1, 0, 0, -1, 0, 0, -1, 0, 0, -1, 0, 0, -1, 0, 0, -1, 0, 0, -1, 0, 0, -1, 0, 0, -1, 0, 0, -1, 0, 0, -1, 0, 0, -1, 0, 0, -1, 0, 0, -1, 0, 0, -1, 0, 0, -1, 0, 0, -1, 0, 0, -1, 0, 0, -1, 0, 0, -1, 0, 0, -1, 0, 0, -1, 0, 0, -1, 0, 0, -1, 0, 0, -1, 0, 0, -1, 0, 0, -1, 0, 0, -1, 0, 0, -1, 0, 0, -1, 0, 0, -1, 0, 0, -1, 0, 0, -1, 0, 0, -1, 0, 0, -1, 0, 0, -1, 0, 0, -1, 0, 0, -1, 0, 0, -1, 0, 0, -1, 0, 0, -1, 0, 0, -1, 0, 0, -1, 0, 0, -1, 0, 0, -1, 0, 0, -1, 0, 0, -1, 0, 0, -1, 0, 0, -1, 0, 0, -1, 0, 0, -1, 0, 0, -1, 0, 0, -1, 0, 0, -1, 0, 0, -1, 0, 0, -1, 0, 0, -1, 0, 0, -1, 0, 0, -1, 0, 0, -1, 0, 0, -1, 0, 0, -1, 0, 0, -1, 0, 0, -1, 0, 0, -1, 0, 0, -1, 0, 0, -1, 0, 0, -1, 0, 0, -1, 0, 0, -1, 0, 0, -1, 0, 0, -1, 0, 0, -1, 0, 0, -1, 0, 0, -1, 0, 0, -1, 0, 0, -1, 0, 0, -1, 0, 0, -1, 0, 0, -1, 0, 0, -1, 0, 0, -1, 0, 0, -1, 0, 0, -1, 0, 0, -1, 0, 0, -1, 0, 0, -1, 0, 0, -1, 0, 0, -1, 0, 0, -1, 0, 0, -1, 0, 0, -1, 0, 0, -1
    ]
  }
}
DEF Supervisior1 Robot {
  translation 0 -1 0
  children [
    DEF emittertoyellowbox Emitter {
      name "emittertoyellowbox"
      channel 7
    }
    Receiver {
      channel 8
    }
    DEF emitter Emitter {
      channel 8
    }
    Receiver {
      name "receiver2"
      channel 3
    }
    Receiver {
      name "receiver1"
      channel 2
    }
    Receiver {
      name "receiver0"
      channel 1
    }
  ]
  controller "matlab_supervisor"
  supervisor TRUE
  cpuConsumption 0.5
}
DEF PIONEER_3AT Pioneer3at {
  hidden position_0_0 3380.631692045649
  hidden position_0_1 3445.516262187919
  hidden position_0_2 3482.594771379286
  hidden position_0_3 3554.6695240612253
  hidden linearVelocity_0 -0.28582130873031547 6.852577390645796e-06 -0.005873667824446091
  hidden angularVelocity_0 1.6023030193349332e-05 -0.002913835202053332 -0.0007938543926145681
  hidden rotation_8 -1 0 0 4.8835182310128
  hidden linearVelocity_8 -0.286461445938656 -0.0001028722435098943 -0.0055110489991297045
  hidden angularVelocity_8 -0.049117041906536645 -0.002847354625934852 2.346843413537237
  hidden rotation_9 -1 0 0 6.188553134605536
  hidden linearVelocity_9 -0.285176246354622 -0.00010318750103984029 -0.00560652765279286
  hidden angularVelocity_9 -0.0516657729178499 -0.002839705082687505 2.470578712144082
  hidden rotation_10 1 0 0 0.3115414447477107
  hidden linearVelocity_10 -0.28658868386054875 0.00010450184708659494 -0.006095703673435711
  hidden angularVelocity_10 -0.05459644113592229 -0.002839357952681114 2.60762787986094
  hidden rotation_11 1 0 0 1.1451900659963954
  hidden linearVelocity_11 -0.2852964663939168 0.00010418659080215799 -0.0061956704590066325
  hidden angularVelocity_11 -0.05742851954335348 -0.0028354135475804304 2.745106866173772
  translation 16.9207983434193 0.10761106606042202 -26.983194488589028
  rotation -0.0003677583081722501 0.9999998691260152 0.0003556708855812817 1.5496964564825821
  controller "ros"
  controllerArgs "--name=pioneer3at"
  extensionSlot [
    DEF RADAR_TARGET Solid {
      translation 0 0.19999999999999998 0
      children [
        Shape {
          appearance PBRAppearance {
            baseColor 1 0 0
            roughness 1
            metalness 0
          }
          geometry DEF BOX Box {
            size 0.04 0.04 0.04
          }
        }
      ]
      name ""
      radarCrossSection 1
    }
    Camera {
      translation 0 0.17 -0.22
      width 256
      height 128
      motionBlur 500
      noise 0.02
    }
    Accelerometer {
      lookupTable [
        -39.24 -39.24 0.005
        39.24 39.24 0.005
      ]
    }
    Gyro {
      lookupTable [
        -50 -50 0.005
        50 50 0.005
      ]
    }
    SickLms291 {
      translation 0 0.23 -0.136
      rotation 0 1 0 6.28318525556045
      noise 0.1
    }
    GPS {
    }
    InertialUnit {
    }
  ]
}
SolidTorus {
  translation -24.704992292002316 -1.0516032489249483e-12 -7.615645548699751
}
SolidTorus {
  translation -24.298614082938528 -7.247535904753022e-13 5.894821041662505
  name "torus(1)"
}
SolidTorus {
  translation -15.099835737317974 -6.963318810448982e-13 24.913351074303673
  name "torus(2)"
}
