#VRML_SIM R2019a utf8
WorldInfo {
  info [
    "Example use of a Radar device."
  ]
}
Viewpoint {
  orientation -0.29157014117136937 0.8976780367065053 0.33039521060702737 1.7986989640074529
  position 48.92297549169167 33.99625570296642 -15.120023938181285
  follow "wall(13)17"
  followOrientation TRUE
}
TexturedBackground {
}
TexturedBackgroundLight {
}
Floor {
  translation 30 0 0
  rotation 0.7071067811865475 0.7071067811865475 0 0
  size 120 60
  tileSize 1 1
  appearance ThreadMetalPlate {
  }
}
SolidTorus {
  translation 64.93577802139102 -1.0942358130705543e-12 4.581355359919176
  name "torus(3)"
}
DEF OUT_WALL Wall {
  translation 58.204489205248386 -2.9416469260468148e-12 5.555860459680742
  rotation 0 1 0 1.5707998847994753
  name "outwall6(7)"
  size 13 2.4 0.2
}
DEF OUT_WALL Wall {
  translation 90.01610721073573 -5.115907697472721e-13 0.02521955938559728
  rotation 0 -1 0 4.712385326405865
  name "outwall3"
  size 60 2.4 0.2
}
DEF OUT_WALL Wall {
  translation 38.11850114797957 -1.9895196601282805e-12 4.9489028097222025
  rotation 0 -1 0 4.712385326405865
  name "outwall4"
  size 50 2.4 0.2
}
DEF OUT_WALL Wall {
  translation 58.53885349408546 -2.0463630789890885e-12 -20.116021857576317
  rotation 0 1 0 3.639545706734746e-06
  name "outwall6"
  size 41 2.4 0.2
}
DEF OUT_WALL Wall {
  translation 79.11112601391267 -3.069544618483633e-12 0.5995430799751702
  rotation 0 1 0 1.5707999615457071
  name "outwall6(1)"
  size 41 2.4 0.2
}
DEF OUT_WALL Wall {
  translation 64.66909011208931 -3.367972567502875e-12 21.09675680699851
  rotation 0 -1 0 6.283181686841351
  name "outwall6(2)"
  size 29 2.4 0.2
}
DEF OUT_WALL Wall {
  translation 71.66121731166321 -2.9416469260468148e-12 2.171535761005348
  rotation 0 1 0 4.712392567158649
  name "outwall6(3)"
  size 20 2.4 0.2
}
DEF OUT_WALL Wall {
  translation 64.77492156143019 -2.9416469260468148e-12 12.071773095761873
  rotation 0 -1 0 3.1415890812005243
  name "outwall6(6)"
  size 13 2.4 0.2
}
DEF OUT_WALL Wall {
  translation 50.02370638457367 -2.9416469260468148e-12 6.580572468498337
  rotation 0 1 0 4.712392567158649
  name "outwall6(5)"
  size 29 2.4 0.2
}
DEF OUT_WALL Wall {
  translation 61.159057737052066 -2.8705926524708048e-12 -7.735770799816559
  rotation 0 1 0 3.141596206799475
  name "outwall6(4)"
  size 21 2.4 0.2
}
DEF OUT_WALL Wall {
  translation 59.87835135727737 -5.115907697472721e-13 -29.855079565529415
  rotation 0 -1 0 6.283181648405866
  name "outwall2"
  size 60 2.4 0.2
}
DEF YELLOW_BOX Solid {
  translation -1.456749798847497 1.2299999999997016 3.155366814255416
  rotation 0 0.9999999999999999 0 3.142388812563314
  children [
    DEF Shape Shape {
      appearance DEF PBR PBRAppearance {
        roughness 0.03934117200000009
        metalness 0
      }
      geometry DEF geometryBox Box {
        size 0.30000000000000004 2.6999999999999997 35
      }
    }
  ]
  name "YELLOW_BOX"
  boundingObject Shape {
    appearance PBRAppearance {
      roughness 1.1102230246251565e-16
      metalness 0
    }
    geometry USE geometryBox
  }
}
SolidRoundedBox {
  translation -17.7943406357252 -3.410605131648481e-13 -26.48373355845466
}
DEF OFFICES Transform {
  rotation 0 1 0 3.14159
  children [
    Panel {
      translation 28.4604 0 -24.5373
      name "panel(35)"
    }
    Panel {
      translation 28.4604 0 -17.2973
      name "panel(36)"
    }
    Panel {
      translation 28.4604 0 -10.2573
      name "panel(37)"
    }
    Panel {
      translation 27.0304 0 -24.5573
      name "panel(38)"
    }
    Panel {
      translation 27.0304 0 -17.2873
      name "panel(39)"
    }
    Panel {
      translation 27.0304 0 -10.2573
      name "panel(40)"
    }
    Panel {
      translation 27.0774 0 -10.6551
      rotation 0 1 0 1.5708
      name "panel(41)"
    }
    Panel {
      translation 27.0774 0 -15.6551
      rotation 0 1 0 1.5708
      name "panel(42)"
    }
    Panel {
      translation 27.0774 0 -17.7651
      rotation 0 1 0 1.5708
      name "panel(43)"
    }
    Panel {
      translation 27.0774 0 -22.8751
      rotation 0 1 0 1.5708
      name "panel(44)"
    }
    Panel {
      translation 27.0774 0 -24.9451
      rotation 0 1 0 1.5708
      name "panel(45)"
    }
    Panel {
      translation 24.2974 0 -10.6551
      rotation 0 1 0 1.5708
      name "panel(46)"
    }
    Panel {
      translation 24.2974 0 -15.6951
      rotation 0 1 0 1.5708
      name "panel(47)"
    }
    Panel {
      translation 24.2974 0 -17.8051
      rotation 0 1 0 1.5708
      name "panel(48)"
    }
    Panel {
      translation 24.2974 0 -22.8551
      rotation 0 1 0 1.5708
      name "panel(49)"
    }
    Panel {
      translation 24.2974 0 -25.0151
      rotation 0 1 0 1.5708
      name "panel(50)"
    }
    Panel {
      translation 21.2474 0 -10.6551
      rotation 0 1 0 1.5708
      name "panel(51)"
    }
    Panel {
      translation 21.2474 0 -15.6951
      rotation 0 1 0 1.5708
      name "panel(52)"
    }
    Panel {
      translation 21.2474 0 -17.7551
      rotation 0 1 0 1.5708
      name "panel(53)"
    }
    Panel {
      translation 21.2474 0 -22.8651
      rotation 0 1 0 1.5708
      name "panel(54)"
    }
    Panel {
      translation 21.27941328705038 -3.552713678800501e-15 -19.54699077672662
      rotation 0 1 0 1.5708
      name "panel(72)"
    }
    Panel {
      translation 21.331013210072776 0 -21.225957180431337
      rotation 0 1 0 1.5708
      name "panel(73)"
    }
    Panel {
      translation 21.242538389055508 -1.4566126083082054e-13 -12.525967859818088
      rotation 0 1 0 1.5708
      name "panel(23)"
    }
    Panel {
      translation 21.243462812112455 -8.881784197001252e-14 -14.137965874591316
      rotation 0 1 0 1.5708
      name "panel(71)"
    }
    Panel {
      translation 21.2474 0 -24.8851
      rotation 0 1 0 1.5708
      name "panel(55)"
    }
    Panel {
      translation 21.2474 0 -26.6151
      rotation 0 1 0 1.5708
      name "panel(56)"
    }
    Panel {
      translation 21.2474 0 -28.2551
      rotation 0 1 0 1.5708
      name "panel(57)"
    }
    Panel {
      translation 25.5604 0 -24.5873
      name "panel(58)"
    }
    Panel {
      translation 25.5604 0 -17.3073
      name "panel(59)"
    }
    Panel {
      translation 25.5604 0 -10.2573
      name "panel(60)"
    }
    Panel {
      translation 24.1004 0 -24.5973
      name "panel(61)"
    }
    Panel {
      translation 24.1004 0 -17.3373
      name "panel(62)"
    }
    Panel {
      translation 24.1004 0 -10.2573
      name "panel(63)"
    }
    Panel {
      translation 22.5504 0 -24.5873
      name "panel(64)"
    }
    Panel {
      translation 22.5504 0 -17.3273
      name "panel(65)"
    }
    Panel {
      translation 22.5504 0 -10.2573
      name "panel(66)"
    }
    Panel {
      translation 20.9704 0 -10.2573
      name "panel(67)"
    }
    Panel {
      translation 20.9704 0 -24.5773
      name "panel(68)"
    }
    Panel {
      translation 20.9704 0 -17.3573
      name "panel(69)"
    }
    WoodenChair {
      translation 28.2877 7.10543e-15 -16.5637
      name "wooden chair(15)"
    }
    WoodenChair {
      translation 28.2877 7.10543e-15 -23.9137
      name "wooden chair(16)"
    }
    WoodenChair {
      translation 28.2877 7.10543e-15 -18.1537
      rotation 0 1 0 3.14159
      name "wooden chair(17)"
    }
    WoodenChair {
      translation 28.2877 7.10543e-15 -25.1237
      rotation 0 1 0 3.14159
      name "wooden chair(18)"
    }
    WoodenChair {
      translation 25.7177 7.10543e-15 -23.8937
      name "wooden chair(19)"
    }
    WoodenChair {
      translation 25.7177 7.10543e-15 -18.0837
      rotation 0 1 0 3.14159
      name "wooden chair(20)"
    }
    WoodenChair {
      translation 28.2877 7.10543e-15 -11.1637
      rotation 0 1 0 3.14159
      name "wooden chair(21)"
    }
    WoodenChair {
      translation 25.7177 7.10543e-15 -25.2037
      rotation 0 1 0 3.14159
      name "wooden chair(22)"
    }
    WoodenChair {
      translation 22.9577 7.10543e-15 -23.8537
      name "wooden chair(23)"
    }
    WoodenChair {
      translation 25.7177 7.10543e-15 -16.5637
      name "wooden chair(24)"
    }
    WoodenChair {
      translation 22.9577 7.10543e-15 -18.0537
      rotation 0 1 0 3.14159
      name "wooden chair(25)"
    }
    WoodenChair {
      translation 25.7177 7.10543e-15 -11.1037
      rotation 0 1 0 3.14159
      name "wooden chair(26)"
    }
    WoodenChair {
      translation 22.9577 7.10543e-15 -25.0837
      rotation 0 1 0 3.14159
      name "wooden chair(27)"
    }
    WoodenChair {
      translation 22.9577 7.10543e-15 -16.5637
      name "wooden chair(28)"
    }
    WoodenChair {
      translation 22.9577 7.10543e-15 -11.1937
      rotation 0 1 0 3.14159
      name "wooden chair(29)"
    }
    Desk {
      translation 28.2877 7.10543e-15 -16.1837
      rotation 0 1 0 6.28319
      name "desk(15)"
    }
    Desk {
      translation 28.2877 7.10543e-15 -25.5337
      rotation 0 1 0 6.28319
      name "desk(16)"
    }
    Desk {
      translation 28.2877 7.10543e-15 -11.5037
      rotation 0 1 0 6.28319
      name "desk(17)"
    }
    Desk {
      translation 28.2877 7.10543e-15 -23.5237
      rotation 0 1 0 6.28319
      name "desk(18)"
    }
    Desk {
      translation 25.6977 7.10543e-15 -16.1837
      rotation 0 1 0 6.28319
      name "desk(19)"
    }
    Desk {
      translation 25.6977 7.10543e-15 -18.4537
      rotation 0 1 0 6.28319
      name "desk(20)"
    }
    Desk {
      translation 25.6977 7.10543e-15 -11.5337
      rotation 0 1 0 6.28319
      name "desk(21)"
    }
    Desk {
      translation 22.9277 7.10543e-15 -16.1837
      rotation 0 1 0 6.28319
      name "desk(22)"
    }
    Desk {
      translation 22.9277 7.10543e-15 -11.5737
      rotation 0 1 0 6.28319
      name "desk(23)"
    }
    Desk {
      translation 25.6977 7.10543e-15 -25.5537
      rotation 0 1 0 6.28319
      name "desk(24)"
    }
    Desk {
      translation 28.2877 7.10543e-15 -18.5337
      rotation 0 1 0 6.28319
      name "desk(25)"
    }
    Desk {
      translation 22.9277 7.10543e-15 -18.4537
      rotation 0 1 0 6.28319
      name "desk(26)"
    }
    Desk {
      translation 25.6977 7.10543e-15 -23.4937
      rotation 0 1 0 6.28319
      name "desk(27)"
    }
    Desk {
      translation 22.9277 7.10543e-15 -23.5337
      rotation 0 1 0 6.28319
      name "desk(28)"
    }
    Desk {
      translation 22.9277 7.10543e-15 -25.4837
      rotation 0 1 0 6.28319
      name "desk(29)"
    }
  ]
}
DEF OFFICES Transform {
  translation 0 0 -40
  rotation 0 1 0 3.14159
  children [
    Panel {
      translation 28.4604 0 -24.5373
      name "panel(1)"
    }
    Panel {
      translation 28.4604 0 -17.2973
      name "panel(2)"
    }
    Panel {
      translation 28.4604 0 -10.2573
      name "panel(3)"
    }
    Panel {
      translation 27.0304 0 -24.5573
      name "panel(4)"
    }
    Panel {
      translation 27.0304 0 -17.2873
      name "panel(5)"
    }
    Panel {
      translation 27.0304 0 -10.2573
      name "panel(6)"
    }
    Panel {
      translation 27.0774 0 -10.6551
      rotation 0 1 0 1.5708
      name "panel(7)"
    }
    Panel {
      translation 27.0774 0 -15.6551
      rotation 0 1 0 1.5708
      name "panel(8)"
    }
    Panel {
      translation 27.0774 0 -17.7651
      rotation 0 1 0 1.5708
      name "panel(9)"
    }
    Panel {
      translation 27.0774 0 -22.8751
      rotation 0 1 0 1.5708
      name "panel(10)"
    }
    Panel {
      translation 24.2974 0 -10.6551
      rotation 0 1 0 1.5708
      name "panel(12)"
    }
    Panel {
      translation 24.2974 0 -15.6951
      rotation 0 1 0 1.5708
      name "panel(13)"
    }
    Panel {
      translation 24.2974 0 -17.8051
      rotation 0 1 0 1.5708
      name "panel(14)"
    }
    Panel {
      translation 24.2974 0 -22.8551
      rotation 0 1 0 1.5708
      name "panel(15)"
    }
    Panel {
      translation 21.2474 0 -10.6551
      rotation 0 1 0 1.5708
      name "panel(17)"
    }
    Panel {
      translation 21.3952621435841 -9.947598300641403e-14 -15.729109202722
      rotation 0 1 0 1.5708
      name "panel(18)"
    }
    Panel {
      translation 21.31044627075896 -9.947598300641403e-14 -14.04973964987817
      rotation 0 1 0 1.5708
      name "panel(21)"
    }
    Panel {
      translation 21.296215948418833 -9.237055564881302e-14 -12.31909108621101
      rotation 0 1 0 1.5708
      name "panel(22)"
    }
    Panel {
      translation 21.2474 0 -17.7551
      rotation 0 1 0 1.5708
      name "panel(19)"
    }
    Panel {
      translation 21.181637678529647 1.0658141036401503e-14 -22.679400631189946
      rotation 0 1 0 1.5708
      name "panel(20)"
    }
    Panel {
      translation 21.187549941856076 7.105427357601002e-15 -21.115898284791456
      rotation 0 1 0 1.5708
      name "panel(11)2"
    }
    Panel {
      translation 21.20323799951621 2.2382096176443156e-13 -19.58767785752691
      rotation 0 1 0 1.5708
      name "panel(16)1"
    }
    Panel {
      translation 25.5604 0 -24.5873
      name "panel(24)"
    }
    Panel {
      translation 25.5604 0 -17.3073
      name "panel(25)"
    }
    Panel {
      translation 25.5604 0 -10.2573
      name "panel(26)"
    }
    Panel {
      translation 24.1004 0 -24.5973
      name "panel(27)"
    }
    Panel {
      translation 24.1004 0 -17.3373
      name "panel(28)"
    }
    Panel {
      translation 24.1004 0 -10.2573
      name "panel(29)"
    }
    Panel {
      translation 22.5504 0 -24.5873
      name "panel(30)"
    }
    Panel {
      translation 22.5504 0 -17.3273
      name "panel(31)"
    }
    Panel {
      translation 22.5504 0 -10.2573
      name "panel(32)"
    }
    Panel {
      translation 20.9704 0 -10.2573
      name "panel(33)"
    }
    Panel {
      translation 20.9704 0 -24.5773
      name "panel(34)"
    }
    Panel {
      translation 20.9704 0 -17.3573
      name "panel(70)"
    }
    WoodenChair {
      translation 28.2877 7.10543e-15 -16.5637
      name "wooden chair(1)"
    }
    WoodenChair {
      translation 28.2877 7.10543e-15 -23.9137
      name "wooden chair(2)"
    }
    WoodenChair {
      translation 28.2877 7.10543e-15 -18.1537
      rotation 0 1 0 3.14159
      name "wooden chair(3)"
    }
    WoodenChair {
      translation 25.7177 7.10543e-15 -23.8937
      name "wooden chair(5)"
    }
    WoodenChair {
      translation 25.7177 7.10543e-15 -18.0837
      rotation 0 1 0 3.14159
      name "wooden chair(6)"
    }
    WoodenChair {
      translation 28.2877 7.10543e-15 -11.1637
      rotation 0 1 0 3.14159
      name "wooden chair(7)"
    }
    WoodenChair {
      translation 22.9577 7.10543e-15 -23.8537
      name "wooden chair(9)"
    }
    WoodenChair {
      translation 25.7177 7.10543e-15 -16.5637
      name "wooden chair(10)"
    }
    WoodenChair {
      translation 22.9577 7.10543e-15 -18.0537
      rotation 0 1 0 3.14159
      name "wooden chair(11)"
    }
    WoodenChair {
      translation 25.7177 7.10543e-15 -11.1037
      rotation 0 1 0 3.14159
      name "wooden chair(12)"
    }
    WoodenChair {
      translation 22.9577 7.10543e-15 -16.5637
      name "wooden chair(14)"
    }
    WoodenChair {
      translation 22.9577 7.10543e-15 -11.1937
      rotation 0 1 0 3.14159
      name "wooden chair(30)"
    }
    Desk {
      translation 28.2877 7.10543e-15 -16.1837
      rotation 0 1 0 6.28319
      name "desk(1)"
    }
    Desk {
      translation 28.2877 7.10543e-15 -11.5037
      rotation 0 1 0 6.28319
      name "desk(3)"
    }
    Desk {
      translation 28.2877 7.10543e-15 -23.5237
      rotation 0 1 0 6.28319
      name "desk(4)"
    }
    Desk {
      translation 25.6977 7.10543e-15 -16.1837
      rotation 0 1 0 6.28319
      name "desk(5)"
    }
    Desk {
      translation 25.6977 7.10543e-15 -18.4537
      rotation 0 1 0 6.28319
      name "desk(6)"
    }
    Desk {
      translation 25.6977 7.10543e-15 -11.5337
      rotation 0 1 0 6.28319
      name "desk(7)"
    }
    Desk {
      translation 22.9277 7.10543e-15 -16.1837
      rotation 0 1 0 6.28319
      name "desk(8)"
    }
    Desk {
      translation 22.9277 7.10543e-15 -11.5737
      rotation 0 1 0 6.28319
      name "desk(9)"
    }
    Desk {
      translation 28.2877 7.10543e-15 -18.5337
      rotation 0 1 0 6.28319
      name "desk(11)"
    }
    Desk {
      translation 22.9277 7.10543e-15 -18.4537
      rotation 0 1 0 6.28319
      name "desk(12)"
    }
    Desk {
      translation 25.6977 7.10543e-15 -23.4937
      rotation 0 1 0 6.28319
      name "desk(13)"
    }
    Desk {
      translation 22.9277 7.10543e-15 -23.5337
      rotation 0 1 0 6.28319
      name "desk(14)"
    }
  ]
}
DEF INTERNAL_WALL Wall {
  translation -20.841722096896945 1.7763568394002505e-15 -0.895663661597073
  name "wall(7)"
  size 18.2 2.7 0.2
}
DEF INTERNAL_WALL Wall {
  translation 23.946530533498798 -1.0006980318164795e-09 -1.3465451669858979
  rotation 0 1 0 1.5707963220000003
  name "wall(13)17"
  size 31.5 2.4 0.2
}
DEF INTERNAL_WALL Wall {
  translation 15.468528286713703 -1.0017070025012588e-09 3.449740374749524
  rotation 0 -1 0 4.7123890043591725
  name "wall(1316"
  size 34.300000000000004 2.4 0.2
}
DEF INTERNAL_WALL Wall {
  translation 6.647038693892407 -1.0007193480985523e-09 0.6961701130002744
  rotation 0 -1 0 4.7123890043591725
  name "wall(1315"
  size 30.6 2.4 0.2
}
DEF INTERNAL_WALL Wall {
  translation 6.580376805989836 -1.0000727542090106e-09 -22.393753290059422
  rotation 0 1 0 1.5707963220000003
  name "wall(13123"
  size 15.9 2.4 0.2
}
DEF INTERNAL_WALL Wall {
  translation 15.504357040818558 -9.999093293797858e-10 -17.205538702438112
  name "wall(1312"
  size 17.099999999999998 2.4 0.2
}
DEF INTERNAL_WALL Wall {
  translation 20.527249419994213 -1.0000976232047622e-09 -24.03975349060693
  name "wall(1311"
  size 18.9 2.4 0.2
}
DEF INTERNAL_WALL Wall {
  translation 14.296785349750635 -1.0003249968802055e-09 20.5767634177167
  name "wall(14)"
  size 31.299999999999997 2.4 0.2
}
DEF EXTERNAL_WALL Wall {
  translation -30 0 0
  rotation 0 1 0 1.5708
  name "wall(12)"
  size 60 2.4 0.2
}
DEF EXTERNAL_WALL Wall {
  translation 29.840857291770405 -5.115907697472721e-13 -4.748827247581081
  rotation 0 1 0 1.5708
  name "wall(14)44"
  size 51 2.4 0.2
}
DEF OUT_WALL Wall {
  translation 60.23640877327777 -5.115907697472721e-13 29.96804236086333
  rotation 0 -1 0 6.283181648405866
  name "outwall1"
  size 60 2.4 0.2
}
DEF EXTERNAL_WALL Wall {
  translation -27.45 0 30
  name "wall(10)"
  size 5.3 2.4 0.2
}
DEF DOUBLE_WINDOW Transform {
  translation -24 0 30
  children [
    Window {
      translation -0.4 0 0
      name "window(21)"
    }
    Window {
      translation 0.4 0 0
      name "window(22)"
    }
  ]
}
DEF DOUBLE_WINDOW Transform {
  translation -12 0 30
  children [
    Window {
      translation -0.4 0 0
      name "window(19)"
    }
    Window {
      translation 0.4 0 0
      name "window(20)"
    }
  ]
}
DEF DOUBLE_WINDOW Transform {
  translation 12 0 30
}
DEF DOUBLE_WINDOW Transform {
  translation 24 0 30
  children [
    Window {
      translation -0.4 0 0
      name "window(15)"
    }
    Window {
      translation 0.4 0 0
      name "window(16)"
    }
  ]
}
DEF EXTERNAL_WALL Wall {
  translation -18 0 30
  name "wall(8)"
  size 10.4 2.4 0.2
}
DEF EXTERNAL_WALL Wall {
  translation 27.45 0 30
  name "wall(9)"
  size 5.3 2.4 0.2
}
DEF EXTERNAL_WALL Wall {
  translation 18 0 30
  name "wall(6)"
  size 10.4 2.4 0.2
}
DEF EXTERNAL_WALL Wall {
  translation 0.7995902474737342 -2.5579538487363607e-13 29.963116458244034
  name "wall(5)"
  size 24 2.4 0.2
}
DEF DOUBLE_WINDOW Transform {
  translation -12 0 -30
  children [
    Window {
      translation -0.4 0 0
      name "window(11)"
    }
    Window {
      translation 0.4 0 0
      name "window(12)"
    }
  ]
}
DEF DOUBLE_WINDOW Transform {
  translation -24 0 -30
  children [
    Window {
      translation -0.4 0 0
      name "window(13)"
    }
    Window {
      translation 0.4 0 0
      name "window(14)"
    }
  ]
}
DEF DOUBLE_WINDOW Transform {
  translation 24 0 -30
  children [
    Window {
      translation -0.4 0 0
      name "window(7)"
    }
    Window {
      translation 0.4 0 0
      name "window(8)"
    }
  ]
}
DEF EXTERNAL_WALL Wall {
  translation -27.45 0 -30
  name "wall(4)"
  size 5.3 2.4 0.2
}
DEF EXTERNAL_WALL Wall {
  translation 27.45 0 -30
  name "wall(3)"
  size 5.3 2.4 0.2
}
DEF EXTERNAL_WALL Wall {
  translation -18 0 -30
  name "wall(2)"
  size 10.4 2.4 0.2
}
DEF EXTERNAL_WALL Wall {
  translation 18 0 -30
  name "wall(1)"
  size 10.4 2.4 0.2
}
DEF EXTERNAL_WALL Wall {
  translation 0 0 -30
  size 22.4 2.4 0.2
}
Shape {
  appearance PBRAppearance {
    baseColor 0 0 1
    roughness 1
    metalness 0
  }
  geometry IndexedFaceSet {
    coord Coordinate {
      point [
        0.21 0 0.07
        0.09 0 0.22
        0.25 0 0.26
        0.21 0.0001 0.07
        0.09 0.0001 0.22
        0.25 0.0001 0.26
      ]
    }
    coordIndex [
      2, 1, 0, -1, 3, 4, 5, -1, 0, 1
      4, 3, -1, 1, 2, 5, 4, -1, 2, 0
      3, 5, -1
    ]
  }
}
DEF MyBot1 Robot {
  translation 27.999999793742376 -0.00044264672009044354 27.99999984219033
  rotation 0.02467235518677575 -0.9996258023728838 -0.01181228681948517 -0.8936434632449604
  children [
    Emitter {
      channel 1
      baudRate 115200
    }
    Transform {
      translation 0 0.0415 0
      children [
        Shape {
          appearance PBRAppearance {
            baseColor 0.0820075 0.364731 0.8
            roughness 1
            metalness 0
          }
          geometry DEF BODY Cylinder {
            height 0.08
            radius 0.045
          }
        }
      ]
    }
    HingeJoint {
      jointParameters HingeJointParameters {
        position 76.03201001946653
        axis -1 0 0
        anchor 0 0.025 0
      }
      device [
        RotationalMotor {
          name "left wheel motor1"
          consumptionFactor 70
        }
        PositionSensor {
          name "left wheel sensor"
        }
      ]
      endPoint Solid {
        translation -0.04499997587308602 0.025212115180126716 -1.5429881410051978e-06
        rotation -0.9999998918030001 0.00038063692355777155 -0.0002674126410691264 1.931646751708349
        children [
          DEF WHEEL Transform {
            rotation 0 0 1 1.57
            children [
              Shape {
                appearance PBRAppearance {
                  baseColor 1 0 0
                  roughness 1
                  metalness 0
                }
                geometry Cylinder {
                  height 0.01
                  radius 0.025
                }
              }
            ]
          }
        ]
        name "left wheel"
        boundingObject USE WHEEL
        physics DEF PHYSICS_WHEEL Physics {
          density -1
          mass 0.05
        }
        linearVelocity 8.703688395813737e-08 -1.4272408698448543e-07 7.006002093074107e-08
        angularVelocity 2.9737239611088903e-06 -4.875637904821796e-10 -3.6956354645511137e-06
      }
    }
    HingeJoint {
      jointParameters HingeJointParameters {
        position 76.03204472494872
        axis -1 0 0
        anchor 0 0.025 0
      }
      device [
        RotationalMotor {
          name "right wheel motor1"
          consumptionFactor 70
        }
        PositionSensor {
          name "right wheel sensor"
        }
      ]
      endPoint Solid {
        translation 0.044999989753531276 0.025212064462487558 -1.5433734616981124e-06
        rotation -0.9999999132084254 -0.00038147673019648076 0.00016750715193260328 2.3290012582286885
        children [
          USE WHEEL
        ]
        name "right wheel"
        boundingObject USE WHEEL
        physics USE PHYSICS_WHEEL
        linearVelocity 8.700985290811891e-08 -1.4267980269262067e-07 7.003722072675355e-08
        angularVelocity 2.973742420559583e-06 -1.3965720391190415e-09 -3.6956639335986765e-06
      }
    }
    DistanceSensor {
      translation -0.02 0.063 -0.042
      rotation 0 1 0 2.07
      children [
        DEF SENSOR Transform {
          rotation 0 0 1 1.57
          children [
            Shape {
              appearance PBRAppearance {
                baseColor 0.975691 0.981481 0.0252992
                roughness 1
                metalness 0
              }
              geometry Cylinder {
                height 0.004
                radius 0.008
              }
            }
          ]
        }
      ]
      name "ds0"
      lookupTable [
        0 1024 0
        0.05 1024 0
        0.15 0 0
      ]
      numberOfRays 2
      aperture 1
    }
    DistanceSensor {
      translation 0.02 0.063 -0.042
      rotation 0 1 0 1.07
      children [
        USE SENSOR
      ]
      name "ds1"
      lookupTable [
        0 1024 0
        0.05 1024 0
        0.15 0 0
      ]
      numberOfRays 2
      aperture 1
    }
    DEF SMILE Transform {
      translation 0 0.025 -0.036
      rotation 0.7745972408364944 0.44721228048294853 0.4472139204829502 1.8234794
      children [
        Shape {
          appearance PBRAppearance {
            baseColor 0.721569 0.290196 0.290196
            roughness 1
            metalness 0
          }
          geometry Cylinder {
            height 0.018
            radius 0.009
            subdivision 3
          }
        }
      ]
    }
    Radar {
      translation 0 0.1 0
      children [
        Shape {
          appearance PBRAppearance {
            baseColor 0.403922 0.403922 0.403922
            roughness 1
            metalness 0
          }
          geometry DEF BOX Box {
            size 0.04 0.04 0.04
          }
        }
      ]
      minRange 0.01
      maxRange 80
      horizontalFieldOfView 2
      verticalFieldOfView 0.5
      frequency 28
      transmittedPower 28
    }
  ]
  name "MyBot1"
  boundingObject Transform {
    translation 0 0.0415 0
    children [
      USE BODY
    ]
  }
  physics Physics {
    density -1
    mass 0.5
  }
  controller "unmovingrobot1"
  battery [
    0, 100, 30
  ]
  cpuConsumption 5
  linearVelocity 1.1654478832977865e-07 -1.415371821167459e-07 9.374549854061885e-08
  angularVelocity 1.864282764893088e-06 -9.376261669618486e-10 -2.3164951303659204e-06
}
DEF MyBot2 Robot {
  translation 28.999999951103824 -0.0004426479879969039 -28.99999974780482
  rotation 0.0018735368659504124 -0.9999283922009147 -0.011819489418161985 -2.8275241532973845
  children [
    Emitter {
      name "emitter2"
      channel 2
      baudRate 115200
    }
    Transform {
      translation 0 0.0415 0
      children [
        Shape {
          appearance PBRAppearance {
            baseColor 0.0820075 0.364731 0.8
            roughness 1
            metalness 0
          }
          geometry DEF BODY Cylinder {
            height 0.08
            radius 0.045
          }
        }
      ]
    }
    HingeJoint {
      jointParameters HingeJointParameters {
        position 76.0319943543041
        axis -1 0 0
        anchor 0 0.025 0
      }
      device [
        RotationalMotor {
          name "left wheel motor1"
          consumptionFactor 70
        }
        PositionSensor {
          name "left wheel sensor"
        }
      ]
      endPoint Solid {
        translation -0.04499995669495851 0.025212115598393252 -1.4988248070696674e-06
        rotation -0.9999998918133463 0.00038067397024884496 -0.00026732120033818235 1.9316357393720418
        children [
          DEF WHEEL Transform {
            rotation 0 0 1 1.57
            children [
              Shape {
                appearance PBRAppearance {
                  baseColor 1 0 0
                  roughness 1
                  metalness 0
                }
                geometry Cylinder {
                  height 0.01
                  radius 0.025
                }
              }
            ]
          }
        ]
        name "left wheel"
        boundingObject USE WHEEL
        physics DEF PHYSICS_WHEEL Physics {
          density -1
          mass 0.05
        }
        linearVelocity 3.461271686923569e-08 -1.4268474082251435e-07 -1.063180505980577e-07
        angularVelocity -4.5123410677932955e-06 -3.393499151512425e-09 -1.4653361901111466e-06
      }
    }
    HingeJoint {
      jointParameters HingeJointParameters {
        position 76.03196470886355
        axis -1 0 0
        anchor 0 0.025 0
      }
      device [
        RotationalMotor {
          name "right wheel motor1"
          consumptionFactor 70
        }
        PositionSensor {
          name "right wheel sensor"
        }
      ]
      endPoint Solid {
        translation 0.04499997063249224 0.025212064872950326 -1.4989540662640663e-06
        rotation -0.9999999132146101 -0.0003814925187302536 0.0001674342567321184 2.328925902631159
        children [
          USE WHEEL
        ]
        name "right wheel"
        boundingObject USE WHEEL
        physics USE PHYSICS_WHEEL
        linearVelocity 3.4561365330920474e-08 -1.4273440193343868e-07 -1.061626681932458e-07
        angularVelocity -4.512484628204794e-06 -4.29970704177505e-09 -1.4653788435200727e-06
      }
    }
    DistanceSensor {
      translation -0.02 0.063 -0.042
      rotation 0 1 0 2.07
      children [
        DEF SENSOR Transform {
          rotation 0 0 1 1.57
          children [
            Shape {
              appearance PBRAppearance {
                baseColor 0.975691 0.981481 0.0252992
                roughness 1
                metalness 0
              }
              geometry Cylinder {
                height 0.004
                radius 0.008
              }
            }
          ]
        }
      ]
      name "ds0"
      lookupTable [
        0 1024 0
        0.05 1024 0
        0.15 0 0
      ]
      numberOfRays 2
      aperture 1
    }
    DistanceSensor {
      translation 0.02 0.063 -0.042
      rotation 0 1 0 1.07
      children [
        USE SENSOR
      ]
      name "ds1"
      lookupTable [
        0 1024 0
        0.05 1024 0
        0.15 0 0
      ]
      numberOfRays 2
      aperture 1
    }
    DEF SMILE Transform {
      translation 0 0.025 -0.036
      rotation 0.7745972408364944 0.44721228048294853 0.4472139204829502 1.8234794
      children [
        Shape {
          appearance PBRAppearance {
            baseColor 0.721569 0.290196 0.290196
            roughness 1
            metalness 0
          }
          geometry Cylinder {
            height 0.018
            radius 0.009
            subdivision 3
          }
        }
      ]
    }
    Radar {
      translation 0 0.1 0
      rotation 0 1 0 6.021385901
      children [
        Shape {
          appearance PBRAppearance {
            baseColor 0.403922 0.403922 0.403922
            roughness 1
            metalness 0
          }
          geometry DEF BOX Box {
            size 0.04 0.04 0.04
          }
        }
      ]
      minRange 0.01
      maxRange 78
      horizontalFieldOfView 2
      verticalFieldOfView 0.4
    }
  ]
  name "MyBot2"
  boundingObject Transform {
    translation 0 0.0415 0
    children [
      USE BODY
    ]
  }
  physics Physics {
    density -1
    mass 0.5
  }
  controller "unmovingrobot2"
  cpuConsumption 0.5
  linearVelocity 4.605655490141454e-08 -1.4154443209687978e-07 -1.4236568349484007e-07
  angularVelocity -2.828982592754405e-06 -3.8507650276540355e-09 -9.185120058912379e-07
}
DEF DOUBLE_WINDOW Transform {
  translation 12 0 -30
  children [
    Window {
      translation -0.4 0 0
      name "window(9)"
    }
    Window {
      translation 0.4 0 0
      name "window(10)"
    }
  ]
}
DEF MyBot3 Robot {
  translation -25.999999803303837 -0.0004427057089784886 -26.99999983210443
  rotation -0.005357328241038177 -0.9999157845985216 -0.011820437590911692 2.2902699651971172
  children [
    Emitter {
      name "emitter3"
      channel 3
      baudRate 115200
    }
    Transform {
      translation 0 0.0415 0
      children [
        Shape {
          appearance PBRAppearance {
            baseColor 0.0820075 0.364731 0.8
            roughness 1
            metalness 0
          }
          geometry DEF BODY Cylinder {
            height 0.08
            radius 0.045
          }
        }
      ]
    }
    HingeJoint {
      jointParameters HingeJointParameters {
        position 76.0319916476497
        axis -1 0 0
        anchor 0 0.025 0
      }
      device [
        RotationalMotor {
          name "left wheel motor1"
          consumptionFactor 70
        }
        PositionSensor {
          name "left wheel sensor"
        }
      ]
      endPoint Solid {
        translation -0.04499995633981136 0.02521211546560734 1.5100651215739361e-06
        rotation -0.999999891910742 0.00038451677689602186 -0.00026139118725228316 1.9329365003398622
        children [
          DEF WHEEL Transform {
            rotation 0 0 1 1.57
            children [
              Shape {
                appearance PBRAppearance {
                  baseColor 1 0 0
                  roughness 1
                  metalness 0
                }
                geometry Cylinder {
                  height 0.01
                  radius 0.025
                }
              }
            ]
          }
        ]
        name "left wheel"
        boundingObject USE WHEEL
        physics DEF PHYSICS_WHEEL Physics {
          density -1
          mass 0.05
        }
        linearVelocity -8.399216877995286e-08 -1.4272084229112838e-07 -7.361861677712923e-08
        angularVelocity -3.1252908684857957e-06 -1.4212071570387993e-10 3.566447579527854e-06
      }
    }
    HingeJoint {
      jointParameters HingeJointParameters {
        position 76.03193912978762
        axis -1 0 0
        anchor 0 0.025 0
      }
      device [
        RotationalMotor {
          name "right wheel motor1"
          consumptionFactor 70
        }
        PositionSensor {
          name "right wheel sensor"
        }
      ]
      endPoint Solid {
        translation 0.04499997016563727 0.025212064861763913 1.5105843876374742e-06
        rotation -0.9999999132624485 -0.0003838845016679267 0.00016157903580532932 2.3302041088595447
        children [
          USE WHEEL
        ]
        name "right wheel"
        boundingObject USE WHEEL
        physics USE PHYSICS_WHEEL
        linearVelocity -8.397760891116587e-08 -1.4266525091950765e-07 -7.360475247110689e-08
        angularVelocity -3.1253016445608095e-06 -1.051654388081225e-09 3.566464956848e-06
      }
    }
    DistanceSensor {
      translation -0.02 0.063 -0.042
      rotation 0 1 0 2.8553981609999997
      children [
        DEF SENSOR Transform {
          rotation 0 0 1 1.57
          children [
            Shape {
              appearance PBRAppearance {
                baseColor 0.975691 0.981481 0.0252992
                roughness 1
                metalness 0
              }
              geometry Cylinder {
                height 0.004
                radius 0.008
              }
            }
          ]
        }
      ]
      name "ds0"
      lookupTable [
        0 1024 0
        0.05 1024 0
        0.15 0 0
      ]
      numberOfRays 2
      aperture 1
    }
    DistanceSensor {
      translation 0.02 0.063 -0.042
      rotation 0 1 0 1.07
      children [
        USE SENSOR
      ]
      name "ds1"
      lookupTable [
        0 1024 0
        0.05 1024 0
        0.15 0 0
      ]
      numberOfRays 2
      aperture 1
    }
    DEF SMILE Transform {
      translation 0 0.025 -0.036
      rotation 0.7745972408364944 0.44721228048294853 0.4472139204829502 1.8234794
      children [
        Shape {
          appearance PBRAppearance {
            baseColor 0.721569 0.290196 0.290196
            roughness 1
            metalness 0
          }
          geometry Cylinder {
            height 0.018
            radius 0.009
            subdivision 3
          }
        }
      ]
    }
    DEF Radar Radar {
      translation 0 0.1 0
      rotation 0 1 0 6.283185307179586
      children [
        Shape {
          appearance PBRAppearance {
            baseColor 0.403922 0.403922 0.403922
            roughness 1
            metalness 0
          }
          geometry DEF BOX Box {
            size 0.04 0.04 0.04
          }
        }
      ]
      minRange 0.01
      maxRange 79.23140049567527
      horizontalFieldOfView 2
      transmittedPower 77
    }
  ]
  name "MyBot3"
  boundingObject Transform {
    translation 0 0.0415 0
    children [
      USE BODY
    ]
  }
  physics Physics {
    density -1
    mass 0.5
  }
  controller "unmovingrobot3"
  linearVelocity -1.1244882156601446e-07 -1.415143033796389e-07 -9.852717975599594e-08
  angularVelocity -1.9590435802242277e-06 -5.913910066766206e-10 2.235154876557425e-06
}
DEF TRAIL Shape {
  appearance Appearance {
    material Material {
      diffuseColor 0 1 0
      emissiveColor 0 1 0
    }
  }
  geometry DEF TRAIL_LINE_SET IndexedLineSet {
    coord Coordinate {
      point [
        0 0 0, 0 0 0, 0 0 0, 0 0 0, 0 0 0, 0 0 0, 0 0 0, 0 0 0, 0 0 0, 0 0 0, 0 0 0, 0 0 0, 0 0 0, 0 0 0, 0 0 0, 0 0 0, 0 0 0, 0 0 0, 0 0 0, 0 0 0, 0 0 0, 0 0 0, 0 0 0, 0 0 0, 0 0 0, 0 0 0, 0 0 0, 0 0 0, 0 0 0, 0 0 0, 0 0 0, 0 0 0, 0 0 0, 0 0 0, 0 0 0, 0 0 0, 0 0 0, 0 0 0, 0 0 0, 0 0 0, 0 0 0, 0 0 0, 0 0 0, 0 0 0, 0 0 0, 0 0 0, 0 0 0, 0 0 0, 0 0 0, 0 0 0, 0 0 0, 0 0 0, 0 0 0, 0 0 0, 0 0 0, 0 0 0, 0 0 0, 0 0 0, 0 0 0, 0 0 0, 0 0 0, 0 0 0, 0 0 0, 0 0 0, 0 0 0, 0 0 0, 0 0 0, 0 0 0, 0 0 0, 0 0 0, 0 0 0, 0 0 0, 0 0 0, 0 0 0, 0 0 0, 0 0 0, 0 0 0, 0 0 0, 0 0 0, 0 0 0, 0 0 0, 0 0 0, 0 0 0, 0 0 0, 0 0 0, 0 0 0, 0 0 0, 0 0 0, 0 0 0, 0 0 0, 0 0 0, 0 0 0, 0 0 0, 0 0 0, 0 0 0, 0 0 0, 0 0 0, 0 0 0, 0 0 0, 0 0 0, 0 0 0, 0 0 0, 0 0 0, 0 0 0, 0 0 0, 0 0 0, 0 0 0, 0 0 0, 0 0 0, 0 0 0, 0 0 0, 0 0 0, 0 0 0, 0 0 0, 0 0 0, 0 0 0, 0 0 0, 0 0 0, 0 0 0, 0 0 0, 0 0 0, 0 0 0, 0 0 0, 0 0 0, 0 0 0, 0 0 0, 0 0 0, 0 0 0, 0 0 0, 0 0 0, 0 0 0, 0 0 0, 0 0 0, 0 0 0, 0 0 0, 0 0 0, 0 0 0, 0 0 0, 0 0 0, 0 0 0, 0 0 0, 0 0 0, 0 0 0, 0 0 0, 0 0 0, 0 0 0, 0 0 0, 0 0 0, 0 0 0, 0 0 0, 0 0 0, 0 0 0, 0 0 0, 0 0 0, 0 0 0, 0 0 0, 0 0 0, 0 0 0, 0 0 0, 0 0 0, 0 0 0, 0 0 0, 0 0 0, 0 0 0, 0 0 0, 0 0 0, 0 0 0, 0 0 0, 0 0 0, 0 0 0, 0 0 0, 0 0 0, 0 0 0, 0 0 0, 0 0 0, 0 0 0, 0 0 0, 0 0 0, 0 0 0, 0 0 0, 0 0 0, 0 0 0, 0 0 0, 0 0 0, 0 0 0, 0 0 0, 0 0 0, 0 0 0, 0 0 0, 0 0 0, 0 0 0, 0 0 0, 0 0 0, 0 0 0, 0 0 0, 0 0 0, 0 0 0, 0 0 0, 0 0 0, 0 0 0
      ]
    }
    coordIndex [
      0, 1, -1, 1, 2, -1, 2, 2, -1, 0, 0, -1, 0, 0, -1, 0, 0, -1, 0, 0, -1, 0, 0, -1, 0, 0, -1, 0, 0, -1, 0, 0, -1, 0, 0, -1, 0, 0, -1, 0, 0, -1, 0, 0, -1, 0, 0, -1, 0, 0, -1, 0, 0, -1, 0, 0, -1, 0, 0, -1, 0, 0, -1, 0, 0, -1, 0, 0, -1, 0, 0, -1, 0, 0, -1, 0, 0, -1, 0, 0, -1, 0, 0, -1, 0, 0, -1, 0, 0, -1, 0, 0, -1, 0, 0, -1, 0, 0, -1, 0, 0, -1, 0, 0, -1, 0, 0, -1, 0, 0, -1, 0, 0, -1, 0, 0, -1, 0, 0, -1, 0, 0, -1, 0, 0, -1, 0, 0, -1, 0, 0, -1, 0, 0, -1, 0, 0, -1, 0, 0, -1, 0, 0, -1, 0, 0, -1, 0, 0, -1, 0, 0, -1, 0, 0, -1, 0, 0, -1, 0, 0, -1, 0, 0, -1, 0, 0, -1, 0, 0, -1, 0, 0, -1, 0, 0, -1, 0, 0, -1, 0, 0, -1, 0, 0, -1, 0, 0, -1, 0, 0, -1, 0, 0, -1, 0, 0, -1, 0, 0, -1, 0, 0, -1, 0, 0, -1, 0, 0, -1, 0, 0, -1, 0, 0, -1, 0, 0, -1, 0, 0, -1, 0, 0, -1, 0, 0, -1, 0, 0, -1, 0, 0, -1, 0, 0, -1, 0, 0, -1, 0, 0, -1, 0, 0, -1, 0, 0, -1, 0, 0, -1, 0, 0, -1, 0, 0, -1, 0, 0, -1, 0, 0, -1, 0, 0, -1, 0, 0, -1, 0, 0, -1, 0, 0, -1, 0, 0, -1, 0, 0, -1, 0, 0, -1, 0, 0, -1, 0, 0, -1, 0, 0, -1, 0, 0, -1, 0, 0, -1, 0, 0, -1, 0, 0, -1, 0, 0, -1, 0, 0, -1, 0, 0, -1, 0, 0, -1, 0, 0, -1, 0, 0, -1, 0, 0, -1, 0, 0, -1, 0, 0, -1, 0, 0, -1, 0, 0, -1, 0, 0, -1, 0, 0, -1, 0, 0, -1, 0, 0, -1, 0, 0, -1, 0, 0, -1, 0, 0, -1, 0, 0, -1, 0, 0, -1, 0, 0, -1, 0, 0, -1, 0, 0, -1, 0, 0, -1, 0, 0, -1, 0, 0, -1, 0, 0, -1, 0, 0, -1, 0, 0, -1, 0, 0, -1, 0, 0, -1, 0, 0, -1, 0, 0, -1, 0, 0, -1, 0, 0, -1, 0, 0, -1, 0, 0, -1, 0, 0, -1, 0, 0, -1, 0, 0, -1, 0, 0, -1, 0, 0, -1, 0, 0, -1, 0, 0, -1, 0, 0, -1, 0, 0, -1, 0, 0, -1, 0, 0, -1, 0, 0, -1, 0, 0, -1, 0, 0, -1, 0, 0, -1, 0, 0, -1, 0, 0, -1, 0, 0, -1, 0, 0, -1, 0, 0, -1, 0, 0, -1, 0, 0, -1, 0, 0, -1, 0, 0, -1, 0, 0, -1, 0, 0, -1, 0, 0, -1, 0, 0, -1, 0, 0, -1, 0, 0, -1, 0, 0, -1, 0, 0, -1, 0, 0, -1, 0, 0, -1, 0, 0, -1, 0, 0, -1, 0, 0, -1, 0, 0, -1, 0, 0, -1, 0, 0, -1, 0, 0, -1, 0, 0, -1, 0, 0, -1, 0, 0, -1, 0, 0, -1, 0, 0, -1, 0, 0, -1, 0, 0, -1, 0, 0, -1, 0, 0, -1, 0, 0, -1, 0, 0, -1, 0, 0, -1, 0, 0, -1, 0, 0, -1, 0, 0, -1, 0, 0, -1, 0, 0, -1, 0, 0, -1, 0, 0, -1, 0, 0, -1
    ]
  }
}
DEF Supervisior1 Robot {
  translation 0 -1 0
  children [
    DEF emittertoyellowbox Emitter {
      name "emittertoyellowbox"
      channel 7
    }
    Receiver {
      channel 8
    }
    DEF emitter Emitter {
      channel 8
    }
    Receiver {
      name "receiver2"
      channel 3
    }
    Receiver {
      name "receiver1"
      channel 2
    }
    Receiver {
      name "receiver0"
      channel 1
    }
  ]
  controller "matlab_supervisor"
  supervisor TRUE
  cpuConsumption 0.5
}
DEF PIONEER_3AT Pioneer3at {
  hidden position_0_0 3320.7956290594484
  hidden position_0_1 3381.5031059125404
  hidden position_0_2 3416.13421642521
  hidden position_0_3 3483.5678313838484
  hidden linearVelocity_0 0.0009416658810555194 1.6500126090902223e-06 0.289468938108116
  hidden angularVelocity_0 0.0010245335162643778 0.0004373838264615495 -0.0011250809137393293
  hidden rotation_8 1 0 0 4.68706229775094
  hidden linearVelocity_8 0.0008003894993803914 0.00011247198201336415 0.28898581840918175
  hidden angularVelocity_8 2.373222653725142 -0.0003508456640437318 -0.007425641449812975
  hidden rotation_9 -1 0 0 5.007249931022791
  hidden linearVelocity_9 0.0007927081529256159 -0.0001028546484634333 0.28938938877032433
  hidden angularVelocity_9 2.3738309193240243 -0.00034990922114285937 -0.007427994483192166
  hidden rotation_10 1 0 0 3.940243327027935
  hidden linearVelocity_10 0.0009201348100401287 -1.5913534329530496e-05 0.289583177873507
  hidden angularVelocity_10 2.6367373910538263 -0.00044005872858325526 -0.008129109408757553
  hidden rotation_11 -1 0 0 3.15134094278181
  hidden linearVelocity_11 0.0009091843821967514 1.037739503663242e-05 0.2888981135891069
  hidden angularVelocity_11 2.637408068968224 -0.00043860047538154374 -0.00813003224833509
  translation 26.86561606084556 0.1076838070075216 -5.052387926711128
  rotation 0.00017681101663059355 0.9999998868558764 0.00044161759345378806 -3.1389362340124687
  controller "ros"
  controllerArgs "--name=pioneer3at"
  extensionSlot [
    DEF RADAR_TARGET Solid {
      translation 0 0.19999999999999998 0
      children [
        Shape {
          appearance PBRAppearance {
            baseColor 1 0 0
            roughness 1
            metalness 0
          }
          geometry DEF BOX Box {
            size 0.04 0.04 0.04
          }
        }
      ]
      name ""
      radarCrossSection 1
    }
    Camera {
      translation 0 0.17 -0.22
      width 256
      height 128
      motionBlur 500
      noise 0.02
    }
    Accelerometer {
      lookupTable [
        -39.24 -39.24 0.005
        39.24 39.24 0.005
      ]
    }
    Gyro {
      lookupTable [
        -50 -50 0.005
        50 50 0.005
      ]
    }
    SickLms291 {
      translation 0 0.23 -0.136
      rotation 0 1 0 6.28318525556045
      noise 0.1
    }
    GPS {
    }
    InertialUnit {
    }
  ]
}
SolidTorus {
  translation -24.704992292002316 -1.0516032489249483e-12 -7.615645548699751
}
SolidTorus {
  translation -24.298614082938528 -7.247535904753022e-13 5.894821041662505
  name "torus(1)"
}
SolidTorus {
  translation -15.099835737317974 -6.963318810448982e-13 24.913351074303673
  name "torus(2)"
}
